{"t":19.0645,"stream":"btcusdt@depth20@100ms","data":{"lastUpdateId":97344798630,"bids":[["62641.14000000","3.73356000"],["62641.13000000","0.00034000"],["62641.12000000","0.00016000"],["62640.96000000","0.00018000"],["62640.95000000","0.63005000"],["62640.90000000","0.00008000"],["62640.35000000","0.00018000"],["62640.34000000","0.30181000"],["62640.32000000","0.00009000"],["62640.01000000","0.02755000"],["62640.00000000","1.91799000"],["62639.99000000","0.54430000"],["62639.98000000","0.00449000"],["62639.86000000","0.00400000"],["62639.83000000","0.00016000"],["62639.77000000","0.04091000"],["62638.51000000","0.00816000"],["62638.49000000","0.03966000"],["62638.44000000","0.00009000"],["62638.42000000","0.00008000"]],"asks":[["62641.15000000","0.82110000"],["62641.16000000","0.00115000"],["62641.17000000","0.00016000"],["62641.98000000","0.00008000"],["62641.99000000","0.00041000"],["62642.00000000","0.03469000"],["62642.19000000","0.00009000"],["62642.25000000","0.00008000"],["62642.40000000","0.00018000"],["62642.41000000","0.07781000"],["62642.81000000","0.00009000"],["62642.83000000","0.00256000"],["62642.91000000","0.00032000"],["62643.09000000","0.00016000"],["62643.20000000","0.00008000"],["62643.56000000","0.00018000"],["62643.57000000","0.17274000"],["62643.76000000","0.00008000"],["62643.97000000","0.00030000"],["62643.99000000","0.00018000"]]}}
{"t":19.1316,"stream":"btcusdt@aggTrade","data":{"e":"aggTrade","E":1783948021780,"s":"BTCUSDT","a":4013160613,"p":"62641.14000000","q":"0.00059000","f":6501833933,"l":6501833933,"T":1783948021779,"m":true,"M":true}}
{"t":19.1648,"stream":"btcusdt@depth@100ms","data":{"e":"depthUpdate","E":1783948021814,"s":"BTCUSDT","U":97344798631,"u":97344798646,"b":[["62641.14000000","3.73297000"],["62640.34000000","0.30016000"],["62627.12000000","0.00008000"],["56377.03000000","0.00460000"],["56377.02000000","0.00010000"]],"a":[["62652.19000000","0.00008000"],["62764.31000000","0.15970000"],["68905.26000000","0.00008000"]]}}
{"t":19.165,"stream":"btcusdt@depth20@100ms","data":{"lastUpdateId":97344798646,"bids":[["62641.14000000","3.73297000"],["62641.13000000","0.00034000"],["62641.12000000","0.00016000"],["62640.96000000","0.00018000"],["62640.95000000","0.63005000"],["62640.90000000","0.00008000"],["62640.35000000","0.00018000"],["62640.34000000","0.30016000"],["62640.32000000","0.00009000"],["62640.01000000","0.02755000"],["62640.00000000","1.91799000"],["62639.99000000","0.54430000"],["62639.98000000","0.00449000"],["62639.86000000","0.00400000"],["62639.83000000","0.00016000"],["62639.77000000","0.04091000"],["62638.51000000","0.00816000"],["62638.49000000","0.03966000"],["62638.44000000","0.00009000"],["62638.42000000","0.00008000"]],"asks":[["62641.15000000","0.82110000"],["62641.16000000","0.00115000"],["62641.17000000","0.00016000"],["62641.98000000","0.00008000"],["62641.99000000","0.00041000"],["62642.00000000","0.03469000"],["62642.19000000","0.00009000"],["62642.25000000","0.00008000"],["62642.40000000","0.00018000"],["62642.41000000","0.07781000"],["62642.81000000","0.00009000"],["62642.83000000","0.00256000"],["62642.91000000","0.00032000"],["62643.09000000","0.00016000"],["62643.20000000","0.00008000"],["62643.56000000","0.00018000"],["62643.57000000","0.17274000"],["62643.76000000","0.00008000"],["62643.97000000","0.00030000"],["62643.99000000","0.00018000"]]}}
{"t":19.2636,"stream":"btcusdt@depth@100ms","data":{"e":"depthUpdate","E":1783948021914,"s":"BTCUSDT","U":97344798647,"u":97344798663,"b":[["56377.03000000","0.00460000"],["50112.91000000","0.00000000"]],"a":[["62755.34000000","0.02500000"],["62764.31000000","0.15970000"],["62772.74000000","0.00087000"],["68905.26000000","0.00000000"]]}}
{"t":19.2638,"stream":"btcusdt@depth20@100ms","data":{"lastUpdateId":97344798663,"bids":[["62641.14000000","3.73297000"],["62641.13000000","0.00034000"],["62641.12000000","0.00016000"],["62640.96000000","0.00018000"],["62640.95000000","0.63005000"],["62640.90000000","0.00008000"],["62640.35000000","0.00018000"],["62640.34000000","0.30016000"],["62640.32000000","0.00009000"],["62640.01000000","0.02755000"],["62640.00000000","1.91799000"],["62639.99000000","0.54430000"],["62639.98000000","0.00449000"],["62639.86000000","0.00400000"],["62639.83000000","0.00016000"],["62639.77000000","0.04091000"],["62638.51000000","0.00816000"],["62638.49000000","0.03966000"],["62638.44000000","0.00009000"],["62638.42000000","0.00008000"]],"asks":[["62641.15000000","0.82110000"],["62641.16000000","0.00115000"],["62641.17000000","0.00016000"],["62641.98000000","0.00008000"],["62641.99000000","0.00041000"],["62642.00000000","0.03469000"],["62642.19000000","0.00009000"],["62642.25000000","0.00008000"],["62642.40000000","0.00018000"],["62642.41000000","0.07781000"],["62642.81000000","0.00009000"],["62642.83000000","0.00256000"],["62642.91000000","0.00032000"],["62643.09000000","0.00016000"],["62643.20000000","0.00008000"],["62643.56000000","0.00018000"],["62643.57000000","0.17274000"],["62643.76000000","0.00008000"],["62643.97000000","0.00030000"],["62643.99000000","0.00018000"]]}}
{"t":19.363,"stream":"btcusdt@depth@100ms","data":{"e":"depthUpdate","E":1783948022014,"s":"BTCUSDT","U":97344798664,"u":97344798701,"b":[["62588.02000000","0.00000000"],["62525.48000000","0.00045000"],["61701.52000000","0.00030000"],["56377.03000000","0.00460000"],["50112.92000000","0.00039000"],["50112.91000000","0.00000000"]],"a":[["62641.15000000","0.82110000"],["62641.16000000","0.00115000"],["62643.57000000","0.17282000"],["62644.57000000","0.00009000"],["62644.58000000","0.08524000"],["62645.24000000","0.00000000"],["62645.25000000","0.00018000"],["62657.99000000","0.39206000"],["62659.14000000","0.00000000"],["62659.75000000","0.79884000"],["62661.79000000","0.00000000"],["62764.31000000","0.00000000"]]}}
{"t":19.3643,"stream":"btcusdt@depth20@100ms","data":{"lastUpdateId":97344798701,"bids":[["62641.14000000","3.73297000"],["62641.13000000","0.00034000"],["62641.12000000","0.00016000"],["62640.96000000","0.00018000"],["62640.95000000","0.63005000"],["62640.90000000","0.00008000"],["62640.35000000","0.00018000"],["62640.34000000","0.30016000"],["62640.32000000","0.00009000"],["62640.01000000","0.02755000"],["62640.00000000","1.91799000"],["62639.99000000","0.54430000"],["62639.98000000","0.00449000"],["62639.86000000","0.00400000"],["62639.83000000","0.00016000"],["62639.77000000","0.04091000"],["62638.51000000","0.00816000"],["62638.49000000","0.03966000"],["62638.44000000","0.00009000"],["62638.42000000","0.00008000"]],"asks":[["62641.15000000","0.82110000"],["62641.16000000","0.00115000"],["62641.17000000","0.00016000"],["62641.98000000","0.00008000"],["62641.99000000","0.00041000"],["62642.00000000","0.03469000"],["62642.19000000","0.00009000"],["62642.25000000","0.00008000"],["62642.40000000","0.00018000"],["62642.41000000","0.07781000"],["62642.81000000","0.00009000"],["62642.83000000","0.00256000"],["62642.91000000","0.00032000"],["62643.09000000","0.00016000"],["62643.20000000","0.00008000"],["62643.56000000","0.00018000"],["62643.57000000","0.17282000"],["62643.76000000","0.00008000"],["62643.97000000","0.00030000"],["62643.99000000","0.00018000"]]}}
{"t":19.4642,"stream":"btcusdt@depth@100ms","data":{"e":"depthUpdate","E":1783948022114,"s":"BTCUSDT","U":97344798702,"u":97344798724,"b":[["62637.37000000","0.06704000"],["62635.60000000","0.00000000"],["62634.01000000","0.59914000"],["56377.03000000","0.00460000"],["40000.00000000","258.07540000"]],"a":[["62642.41000000","0.07773000"],["62644.00000000","0.02418000"],["62644.58000000","0.08542000"],["62645.25000000","0.00000000"],["62764.31000000","0.00000000"]]}}
{"t":19.4643,"stream":"btcusdt@depth20@100ms","data":{"lastUpdateId":97344798724,"bids":[["62641.14000000","3.73297000"],["62641.13000000","0.00034000"],["62641.12000000","0.00016000"],["62640.96000000","0.00018000"],["62640.95000000","0.63005000"],["62640.90000000","0.00008000"],["62640.35000000","0.00018000"],["62640.34000000","0.30016000"],["62640.32000000","0.00009000"],["62640.01000000","0.02755000"],["62640.00000000","1.91799000"],["62639.99000000","0.54430000"],["62639.98000000","0.00449000"],["62639.86000000","0.00400000"],["62639.83000000","0.00016000"],["62639.77000000","0.04091000"],["62638.51000000","0.00816000"],["62638.49000000","0.03966000"],["62638.44000000","0.00009000"],["62638.42000000","0.00008000"]],"asks":[["62641.15000000","0.82110000"],["62641.16000000","0.00115000"],["62641.17000000","0.00016000"],["62641.98000000","0.00008000"],["62641.99000000","0.00041000"],["62642.00000000","0.03469000"],["62642.19000000","0.00009000"],["62642.25000000","0.00008000"],["62642.40000000","0.00018000"],["62642.41000000","0.07773000"],["62642.81000000","0.00009000"],["62642.83000000","0.00256000"],["62642.91000000","0.00032000"],["62643.09000000","0.00016000"],["62643.20000000","0.00008000"],["62643.56000000","0.00018000"],["62643.57000000","0.17282000"],["62643.76000000","0.00008000"],["62643.97000000","0.00030000"],["62643.99000000","0.00018000"]]}}
{"t":19.5641,"stream":"btcusdt@depth@100ms","data":{"e":"depthUpdate","E":1783948022214,"s":"BTCUSDT","U":97344798725,"u":97344798739,"b":[["56377.03000000","0.00460000"],["50112.92000000","0.00000000"]],"a":[["62764.31000000","0.00000000"],["63580.77000000","0.00030000"]]}}
{"t":19.5642,"stream":"btcusdt@depth20@100ms","data":{"lastUpdateId":97344798739,"bids":[["62641.14000000","3.73297000"],["62641.13000000","0.00034000"],["62641.12000000","0.00016000"],["62640.96000000","0.00018000"],["62640.95000000","0.63005000"],["62640.90000000","0.00008000"],["62640.35000000","0.00018000"],["62640.34000000","0.30016000"],["62640.32000000","0.00009000"],["62640.01000000","0.02755000"],["62640.00000000","1.91799000"],["62639.99000000","0.54430000"],["62639.98000000","0.00449000"],["62639.86000000","0.00400000"],["62639.83000000","0.00016000"],["62639.77000000","0.04091000"],["62638.51000000","0.00816000"],["62638.49000000","0.03966000"],["62638.44000000","0.00009000"],["62638.42000000","0.00008000"]],"asks":[["62641.15000000","0.82110000"],["62641.16000000","0.00115000"],["62641.17000000","0.00016000"],["62641.98000000","0.00008000"],["62641.99000000","0.00041000"],["62642.00000000","0.03469000"],["62642.19000000","0.00009000"],["62642.25000000","0.00008000"],["62642.40000000","0.00018000"],["62642.41000000","0.07773000"],["62642.81000000","0.00009000"],["62642.83000000","0.00256000"],["62642.91000000","0.00032000"],["62643.09000000","0.00016000"],["62643.20000000","0.00008000"],["62643.56000000","0.00018000"],["62643.57000000","0.17282000"],["62643.76000000","0.00008000"],["62643.97000000","0.00030000"],["62643.99000000","0.00018000"]]}}
{"t":19.6634,"stream":"btcusdt@depth@100ms","data":{"e":"depthUpdate","E":1783948022314,"s":"BTCUSDT","U":97344798740,"u":97344798747,"b":[["60950.00000000","0.42756000"],["56377.03000000","0.00460000"],["56377.00000000","0.02164000"]],"a":[["62764.31000000","0.15970000"]]}}
{"t":19.6635,"stream":"btcusdt@depth20@100ms","data":{"lastUpdateId":97344798747,"bids":[["62641.14000000","3.73297000"],["62641.13000000","0.00034000"],["62641.12000000","0.00016000"],["62640.96000000","0.00018000"],["62640.95000000","0.63005000"],["62640.90000000","0.00008000"],["62640.35000000","0.00018000"],["62640.34000000","0.30016000"],["62640.32000000","0.00009000"],["62640.01000000","0.02755000"],["62640.00000000","1.91799000"],["62639.99000000","0.54430000"],["62639.98000000","0.00449000"],["62639.86000000","0.00400000"],["62639.83000000","0.00016000"],["62639.77000000","0.04091000"],["62638.51000000","0.00816000"],["62638.49000000","0.03966000"],["62638.44000000","0.00009000"],["62638.42000000","0.00008000"]],"asks":[["62641.15000000","0.82110000"],["62641.16000000","0.00115000"],["62641.17000000","0.00016000"],["62641.98000000","0.00008000"],["62641.99000000","0.00041000"],["62642.00000000","0.03469000"],["62642.19000000","0.00009000"],["62642.25000000","0.00008000"],["62642.40000000","0.00018000"],["62642.41000000","0.07773000"],["62642.81000000","0.00009000"],["62642.83000000","0.00256000"],["62642.91000000","0.00032000"],["62643.09000000","0.00016000"],["62643.20000000","0.00008000"],["62643.56000000","0.00018000"],["62643.57000000","0.17282000"],["62643.76000000","0.00008000"],["62643.97000000","0.00030000"],["62643.99000000","0.00018000"]]}}
{"t":19.7182,"stream":"btcusdt@aggTrade","data":{"e":"aggTrade","E":1783948022367,"s":"BTCUSDT","a":4013160614,"p":"62641.15000000","q":"0.03194000","f":6501833934,"l":6501833950,"T":1783948022367,"m":false,"M":true}}
{"t":19.7634,"stream":"btcusdt@depth@100ms","data":{"e":"depthUpdate","E":1783948022414,"s":"BTCUSDT","U":97344798748,"u":97344798774,"b":[["62641.14000000","3.73297000"],["62472.00000000","0.03201000"],["56377.03000000","0.00460000"]],"a":[["62641.15000000","0.79031000"],["62642.41000000","0.07705000"],["62642.49000000","0.00068000"],["62677.93000000","0.00000000"],["62764.31000000","0.00000000"]]}}
{"t":19.7651,"stream":"btcusdt@depth20@100ms","data":{"lastUpdateId":97344798774,"bids":[["62641.14000000","3.73297000"],["62641.13000000","0.00034000"],["62641.12000000","0.00016000"],["62640.96000000","0.00018000"],["62640.95000000","0.63005000"],["62640.90000000","0.00008000"],["62640.35000000","0.00018000"],["62640.34000000","0.30016000"],["62640.32000000","0.00009000"],["62640.01000000","0.02755000"],["62640.00000000","1.91799000"],["62639.99000000","0.54430000"],["62639.98000000","0.00449000"],["62639.86000000","0.00400000"],["62639.83000000","0.00016000"],["62639.77000000","0.04091000"],["62638.51000000","0.00816000"],["62638.49000000","0.03966000"],["62638.44000000","0.00009000"],["62638.42000000","0.00008000"]],"asks":[["62641.15000000","0.79031000"],["62641.16000000","0.00115000"],["62641.17000000","0.00016000"],["62641.98000000","0.00008000"],["62641.99000000","0.00041000"],["62642.00000000","0.03469000"],["62642.19000000","0.00009000"],["62642.25000000","0.00008000"],["62642.40000000","0.00018000"],["62642.41000000","0.07705000"],["62642.49000000","0.00068000"],["62642.81000000","0.00009000"],["62642.83000000","0.00256000"],["62642.91000000","0.00032000"],["62643.09000000","0.00016000"],["62643.20000000","0.00008000"],["62643.56000000","0.00018000"],["62643.57000000","0.17282000"],["62643.76000000","0.00008000"],["62643.97000000","0.00030000"]]}}
{"t":19.8653,"stream":"btcusdt@depth@100ms","data":{"e":"depthUpdate","E":1783948022514,"s":"BTCUSDT","U":97344798775,"u":97344798792,"b":[["56377.03000000","0.00480000"]],"a":[["62641.15000000","0.10100000"],["62641.16000000","0.00106000"],["62642.49000000","0.00000000"],["62643.01000000","0.00068000"],["62644.57000000","0.00000000"],["62644.58000000","0.00018000"],["62645.54000000","0.00009000"],["62657.99000000","0.08118000"],["62659.75000000","0.00000000"],["62661.79000000","0.79884000"],["62678.05000000","0.00011000"],["62683.85000000","0.00000000"],["62715.52000000","2.15344000"],["62717.63000000","0.00000000"]]}}
{"t":19.8653,"stream":"btcusdt@depth20@100ms","data":{"lastUpdateId":97344798792,"bids":[["62641.14000000","3.73297000"],["62641.13000000","0.00034000"],["62641.12000000","0.00016000"],["62640.96000000","0.00018000"],["62640.95000000","0.63005000"],["62640.90000000","0.00008000"],["62640.35000000","0.00018000"],["62640.34000000","0.30016000"],["62640.32000000","0.00009000"],["62640.01000000","0.02755000"],["62640.00000000","1.91799000"],["62639.99000000","0.54430000"],["62639.98000000","0.00449000"],["62639.86000000","0.00400000"],["62639.83000000","0.00016000"],["62639.77000000","0.04091000"],["62638.51000000","0.00816000"],["62638.49000000","0.03966000"],["62638.44000000","0.00009000"],["62638.42000000","0.00008000"]],"asks":[["62641.15000000","0.10100000"],["62641.16000000","0.00106000"],["62641.17000000","0.00016000"],["62641.98000000","0.00008000"],["62641.99000000","0.00041000"],["62642.00000000","0.03469000"],["62642.19000000","0.00009000"],["62642.25000000","0.00008000"],["62642.40000000","0.00018000"],["62642.41000000","0.07705000"],["62642.81000000","0.00009000"],["62642.83000000","0.00256000"],["62642.91000000","0.00032000"],["62643.01000000","0.00068000"],["62643.09000000","0.00016000"],["62643.20000000","0.00008000"],["62643.56000000","0.00018000"],["62643.57000000","0.17282000"],["62643.76000000","0.00008000"],["62643.97000000","0.00030000"]]}}
{"t":19.9643,"stream":"btcusdt@depth@100ms","data":{"e":"depthUpdate","E":1783948022614,"s":"BTCUSDT","U":97344798793,"u":97344798809,"b":[["62638.60000000","0.00032000"],["62630.77000000","0.00000000"],["56377.03000000","0.00480000"]],"a":[["62641.15000000","0.08430000"],["62643.57000000","0.17274000"],["62644.00000000","0.02418000"],["62644.58000000","0.00000000"],["62647.59000000","0.14118000"]]}}
{"t":19.9644,"stream":"btcusdt@depth20@100ms","data":{"lastUpdateId":97344798809,"bids":[["62641.14000000","3.73297000"],["62641.13000000","0.00034000"],["62641.12000000","0.00016000"],["62640.96000000","0.00018000"],["62640.95000000","0.63005000"],["62640.90000000","0.00008000"],["62640.35000000","0.00018000"],["62640.34000000","0.30016000"],["62640.32000000","0.00009000"],["62640.01000000","0.02755000"],["62640.00000000","1.91799000"],["62639.99000000","0.54430000"],["62639.98000000","0.00449000"],["62639.86000000","0.00400000"],["62639.83000000","0.00016000"],["62639.77000000","0.04091000"],["62638.60000000","0.00032000"],["62638.51000000","0.00816000"],["62638.49000000","0.03966000"],["62638.44000000","0.00009000"]],"asks":[["62641.15000000","0.08430000"],["62641.16000000","0.00106000"],["62641.17000000","0.00016000"],["62641.98000000","0.00008000"],["62641.99000000","0.00041000"],["62642.00000000","0.03469000"],["62642.19000000","0.00009000"],["62642.25000000","0.00008000"],["62642.40000000","0.00018000"],["62642.41000000","0.07705000"],["62642.81000000","0.00009000"],["62642.83000000","0.00256000"],["62642.91000000","0.00032000"],["62643.01000000","0.00068000"],["62643.09000000","0.00016000"],["62643.20000000","0.00008000"],["62643.56000000","0.00018000"],["62643.57000000","0.17274000"],["62643.76000000","0.00008000"],["62643.97000000","0.00030000"]]}}
{"t":19.9709,"stream":"btcusdt@aggTrade","data":{"e":"aggTrade","E":1783948022620,"s":"BTCUSDT","a":4013160615,"p":"62641.14000000","q":"0.00082000","f":6501833951,"l":6501833951,"T":1783948022620,"m":true,"M":true}}
{"t":20.0644,"stream":"btcusdt@depth@100ms","data":{"e":"depthUpdate","E":1783948022714,"s":"BTCUSDT","U":97344798810,"u":97344798848,"b":[["62641.14000000","3.73215000"],["62630.64000000","0.57526000"],["62620.54000000","0.00000000"],["62525.79000000","0.09596000"],["56377.03000000","0.00480000"]],"a":[["62641.15000000","0.79181000"],["62641.56000000","0.00009000"],["62646.56000000","0.13039000"],["62647.08000000","0.11194000"],["62650.94000000","0.00000000"],["62652.18000000","0.00000000"],["62652.55000000","0.00000000"],["62652.68000000","0.00000000"],["62652.78000000","0.00400000"],["62652.92000000","0.47600000"],["62652.95000000","0.00000000"],["62658.81000000","0.00000000"],["62658.95000000","0.00000000"],["62659.04000000","0.00400000"],["62660.05000000","0.00000000"],["62665.08000000","0.00340000"],["62665.21000000","0.00000000"],["62665.30000000","0.00400000"],["62667.98000000","0.00000000"]]}}
{"t":20.0647,"stream":"btcusdt@depth20@100ms","data":{"lastUpdateId":97344798848,"bids":[["62641.14000000","3.73215000"],["62641.13000000","0.00034000"],["62641.12000000","0.00016000"],["62640.96000000","0.00018000"],["62640.95000000","0.63005000"],["62640.90000000","0.00008000"],["62640.35000000","0.00018000"],["62640.34000000","0.30016000"],["62640.32000000","0.00009000"],["62640.01000000","0.02755000"],["62640.00000000","1.91799000"],["62639.99000000","0.54430000"],["62639.98000000","0.00449000"],["62639.86000000","0.00400000"],["62639.83000000","0.00016000"],["62639.77000000","0.04091000"],["62638.60000000","0.00032000"],["62638.51000000","0.00816000"],["62638.49000000","0.03966000"],["62638.44000000","0.00009000"]],"asks":[["62641.15000000","0.79181000"],["62641.16000000","0.00106000"],["62641.17000000","0.00016000"],["62641.56000000","0.00009000"],["62641.98000000","0.00008000"],["62641.99000000","0.00041000"],["62642.00000000","0.03469000"],["62642.19000000","0.00009000"],["62642.25000000","0.00008000"],["62642.40000000","0.00018000"],["62642.41000000","0.07705000"],["62642.81000000","0.00009000"],["62642.83000000","0.00256000"],["62642.91000000","0.00032000"],["62643.01000000","0.00068000"],["62643.09000000","0.00016000"],["62643.20000000","0.00008000"],["62643.56000000","0.00018000"],["62643.57000000","0.17274000"],["62643.76000000","0.00008000"]]}}
{"t":20.1631,"stream":"btcusdt@depth@100ms","data":{"e":"depthUpdate","E":1783948022814,"s":"BTCUSDT","U":97344798849,"u":97344798892,"b":[["62641.14000000","3.55703000"],["62640.90000000","0.00000000"],["62638.60000000","0.00000000"],["62637.75000000","0.00000000"],["62634.60000000","0.00000000"],["62631.45000000","0.00000000"],["62628.30000000","0.00000000"],["62627.12000000","0.00008000"],["62625.15000000","0.00000000"],["62622.00000000","0.02400000"],["62618.85000000","0.00000000"],["62615.70000000","0.00000000"],["62612.55000000","0.00000000"],["56377.03000000","0.00480000"]],"a":[["62641.15000000","0.10127000"],["62641.16000000","0.00124000"],["62642.44000000","0.00000000"],["62642.83000000","0.00000000"],["62643.00000000","0.00068000"],["62643.01000000","0.00000000"],["62643.57000000","0.17282000"],["62643.69000000","0.00256000"],["62645.53000000","0.00009000"],["62645.54000000","0.12886000"],["62646.10000000","0.08718000"],["62646.56000000","0.13039000"],["62647.08000000","0.00018000"],["62647.59000000","0.14100000"],["62652.19000000","0.00008000"],["62672.19000000","0.01400000"]]}}
{"t":20.1635,"stream":"btcusdt@depth20@100ms","data":{"lastUpdateId":97344798892,"bids":[["62641.14000000","3.55703000"],["62641.13000000","0.00034000"],["62641.12000000","0.00016000"],["62640.96000000","0.00018000"],["62640.95000000","0.63005000"],["62640.35000000","0.00018000"],["62640.34000000","0.30016000"],["62640.32000000","0.00009000"],["62640.01000000","0.02755000"],["62640.00000000","1.91799000"],["62639.99000000","0.54430000"],["62639.98000000","0.00449000"],["62639.86000000","0.00400000"],["62639.83000000","0.00016000"],["62639.77000000","0.04091000"],["62638.51000000","0.00816000"],["62638.49000000","0.03966000"],["62638.44000000","0.00009000"],["62638.42000000","0.00008000"],["62638.29000000","0.00400000"]],"asks":[["62641.15000000","0.10127000"],["62641.16000000","0.00124000"],["62641.17000000","0.00016000"],["62641.56000000","0.00009000"],["62641.98000000","0.00008000"],["62641.99000000","0.00041000"],["62642.00000000","0.03469000"],["62642.19000000","0.00009000"],["62642.25000000","0.00008000"],["62642.40000000","0.00018000"],["62642.41000000","0.07705000"],["62642.81000000","0.00009000"],["62642.91000000","0.00032000"],["62643.00000000","0.00068000"],["62643.09000000","0.00016000"],["62643.20000000","0.00008000"],["62643.56000000","0.00018000"],["62643.57000000","0.17282000"],["62643.69000000","0.00256000"],["62643.76000000","0.00008000"]]}}
{"t":20.2263,"stream":"btcusdt@aggTrade","data":{"e":"aggTrade","E":1783948022874,"s":"BTCUSDT","a":4013160616,"p":"62641.15000000","q":"0.00319000","f":6501833952,"l":6501833952,"T":1783948022874,"m":false,"M":true}}
{"t":20.2685,"stream":"btcusdt@depth@100ms","data":{"e":"depthUpdate","E":1783948022914,"s":"BTCUSDT","U":97344798893,"u":97344798942,"b":[["62641.14000000","3.55959000"],["62640.90000000","0.00008000"],["62637.75000000","0.00008000"],["62634.60000000","0.00008000"],["62631.45000000","0.00008000"],["62628.30000000","0.00008000"],["62627.99000000","0.00000000"],["62625.15000000","0.00008000"],["62622.00000000","0.02408000"],["62618.85000000","0.00008000"],["62615.70000000","0.00008000"],["62612.55000000","0.00008000"],["62548.20000000","0.00084000"],["62542.11000000","0.00000000"],["56377.03000000","0.00480000"],["56377.02000000","0.00000000"],["56377.01000000","0.00187000"],["50112.91000000","0.00000000"]],"a":[["62641.15000000","0.08479000"],["62641.16000000","0.00115000"],["62644.00000000","0.02418000"],["62645.54000000","0.12904000"],["62645.55000000","0.07697000"],["62646.00000000","0.02418000"],["62646.10000000","0.08736000"],["62646.56000000","0.13013000"],["62647.08000000","0.00000000"],["62740.30000000","0.00000000"],["62746.43000000","0.00084000"],["62831.12000000","0.09549000"]]}}
{"t":20.2687,"stream":"btcusdt@depth20@100ms","data":{"lastUpdateId":97344798942,"bids":[["62641.14000000","3.55959000"],["62641.13000000","0.00034000"],["62641.12000000","0.00016000"],["62640.96000000","0.00018000"],["62640.95000000","0.63005000"],["62640.90000000","0.00008000"],["62640.35000000","0.00018000"],["62640.34000000","0.30016000"],["62640.32000000","0.00009000"],["62640.01000000","0.02755000"],["62640.00000000","1.91799000"],["62639.99000000","0.54430000"],["62639.98000000","0.00449000"],["62639.86000000","0.00400000"],["62639.83000000","0.00016000"],["62639.77000000","0.04091000"],["62638.51000000","0.00816000"],["62638.49000000","0.03966000"],["62638.44000000","0.00009000"],["62638.42000000","0.00008000"]],"asks":[["62641.15000000","0.08479000"],["62641.16000000","0.00115000"],["62641.17000000","0.00016000"],["62641.56000000","0.00009000"],["62641.98000000","0.00008000"],["62641.99000000","0.00041000"],["62642.00000000","0.03469000"],["62642.19000000","0.00009000"],["62642.25000000","0.00008000"],["62642.40000000","0.00018000"],["62642.41000000","0.07705000"],["62642.81000000","0.00009000"],["62642.91000000","0.00032000"],["62643.00000000","0.00068000"],["62643.09000000","0.00016000"],["62643.20000000","0.00008000"],["62643.56000000","0.00018000"],["62643.57000000","0.17282000"],["62643.69000000","0.00256000"],["62643.76000000","0.00008000"]]}}
{"t":20.3636,"stream":"btcusdt@depth@100ms","data":{"e":"depthUpdate","E":1783948023014,"s":"BTCUSDT","U":97344798943,"u":97344798969,"b":[["62639.99000000","0.54340000"],["62635.60000000","0.59914000"],["62634.01000000","0.00000000"],["62630.99000000","0.06712000"],["62588.02000000","0.00113000"],["62525.80000000","0.00045000"],["62525.48000000","0.00000000"],["62486.71000000","0.00250000"],["61701.52000000","0.00030000"],["56377.03000000","0.00460000"],["50112.92000000","0.00039000"],["50112.91000000","0.00000000"]],"a":[["62641.15000000","0.09923000"],["62703.53000000","0.00000000"],["62763.65000000","0.08479000"],["63053.99000000","0.00250000"]]}}
{"t":20.3645,"stream":"btcusdt@depth20@100ms","data":{"lastUpdateId":97344798969,"bids":[["62641.14000000","3.55959000"],["62641.13000000","0.00034000"],["62641.12000000","0.00016000"],["62640.96000000","0.00018000"],["62640.95000000","0.63005000"],["62640.90000000","0.00008000"],["62640.35000000","0.00018000"],["62640.34000000","0.30016000"],["62640.32000000","0.00009000"],["62640.01000000","0.02755000"],["62640.00000000","1.91799000"],["62639.99000000","0.54340000"],["62639.98000000","0.00449000"],["62639.86000000","0.00400000"],["62639.83000000","0.00016000"],["62639.77000000","0.04091000"],["62638.51000000","0.00816000"],["62638.49000000","0.03966000"],["62638.44000000","0.00009000"],["62638.42000000","0.00008000"]],"asks":[["62641.15000000","0.09923000"],["62641.16000000","0.00115000"],["62641.17000000","0.00016000"],["62641.56000000","0.00009000"],["62641.98000000","0.00008000"],["62641.99000000","0.00041000"],["62642.00000000","0.03469000"],["62642.19000000","0.00009000"],["62642.25000000","0.00008000"],["62642.40000000","0.00018000"],["62642.41000000","0.07705000"],["62642.81000000","0.00009000"],["62642.91000000","0.00032000"],["62643.00000000","0.00068000"],["62643.09000000","0.00016000"],["62643.20000000","0.00008000"],["62643.56000000","0.00018000"],["62643.57000000","0.17282000"],["62643.69000000","0.00256000"],["62643.76000000","0.00008000"]]}}
{"t":20.4644,"stream":"btcusdt@depth@100ms","data":{"e":"depthUpdate","E":1783948023114,"s":"BTCUSDT","U":97344798970,"u":97344798991,"b":[["62637.37000000","0.06712000"],["62588.02000000","0.00113000"],["62525.80000000","0.00000000"],["56377.03000000","0.00460000"],["40000.00000000","258.07540000"]],"a":[["62641.15000000","0.09923000"],["62641.16000000","0.00124000"],["62643.57000000","0.17290000"],["62645.40000000","0.00009000"],["62645.41000000","0.09884000"],["62645.54000000","0.12895000"],["62646.10000000","0.00018000"],["62648.85000000","0.13966000"],["62652.15000000","0.13966000"],["62652.94000000","0.00000000"],["62678.05000000","0.00000000"],["62763.65000000","0.00000000"]]}}
{"t":20.4645,"stream":"btcusdt@depth20@100ms","data":{"lastUpdateId":97344798991,"bids":[["62641.14000000","3.55959000"],["62641.13000000","0.00034000"],["62641.12000000","0.00016000"],["62640.96000000","0.00018000"],["62640.95000000","0.63005000"],["62640.90000000","0.00008000"],["62640.35000000","0.00018000"],["62640.34000000","0.30016000"],["62640.32000000","0.00009000"],["62640.01000000","0.02755000"],["62640.00000000","1.91799000"],["62639.99000000","0.54340000"],["62639.98000000","0.00449000"],["62639.86000000","0.00400000"],["62639.83000000","0.00016000"],["62639.77000000","0.04091000"],["62638.51000000","0.00816000"],["62638.49000000","0.03966000"],["62638.44000000","0.00009000"],["62638.42000000","0.00008000"]],"asks":[["62641.15000000","0.09923000"],["62641.16000000","0.00124000"],["62641.17000000","0.00016000"],["62641.56000000","0.00009000"],["62641.98000000","0.00008000"],["62641.99000000","0.00041000"],["62642.00000000","0.03469000"],["62642.19000000","0.00009000"],["62642.25000000","0.00008000"],["62642.40000000","0.00018000"],["62642.41000000","0.07705000"],["62642.81000000","0.00009000"],["62642.91000000","0.00032000"],["62643.00000000","0.00068000"],["62643.09000000","0.00016000"],["62643.20000000","0.00008000"],["62643.56000000","0.00018000"],["62643.57000000","0.17290000"],["62643.69000000","0.00256000"],["62643.76000000","0.00008000"]]}}
{"t":20.496,"stream":"btcusdt@aggTrade","data":{"e":"aggTrade","E":1783948023142,"s":"BTCUSDT","a":4013160617,"p":"62641.15000000","q":"0.00052000","f":6501833953,"l":6501833953,"T":1783948023142,"m":false,"M":true}}
{"t":20.5639,"stream":"btcusdt@depth@100ms","data":{"e":"depthUpdate","E":1783948023214,"s":"BTCUSDT","U":97344798992,"u":97344799036,"b":[["62641.14000000","3.55950000"],["62637.37000000","0.06704000"],["62635.60000000","0.00000000"],["62634.01000000","0.59914000"],["56377.03000000","0.00460000"],["50112.92000000","0.00000000"]],"a":[["62641.15000000","0.08542000"],["62641.16000000","0.00115000"],["62641.56000000","0.00000000"],["62642.40000000","0.00018000"],["62643.00000000","0.00068000"],["62644.00000000","0.02418000"],["62645.40000000","0.00000000"],["62645.41000000","0.00018000"],["62645.55000000","0.07689000"],["62646.00000000","0.02418000"],["62646.10000000","0.00000000"],["62657.99000000","0.00000000"],["62659.14000000","0.39940000"],["62659.75000000","0.00000000"],["62661.79000000","0.79883000"],["62663.42000000","0.00000000"],["62678.19000000","0.00011000"],["62715.52000000","0.00000000"],["63580.77000000","0.00030000"],["82071.40000000","0.00000000"]]}}
{"t":20.5641,"stream":"btcusdt@depth20@100ms","data":{"lastUpdateId":97344799036,"bids":[["62641.14000000","3.55950000"],["62641.13000000","0.00034000"],["62641.12000000","0.00016000"],["62640.96000000","0.00018000"],["62640.95000000","0.63005000"],["62640.90000000","0.00008000"],["62640.35000000","0.00018000"],["62640.34000000","0.30016000"],["62640.32000000","0.00009000"],["62640.01000000","0.02755000"],["62640.00000000","1.91799000"],["62639.99000000","0.54340000"],["62639.98000000","0.00449000"],["62639.86000000","0.00400000"],["62639.83000000","0.00016000"],["62639.77000000","0.04091000"],["62638.51000000","0.00816000"],["62638.49000000","0.03966000"],["62638.44000000","0.00009000"],["62638.42000000","0.00008000"]],"asks":[["62641.15000000","0.08542000"],["62641.16000000","0.00115000"],["62641.17000000","0.00016000"],["62641.98000000","0.00008000"],["62641.99000000","0.00041000"],["62642.00000000","0.03469000"],["62642.19000000","0.00009000"],["62642.25000000","0.00008000"],["62642.40000000","0.00018000"],["62642.41000000","0.07705000"],["62642.81000000","0.00009000"],["62642.91000000","0.00032000"],["62643.00000000","0.00068000"],["62643.09000000","0.00016000"],["62643.20000000","0.00008000"],["62643.56000000","0.00018000"],["62643.57000000","0.17290000"],["62643.69000000","0.00256000"],["62643.76000000","0.00008000"],["62643.97000000","0.00030000"]]}}
{"t":20.6638,"stream":"btcusdt@depth@100ms","data":{"e":"depthUpdate","E":1783948023314,"s":"BTCUSDT","U":97344799037,"u":97344799059,"b":[["62638.63000000","0.00032000"],["62630.99000000","0.00000000"],["62391.73000000","0.00922000"],["56377.03000000","0.00460000"],["56377.00000000","0.02184000"]],"a":[["62641.15000000","0.08068000"],["62643.57000000","0.17282000"],["62644.00000000","0.02418000"],["62645.41000000","0.00000000"],["62646.56000000","0.13031000"],["62715.52000000","2.15344000"],["62763.66000000","0.00000000"],["62786.19000000","0.01183000"]]}}
{"t":20.6641,"stream":"btcusdt@depth20@100ms","data":{"lastUpdateId":97344799059,"bids":[["62641.14000000","3.55950000"],["62641.13000000","0.00034000"],["62641.12000000","0.00016000"],["62640.96000000","0.00018000"],["62640.95000000","0.63005000"],["62640.90000000","0.00008000"],["62640.35000000","0.00018000"],["62640.34000000","0.30016000"],["62640.32000000","0.00009000"],["62640.01000000","0.02755000"],["62640.00000000","1.91799000"],["62639.99000000","0.54340000"],["62639.98000000","0.00449000"],["62639.86000000","0.00400000"],["62639.83000000","0.00016000"],["62639.77000000","0.04091000"],["62638.63000000","0.00032000"],["62638.51000000","0.00816000"],["62638.49000000","0.03966000"],["62638.44000000","0.00009000"]],"asks":[["62641.15000000","0.08068000"],["62641.16000000","0.00115000"],["62641.17000000","0.00016000"],["62641.98000000","0.00008000"],["62641.99000000","0.00041000"],["62642.00000000","0.03469000"],["62642.19000000","0.00009000"],["62642.25000000","0.00008000"],["62642.40000000","0.00018000"],["62642.41000000","0.07705000"],["62642.81000000","0.00009000"],["62642.91000000","0.00032000"],["62643.00000000","0.00068000"],["62643.09000000","0.00016000"],["62643.20000000","0.00008000"],["62643.56000000","0.00018000"],["62643.57000000","0.17282000"],["62643.69000000","0.00256000"],["62643.76000000","0.00008000"],["62643.97000000","0.00030000"]]}}
{"t":20.7343,"stream":"btcusdt@aggTrade","data":{"e":"aggTrade","E":1783948023383,"s":"BTCUSDT","a":4013160618,"p":"62641.14000000","q":"0.00078000","f":6501833954,"l":6501833954,"T":1783948023382,"m":true,"M":true}}
{"t":20.7637,"stream":"btcusdt@depth@100ms","data":{"e":"depthUpdate","E":1783948023414,"s":"BTCUSDT","U":97344799060,"u":97344799073,"b":[["62641.14000000","3.55881000"],["62641.13000000","0.00157000"],["56377.03000000","0.00460000"],["56377.00000000","0.02164000"]],"a":[["62641.15000000","0.08068000"],["62646.56000000","0.13039000"],["62647.18000000","0.09663000"],["62763.62000000","0.08068000"],["63443.53000000","0.00011000"]]}}
{"t":20.7638,"stream":"btcusdt@depth20@100ms","data":{"lastUpdateId":97344799073,"bids":[["62641.14000000","3.55881000"],["62641.13000000","0.00157000"],["62641.12000000","0.00016000"],["62640.96000000","0.00018000"],["62640.95000000","0.63005000"],["62640.90000000","0.00008000"],["62640.35000000","0.00018000"],["62640.34000000","0.30016000"],["62640.32000000","0.00009000"],["62640.01000000","0.02755000"],["62640.00000000","1.91799000"],["62639.99000000","0.54340000"],["62639.98000000","0.00449000"],["62639.86000000","0.00400000"],["62639.83000000","0.00016000"],["62639.77000000","0.04091000"],["62638.63000000","0.00032000"],["62638.51000000","0.00816000"],["62638.49000000","0.03966000"],["62638.44000000","0.00009000"]],"asks":[["62641.15000000","0.08068000"],["62641.16000000","0.00115000"],["62641.17000000","0.00016000"],["62641.98000000","0.00008000"],["62641.99000000","0.00041000"],["62642.00000000","0.03469000"],["62642.19000000","0.00009000"],["62642.25000000","0.00008000"],["62642.40000000","0.00018000"],["62642.41000000","0.07705000"],["62642.81000000","0.00009000"],["62642.91000000","0.00032000"],["62643.00000000","0.00068000"],["62643.09000000","0.00016000"],["62643.20000000","0.00008000"],["62643.56000000","0.00018000"],["62643.57000000","0.17282000"],["62643.69000000","0.00256000"],["62643.76000000","0.00008000"],["62643.97000000","0.00030000"]]}}
{"t":20.865,"stream":"btcusdt@depth@100ms","data":{"e":"depthUpdate","E":1783948023514,"s":"BTCUSDT","U":97344799074,"u":97344799120,"b":[["62641.14000000","3.99500000"],["62640.35000000","0.00000000"],["62640.01000000","0.02737000"],["62640.00000000","1.91781000"],["62639.45000000","0.00146000"],["62638.51000000","0.00018000"],["62636.79000000","0.59920000"],["62634.01000000","0.00000000"],["62525.79000000","0.00000000"],["56377.03000000","0.00460000"]],"a":[["62641.15000000","0.08077000"],["62641.16000000","0.00124000"],["62643.56000000","0.00000000"],["62643.57000000","0.00026000"],["62643.69000000","0.00000000"],["62645.21000000","0.00256000"],["62645.44000000","0.00000000"],["62645.53000000","0.00018000"],["62645.54000000","0.12904000"],["62646.56000000","0.13039000"],["62647.18000000","0.00000000"],["62647.20000000","0.00000000"],["62652.24000000","0.00000000"],["62652.78000000","0.00000000"],["62652.91000000","0.59912000"],["62652.93000000","0.00000000"],["62652.96000000","0.00000000"],["62653.49000000","0.00798000"],["62654.03000000","0.00400000"],["62658.18000000","0.00032000"],["62659.14000000","0.00000000"],["62659.75000000","0.11159000"],["62667.35000000","0.00000000"],["62678.70000000","0.00008000"],["62763.62000000","0.00000000"],["62831.12000000","0.00000000"]]}}
{"t":20.8652,"stream":"btcusdt@depth20@100ms","data":{"lastUpdateId":97344799120,"bids":[["62641.14000000","3.99500000"],["62641.13000000","0.00157000"],["62641.12000000","0.00016000"],["62640.96000000","0.00018000"],["62640.95000000","0.63005000"],["62640.90000000","0.00008000"],["62640.34000000","0.30016000"],["62640.32000000","0.00009000"],["62640.01000000","0.02737000"],["62640.00000000","1.91781000"],["62639.99000000","0.54340000"],["62639.98000000","0.00449000"],["62639.86000000","0.00400000"],["62639.83000000","0.00016000"],["62639.77000000","0.04091000"],["62639.45000000","0.00146000"],["62638.63000000","0.00032000"],["62638.51000000","0.00018000"],["62638.49000000","0.03966000"],["62638.44000000","0.00009000"]],"asks":[["62641.15000000","0.08077000"],["62641.16000000","0.00124000"],["62641.17000000","0.00016000"],["62641.98000000","0.00008000"],["62641.99000000","0.00041000"],["62642.00000000","0.03469000"],["62642.19000000","0.00009000"],["62642.25000000","0.00008000"],["62642.40000000","0.00018000"],["62642.41000000","0.07705000"],["62642.81000000","0.00009000"],["62642.91000000","0.00032000"],["62643.00000000","0.00068000"],["62643.09000000","0.00016000"],["62643.20000000","0.00008000"],["62643.57000000","0.00026000"],["62643.76000000","0.00008000"],["62643.97000000","0.00030000"],["62643.99000000","0.00018000"],["62644.00000000","0.02418000"]]}}
{"t":20.9645,"stream":"btcusdt@depth@100ms","data":{"e":"depthUpdate","E":1783948023614,"s":"BTCUSDT","U":97344799121,"u":97344799158,"b":[["62640.00000000","1.91796000"],["62639.77000000","0.04091000"],["62638.51000000","0.00000000"],["62638.49000000","0.03984000"],["62630.99000000","0.09376000"],["56377.03000000","0.00460000"],["50113.00000000","0.00193000"]],"a":[["62641.15000000","0.08059000"],["62641.16000000","0.00106000"],["62642.41000000","0.07705000"],["62643.57000000","0.00008000"],["62645.51000000","0.00032000"],["62646.56000000","0.13031000"],["62647.59000000","0.14118000"],["62652.89000000","0.00000000"],["62652.90000000","1.91755000"],["62652.91000000","0.00000000"],["62658.17000000","0.59913000"],["62658.18000000","0.00032000"]]}}
{"t":20.9647,"stream":"btcusdt@depth20@100ms","data":{"lastUpdateId":97344799158,"bids":[["62641.14000000","3.99500000"],["62641.13000000","0.00157000"],["62641.12000000","0.00016000"],["62640.96000000","0.00018000"],["62640.95000000","0.63005000"],["62640.90000000","0.00008000"],["62640.34000000","0.30016000"],["62640.32000000","0.00009000"],["62640.01000000","0.02737000"],["62640.00000000","1.91796000"],["62639.99000000","0.54340000"],["62639.98000000","0.00449000"],["62639.86000000","0.00400000"],["62639.83000000","0.00016000"],["62639.77000000","0.04091000"],["62639.45000000","0.00146000"],["62638.63000000","0.00032000"],["62638.49000000","0.03984000"],["62638.44000000","0.00009000"],["62638.42000000","0.00008000"]],"asks":[["62641.15000000","0.08059000"],["62641.16000000","0.00106000"],["62641.17000000","0.00016000"],["62641.98000000","0.00008000"],["62641.99000000","0.00041000"],["62642.00000000","0.03469000"],["62642.19000000","0.00009000"],["62642.25000000","0.00008000"],["62642.40000000","0.00018000"],["62642.41000000","0.07705000"],["62642.81000000","0.00009000"],["62642.91000000","0.00032000"],["62643.00000000","0.00068000"],["62643.09000000","0.00016000"],["62643.20000000","0.00008000"],["62643.57000000","0.00008000"],["62643.76000000","0.00008000"],["62643.97000000","0.00030000"],["62643.99000000","0.00018000"],["62644.00000000","0.02418000"]]}}
{"t":21.0278,"stream":"btcusdt@aggTrade","data":{"e":"aggTrade","E":1783948023675,"s":"BTCUSDT","a":4013160619,"p":"62641.15000000","q":"0.00030000","f":6501833955,"l":6501833955,"T":1783948023675,"m":false,"M":true}}
{"t":21.0639,"stream":"btcusdt@depth@100ms","data":{"e":"depthUpdate","E":1783948023714,"s":"BTCUSDT","U":97344799159,"u":97344799168,"b":[["56377.03000000","0.00460000"],["50113.00000000","0.00193000"]],"a":[["62641.15000000","0.08029000"],["62641.56000000","0.00009000"],["62648.27000000","0.11094000"],["82071.40000000","0.00010000"]]}}
{"t":21.0641,"stream":"btcusdt@depth20@100ms","data":{"lastUpdateId":97344799168,"bids":[["62641.14000000","3.99500000"],["62641.13000000","0.00157000"],["62641.12000000","0.00016000"],["62640.96000000","0.00018000"],["62640.95000000","0.63005000"],["62640.90000000","0.00008000"],["62640.34000000","0.30016000"],["62640.32000000","0.00009000"],["62640.01000000","0.02737000"],["62640.00000000","1.91796000"],["62639.99000000","0.54340000"],["62639.98000000","0.00449000"],["62639.86000000","0.00400000"],["62639.83000000","0.00016000"],["62639.77000000","0.04091000"],["62639.45000000","0.00146000"],["62638.63000000","0.00032000"],["62638.49000000","0.03984000"],["62638.44000000","0.00009000"],["62638.42000000","0.00008000"]],"asks":[["62641.15000000","0.08029000"],["62641.16000000","0.00106000"],["62641.17000000","0.00016000"],["62641.56000000","0.00009000"],["62641.98000000","0.00008000"],["62641.99000000","0.00041000"],["62642.00000000","0.03469000"],["62642.19000000","0.00009000"],["62642.25000000","0.00008000"],["62642.40000000","0.00018000"],["62642.41000000","0.07705000"],["62642.81000000","0.00009000"],["62642.91000000","0.00032000"],["62643.00000000","0.00068000"],["62643.09000000","0.00016000"],["62643.20000000","0.00008000"],["62643.57000000","0.00008000"],["62643.76000000","0.00008000"],["62643.97000000","0.00030000"],["62643.99000000","0.00018000"]]}}
{"t":21.1646,"stream":"btcusdt@depth@100ms","data":{"e":"depthUpdate","E":1783948023814,"s":"BTCUSDT","U":97344799169,"u":97344799241,"b":[["62641.14000000","7.18778000"],["62640.96000000","0.00000000"],["62639.45000000","0.00000000"],["62617.62000000","0.00000000"],["62500.77000000","0.00999000"],["62500.01000000","0.06451000"],["56377.03000000","0.00460000"]],"a":[["62641.15000000","0.08011000"],["62641.16000000","0.00088000"],["62643.00000000","0.00000000"],["62643.07000000","0.00068000"],["62645.21000000","0.00000000"],["62645.44000000","0.00032000"],["62645.51000000","0.00000000"],["62645.53000000","0.00000000"],["62645.54000000","0.00036000"],["62645.55000000","0.07945000"],["62645.99000000","0.00009000"],["62646.56000000","0.13031000"],["62646.97000000","0.00000000"],["62647.26000000","0.00000000"],["62647.59000000","0.14126000"],["62648.47000000","0.00000000"],["62649.51000000","0.00000000"],["62650.33000000","0.00000000"],["62650.35000000","0.00017000"],["62652.90000000","0.00000000"],["62652.92000000","0.00000000"],["62659.04000000","0.00000000"],["62659.74000000","0.09123000"],["62659.75000000","0.00000000"],["62660.79000000","0.00415000"],["62661.79000000","0.00000000"],["62664.40000000","0.79881000"],["62667.62000000","0.00000000"],["62667.69000000","0.02256000"],["62670.54000000","0.00000000"],["62670.61000000","0.00000000"],["62671.78000000","0.01900000"],["62681.85000000","0.00000000"],["62695.60000000","0.00000000"],["62695.67000000","0.00000000"],["62703.18000000","0.00000000"]]}}
{"t":21.165,"stream":"btcusdt@depth20@100ms","data":{"lastUpdateId":97344799241,"bids":[["62641.14000000","7.18778000"],["62641.13000000","0.00157000"],["62641.12000000","0.00016000"],["62640.95000000","0.63005000"],["62640.90000000","0.00008000"],["62640.34000000","0.30016000"],["62640.32000000","0.00009000"],["62640.01000000","0.02737000"],["62640.00000000","1.91796000"],["62639.99000000","0.54340000"],["62639.98000000","0.00449000"],["62639.86000000","0.00400000"],["62639.83000000","0.00016000"],["62639.77000000","0.04091000"],["62638.63000000","0.00032000"],["62638.49000000","0.03984000"],["62638.44000000","0.00009000"],["62638.42000000","0.00008000"],["62638.29000000","0.00400000"],["62638.00000000","0.02400000"]],"asks":[["62641.15000000","0.08011000"],["62641.16000000","0.00088000"],["62641.17000000","0.00016000"],["62641.56000000","0.00009000"],["62641.98000000","0.00008000"],["62641.99000000","0.00041000"],["62642.00000000","0.03469000"],["62642.19000000","0.00009000"],["62642.25000000","0.00008000"],["62642.40000000","0.00018000"],["62642.41000000","0.07705000"],["62642.81000000","0.00009000"],["62642.91000000","0.00032000"],["62643.07000000","0.00068000"],["62643.09000000","0.00016000"],["62643.20000000","0.00008000"],["62643.57000000","0.00008000"],["62643.76000000","0.00008000"],["62643.97000000","0.00030000"],["62643.99000000","0.00018000"]]}}
{"t":21.2637,"stream":"btcusdt@depth@100ms","data":{"e":"depthUpdate","E":1783948023914,"s":"BTCUSDT","U":97344799242,"u":97344799259,"b":[["62627.12000000","0.00008000"],["56377.03000000","0.00480000"],["50112.91000000","0.00020000"]],"a":[["62644.00000000","0.02418000"],["62645.54000000","0.00018000"],["62647.80000000","0.00574000"],["62652.19000000","0.00008000"],["62655.45000000","0.13966000"],["62656.42000000","0.13966000"],["62671.10000000","0.02662000"]]}}
{"t":21.2638,"stream":"btcusdt@depth20@100ms","data":{"lastUpdateId":97344799259,"bids":[["62641.14000000","7.18778000"],["62641.13000000","0.00157000"],["62641.12000000","0.00016000"],["62640.95000000","0.63005000"],["62640.90000000","0.00008000"],["62640.34000000","0.30016000"],["62640.32000000","0.00009000"],["62640.01000000","0.02737000"],["62640.00000000","1.91796000"],["62639.99000000","0.54340000"],["62639.98000000","0.00449000"],["62639.86000000","0.00400000"],["62639.83000000","0.00016000"],["62639.77000000","0.04091000"],["62638.63000000","0.00032000"],["62638.49000000","0.03984000"],["62638.44000000","0.00009000"],["62638.42000000","0.00008000"],["62638.29000000","0.00400000"],["62638.00000000","0.02400000"]],"asks":[["62641.15000000","0.08011000"],["62641.16000000","0.00088000"],["62641.17000000","0.00016000"],["62641.56000000","0.00009000"],["62641.98000000","0.00008000"],["62641.99000000","0.00041000"],["62642.00000000","0.03469000"],["62642.19000000","0.00009000"],["62642.25000000","0.00008000"],["62642.40000000","0.00018000"],["62642.41000000","0.07705000"],["62642.81000000","0.00009000"],["62642.91000000","0.00032000"],["62643.07000000","0.00068000"],["62643.09000000","0.00016000"],["62643.20000000","0.00008000"],["62643.57000000","0.00008000"],["62643.76000000","0.00008000"],["62643.97000000","0.00030000"],["62643.99000000","0.00018000"]]}}
{"t":21.3658,"stream":"btcusdt@depth@100ms","data":{"e":"depthUpdate","E":1783948024014,"s":"BTCUSDT","U":97344799260,"u":97344799288,"b":[["62636.01000000","0.14271000"],["62633.23000000","0.00000000"],["62632.62000000","0.79880000"],["62630.09000000","0.00000000"],["62588.02000000","0.00113000"],["62525.48000000","0.00045000"],["61701.52000000","0.00030000"],["56377.03000000","0.00480000"],["50112.92000000","0.00039000"],["50112.91000000","0.00020000"]],"a":[["62647.59000000","0.14118000"],["62648.27000000","0.00000000"],["62650.85000000","0.00000000"],["62658.17000000","0.00000000"],["62659.15000000","0.61162000"],["62659.74000000","0.00000000"],["62661.79000000","0.58327000"],["62662.56000000","0.00000000"],["62664.40000000","0.79880000"],["62671.10000000","0.00000000"],["62679.11000000","0.00400000"],["62715.52000000","0.00000000"]]}}
{"t":21.366,"stream":"btcusdt@depth20@100ms","data":{"lastUpdateId":97344799288,"bids":[["62641.14000000","7.18778000"],["62641.13000000","0.00157000"],["62641.12000000","0.00016000"],["62640.95000000","0.63005000"],["62640.90000000","0.00008000"],["62640.34000000","0.30016000"],["62640.32000000","0.00009000"],["62640.01000000","0.02737000"],["62640.00000000","1.91796000"],["62639.99000000","0.54340000"],["62639.98000000","0.00449000"],["62639.86000000","0.00400000"],["62639.83000000","0.00016000"],["62639.77000000","0.04091000"],["62638.63000000","0.00032000"],["62638.49000000","0.03984000"],["62638.44000000","0.00009000"],["62638.42000000","0.00008000"],["62638.29000000","0.00400000"],["62638.00000000","0.02400000"]],"asks":[["62641.15000000","0.08011000"],["62641.16000000","0.00088000"],["62641.17000000","0.00016000"],["62641.56000000","0.00009000"],["62641.98000000","0.00008000"],["62641.99000000","0.00041000"],["62642.00000000","0.03469000"],["62642.19000000","0.00009000"],["62642.25000000","0.00008000"],["62642.40000000","0.00018000"],["62642.41000000","0.07705000"],["62642.81000000","0.00009000"],["62642.91000000","0.00032000"],["62643.07000000","0.00068000"],["62643.09000000","0.00016000"],["62643.20000000","0.00008000"],["62643.57000000","0.00008000"],["62643.76000000","0.00008000"],["62643.97000000","0.00030000"],["62643.99000000","0.00018000"]]}}
{"t":21.3667,"stream":"btcusdt@aggTrade","data":{"e":"aggTrade","E":1783948024016,"s":"BTCUSDT","a":4013160620,"p":"62641.15000000","q":"0.00400000","f":6501833956,"l":6501833956,"T":1783948024015,"m":false,"M":true}}
{"t":21.4097,"stream":"btcusdt@aggTrade","data":{"e":"aggTrade","E":1783948024059,"s":"BTCUSDT","a":4013160621,"p":"62641.15000000","q":"0.00009000","f":6501833957,"l":6501833957,"T":1783948024059,"m":false,"M":true}}
{"t":21.4644,"stream":"btcusdt@depth@100ms","data":{"e":"depthUpdate","E":1783948024114,"s":"BTCUSDT","U":97344799289,"u":97344799305,"b":[["62636.79000000","0.59928000"],["62588.02000000","0.00000000"],["62525.48000000","0.00045000"],["56377.03000000","0.00480000"],["56377.01000000","0.00177000"],["50112.91000000","0.00000000"],["40000.00000000","258.07540000"]],"a":[["62641.15000000","0.07602000"],["62646.21000000","0.17256000"],["62659.75000000","0.00000000"],["62659.99000000","0.08551000"],["62661.78000000","0.00000000"],["62661.79000000","0.00000000"]]}}
{"t":21.4645,"stream":"btcusdt@depth20@100ms","data":{"lastUpdateId":97344799305,"bids":[["62641.14000000","7.18778000"],["62641.13000000","0.00157000"],["62641.12000000","0.00016000"],["62640.95000000","0.63005000"],["62640.90000000","0.00008000"],["62640.34000000","0.30016000"],["62640.32000000","0.00009000"],["62640.01000000","0.02737000"],["62640.00000000","1.91796000"],["62639.99000000","0.54340000"],["62639.98000000","0.00449000"],["62639.86000000","0.00400000"],["62639.83000000","0.00016000"],["62639.77000000","0.04091000"],["62638.63000000","0.00032000"],["62638.49000000","0.03984000"],["62638.44000000","0.00009000"],["62638.42000000","0.00008000"],["62638.29000000","0.00400000"],["62638.00000000","0.02400000"]],"asks":[["62641.15000000","0.07602000"],["62641.16000000","0.00088000"],["62641.17000000","0.00016000"],["62641.56000000","0.00009000"],["62641.98000000","0.00008000"],["62641.99000000","0.00041000"],["62642.00000000","0.03469000"],["62642.19000000","0.00009000"],["62642.25000000","0.00008000"],["62642.40000000","0.00018000"],["62642.41000000","0.07705000"],["62642.81000000","0.00009000"],["62642.91000000","0.00032000"],["62643.07000000","0.00068000"],["62643.09000000","0.00016000"],["62643.20000000","0.00008000"],["62643.57000000","0.00008000"],["62643.76000000","0.00008000"],["62643.97000000","0.00030000"],["62643.99000000","0.00018000"]]}}
{"t":21.5633,"stream":"btcusdt@depth@100ms","data":{"e":"depthUpdate","E":1783948024214,"s":"BTCUSDT","U":97344799306,"u":97344799325,"b":[["62638.63000000","0.00000000"],["56377.03000000","0.00480000"],["50112.92000000","0.00000000"]],"a":[["62641.15000000","0.07611000"],["62641.16000000","0.00097000"],["62645.55000000","0.07953000"],["62646.00000000","0.02418000"],["62646.21000000","0.17274000"],["62647.80000000","0.00556000"],["62648.74000000","0.10265000"],["62678.19000000","0.00000000"],["62763.62000000","0.07602000"]]}}
{"t":21.5638,"stream":"btcusdt@depth20@100ms","data":{"lastUpdateId":97344799325,"bids":[["62641.14000000","7.18778000"],["62641.13000000","0.00157000"],["62641.12000000","0.00016000"],["62640.95000000","0.63005000"],["62640.90000000","0.00008000"],["62640.34000000","0.30016000"],["62640.32000000","0.00009000"],["62640.01000000","0.02737000"],["62640.00000000","1.91796000"],["62639.99000000","0.54340000"],["62639.98000000","0.00449000"],["62639.86000000","0.00400000"],["62639.83000000","0.00016000"],["62639.77000000","0.04091000"],["62638.49000000","0.03984000"],["62638.44000000","0.00009000"],["62638.42000000","0.00008000"],["62638.29000000","0.00400000"],["62638.00000000","0.02400000"],["62637.99000000","0.00008000"]],"asks":[["62641.15000000","0.07611000"],["62641.16000000","0.00097000"],["62641.17000000","0.00016000"],["62641.56000000","0.00009000"],["62641.98000000","0.00008000"],["62641.99000000","0.00041000"],["62642.00000000","0.03469000"],["62642.19000000","0.00009000"],["62642.25000000","0.00008000"],["62642.40000000","0.00018000"],["62642.41000000","0.07705000"],["62642.81000000","0.00009000"],["62642.91000000","0.00032000"],["62643.07000000","0.00068000"],["62643.09000000","0.00016000"],["62643.20000000","0.00008000"],["62643.57000000","0.00008000"],["62643.76000000","0.00008000"],["62643.97000000","0.00030000"],["62643.99000000","0.00018000"]]}}
{"t":21.6169,"stream":"btcusdt@aggTrade","data":{"e":"aggTrade","E":1783948024267,"s":"BTCUSDT","a":4013160622,"p":"62641.15000000","q":"0.00081000","f":6501833958,"l":6501833958,"T":1783948024267,"m":false,"M":true}}
{"t":21.6643,"stream":"btcusdt@depth@100ms","data":{"e":"depthUpdate","E":1783948024314,"s":"BTCUSDT","U":97344799326,"u":97344799335,"b":[["56377.03000000","0.00480000"]],"a":[["62641.15000000","0.07530000"],["62670.63000000","0.03279000"],["62695.69000000","0.06062000"],["62763.62000000","0.00000000"],["63580.77000000","0.00030000"]]}}
{"t":21.6645,"stream":"btcusdt@depth20@100ms","data":{"lastUpdateId":97344799335,"bids":[["62641.14000000","7.18778000"],["62641.13000000","0.00157000"],["62641.12000000","0.00016000"],["62640.95000000","0.63005000"],["62640.90000000","0.00008000"],["62640.34000000","0.30016000"],["62640.32000000","0.00009000"],["62640.01000000","0.02737000"],["62640.00000000","1.91796000"],["62639.99000000","0.54340000"],["62639.98000000","0.00449000"],["62639.86000000","0.00400000"],["62639.83000000","0.00016000"],["62639.77000000","0.04091000"],["62638.49000000","0.03984000"],["62638.44000000","0.00009000"],["62638.42000000","0.00008000"],["62638.29000000","0.00400000"],["62638.00000000","0.02400000"],["62637.99000000","0.00008000"]],"asks":[["62641.15000000","0.07530000"],["62641.16000000","0.00097000"],["62641.17000000","0.00016000"],["62641.56000000","0.00009000"],["62641.98000000","0.00008000"],["62641.99000000","0.00041000"],["62642.00000000","0.03469000"],["62642.19000000","0.00009000"],["62642.25000000","0.00008000"],["62642.40000000","0.00018000"],["62642.41000000","0.07705000"],["62642.81000000","0.00009000"],["62642.91000000","0.00032000"],["62643.07000000","0.00068000"],["62643.09000000","0.00016000"],["62643.20000000","0.00008000"],["62643.57000000","0.00008000"],["62643.76000000","0.00008000"],["62643.97000000","0.00030000"],["62643.99000000","0.00018000"]]}}
{"t":21.7633,"stream":"btcusdt@depth@100ms","data":{"e":"depthUpdate","E":1783948024414,"s":"BTCUSDT","U":97344799336,"u":97344799344,"b":[["56377.03000000","0.00480000"]],"a":[["62652.97000000","1.91755000"],["62655.45000000","0.00000000"],["62656.42000000","0.00000000"],["62678.47000000","0.00011000"],["62763.60000000","0.07530000"]]}}
{"t":21.7635,"stream":"btcusdt@depth20@100ms","data":{"lastUpdateId":97344799344,"bids":[["62641.14000000","7.18778000"],["62641.13000000","0.00157000"],["62641.12000000","0.00016000"],["62640.95000000","0.63005000"],["62640.90000000","0.00008000"],["62640.34000000","0.30016000"],["62640.32000000","0.00009000"],["62640.01000000","0.02737000"],["62640.00000000","1.91796000"],["62639.99000000","0.54340000"],["62639.98000000","0.00449000"],["62639.86000000","0.00400000"],["62639.83000000","0.00016000"],["62639.77000000","0.04091000"],["62638.49000000","0.03984000"],["62638.44000000","0.00009000"],["62638.42000000","0.00008000"],["62638.29000000","0.00400000"],["62638.00000000","0.02400000"],["62637.99000000","0.00008000"]],"asks":[["62641.15000000","0.07530000"],["62641.16000000","0.00097000"],["62641.17000000","0.00016000"],["62641.56000000","0.00009000"],["62641.98000000","0.00008000"],["62641.99000000","0.00041000"],["62642.00000000","0.03469000"],["62642.19000000","0.00009000"],["62642.25000000","0.00008000"],["62642.40000000","0.00018000"],["62642.41000000","0.07705000"],["62642.81000000","0.00009000"],["62642.91000000","0.00032000"],["62643.07000000","0.00068000"],["62643.09000000","0.00016000"],["62643.20000000","0.00008000"],["62643.57000000","0.00008000"],["62643.76000000","0.00008000"],["62643.97000000","0.00030000"],["62643.99000000","0.00018000"]]}}
{"t":21.8648,"stream":"btcusdt@depth@100ms","data":{"e":"depthUpdate","E":1783948024514,"s":"BTCUSDT","U":97344799345,"u":97344799354,"b":[["62500.76000000","0.97406000"],["56377.03000000","0.00460000"],["56377.00000000","0.02164000"]],"a":[["62648.11000000","0.08493000"],["62648.74000000","0.00000000"],["62717.63000000","2.15344000"],["62763.60000000","0.00000000"]]}}
{"t":21.8649,"stream":"btcusdt@depth20@100ms","data":{"lastUpdateId":97344799354,"bids":[["62641.14000000","7.18778000"],["62641.13000000","0.00157000"],["62641.12000000","0.00016000"],["62640.95000000","0.63005000"],["62640.90000000","0.00008000"],["62640.34000000","0.30016000"],["62640.32000000","0.00009000"],["62640.01000000","0.02737000"],["62640.00000000","1.91796000"],["62639.99000000","0.54340000"],["62639.98000000","0.00449000"],["62639.86000000","0.00400000"],["62639.83000000","0.00016000"],["62639.77000000","0.04091000"],["62638.49000000","0.03984000"],["62638.44000000","0.00009000"],["62638.42000000","0.00008000"],["62638.29000000","0.00400000"],["62638.00000000","0.02400000"],["62637.99000000","0.00008000"]],"asks":[["62641.15000000","0.07530000"],["62641.16000000","0.00097000"],["62641.17000000","0.00016000"],["62641.56000000","0.00009000"],["62641.98000000","0.00008000"],["62641.99000000","0.00041000"],["62642.00000000","0.03469000"],["62642.19000000","0.00009000"],["62642.25000000","0.00008000"],["62642.40000000","0.00018000"],["62642.41000000","0.07705000"],["62642.81000000","0.00009000"],["62642.91000000","0.00032000"],["62643.07000000","0.00068000"],["62643.09000000","0.00016000"],["62643.20000000","0.00008000"],["62643.57000000","0.00008000"],["62643.76000000","0.00008000"],["62643.97000000","0.00030000"],["62643.99000000","0.00018000"]]}}
{"t":21.9644,"stream":"btcusdt@depth@100ms","data":{"e":"depthUpdate","E":1783948024614,"s":"BTCUSDT","U":97344799355,"u":97344799363,"b":[["62563.56000000","0.00159000"],["61000.00000000","1359.25962000"],["56377.03000000","0.00460000"]],"a":[["62647.41000000","0.11098000"],["62647.59000000","0.14126000"],["62648.11000000","0.00000000"]]}}
{"t":21.9646,"stream":"btcusdt@depth20@100ms","data":{"lastUpdateId":97344799363,"bids":[["62641.14000000","7.18778000"],["62641.13000000","0.00157000"],["62641.12000000","0.00016000"],["62640.95000000","0.63005000"],["62640.90000000","0.00008000"],["62640.34000000","0.30016000"],["62640.32000000","0.00009000"],["62640.01000000","0.02737000"],["62640.00000000","1.91796000"],["62639.99000000","0.54340000"],["62639.98000000","0.00449000"],["62639.86000000","0.00400000"],["62639.83000000","0.00016000"],["62639.77000000","0.04091000"],["62638.49000000","0.03984000"],["62638.44000000","0.00009000"],["62638.42000000","0.00008000"],["62638.29000000","0.00400000"],["62638.00000000","0.02400000"],["62637.99000000","0.00008000"]],"asks":[["62641.15000000","0.07530000"],["62641.16000000","0.00097000"],["62641.17000000","0.00016000"],["62641.56000000","0.00009000"],["62641.98000000","0.00008000"],["62641.99000000","0.00041000"],["62642.00000000","0.03469000"],["62642.19000000","0.00009000"],["62642.25000000","0.00008000"],["62642.40000000","0.00018000"],["62642.41000000","0.07705000"],["62642.81000000","0.00009000"],["62642.91000000","0.00032000"],["62643.07000000","0.00068000"],["62643.09000000","0.00016000"],["62643.20000000","0.00008000"],["62643.57000000","0.00008000"],["62643.76000000","0.00008000"],["62643.97000000","0.00030000"],["62643.99000000","0.00018000"]]}}
{"t":22.063,"stream":"btcusdt@depth@100ms","data":{"e":"depthUpdate","E":1783948024714,"s":"BTCUSDT","U":97344799364,"u":97344799377,"b":[["56377.03000000","0.00460000"]],"a":[["62646.56000000","0.13039000"],["62647.41000000","0.11116000"],["62647.59000000","0.14100000"]]}}
{"t":22.0641,"stream":"btcusdt@depth20@100ms","data":{"lastUpdateId":97344799377,"bids":[["62641.14000000","7.18778000"],["62641.13000000","0.00157000"],["62641.12000000","0.00016000"],["62640.95000000","0.63005000"],["62640.90000000","0.00008000"],["62640.34000000","0.30016000"],["62640.32000000","0.00009000"],["62640.01000000","0.02737000"],["62640.00000000","1.91796000"],["62639.99000000","0.54340000"],["62639.98000000","0.00449000"],["62639.86000000","0.00400000"],["62639.83000000","0.00016000"],["62639.77000000","0.04091000"],["62638.49000000","0.03984000"],["62638.44000000","0.00009000"],["62638.42000000","0.00008000"],["62638.29000000","0.00400000"],["62638.00000000","0.02400000"],["62637.99000000","0.00008000"]],"asks":[["62641.15000000","0.07530000"],["62641.16000000","0.00097000"],["62641.17000000","0.00016000"],["62641.56000000","0.00009000"],["62641.98000000","0.00008000"],["62641.99000000","0.00041000"],["62642.00000000","0.03469000"],["62642.19000000","0.00009000"],["62642.25000000","0.00008000"],["62642.40000000","0.00018000"],["62642.41000000","0.07705000"],["62642.81000000","0.00009000"],["62642.91000000","0.00032000"],["62643.07000000","0.00068000"],["62643.09000000","0.00016000"],["62643.20000000","0.00008000"],["62643.57000000","0.00008000"],["62643.76000000","0.00008000"],["62643.97000000","0.00030000"],["62643.99000000","0.00018000"]]}}
{"t":22.1633,"stream":"btcusdt@depth@100ms","data":{"e":"depthUpdate","E":1783948024814,"s":"BTCUSDT","U":97344799378,"u":97344799386,"b":[["62641.14000000","7.18934000"],["62500.77000000","0.00000000"],["62500.01000000","0.07450000"],["56377.03000000","0.00460000"]],"a":[["62652.95000000","0.59912000"],["62652.96000000","0.47600000"],["62659.15000000","0.01252000"]]}}
{"t":22.1634,"stream":"btcusdt@depth20@100ms","data":{"lastUpdateId":97344799386,"bids":[["62641.14000000","7.18934000"],["62641.13000000","0.00157000"],["62641.12000000","0.00016000"],["62640.95000000","0.63005000"],["62640.90000000","0.00008000"],["62640.34000000","0.30016000"],["62640.32000000","0.00009000"],["62640.01000000","0.02737000"],["62640.00000000","1.91796000"],["62639.99000000","0.54340000"],["62639.98000000","0.00449000"],["62639.86000000","0.00400000"],["62639.83000000","0.00016000"],["62639.77000000","0.04091000"],["62638.49000000","0.03984000"],["62638.44000000","0.00009000"],["62638.42000000","0.00008000"],["62638.29000000","0.00400000"],["62638.00000000","0.02400000"],["62637.99000000","0.00008000"]],"asks":[["62641.15000000","0.07530000"],["62641.16000000","0.00097000"],["62641.17000000","0.00016000"],["62641.56000000","0.00009000"],["62641.98000000","0.00008000"],["62641.99000000","0.00041000"],["62642.00000000","0.03469000"],["62642.19000000","0.00009000"],["62642.25000000","0.00008000"],["62642.40000000","0.00018000"],["62642.41000000","0.07705000"],["62642.81000000","0.00009000"],["62642.91000000","0.00032000"],["62643.07000000","0.00068000"],["62643.09000000","0.00016000"],["62643.20000000","0.00008000"],["62643.57000000","0.00008000"],["62643.76000000","0.00008000"],["62643.97000000","0.00030000"],["62643.99000000","0.00018000"]]}}
{"t":22.2636,"stream":"btcusdt@depth@100ms","data":{"e":"depthUpdate","E":1783948024914,"s":"BTCUSDT","U":97344799387,"u":97344799396,"b":[["62627.12000000","0.00008000"],["56377.03000000","0.00460000"]],"a":[["62652.19000000","0.00008000"],["62652.95000000","0.00000000"],["62658.69000000","0.59912000"],["62677.54000000","0.00400000"],["62679.11000000","0.00000000"]]}}
{"t":22.2637,"stream":"btcusdt@depth20@100ms","data":{"lastUpdateId":97344799396,"bids":[["62641.14000000","7.18934000"],["62641.13000000","0.00157000"],["62641.12000000","0.00016000"],["62640.95000000","0.63005000"],["62640.90000000","0.00008000"],["62640.34000000","0.30016000"],["62640.32000000","0.00009000"],["62640.01000000","0.02737000"],["62640.00000000","1.91796000"],["62639.99000000","0.54340000"],["62639.98000000","0.00449000"],["62639.86000000","0.00400000"],["62639.83000000","0.00016000"],["62639.77000000","0.04091000"],["62638.49000000","0.03984000"],["62638.44000000","0.00009000"],["62638.42000000","0.00008000"],["62638.29000000","0.00400000"],["62638.00000000","0.02400000"],["62637.99000000","0.00008000"]],"asks":[["62641.15000000","0.07530000"],["62641.16000000","0.00097000"],["62641.17000000","0.00016000"],["62641.56000000","0.00009000"],["62641.98000000","0.00008000"],["62641.99000000","0.00041000"],["62642.00000000","0.03469000"],["62642.19000000","0.00009000"],["62642.25000000","0.00008000"],["62642.40000000","0.00018000"],["62642.41000000","0.07705000"],["62642.81000000","0.00009000"],["62642.91000000","0.00032000"],["62643.07000000","0.00068000"],["62643.09000000","0.00016000"],["62643.20000000","0.00008000"],["62643.57000000","0.00008000"],["62643.76000000","0.00008000"],["62643.97000000","0.00030000"],["62643.99000000","0.00018000"]]}}
{"t":22.3647,"stream":"btcusdt@depth@100ms","data":{"e":"depthUpdate","E":1783948025014,"s":"BTCUSDT","U":97344799397,"u":97344799419,"b":[["62639.99000000","0.15856000"],["62588.02000000","0.00113000"],["62525.48000000","0.00045000"],["61701.52000000","0.00030000"],["57628.79000000","0.00018000"],["56377.03000000","0.00460000"],["50112.92000000","0.00039000"],["50112.91000000","0.00000000"]],"a":[["62652.95000000","0.00000000"],["62658.69000000","0.59912000"],["62763.53000000","0.00000000"]]}}
{"t":22.3648,"stream":"btcusdt@depth20@100ms","data":{"lastUpdateId":97344799419,"bids":[["62641.14000000","7.18934000"],["62641.13000000","0.00157000"],["62641.12000000","0.00016000"],["62640.95000000","0.63005000"],["62640.90000000","0.00008000"],["62640.34000000","0.30016000"],["62640.32000000","0.00009000"],["62640.01000000","0.02737000"],["62640.00000000","1.91796000"],["62639.99000000","0.15856000"],["62639.98000000","0.00449000"],["62639.86000000","0.00400000"],["62639.83000000","0.00016000"],["62639.77000000","0.04091000"],["62638.49000000","0.03984000"],["62638.44000000","0.00009000"],["62638.42000000","0.00008000"],["62638.29000000","0.00400000"],["62638.00000000","0.02400000"],["62637.99000000","0.00008000"]],"asks":[["62641.15000000","0.07530000"],["62641.16000000","0.00097000"],["62641.17000000","0.00016000"],["62641.56000000","0.00009000"],["62641.98000000","0.00008000"],["62641.99000000","0.00041000"],["62642.00000000","0.03469000"],["62642.19000000","0.00009000"],["62642.25000000","0.00008000"],["62642.40000000","0.00018000"],["62642.41000000","0.07705000"],["62642.81000000","0.00009000"],["62642.91000000","0.00032000"],["62643.07000000","0.00068000"],["62643.09000000","0.00016000"],["62643.20000000","0.00008000"],["62643.57000000","0.00008000"],["62643.76000000","0.00008000"],["62643.97000000","0.00030000"],["62643.99000000","0.00018000"]]}}
{"t":22.4643,"stream":"btcusdt@depth@100ms","data":{"e":"depthUpdate","E":1783948025114,"s":"BTCUSDT","U":97344799420,"u":97344799432,"b":[["62588.02000000","0.00113000"],["62525.48000000","0.00000000"],["56377.03000000","0.00460000"],["50112.91000000","0.00000000"],["40000.00000000","258.07540000"]],"a":[["62647.41000000","0.00018000"],["62659.76000000","0.00000000"],["62659.99000000","0.00000000"],["62661.79000000","0.59539000"]]}}
{"t":22.4644,"stream":"btcusdt@depth20@100ms","data":{"lastUpdateId":97344799432,"bids":[["62641.14000000","7.18934000"],["62641.13000000","0.00157000"],["62641.12000000","0.00016000"],["62640.95000000","0.63005000"],["62640.90000000","0.00008000"],["62640.34000000","0.30016000"],["62640.32000000","0.00009000"],["62640.01000000","0.02737000"],["62640.00000000","1.91796000"],["62639.99000000","0.15856000"],["62639.98000000","0.00449000"],["62639.86000000","0.00400000"],["62639.83000000","0.00016000"],["62639.77000000","0.04091000"],["62638.49000000","0.03984000"],["62638.44000000","0.00009000"],["62638.42000000","0.00008000"],["62638.29000000","0.00400000"],["62638.00000000","0.02400000"],["62637.99000000","0.00008000"]],"asks":[["62641.15000000","0.07530000"],["62641.16000000","0.00097000"],["62641.17000000","0.00016000"],["62641.56000000","0.00009000"],["62641.98000000","0.00008000"],["62641.99000000","0.00041000"],["62642.00000000","0.03469000"],["62642.19000000","0.00009000"],["62642.25000000","0.00008000"],["62642.40000000","0.00018000"],["62642.41000000","0.07705000"],["62642.81000000","0.00009000"],["62642.91000000","0.00032000"],["62643.07000000","0.00068000"],["62643.09000000","0.00016000"],["62643.20000000","0.00008000"],["62643.57000000","0.00008000"],["62643.76000000","0.00008000"],["62643.97000000","0.00030000"],["62643.99000000","0.00018000"]]}}
{"t":22.5635,"stream":"btcusdt@depth@100ms","data":{"e":"depthUpdate","E":1783948025214,"s":"BTCUSDT","U":97344799433,"u":97344799451,"b":[["62641.13000000","0.00034000"],["56377.03000000","0.00460000"],["50112.92000000","0.00000000"]],"a":[["62646.56000000","0.13031000"],["62647.41000000","0.00000000"],["62647.59000000","0.14118000"],["62659.99000000","0.08072000"],["62661.79000000","0.00000000"],["62678.47000000","0.00000000"],["62763.58000000","0.00000000"]]}}
{"t":22.5635,"stream":"btcusdt@depth20@100ms","data":{"lastUpdateId":97344799451,"bids":[["62641.14000000","7.18934000"],["62641.13000000","0.00034000"],["62641.12000000","0.00016000"],["62640.95000000","0.63005000"],["62640.90000000","0.00008000"],["62640.34000000","0.30016000"],["62640.32000000","0.00009000"],["62640.01000000","0.02737000"],["62640.00000000","1.91796000"],["62639.99000000","0.15856000"],["62639.98000000","0.00449000"],["62639.86000000","0.00400000"],["62639.83000000","0.00016000"],["62639.77000000","0.04091000"],["62638.49000000","0.03984000"],["62638.44000000","0.00009000"],["62638.42000000","0.00008000"],["62638.29000000","0.00400000"],["62638.00000000","0.02400000"],["62637.99000000","0.00008000"]],"asks":[["62641.15000000","0.07530000"],["62641.16000000","0.00097000"],["62641.17000000","0.00016000"],["62641.56000000","0.00009000"],["62641.98000000","0.00008000"],["62641.99000000","0.00041000"],["62642.00000000","0.03469000"],["62642.19000000","0.00009000"],["62642.25000000","0.00008000"],["62642.40000000","0.00018000"],["62642.41000000","0.07705000"],["62642.81000000","0.00009000"],["62642.91000000","0.00032000"],["62643.07000000","0.00068000"],["62643.09000000","0.00016000"],["62643.20000000","0.00008000"],["62643.57000000","0.00008000"],["62643.76000000","0.00008000"],["62643.97000000","0.00030000"],["62643.99000000","0.00018000"]]}}
{"t":22.6642,"stream":"btcusdt@depth@100ms","data":{"e":"depthUpdate","E":1783948025314,"s":"BTCUSDT","U":97344799452,"u":97344799463,"b":[["56377.03000000","0.00460000"],["51000.00000000","167.99296000"]],"a":[["62641.15000000","0.07652000"],["62763.58000000","0.00000000"],["63580.77000000","0.00030000"]]}}
{"t":22.6643,"stream":"btcusdt@depth20@100ms","data":{"lastUpdateId":97344799463,"bids":[["62641.14000000","7.18934000"],["62641.13000000","0.00034000"],["62641.12000000","0.00016000"],["62640.95000000","0.63005000"],["62640.90000000","0.00008000"],["62640.34000000","0.30016000"],["62640.32000000","0.00009000"],["62640.01000000","0.02737000"],["62640.00000000","1.91796000"],["62639.99000000","0.15856000"],["62639.98000000","0.00449000"],["62639.86000000","0.00400000"],["62639.83000000","0.00016000"],["62639.77000000","0.04091000"],["62638.49000000","0.03984000"],["62638.44000000","0.00009000"],["62638.42000000","0.00008000"],["62638.29000000","0.00400000"],["62638.00000000","0.02400000"],["62637.99000000","0.00008000"]],"asks":[["62641.15000000","0.07652000"],["62641.16000000","0.00097000"],["62641.17000000","0.00016000"],["62641.56000000","0.00009000"],["62641.98000000","0.00008000"],["62641.99000000","0.00041000"],["62642.00000000","0.03469000"],["62642.19000000","0.00009000"],["62642.25000000","0.00008000"],["62642.40000000","0.00018000"],["62642.41000000","0.07705000"],["62642.81000000","0.00009000"],["62642.91000000","0.00032000"],["62643.07000000","0.00068000"],["62643.09000000","0.00016000"],["62643.20000000","0.00008000"],["62643.57000000","0.00008000"],["62643.76000000","0.00008000"],["62643.97000000","0.00030000"],["62643.99000000","0.00018000"]]}}
{"t":22.7635,"stream":"btcusdt@depth@100ms","data":{"e":"depthUpdate","E":1783948025414,"s":"BTCUSDT","U":97344799464,"u":97344799471,"b":[["62641.14000000","7.21088000"],["62635.27000000","0.00000000"],["56377.03000000","0.00480000"]],"a":[["62678.58000000","0.00011000"]]}}
{"t":22.7636,"stream":"btcusdt@depth20@100ms","data":{"lastUpdateId":97344799471,"bids":[["62641.14000000","7.21088000"],["62641.13000000","0.00034000"],["62641.12000000","0.00016000"],["62640.95000000","0.63005000"],["62640.90000000","0.00008000"],["62640.34000000","0.30016000"],["62640.32000000","0.00009000"],["62640.01000000","0.02737000"],["62640.00000000","1.91796000"],["62639.99000000","0.15856000"],["62639.98000000","0.00449000"],["62639.86000000","0.00400000"],["62639.83000000","0.00016000"],["62639.77000000","0.04091000"],["62638.49000000","0.03984000"],["62638.44000000","0.00009000"],["62638.42000000","0.00008000"],["62638.29000000","0.00400000"],["62638.00000000","0.02400000"],["62637.99000000","0.00008000"]],"asks":[["62641.15000000","0.07652000"],["62641.16000000","0.00097000"],["62641.17000000","0.00016000"],["62641.56000000","0.00009000"],["62641.98000000","0.00008000"],["62641.99000000","0.00041000"],["62642.00000000","0.03469000"],["62642.19000000","0.00009000"],["62642.25000000","0.00008000"],["62642.40000000","0.00018000"],["62642.41000000","0.07705000"],["62642.81000000","0.00009000"],["62642.91000000","0.00032000"],["62643.07000000","0.00068000"],["62643.09000000","0.00016000"],["62643.20000000","0.00008000"],["62643.57000000","0.00008000"],["62643.76000000","0.00008000"],["62643.97000000","0.00030000"],["62643.99000000","0.00018000"]]}}
{"t":22.865,"stream":"btcusdt@depth@100ms","data":{"e":"depthUpdate","E":1783948025514,"s":"BTCUSDT","U":97344799472,"u":97344799484,"b":[["62636.79000000","0.59920000"],["62636.01000000","0.00000000"],["62634.24000000","0.31460000"],["57628.79000000","0.00000000"],["56377.03000000","0.00480000"]],"a":[["62647.59000000","0.14126000"],["62648.16000000","0.09532000"],["62650.33000000","0.00009000"],["62652.94000000","0.59912000"],["62652.95000000","0.00000000"],["62658.69000000","0.00000000"]]}}
{"t":22.8652,"stream":"btcusdt@depth20@100ms","data":{"lastUpdateId":97344799484,"bids":[["62641.14000000","7.21088000"],["62641.13000000","0.00034000"],["62641.12000000","0.00016000"],["62640.95000000","0.63005000"],["62640.90000000","0.00008000"],["62640.34000000","0.30016000"],["62640.32000000","0.00009000"],["62640.01000000","0.02737000"],["62640.00000000","1.91796000"],["62639.99000000","0.15856000"],["62639.98000000","0.00449000"],["62639.86000000","0.00400000"],["62639.83000000","0.00016000"],["62639.77000000","0.04091000"],["62638.49000000","0.03984000"],["62638.44000000","0.00009000"],["62638.42000000","0.00008000"],["62638.29000000","0.00400000"],["62638.00000000","0.02400000"],["62637.99000000","0.00008000"]],"asks":[["62641.15000000","0.07652000"],["62641.16000000","0.00097000"],["62641.17000000","0.00016000"],["62641.56000000","0.00009000"],["62641.98000000","0.00008000"],["62641.99000000","0.00041000"],["62642.00000000","0.03469000"],["62642.19000000","0.00009000"],["62642.25000000","0.00008000"],["62642.40000000","0.00018000"],["62642.41000000","0.07705000"],["62642.81000000","0.00009000"],["62642.91000000","0.00032000"],["62643.07000000","0.00068000"],["62643.09000000","0.00016000"],["62643.20000000","0.00008000"],["62643.57000000","0.00008000"],["62643.76000000","0.00008000"],["62643.97000000","0.00030000"],["62643.99000000","0.00018000"]]}}
{"t":22.8807,"stream":"btcusdt@aggTrade","data":{"e":"aggTrade","E":1783948025529,"s":"BTCUSDT","a":4013160623,"p":"62641.14000000","q":"0.00958000","f":6501833959,"l":6501833959,"T":1783948025528,"m":true,"M":true}}
{"t":22.9646,"stream":"btcusdt@depth@100ms","data":{"e":"depthUpdate","E":1783948025614,"s":"BTCUSDT","U":97344799485,"u":97344799494,"b":[["62641.14000000","7.20130000"],["62551.00000000","0.00000000"],["56377.03000000","0.00480000"],["56377.02000000","0.00010000"],["56377.00000000","0.02184000"]],"a":[["62652.94000000","0.00000000"],["62658.69000000","0.59911000"],["62660.96000000","0.13189000"]]}}
{"t":22.9647,"stream":"btcusdt@depth20@100ms","data":{"lastUpdateId":97344799494,"bids":[["62641.14000000","7.20130000"],["62641.13000000","0.00034000"],["62641.12000000","0.00016000"],["62640.95000000","0.63005000"],["62640.90000000","0.00008000"],["62640.34000000","0.30016000"],["62640.32000000","0.00009000"],["62640.01000000","0.02737000"],["62640.00000000","1.91796000"],["62639.99000000","0.15856000"],["62639.98000000","0.00449000"],["62639.86000000","0.00400000"],["62639.83000000","0.00016000"],["62639.77000000","0.04091000"],["62638.49000000","0.03984000"],["62638.44000000","0.00009000"],["62638.42000000","0.00008000"],["62638.29000000","0.00400000"],["62638.00000000","0.02400000"],["62637.99000000","0.00008000"]],"asks":[["62641.15000000","0.07652000"],["62641.16000000","0.00097000"],["62641.17000000","0.00016000"],["62641.56000000","0.00009000"],["62641.98000000","0.00008000"],["62641.99000000","0.00041000"],["62642.00000000","0.03469000"],["62642.19000000","0.00009000"],["62642.25000000","0.00008000"],["62642.40000000","0.00018000"],["62642.41000000","0.07705000"],["62642.81000000","0.00009000"],["62642.91000000","0.00032000"],["62643.07000000","0.00068000"],["62643.09000000","0.00016000"],["62643.20000000","0.00008000"],["62643.57000000","0.00008000"],["62643.76000000","0.00008000"],["62643.97000000","0.00030000"],["62643.99000000","0.00018000"]]}}
{"t":23.0639,"stream":"btcusdt@depth@100ms","data":{"e":"depthUpdate","E":1783948025714,"s":"BTCUSDT","U":97344799495,"u":97344799503,"b":[["62614.96000000","1.91755000"],["62562.50000000","0.00275000"],["62553.63000000","0.04954000"],["56377.03000000","0.00480000"],["56377.00000000","0.02164000"]],"a":[["62652.97000000","0.00000000"]]}}
{"t":23.064,"stream":"btcusdt@depth20@100ms","data":{"lastUpdateId":97344799503,"bids":[["62641.14000000","7.20130000"],["62641.13000000","0.00034000"],["62641.12000000","0.00016000"],["62640.95000000","0.63005000"],["62640.90000000","0.00008000"],["62640.34000000","0.30016000"],["62640.32000000","0.00009000"],["62640.01000000","0.02737000"],["62640.00000000","1.91796000"],["62639.99000000","0.15856000"],["62639.98000000","0.00449000"],["62639.86000000","0.00400000"],["62639.83000000","0.00016000"],["62639.77000000","0.04091000"],["62638.49000000","0.03984000"],["62638.44000000","0.00009000"],["62638.42000000","0.00008000"],["62638.29000000","0.00400000"],["62638.00000000","0.02400000"],["62637.99000000","0.00008000"]],"asks":[["62641.15000000","0.07652000"],["62641.16000000","0.00097000"],["62641.17000000","0.00016000"],["62641.56000000","0.00009000"],["62641.98000000","0.00008000"],["62641.99000000","0.00041000"],["62642.00000000","0.03469000"],["62642.19000000","0.00009000"],["62642.25000000","0.00008000"],["62642.40000000","0.00018000"],["62642.41000000","0.07705000"],["62642.81000000","0.00009000"],["62642.91000000","0.00032000"],["62643.07000000","0.00068000"],["62643.09000000","0.00016000"],["62643.20000000","0.00008000"],["62643.57000000","0.00008000"],["62643.76000000","0.00008000"],["62643.97000000","0.00030000"],["62643.99000000","0.00018000"]]}}
{"t":23.1634,"stream":"btcusdt@depth@100ms","data":{"e":"depthUpdate","E":1783948025814,"s":"BTCUSDT","U":97344799504,"u":97344799508,"b":[["62636.01000000","0.08556000"],["62634.24000000","0.00000000"],["56377.03000000","0.00480000"]],"a":[]}}
{"t":23.1635,"stream":"btcusdt@depth20@100ms","data":{"lastUpdateId":97344799508,"bids":[["62641.14000000","7.20130000"],["62641.13000000","0.00034000"],["62641.12000000","0.00016000"],["62640.95000000","0.63005000"],["62640.90000000","0.00008000"],["62640.34000000","0.30016000"],["62640.32000000","0.00009000"],["62640.01000000","0.02737000"],["62640.00000000","1.91796000"],["62639.99000000","0.15856000"],["62639.98000000","0.00449000"],["62639.86000000","0.00400000"],["62639.83000000","0.00016000"],["62639.77000000","0.04091000"],["62638.49000000","0.03984000"],["62638.44000000","0.00009000"],["62638.42000000","0.00008000"],["62638.29000000","0.00400000"],["62638.00000000","0.02400000"],["62637.99000000","0.00008000"]],"asks":[["62641.15000000","0.07652000"],["62641.16000000","0.00097000"],["62641.17000000","0.00016000"],["62641.56000000","0.00009000"],["62641.98000000","0.00008000"],["62641.99000000","0.00041000"],["62642.00000000","0.03469000"],["62642.19000000","0.00009000"],["62642.25000000","0.00008000"],["62642.40000000","0.00018000"],["62642.41000000","0.07705000"],["62642.81000000","0.00009000"],["62642.91000000","0.00032000"],["62643.07000000","0.00068000"],["62643.09000000","0.00016000"],["62643.20000000","0.00008000"],["62643.57000000","0.00008000"],["62643.76000000","0.00008000"],["62643.97000000","0.00030000"],["62643.99000000","0.00018000"]]}}
{"t":23.2643,"stream":"btcusdt@depth@100ms","data":{"e":"depthUpdate","E":1783948025914,"s":"BTCUSDT","U":97344799509,"u":97344799529,"b":[["62641.14000000","4.00852000"],["62636.79000000","0.59928000"],["62635.60000000","3.19278000"],["62627.12000000","0.00008000"],["56377.03000000","0.00480000"]],"a":[["62641.15000000","0.07661000"],["62646.26000000","0.08778000"],["62646.56000000","0.13039000"],["62646.91000000","0.00000000"],["62647.59000000","0.14118000"],["62648.16000000","0.00000000"],["62652.19000000","0.00008000"],["62652.95000000","0.59912000"],["62652.97000000","1.91755000"],["62658.68000000","0.00000000"],["62658.69000000","0.00000000"]]}}
{"t":23.2644,"stream":"btcusdt@depth20@100ms","data":{"lastUpdateId":97344799529,"bids":[["62641.14000000","4.00852000"],["62641.13000000","0.00034000"],["62641.12000000","0.00016000"],["62640.95000000","0.63005000"],["62640.90000000","0.00008000"],["62640.34000000","0.30016000"],["62640.32000000","0.00009000"],["62640.01000000","0.02737000"],["62640.00000000","1.91796000"],["62639.99000000","0.15856000"],["62639.98000000","0.00449000"],["62639.86000000","0.00400000"],["62639.83000000","0.00016000"],["62639.77000000","0.04091000"],["62638.49000000","0.03984000"],["62638.44000000","0.00009000"],["62638.42000000","0.00008000"],["62638.29000000","0.00400000"],["62638.00000000","0.02400000"],["62637.99000000","0.00008000"]],"asks":[["62641.15000000","0.07661000"],["62641.16000000","0.00097000"],["62641.17000000","0.00016000"],["62641.56000000","0.00009000"],["62641.98000000","0.00008000"],["62641.99000000","0.00041000"],["62642.00000000","0.03469000"],["62642.19000000","0.00009000"],["62642.25000000","0.00008000"],["62642.40000000","0.00018000"],["62642.41000000","0.07705000"],["62642.81000000","0.00009000"],["62642.91000000","0.00032000"],["62643.07000000","0.00068000"],["62643.09000000","0.00016000"],["62643.20000000","0.00008000"],["62643.57000000","0.00008000"],["62643.76000000","0.00008000"],["62643.97000000","0.00030000"],["62643.99000000","0.00018000"]]}}
{"t":23.3649,"stream":"btcusdt@depth@100ms","data":{"e":"depthUpdate","E":1783948026014,"s":"BTCUSDT","U":97344799530,"u":97344799593,"b":[["62640.96000000","0.00018000"],["62640.35000000","0.00018000"],["62640.01000000","0.02755000"],["62640.00000000","1.91814000"],["62636.79000000","0.00016000"],["62636.01000000","0.00000000"],["62635.61000000","0.59913000"],["62634.24000000","0.19916000"],["62632.62000000","0.00000000"],["62631.00000000","0.79882000"],["62588.02000000","0.00113000"],["62525.48000000","0.00045000"],["62500.77000000","0.00999000"],["62500.01000000","0.06451000"],["61701.52000000","0.00030000"],["56377.03000000","0.00460000"],["50112.92000000","0.00039000"],["50112.91000000","0.00000000"]],"a":[["62641.15000000","0.07548000"],["62641.16000000","0.00115000"],["62644.71000000","0.00256000"],["62645.53000000","0.00018000"],["62645.54000000","0.13984000"],["62645.99000000","0.00000000"],["62646.21000000","0.00026000"],["62646.26000000","0.08796000"],["62646.56000000","0.13031000"],["62647.59000000","0.14100000"],["62650.33000000","0.00000000"],["62661.79000000","0.79882000"],["62664.40000000","0.00000000"],["62678.70000000","0.00000000"],["62763.58000000","0.00000000"]]}}
{"t":23.3651,"stream":"btcusdt@depth20@100ms","data":{"lastUpdateId":97344799593,"bids":[["62641.14000000","4.00852000"],["62641.13000000","0.00034000"],["62641.12000000","0.00016000"],["62640.96000000","0.00018000"],["62640.95000000","0.63005000"],["62640.90000000","0.00008000"],["62640.35000000","0.00018000"],["62640.34000000","0.30016000"],["62640.32000000","0.00009000"],["62640.01000000","0.02755000"],["62640.00000000","1.91814000"],["62639.99000000","0.15856000"],["62639.98000000","0.00449000"],["62639.86000000","0.00400000"],["62639.83000000","0.00016000"],["62639.77000000","0.04091000"],["62638.49000000","0.03984000"],["62638.44000000","0.00009000"],["62638.42000000","0.00008000"],["62638.29000000","0.00400000"]],"asks":[["62641.15000000","0.07548000"],["62641.16000000","0.00115000"],["62641.17000000","0.00016000"],["62641.56000000","0.00009000"],["62641.98000000","0.00008000"],["62641.99000000","0.00041000"],["62642.00000000","0.03469000"],["62642.19000000","0.00009000"],["62642.25000000","0.00008000"],["62642.40000000","0.00018000"],["62642.41000000","0.07705000"],["62642.81000000","0.00009000"],["62642.91000000","0.00032000"],["62643.07000000","0.00068000"],["62643.09000000","0.00016000"],["62643.20000000","0.00008000"],["62643.57000000","0.00008000"],["62643.76000000","0.00008000"],["62643.97000000","0.00030000"],["62643.99000000","0.00018000"]]}}
{"t":23.4661,"stream":"btcusdt@depth@100ms","data":{"e":"depthUpdate","E":1783948026114,"s":"BTCUSDT","U":97344799594,"u":97344799628,"b":[["62641.14000000","4.00973000"],["62637.37000000","0.06712000"],["62636.79000000","0.00008000"],["62588.02000000","0.00000000"],["62525.48000000","0.00045000"],["56377.03000000","0.00460000"],["50112.91000000","0.00000000"],["40000.00000000","258.07540000"],["33000.00000000","33.37028000"]],"a":[["62641.15000000","0.07539000"],["62641.16000000","0.00106000"],["62644.00000000","0.02418000"],["62645.54000000","0.14002000"],["62646.00000000","0.02418000"],["62646.21000000","0.00008000"],["62646.26000000","0.00027000"],["62720.31000000","0.00919000"],["62763.58000000","0.00000000"]]}}
{"t":23.4664,"stream":"btcusdt@depth20@100ms","data":{"lastUpdateId":97344799628,"bids":[["62641.14000000","4.00973000"],["62641.13000000","0.00034000"],["62641.12000000","0.00016000"],["62640.96000000","0.00018000"],["62640.95000000","0.63005000"],["62640.90000000","0.00008000"],["62640.35000000","0.00018000"],["62640.34000000","0.30016000"],["62640.32000000","0.00009000"],["62640.01000000","0.02755000"],["62640.00000000","1.91814000"],["62639.99000000","0.15856000"],["62639.98000000","0.00449000"],["62639.86000000","0.00400000"],["62639.83000000","0.00016000"],["62639.77000000","0.04091000"],["62638.49000000","0.03984000"],["62638.44000000","0.00009000"],["62638.42000000","0.00008000"],["62638.29000000","0.00400000"]],"asks":[["62641.15000000","0.07539000"],["62641.16000000","0.00106000"],["62641.17000000","0.00016000"],["62641.56000000","0.00009000"],["62641.98000000","0.00008000"],["62641.99000000","0.00041000"],["62642.00000000","0.03469000"],["62642.19000000","0.00009000"],["62642.25000000","0.00008000"],["62642.40000000","0.00018000"],["62642.41000000","0.07705000"],["62642.81000000","0.00009000"],["62642.91000000","0.00032000"],["62643.07000000","0.00068000"],["62643.09000000","0.00016000"],["62643.20000000","0.00008000"],["62643.57000000","0.00008000"],["62643.76000000","0.00008000"],["62643.97000000","0.00030000"],["62643.99000000","0.00018000"]]}}
{"t":23.5641,"stream":"btcusdt@depth@100ms","data":{"e":"depthUpdate","E":1783948026214,"s":"BTCUSDT","U":97344799629,"u":97344799643,"b":[["56377.03000000","0.00460000"],["50112.92000000","0.00000000"]],"a":[["62641.15000000","0.07889000"],["62646.00000000","0.02418000"],["62646.26000000","0.00009000"],["62647.59000000","0.14118000"],["62763.58000000","0.07539000"]]}}
{"t":23.5643,"stream":"btcusdt@depth20@100ms","data":{"lastUpdateId":97344799643,"bids":[["62641.14000000","4.00973000"],["62641.13000000","0.00034000"],["62641.12000000","0.00016000"],["62640.96000000","0.00018000"],["62640.95000000","0.63005000"],["62640.90000000","0.00008000"],["62640.35000000","0.00018000"],["62640.34000000","0.30016000"],["62640.32000000","0.00009000"],["62640.01000000","0.02755000"],["62640.00000000","1.91814000"],["62639.99000000","0.15856000"],["62639.98000000","0.00449000"],["62639.86000000","0.00400000"],["62639.83000000","0.00016000"],["62639.77000000","0.04091000"],["62638.49000000","0.03984000"],["62638.44000000","0.00009000"],["62638.42000000","0.00008000"],["62638.29000000","0.00400000"]],"asks":[["62641.15000000","0.07889000"],["62641.16000000","0.00106000"],["62641.17000000","0.00016000"],["62641.56000000","0.00009000"],["62641.98000000","0.00008000"],["62641.99000000","0.00041000"],["62642.00000000","0.03469000"],["62642.19000000","0.00009000"],["62642.25000000","0.00008000"],["62642.40000000","0.00018000"],["62642.41000000","0.07705000"],["62642.81000000","0.00009000"],["62642.91000000","0.00032000"],["62643.07000000","0.00068000"],["62643.09000000","0.00016000"],["62643.20000000","0.00008000"],["62643.57000000","0.00008000"],["62643.76000000","0.00008000"],["62643.97000000","0.00030000"],["62643.99000000","0.00018000"]]}}
{"t":23.667,"stream":"btcusdt@depth@100ms","data":{"e":"depthUpdate","E":1783948026314,"s":"BTCUSDT","U":97344799644,"u":97344799671,"b":[["56377.03000000","0.00460000"]],"a":[["62641.15000000","0.07539000"],["62641.16000000","0.00106000"],["62642.41000000","0.07713000"],["62643.54000000","0.00018000"],["62643.55000000","0.17512000"],["62644.71000000","0.00000000"],["62645.54000000","0.13984000"],["62647.20000000","0.00008000"],["62648.87000000","0.11298000"],["62671.10000000","0.00038000"],["62678.58000000","0.00000000"],["62763.58000000","0.00000000"],["62763.61000000","0.00000000"],["63580.77000000","0.00030000"]]}}
{"t":23.6727,"stream":"btcusdt@depth20@100ms","data":{"lastUpdateId":97344799671,"bids":[["62641.14000000","4.00973000"],["62641.13000000","0.00034000"],["62641.12000000","0.00016000"],["62640.96000000","0.00018000"],["62640.95000000","0.63005000"],["62640.90000000","0.00008000"],["62640.35000000","0.00018000"],["62640.34000000","0.30016000"],["62640.32000000","0.00009000"],["62640.01000000","0.02755000"],["62640.00000000","1.91814000"],["62639.99000000","0.15856000"],["62639.98000000","0.00449000"],["62639.86000000","0.00400000"],["62639.83000000","0.00016000"],["62639.77000000","0.04091000"],["62638.49000000","0.03984000"],["62638.44000000","0.00009000"],["62638.42000000","0.00008000"],["62638.29000000","0.00400000"]],"asks":[["62641.15000000","0.07539000"],["62641.16000000","0.00106000"],["62641.17000000","0.00016000"],["62641.56000000","0.00009000"],["62641.98000000","0.00008000"],["62641.99000000","0.00041000"],["62642.00000000","0.03469000"],["62642.19000000","0.00009000"],["62642.25000000","0.00008000"],["62642.40000000","0.00018000"],["62642.41000000","0.07713000"],["62642.81000000","0.00009000"],["62642.91000000","0.00032000"],["62643.07000000","0.00068000"],["62643.09000000","0.00016000"],["62643.20000000","0.00008000"],["62643.54000000","0.00018000"],["62643.55000000","0.17512000"],["62643.57000000","0.00008000"],["62643.76000000","0.00008000"]]}}
{"t":23.7653,"stream":"btcusdt@depth@100ms","data":{"e":"depthUpdate","E":1783948026414,"s":"BTCUSDT","U":97344799672,"u":97344799691,"b":[["62582.61000000","2.89954000"],["62580.50000000","0.00000000"],["56377.03000000","0.00460000"],["50113.00000000","0.00193000"]],"a":[["62642.41000000","0.07713000"],["62643.55000000","0.17530000"],["62647.59000000","0.14100000"],["62671.10000000","0.00000000"],["62678.69000000","0.00011000"],["62763.61000000","0.00000000"]]}}
{"t":23.7655,"stream":"btcusdt@depth20@100ms","data":{"lastUpdateId":97344799691,"bids":[["62641.14000000","4.00973000"],["62641.13000000","0.00034000"],["62641.12000000","0.00016000"],["62640.96000000","0.00018000"],["62640.95000000","0.63005000"],["62640.90000000","0.00008000"],["62640.35000000","0.00018000"],["62640.34000000","0.30016000"],["62640.32000000","0.00009000"],["62640.01000000","0.02755000"],["62640.00000000","1.91814000"],["62639.99000000","0.15856000"],["62639.98000000","0.00449000"],["62639.86000000","0.00400000"],["62639.83000000","0.00016000"],["62639.77000000","0.04091000"],["62638.49000000","0.03984000"],["62638.44000000","0.00009000"],["62638.42000000","0.00008000"],["62638.29000000","0.00400000"]],"asks":[["62641.15000000","0.07539000"],["62641.16000000","0.00106000"],["62641.17000000","0.00016000"],["62641.56000000","0.00009000"],["62641.98000000","0.00008000"],["62641.99000000","0.00041000"],["62642.00000000","0.03469000"],["62642.19000000","0.00009000"],["62642.25000000","0.00008000"],["62642.40000000","0.00018000"],["62642.41000000","0.07713000"],["62642.81000000","0.00009000"],["62642.91000000","0.00032000"],["62643.07000000","0.00068000"],["62643.09000000","0.00016000"],["62643.20000000","0.00008000"],["62643.54000000","0.00018000"],["62643.55000000","0.17530000"],["62643.57000000","0.00008000"],["62643.76000000","0.00008000"]]}}
{"t":23.8649,"stream":"btcusdt@depth@100ms","data":{"e":"depthUpdate","E":1783948026514,"s":"BTCUSDT","U":97344799692,"u":97344799697,"b":[["56377.03000000","0.00460000"]],"a":[["62763.58000000","0.00000000"]]}}
{"t":23.8651,"stream":"btcusdt@depth20@100ms","data":{"lastUpdateId":97344799697,"bids":[["62641.14000000","4.00973000"],["62641.13000000","0.00034000"],["62641.12000000","0.00016000"],["62640.96000000","0.00018000"],["62640.95000000","0.63005000"],["62640.90000000","0.00008000"],["62640.35000000","0.00018000"],["62640.34000000","0.30016000"],["62640.32000000","0.00009000"],["62640.01000000","0.02755000"],["62640.00000000","1.91814000"],["62639.99000000","0.15856000"],["62639.98000000","0.00449000"],["62639.86000000","0.00400000"],["62639.83000000","0.00016000"],["62639.77000000","0.04091000"],["62638.49000000","0.03984000"],["62638.44000000","0.00009000"],["62638.42000000","0.00008000"],["62638.29000000","0.00400000"]],"asks":[["62641.15000000","0.07539000"],["62641.16000000","0.00106000"],["62641.17000000","0.00016000"],["62641.56000000","0.00009000"],["62641.98000000","0.00008000"],["62641.99000000","0.00041000"],["62642.00000000","0.03469000"],["62642.19000000","0.00009000"],["62642.25000000","0.00008000"],["62642.40000000","0.00018000"],["62642.41000000","0.07713000"],["62642.81000000","0.00009000"],["62642.91000000","0.00032000"],["62643.07000000","0.00068000"],["62643.09000000","0.00016000"],["62643.20000000","0.00008000"],["62643.54000000","0.00018000"],["62643.55000000","0.17530000"],["62643.57000000","0.00008000"],["62643.76000000","0.00008000"]]}}
{"t":23.9644,"stream":"btcusdt@depth@100ms","data":{"e":"depthUpdate","E":1783948026614,"s":"BTCUSDT","U":97344799698,"u":97344799718,"b":[["62640.01000000","0.02737000"],["62640.00000000","1.91796000"],["62638.67000000","0.00032000"],["62630.99000000","0.00000000"],["62625.95000000","0.00000000"],["56377.03000000","0.00460000"]],"a":[["62643.54000000","0.00000000"],["62643.55000000","0.00018000"],["62645.54000000","0.13993000"],["62647.20000000","0.00000000"],["62652.94000000","0.59910000"],["62652.95000000","0.00000000"],["62658.18000000","0.00032000"],["62678.70000000","0.00008000"]]}}
{"t":23.9645,"stream":"btcusdt@depth20@100ms","data":{"lastUpdateId":97344799718,"bids":[["62641.14000000","4.00973000"],["62641.13000000","0.00034000"],["62641.12000000","0.00016000"],["62640.96000000","0.00018000"],["62640.95000000","0.63005000"],["62640.90000000","0.00008000"],["62640.35000000","0.00018000"],["62640.34000000","0.30016000"],["62640.32000000","0.00009000"],["62640.01000000","0.02737000"],["62640.00000000","1.91796000"],["62639.99000000","0.15856000"],["62639.98000000","0.00449000"],["62639.86000000","0.00400000"],["62639.83000000","0.00016000"],["62639.77000000","0.04091000"],["62638.67000000","0.00032000"],["62638.49000000","0.03984000"],["62638.44000000","0.00009000"],["62638.42000000","0.00008000"]],"asks":[["62641.15000000","0.07539000"],["62641.16000000","0.00106000"],["62641.17000000","0.00016000"],["62641.56000000","0.00009000"],["62641.98000000","0.00008000"],["62641.99000000","0.00041000"],["62642.00000000","0.03469000"],["62642.19000000","0.00009000"],["62642.25000000","0.00008000"],["62642.40000000","0.00018000"],["62642.41000000","0.07713000"],["62642.81000000","0.00009000"],["62642.91000000","0.00032000"],["62643.07000000","0.00068000"],["62643.09000000","0.00016000"],["62643.20000000","0.00008000"],["62643.55000000","0.00018000"],["62643.57000000","0.00008000"],["62643.76000000","0.00008000"],["62643.97000000","0.00030000"]]}}
{"t":24.0639,"stream":"btcusdt@depth@100ms","data":{"e":"depthUpdate","E":1783948026714,"s":"BTCUSDT","U":97344799719,"u":97344799743,"b":[["62626.08000000","0.53801000"],["56377.03000000","0.00460000"],["56377.00000000","0.02184000"],["52500.00000000","115.44554000"],["48880.00000000","0.00164000"]],"a":[["62641.15000000","0.07530000"],["62641.16000000","0.00097000"],["62642.41000000","0.07705000"],["62643.55000000","0.00000000"],["62647.59000000","0.14126000"],["62648.14000000","0.09050000"],["62648.87000000","0.00000000"],["62660.96000000","0.00009000"],["62661.22000000","0.13214000"],["62670.47000000","0.02159000"],["62672.65000000","0.00000000"]]}}
{"t":24.0644,"stream":"btcusdt@depth20@100ms","data":{"lastUpdateId":97344799743,"bids":[["62641.14000000","4.00973000"],["62641.13000000","0.00034000"],["62641.12000000","0.00016000"],["62640.96000000","0.00018000"],["62640.95000000","0.63005000"],["62640.90000000","0.00008000"],["62640.35000000","0.00018000"],["62640.34000000","0.30016000"],["62640.32000000","0.00009000"],["62640.01000000","0.02737000"],["62640.00000000","1.91796000"],["62639.99000000","0.15856000"],["62639.98000000","0.00449000"],["62639.86000000","0.00400000"],["62639.83000000","0.00016000"],["62639.77000000","0.04091000"],["62638.67000000","0.00032000"],["62638.49000000","0.03984000"],["62638.44000000","0.00009000"],["62638.42000000","0.00008000"]],"asks":[["62641.15000000","0.07530000"],["62641.16000000","0.00097000"],["62641.17000000","0.00016000"],["62641.56000000","0.00009000"],["62641.98000000","0.00008000"],["62641.99000000","0.00041000"],["62642.00000000","0.03469000"],["62642.19000000","0.00009000"],["62642.25000000","0.00008000"],["62642.40000000","0.00018000"],["62642.41000000","0.07705000"],["62642.81000000","0.00009000"],["62642.91000000","0.00032000"],["62643.07000000","0.00068000"],["62643.09000000","0.00016000"],["62643.20000000","0.00008000"],["62643.57000000","0.00008000"],["62643.76000000","0.00008000"],["62643.97000000","0.00030000"],["62643.99000000","0.00018000"]]}}
{"t":24.163,"stream":"btcusdt@depth@100ms","data":{"e":"depthUpdate","E":1783948026814,"s":"BTCUSDT","U":97344799744,"u":97344799753,"b":[["62633.31000000","0.05116000"],["56377.03000000","0.00470000"],["56377.00000000","0.02164000"],["50113.00000000","0.00193000"]],"a":[["62642.00000000","0.03150000"]]}}
{"t":24.1636,"stream":"btcusdt@depth20@100ms","data":{"lastUpdateId":97344799753,"bids":[["62641.14000000","4.00973000"],["62641.13000000","0.00034000"],["62641.12000000","0.00016000"],["62640.96000000","0.00018000"],["62640.95000000","0.63005000"],["62640.90000000","0.00008000"],["62640.35000000","0.00018000"],["62640.34000000","0.30016000"],["62640.32000000","0.00009000"],["62640.01000000","0.02737000"],["62640.00000000","1.91796000"],["62639.99000000","0.15856000"],["62639.98000000","0.00449000"],["62639.86000000","0.00400000"],["62639.83000000","0.00016000"],["62639.77000000","0.04091000"],["62638.67000000","0.00032000"],["62638.49000000","0.03984000"],["62638.44000000","0.00009000"],["62638.42000000","0.00008000"]],"asks":[["62641.15000000","0.07530000"],["62641.16000000","0.00097000"],["62641.17000000","0.00016000"],["62641.56000000","0.00009000"],["62641.98000000","0.00008000"],["62641.99000000","0.00041000"],["62642.00000000","0.03150000"],["62642.19000000","0.00009000"],["62642.25000000","0.00008000"],["62642.40000000","0.00018000"],["62642.41000000","0.07705000"],["62642.81000000","0.00009000"],["62642.91000000","0.00032000"],["62643.07000000","0.00068000"],["62643.09000000","0.00016000"],["62643.20000000","0.00008000"],["62643.57000000","0.00008000"],["62643.76000000","0.00008000"],["62643.97000000","0.00030000"],["62643.99000000","0.00018000"]]}}
{"t":24.2639,"stream":"btcusdt@depth@100ms","data":{"e":"depthUpdate","E":1783948026914,"s":"BTCUSDT","U":97344799754,"u":97344799794,"b":[["62641.14000000","7.20242000"],["62640.35000000","0.00000000"],["62635.60000000","0.00000000"],["62627.12000000","0.00000000"],["56377.03000000","0.00480000"]],"a":[["62645.44000000","0.00000000"],["62645.52000000","0.00032000"],["62645.55000000","0.07697000"],["62647.09000000","0.17512000"],["62647.53000000","0.00000000"],["62647.59000000","0.14118000"],["62648.14000000","0.00000000"],["62649.22000000","0.00000000"],["62650.35000000","0.00017000"],["62652.19000000","0.00000000"],["62652.94000000","0.00000000"],["62652.96000000","0.00000000"],["62652.97000000","0.00000000"],["62658.18000000","0.59942000"],["62659.30000000","0.00000000"],["62667.69000000","0.00000000"],["62670.63000000","0.00000000"],["62674.62000000","0.57486000"],["62681.85000000","0.00000000"],["62695.69000000","0.00000000"]]}}
{"t":24.2641,"stream":"btcusdt@depth20@100ms","data":{"lastUpdateId":97344799794,"bids":[["62641.14000000","7.20242000"],["62641.13000000","0.00034000"],["62641.12000000","0.00016000"],["62640.96000000","0.00018000"],["62640.95000000","0.63005000"],["62640.90000000","0.00008000"],["62640.34000000","0.30016000"],["62640.32000000","0.00009000"],["62640.01000000","0.02737000"],["62640.00000000","1.91796000"],["62639.99000000","0.15856000"],["62639.98000000","0.00449000"],["62639.86000000","0.00400000"],["62639.83000000","0.00016000"],["62639.77000000","0.04091000"],["62638.67000000","0.00032000"],["62638.49000000","0.03984000"],["62638.44000000","0.00009000"],["62638.42000000","0.00008000"],["62638.29000000","0.00400000"]],"asks":[["62641.15000000","0.07530000"],["62641.16000000","0.00097000"],["62641.17000000","0.00016000"],["62641.56000000","0.00009000"],["62641.98000000","0.00008000"],["62641.99000000","0.00041000"],["62642.00000000","0.03150000"],["62642.19000000","0.00009000"],["62642.25000000","0.00008000"],["62642.40000000","0.00018000"],["62642.41000000","0.07705000"],["62642.81000000","0.00009000"],["62642.91000000","0.00032000"],["62643.07000000","0.00068000"],["62643.09000000","0.00016000"],["62643.20000000","0.00008000"],["62643.57000000","0.00008000"],["62643.76000000","0.00008000"],["62643.97000000","0.00030000"],["62643.99000000","0.00018000"]]}}
{"t":24.3649,"stream":"btcusdt@depth@100ms","data":{"e":"depthUpdate","E":1783948027014,"s":"BTCUSDT","U":97344799795,"u":97344799921,"b":[["62641.14000000","8.11069000"],["62640.96000000","0.00000000"],["62640.02000000","0.59911000"],["62635.61000000","0.00000000"],["62635.29000000","0.00000000"],["62633.73000000","0.72980000"],["62633.41000000","0.57524000"],["62631.00000000","0.00000000"],["62627.89000000","0.00000000"],["62627.12000000","0.00008000"],["62619.98000000","0.00419000"],["62616.29000000","0.00000000"],["62615.33000000","0.17500000"],["62611.38000000","0.00000000"],["62588.02000000","0.00113000"],["62525.48000000","0.00045000"],["62500.77000000","0.00000000"],["62500.01000000","0.07450000"],["56377.03000000","0.00480000"],["50112.92000000","0.00039000"],["50112.91000000","0.00000000"]],"a":[["62641.15000000","0.07539000"],["62645.52000000","0.00000000"],["62645.54000000","0.00027000"],["62646.56000000","0.13039000"],["62647.09000000","0.17530000"],["62647.59000000","0.14100000"],["62648.40000000","0.00009000"],["62652.19000000","0.00008000"],["62653.49000000","0.00000000"],["62654.03000000","0.00000000"],["62655.07000000","0.00000000"],["62655.55000000","0.00798000"],["62655.68000000","0.00400000"],["62655.77000000","0.07000000"],["62656.42000000","1.91755000"],["62656.43000000","0.00000000"],["62658.18000000","0.00032000"],["62659.15000000","0.61163000"],["62659.99000000","0.00000000"],["62661.21000000","0.18405000"],["62661.22000000","0.00000000"],["62661.79000000","0.00000000"],["62661.80000000","0.00000000"],["62662.56000000","0.47600000"],["62662.57000000","1.91755000"],["62663.89000000","0.13164000"],["62664.40000000","0.79881000"],["62664.41000000","0.00000000"],["62664.82000000","0.57495000"],["62665.30000000","0.00000000"],["62668.22000000","0.00400000"],["62668.77000000","0.57491000"],["62669.26000000","0.00000000"],["62669.36000000","0.00000000"],["62672.20000000","0.00000000"],["62674.62000000","0.00000000"],["62683.88000000","0.00000000"],["62687.28000000","0.00971000"],["62697.26000000","0.00000000"],["62707.34000000","0.31247000"],["62709.09000000","0.00000000"]]}}
{"t":24.3652,"stream":"btcusdt@depth20@100ms","data":{"lastUpdateId":97344799921,"bids":[["62641.14000000","8.11069000"],["62641.13000000","0.00034000"],["62641.12000000","0.00016000"],["62640.95000000","0.63005000"],["62640.90000000","0.00008000"],["62640.34000000","0.30016000"],["62640.32000000","0.00009000"],["62640.02000000","0.59911000"],["62640.01000000","0.02737000"],["62640.00000000","1.91796000"],["62639.99000000","0.15856000"],["62639.98000000","0.00449000"],["62639.86000000","0.00400000"],["62639.83000000","0.00016000"],["62639.77000000","0.04091000"],["62638.67000000","0.00032000"],["62638.49000000","0.03984000"],["62638.44000000","0.00009000"],["62638.42000000","0.00008000"],["62638.29000000","0.00400000"]],"asks":[["62641.15000000","0.07539000"],["62641.16000000","0.00097000"],["62641.17000000","0.00016000"],["62641.56000000","0.00009000"],["62641.98000000","0.00008000"],["62641.99000000","0.00041000"],["62642.00000000","0.03150000"],["62642.19000000","0.00009000"],["62642.25000000","0.00008000"],["62642.40000000","0.00018000"],["62642.41000000","0.07705000"],["62642.81000000","0.00009000"],["62642.91000000","0.00032000"],["62643.07000000","0.00068000"],["62643.09000000","0.00016000"],["62643.20000000","0.00008000"],["62643.57000000","0.00008000"],["62643.76000000","0.00008000"],["62643.97000000","0.00030000"],["62643.99000000","0.00018000"]]}}
{"t":24.3665,"stream":"btcusdt@aggTrade","data":{"e":"aggTrade","E":1783948027016,"s":"BTCUSDT","a":4013160624,"p":"62641.15000000","q":"0.00400000","f":6501833960,"l":6501833960,"T":1783948027016,"m":false,"M":true}}
{"t":24.4633,"stream":"btcusdt@depth@100ms","data":{"e":"depthUpdate","E":1783948027114,"s":"BTCUSDT","U":97344799922,"u":97344799994,"b":[["62640.34000000","0.30016000"],["62640.02000000","0.00000000"],["62639.99000000","0.15864000"],["62637.56000000","0.59910000"],["62637.37000000","0.06704000"],["62618.29000000","0.03124000"],["62612.18000000","0.00000000"],["62611.88000000","0.25803000"],["62588.02000000","0.00000000"],["62556.36000000","0.04638000"],["62536.42000000","0.00000000"],["62525.48000000","0.00000000"],["62384.17000000","0.00000000"],["61701.52000000","0.00030000"],["56377.03000000","0.00480000"],["56377.02000000","0.00000000"],["56377.01000000","0.00187000"],["50112.91000000","0.00000000"],["40000.00000000","258.07540000"]],"a":[["62641.15000000","0.07121000"],["62641.16000000","0.00088000"],["62642.00000000","0.03011000"],["62643.76000000","0.00000000"],["62643.97000000","0.00000000"],["62644.00000000","0.02418000"],["62645.49000000","0.00032000"],["62645.53000000","0.00000000"],["62645.54000000","0.00018000"],["62645.99000000","0.00009000"],["62647.09000000","0.00018000"],["62647.59000000","0.14118000"],["62648.24000000","0.00256000"],["62648.36000000","0.00000000"],["62649.99000000","0.11345000"],["62650.33000000","0.00009000"],["62650.35000000","0.00009000"],["62652.42000000","0.00000000"],["62656.19000000","0.00000000"],["62662.34000000","0.57497000"],["62667.30000000","0.00059000"],["62677.05000000","0.00000000"],["62680.68000000","0.00400000"],["62681.85000000","0.00008000"],["62694.85000000","0.00000000"],["62713.71000000","0.08198000"],["62723.90000000","2.41057000"]]}}
{"t":24.4642,"stream":"btcusdt@depth20@100ms","data":{"lastUpdateId":97344799994,"bids":[["62641.14000000","8.11069000"],["62641.13000000","0.00034000"],["62641.12000000","0.00016000"],["62640.95000000","0.63005000"],["62640.90000000","0.00008000"],["62640.34000000","0.30016000"],["62640.32000000","0.00009000"],["62640.01000000","0.02737000"],["62640.00000000","1.91796000"],["62639.99000000","0.15864000"],["62639.98000000","0.00449000"],["62639.86000000","0.00400000"],["62639.83000000","0.00016000"],["62639.77000000","0.04091000"],["62638.67000000","0.00032000"],["62638.49000000","0.03984000"],["62638.44000000","0.00009000"],["62638.42000000","0.00008000"],["62638.29000000","0.00400000"],["62638.00000000","0.02400000"]],"asks":[["62641.15000000","0.07121000"],["62641.16000000","0.00088000"],["62641.17000000","0.00016000"],["62641.56000000","0.00009000"],["62641.98000000","0.00008000"],["62641.99000000","0.00041000"],["62642.00000000","0.03011000"],["62642.19000000","0.00009000"],["62642.25000000","0.00008000"],["62642.40000000","0.00018000"],["62642.41000000","0.07705000"],["62642.81000000","0.00009000"],["62642.91000000","0.00032000"],["62643.07000000","0.00068000"],["62643.09000000","0.00016000"],["62643.20000000","0.00008000"],["62643.57000000","0.00008000"],["62643.99000000","0.00018000"],["62644.00000000","0.02418000"],["62644.12000000","0.00008000"]]}}
{"t":24.4937,"stream":"btcusdt@aggTrade","data":{"e":"aggTrade","E":1783948027144,"s":"BTCUSDT","a":4013160625,"p":"62641.15000000","q":"0.03194000","f":6501833961,"l":6501833961,"T":1783948027144,"m":false,"M":true}}
{"t":24.523,"stream":"btcusdt@aggTrade","data":{"e":"aggTrade","E":1783948027173,"s":"BTCUSDT","a":4013160626,"p":"62641.15000000","q":"0.03959000","f":6501833962,"l":6501833981,"T":1783948027172,"m":false,"M":true}}
{"t":24.5231,"stream":"btcusdt@aggTrade","data":{"e":"aggTrade","E":1783948027173,"s":"BTCUSDT","a":4013160627,"p":"62641.16000000","q":"0.00088000","f":6501833982,"l":6501833990,"T":1783948027172,"m":false,"M":true}}
{"t":24.5231,"stream":"btcusdt@aggTrade","data":{"e":"aggTrade","E":1783948027173,"s":"BTCUSDT","a":4013160628,"p":"62641.17000000","q":"0.00016000","f":6501833991,"l":6501833991,"T":1783948027172,"m":false,"M":true}}
{"t":24.5244,"stream":"btcusdt@aggTrade","data":{"e":"aggTrade","E":1783948027174,"s":"BTCUSDT","a":4013160629,"p":"62641.98000000","q":"0.00065000","f":6501833992,"l":6501833999,"T":1783948027174,"m":false,"M":true}}
{"t":24.5244,"stream":"btcusdt@aggTrade","data":{"e":"aggTrade","E":1783948027174,"s":"BTCUSDT","a":4013160630,"p":"62641.99000000","q":"0.00023000","f":6501834000,"l":6501834000,"T":1783948027174,"m":false,"M":true}}
{"t":24.5634,"stream":"btcusdt@depth@100ms","data":{"e":"depthUpdate","E":1783948027214,"s":"BTCUSDT","U":97344799995,"u":97344800361,"b":[["62641.99000000","8.58615000"],["62641.98000000","0.30040000"],["62641.97000000","0.63567000"],["62641.90000000","0.68585000"],["62641.89000000","0.30660000"],["62641.55000000","0.00000000"],["62641.43000000","0.00400000"],["62641.37000000","0.00000000"],["62641.24000000","0.00000000"],["62641.16000000","0.00000000"],["62641.15000000","0.07500000"],["62641.14000000","0.66286000"],["62641.13000000","0.00000000"],["62641.12000000","0.00000000"],["62640.95000000","0.00026000"],["62640.34000000","0.00018000"],["62640.01000000","0.02421000"],["62639.99000000","0.15856000"],["62638.49000000","0.03966000"],["62638.30000000","0.59910000"],["62637.56000000","0.00000000"],["62635.63000000","0.00009000"],["62633.73000000","0.72971000"],["62633.12000000","0.05000000"],["62629.02000000","0.00000000"],["62620.60000000","0.01000000"],["62616.50000000","0.00000000"],["62616.31000000","0.00000000"],["62391.25000000","0.00045000"],["61701.52000000","0.00000000"],["56377.80000000","0.00227000"],["56377.03000000","0.00000000"],["50112.92000000","0.00000000"]],"a":[["62641.15000000","0.00000000"],["62641.16000000","0.00000000"],["62641.17000000","0.00000000"],["62641.56000000","0.00000000"],["62641.98000000","0.00000000"],["62641.99000000","0.00000000"],["62642.00000000","0.03107000"],["62642.01000000","0.00063000"],["62643.07000000","0.00000000"],["62643.94000000","0.00000000"],["62645.49000000","0.00000000"],["62645.99000000","0.00018000"],["62646.21000000","0.00000000"],["62646.26000000","0.00000000"],["62646.55000000","0.00000000"],["62646.56000000","0.00018000"],["62647.09000000","0.00000000"],["62647.59000000","0.00026000"],["62647.80000000","0.00574000"],["62647.99000000","0.00009000"],["62648.00000000","0.02418000"],["62648.23000000","0.00000000"],["62648.24000000","0.00009000"],["62648.37000000","0.00000000"],["62648.52000000","0.00000000"],["62648.65000000","0.00000000"],["62648.85000000","0.00000000"],["62648.88000000","0.00000000"],["62649.65000000","0.00256000"],["62649.99000000","0.00000000"],["62651.49000000","0.00000000"],["62651.90000000","0.13966000"],["62652.25000000","0.00000000"],["62652.31000000","0.00029000"],["62652.87000000","0.00000000"],["62655.76000000","0.13966000"],["62655.77000000","0.15000000"],["62655.78000000","0.00048000"],["62655.89000000","0.00000000"],["62656.40000000","0.12817000"],["62656.41000000","1.91755000"],["62656.42000000","0.00000000"],["62656.74000000","0.00047000"],["62656.89000000","0.00069000"],["62662.34000000","0.00000000"],["62663.89000000","0.00009000"],["62664.03000000","0.13683000"],["62670.76000000","0.00000000"],["62673.00000000","0.00000000"],["62673.70000000","0.00000000"],["62674.00000000","0.03400000"],["62677.59000000","0.00023000"],["62677.89000000","0.57483000"],["62678.69000000","0.00000000"],["62686.30000000","0.00000000"],["62689.99000000","0.00000000"],["62691.66000000","0.00395000"],["62693.83000000","0.00000000"],["62695.13000000","0.00397000"],["62698.20000000","0.00544000"],["62698.76000000","0.00000000"],["63580.77000000","0.00000000"]]}}
{"t":24.5645,"stream":"btcusdt@depth20@100ms","data":{"lastUpdateId":97344800361,"bids":[["62641.99000000","8.58615000"],["62641.98000000","0.30040000"],["62641.97000000","0.63567000"],["62641.90000000","0.68585000"],["62641.89000000","0.30660000"],["62641.43000000","0.00400000"],["62641.15000000","0.07500000"],["62641.14000000","0.66286000"],["62640.95000000","0.00026000"],["62640.90000000","0.00008000"],["62640.34000000","0.00018000"],["62640.32000000","0.00009000"],["62640.01000000","0.02421000"],["62640.00000000","1.91796000"],["62639.99000000","0.15856000"],["62639.98000000","0.00449000"],["62639.86000000","0.00400000"],["62639.83000000","0.00016000"],["62639.77000000","0.04091000"],["62638.67000000","0.00032000"]],"asks":[["62642.00000000","0.03107000"],["62642.01000000","0.00063000"],["62642.19000000","0.00009000"],["62642.25000000","0.00008000"],["62642.40000000","0.00018000"],["62642.41000000","0.07705000"],["62642.81000000","0.00009000"],["62642.91000000","0.00032000"],["62643.09000000","0.00016000"],["62643.20000000","0.00008000"],["62643.57000000","0.00008000"],["62643.99000000","0.00018000"],["62644.00000000","0.02418000"],["62644.12000000","0.00008000"],["62644.29000000","0.00008000"],["62645.00000000","0.00008000"],["62645.47000000","0.00009000"],["62645.54000000","0.00018000"],["62645.55000000","0.07697000"],["62645.89000000","0.00008000"]]}}
{"t":24.6636,"stream":"btcusdt@depth@100ms","data":{"e":"depthUpdate","E":1783948027314,"s":"BTCUSDT","U":97344800362,"u":97344800435,"b":[["62641.99000000","8.68034000"],["62641.98000000","0.30058000"],["62641.97000000","0.63585000"],["62641.90000000","0.68603000"],["62641.89000000","0.30660000"],["62641.15000000","0.07518000"],["62641.14000000","0.65260000"],["62640.95000000","0.00008000"],["62640.34000000","0.00000000"],["62639.99000000","0.15846000"],["62639.77000000","0.04073000"],["62610.00000000","0.04409000"],["62609.00000000","0.00000000"],["62608.30000000","0.00000000"],["62501.66000000","0.00999000"],["62500.01000000","0.06451000"],["56377.80000000","0.00267000"]],"a":[["62645.55000000","0.07713000"],["62645.89000000","0.00000000"],["62646.00000000","0.02418000"],["62646.56000000","0.00000000"],["62647.59000000","0.00008000"],["62648.68000000","0.05143000"],["62648.78000000","0.00000000"],["62649.70000000","0.13966000"],["62650.00000000","0.03418000"],["62652.96000000","0.01284000"],["62653.90000000","0.03700000"],["62655.20000000","0.13978000"],["62656.99000000","0.00048000"],["62657.41000000","0.00000000"],["62660.85000000","0.00158000"],["62667.89000000","0.00191000"],["62668.85000000","0.00000000"],["62678.80000000","0.00011000"],["63581.63000000","0.00030000"]]}}
{"t":24.6637,"stream":"btcusdt@depth20@100ms","data":{"lastUpdateId":97344800435,"bids":[["62641.99000000","8.68034000"],["62641.98000000","0.30058000"],["62641.97000000","0.63585000"],["62641.90000000","0.68603000"],["62641.89000000","0.30660000"],["62641.43000000","0.00400000"],["62641.15000000","0.07518000"],["62641.14000000","0.65260000"],["62640.95000000","0.00008000"],["62640.90000000","0.00008000"],["62640.32000000","0.00009000"],["62640.01000000","0.02421000"],["62640.00000000","1.91796000"],["62639.99000000","0.15846000"],["62639.98000000","0.00449000"],["62639.86000000","0.00400000"],["62639.83000000","0.00016000"],["62639.77000000","0.04073000"],["62638.67000000","0.00032000"],["62638.49000000","0.03966000"]],"asks":[["62642.00000000","0.03107000"],["62642.01000000","0.00063000"],["62642.19000000","0.00009000"],["62642.25000000","0.00008000"],["62642.40000000","0.00018000"],["62642.41000000","0.07705000"],["62642.81000000","0.00009000"],["62642.91000000","0.00032000"],["62643.09000000","0.00016000"],["62643.20000000","0.00008000"],["62643.57000000","0.00008000"],["62643.99000000","0.00018000"],["62644.00000000","0.02418000"],["62644.12000000","0.00008000"],["62644.29000000","0.00008000"],["62645.00000000","0.00008000"],["62645.47000000","0.00009000"],["62645.54000000","0.00018000"],["62645.55000000","0.07713000"],["62645.99000000","0.00018000"]]}}
{"t":24.7428,"stream":"btcusdt@aggTrade","data":{"e":"aggTrade","E":1783948027391,"s":"BTCUSDT","a":4013160631,"p":"62641.99000000","q":"0.00476000","f":6501834001,"l":6501834001,"T":1783948027391,"m":true,"M":true}}
{"t":24.7633,"stream":"btcusdt@depth@100ms","data":{"e":"depthUpdate","E":1783948027414,"s":"BTCUSDT","U":97344800436,"u":97344800497,"b":[["62641.99000000","8.67558000"],["62641.14000000","0.42760000"],["62639.99000000","0.15838000"],["62637.37000000","0.00000000"],["62634.23000000","0.00000000"],["62631.10000000","0.00000000"],["62627.97000000","0.00000000"],["56377.80000000","0.00307000"]],"a":[["62642.00000000","0.03097000"],["62642.01000000","0.00045000"],["62642.40000000","0.00000000"],["62642.41000000","0.00042000"],["62643.57000000","0.00000000"],["62643.95000000","0.00068000"],["62645.54000000","0.00000000"],["62645.55000000","0.00050000"],["62647.99000000","0.00018000"],["62648.59000000","0.00018000"],["62648.60000000","0.12746000"],["62648.68000000","0.00043000"],["62648.69000000","0.08631000"],["62649.65000000","0.00000000"],["62649.69000000","0.00009000"],["62649.70000000","0.13984000"],["62649.96000000","0.00256000"],["62649.99000000","0.00000000"],["62650.00000000","0.03400000"],["62651.48000000","0.00256000"],["62651.76000000","0.00000000"],["62651.81000000","0.00000000"],["62652.96000000","0.00000000"],["62653.50000000","0.00008000"],["62664.03000000","0.00000000"],["62671.00000000","0.02224000"],["62673.94000000","0.03332000"],["62681.98000000","0.04818000"],["62699.00000000","0.06048000"]]}}
{"t":24.7635,"stream":"btcusdt@depth20@100ms","data":{"lastUpdateId":97344800497,"bids":[["62641.99000000","8.67558000"],["62641.98000000","0.30058000"],["62641.97000000","0.63585000"],["62641.90000000","0.68603000"],["62641.89000000","0.30660000"],["62641.43000000","0.00400000"],["62641.15000000","0.07518000"],["62641.14000000","0.42760000"],["62640.95000000","0.00008000"],["62640.90000000","0.00008000"],["62640.32000000","0.00009000"],["62640.01000000","0.02421000"],["62640.00000000","1.91796000"],["62639.99000000","0.15838000"],["62639.98000000","0.00449000"],["62639.86000000","0.00400000"],["62639.83000000","0.00016000"],["62639.77000000","0.04073000"],["62638.67000000","0.00032000"],["62638.49000000","0.03966000"]],"asks":[["62642.00000000","0.03097000"],["62642.01000000","0.00045000"],["62642.19000000","0.00009000"],["62642.25000000","0.00008000"],["62642.41000000","0.00042000"],["62642.81000000","0.00009000"],["62642.91000000","0.00032000"],["62643.09000000","0.00016000"],["62643.20000000","0.00008000"],["62643.95000000","0.00068000"],["62643.99000000","0.00018000"],["62644.00000000","0.02418000"],["62644.12000000","0.00008000"],["62644.29000000","0.00008000"],["62645.00000000","0.00008000"],["62645.47000000","0.00009000"],["62645.55000000","0.00050000"],["62645.99000000","0.00018000"],["62646.00000000","0.02418000"],["62646.40000000","0.00008000"]]}}
{"t":24.8649,"stream":"btcusdt@depth@100ms","data":{"e":"depthUpdate","E":1783948027514,"s":"BTCUSDT","U":97344800498,"u":97344800569,"b":[["62641.99000000","8.73267000"],["62641.89000000","0.30502000"],["62639.99000000","0.15846000"],["62638.38000000","0.06762000"],["62635.24000000","0.06763000"],["62632.11000000","0.04509000"],["62628.98000000","0.04509000"],["62553.63000000","0.00000000"],["62077.37000000","0.00000000"],["56377.80000000","0.00327000"]],"a":[["62642.00000000","0.03114000"],["62642.01000000","0.00054000"],["62642.41000000","0.00016000"],["62643.40000000","0.00018000"],["62643.41000000","0.07612000"],["62644.00000000","0.02418000"],["62645.55000000","0.00032000"],["62646.54000000","0.00018000"],["62646.55000000","0.07604000"],["62648.00000000","0.02418000"],["62648.59000000","0.00000000"],["62648.60000000","0.12772000"],["62648.68000000","0.00016000"],["62648.69000000","0.00018000"],["62649.68000000","0.05069000"],["62649.69000000","0.00000000"],["62650.00000000","0.03418000"],["62652.81000000","0.05069000"]]}}
{"t":24.8651,"stream":"btcusdt@depth20@100ms","data":{"lastUpdateId":97344800569,"bids":[["62641.99000000","8.73267000"],["62641.98000000","0.30058000"],["62641.97000000","0.63585000"],["62641.90000000","0.68603000"],["62641.89000000","0.30502000"],["62641.43000000","0.00400000"],["62641.15000000","0.07518000"],["62641.14000000","0.42760000"],["62640.95000000","0.00008000"],["62640.90000000","0.00008000"],["62640.32000000","0.00009000"],["62640.01000000","0.02421000"],["62640.00000000","1.91796000"],["62639.99000000","0.15846000"],["62639.98000000","0.00449000"],["62639.86000000","0.00400000"],["62639.83000000","0.00016000"],["62639.77000000","0.04073000"],["62638.67000000","0.00032000"],["62638.49000000","0.03966000"]],"asks":[["62642.00000000","0.03114000"],["62642.01000000","0.00054000"],["62642.19000000","0.00009000"],["62642.25000000","0.00008000"],["62642.41000000","0.00016000"],["62642.81000000","0.00009000"],["62642.91000000","0.00032000"],["62643.09000000","0.00016000"],["62643.20000000","0.00008000"],["62643.40000000","0.00018000"],["62643.41000000","0.07612000"],["62643.95000000","0.00068000"],["62643.99000000","0.00018000"],["62644.00000000","0.02418000"],["62644.12000000","0.00008000"],["62644.29000000","0.00008000"],["62645.00000000","0.00008000"],["62645.47000000","0.00009000"],["62645.55000000","0.00032000"],["62645.99000000","0.00018000"]]}}
{"t":24.9632,"stream":"btcusdt@depth@100ms","data":{"e":"depthUpdate","E":1783948027614,"s":"BTCUSDT","U":97344800570,"u":97344800617,"b":[["62641.99000000","8.73427000"],["62641.14000000","0.41310000"],["62640.32000000","0.00000000"],["62637.18000000","0.00000000"],["62633.10000000","0.00015000"],["62609.16000000","0.00015000"],["62559.27000000","0.00015000"],["62555.90000000","0.05433000"],["62504.57000000","0.00999000"],["62501.66000000","0.00000000"],["56377.80000000","0.00367000"]],"a":[["62642.00000000","0.03123000"],["62642.01000000","0.00063000"],["62642.81000000","0.00000000"],["62643.41000000","0.07630000"],["62643.44000000","0.00009000"],["62644.69000000","0.00009000"],["62646.00000000","0.02418000"],["62646.55000000","0.07622000"],["62648.60000000","0.12764000"],["62648.69000000","0.00000000"],["62649.68000000","0.05087000"],["62649.70000000","0.13966000"],["62650.00000000","0.03400000"],["62657.56000000","0.00014000"],["62727.83000000","0.00024000"],["62738.95000000","0.00000000"],["62745.94000000","0.05554000"],["62765.97000000","0.00000000"]]}}
{"t":24.9647,"stream":"btcusdt@depth20@100ms","data":{"lastUpdateId":97344800617,"bids":[["62641.99000000","8.73427000"],["62641.98000000","0.30058000"],["62641.97000000","0.63585000"],["62641.90000000","0.68603000"],["62641.89000000","0.30502000"],["62641.43000000","0.00400000"],["62641.15000000","0.07518000"],["62641.14000000","0.41310000"],["62640.95000000","0.00008000"],["62640.90000000","0.00008000"],["62640.01000000","0.02421000"],["62640.00000000","1.91796000"],["62639.99000000","0.15846000"],["62639.98000000","0.00449000"],["62639.86000000","0.00400000"],["62639.83000000","0.00016000"],["62639.77000000","0.04073000"],["62638.67000000","0.00032000"],["62638.49000000","0.03966000"],["62638.44000000","0.00009000"]],"asks":[["62642.00000000","0.03123000"],["62642.01000000","0.00063000"],["62642.19000000","0.00009000"],["62642.25000000","0.00008000"],["62642.41000000","0.00016000"],["62642.91000000","0.00032000"],["62643.09000000","0.00016000"],["62643.20000000","0.00008000"],["62643.40000000","0.00018000"],["62643.41000000","0.07630000"],["62643.44000000","0.00009000"],["62643.95000000","0.00068000"],["62643.99000000","0.00018000"],["62644.00000000","0.02418000"],["62644.12000000","0.00008000"],["62644.29000000","0.00008000"],["62644.69000000","0.00009000"],["62645.00000000","0.00008000"],["62645.47000000","0.00009000"],["62645.55000000","0.00032000"]]}}
{"t":25.0642,"stream":"btcusdt@depth@100ms","data":{"e":"depthUpdate","E":1783948027714,"s":"BTCUSDT","U":97344800618,"u":97344800620,"b":[["56377.80000000","0.00407000"]],"a":[["62669.71000000","0.00015000"]]}}
{"t":25.0643,"stream":"btcusdt@depth20@100ms","data":{"lastUpdateId":97344800620,"bids":[["62641.99000000","8.73427000"],["62641.98000000","0.30058000"],["62641.97000000","0.63585000"],["62641.90000000","0.68603000"],["62641.89000000","0.30502000"],["62641.43000000","0.00400000"],["62641.15000000","0.07518000"],["62641.14000000","0.41310000"],["62640.95000000","0.00008000"],["62640.90000000","0.00008000"],["62640.01000000","0.02421000"],["62640.00000000","1.91796000"],["62639.99000000","0.15846000"],["62639.98000000","0.00449000"],["62639.86000000","0.00400000"],["62639.83000000","0.00016000"],["62639.77000000","0.04073000"],["62638.67000000","0.00032000"],["62638.49000000","0.03966000"],["62638.44000000","0.00009000"]],"asks":[["62642.00000000","0.03123000"],["62642.01000000","0.00063000"],["62642.19000000","0.00009000"],["62642.25000000","0.00008000"],["62642.41000000","0.00016000"],["62642.91000000","0.00032000"],["62643.09000000","0.00016000"],["62643.20000000","0.00008000"],["62643.40000000","0.00018000"],["62643.41000000","0.07630000"],["62643.44000000","0.00009000"],["62643.95000000","0.00068000"],["62643.99000000","0.00018000"],["62644.00000000","0.02418000"],["62644.12000000","0.00008000"],["62644.29000000","0.00008000"],["62644.69000000","0.00009000"],["62645.00000000","0.00008000"],["62645.47000000","0.00009000"],["62645.55000000","0.00032000"]]}}
{"t":25.0955,"stream":"btcusdt@aggTrade","data":{"e":"aggTrade","E":1783948027745,"s":"BTCUSDT","a":4013160632,"p":"62641.99000000","q":"0.00306000","f":6501834002,"l":6501834002,"T":1783948027745,"m":true,"M":true}}
{"t":25.1322,"stream":"btcusdt@aggTrade","data":{"e":"aggTrade","E":1783948027782,"s":"BTCUSDT","a":4013160633,"p":"62642.00000000","q":"0.03195000","f":6501834003,"l":6501834032,"T":1783948027781,"m":false,"M":true}}
{"t":25.1324,"stream":"btcusdt@aggTrade","data":{"e":"aggTrade","E":1783948027782,"s":"BTCUSDT","a":4013160634,"p":"62642.01000000","q":"0.00063000","f":6501834033,"l":6501834039,"T":1783948027781,"m":false,"M":true}}
{"t":25.1324,"stream":"btcusdt@aggTrade","data":{"e":"aggTrade","E":1783948027782,"s":"BTCUSDT","a":4013160635,"p":"62642.19000000","q":"0.00009000","f":6501834040,"l":6501834040,"T":1783948027781,"m":false,"M":true}}
{"t":25.1324,"stream":"btcusdt@aggTrade","data":{"e":"aggTrade","E":1783948027782,"s":"BTCUSDT","a":4013160636,"p":"62642.25000000","q":"0.00016000","f":6501834041,"l":6501834042,"T":1783948027781,"m":false,"M":true}}
{"t":25.1324,"stream":"btcusdt@aggTrade","data":{"e":"aggTrade","E":1783948027782,"s":"BTCUSDT","a":4013160637,"p":"62642.41000000","q":"0.00032000","f":6501834043,"l":6501834046,"T":1783948027781,"m":false,"M":true}}
{"t":25.1324,"stream":"btcusdt@aggTrade","data":{"e":"aggTrade","E":1783948027782,"s":"BTCUSDT","a":4013160638,"p":"62642.91000000","q":"0.00032000","f":6501834047,"l":6501834047,"T":1783948027781,"m":false,"M":true}}
{"t":25.1325,"stream":"btcusdt@aggTrade","data":{"e":"aggTrade","E":1783948027782,"s":"BTCUSDT","a":4013160639,"p":"62643.09000000","q":"0.00080000","f":6501834048,"l":6501834057,"T":1783948027781,"m":false,"M":true}}
{"t":25.1325,"stream":"btcusdt@aggTrade","data":{"e":"aggTrade","E":1783948027782,"s":"BTCUSDT","a":4013160640,"p":"62643.20000000","q":"0.00008000","f":6501834058,"l":6501834058,"T":1783948027781,"m":false,"M":true}}
{"t":25.1325,"stream":"btcusdt@aggTrade","data":{"e":"aggTrade","E":1783948027782,"s":"BTCUSDT","a":4013160641,"p":"62643.40000000","q":"0.00027000","f":6501834059,"l":6501834061,"T":1783948027781,"m":false,"M":true}}
{"t":25.1325,"stream":"btcusdt@aggTrade","data":{"e":"aggTrade","E":1783948027782,"s":"BTCUSDT","a":4013160642,"p":"62643.41000000","q":"0.04799000","f":6501834062,"l":6501834062,"T":1783948027781,"m":false,"M":true}}
{"t":25.1637,"stream":"btcusdt@depth@100ms","data":{"e":"depthUpdate","E":1783948027814,"s":"BTCUSDT","U":97344800621,"u":97344800923,"b":[["62643.40000000","5.05099000"],["62643.39000000","0.00034000"],["62643.38000000","0.00016000"],["62643.20000000","0.00008000"],["62643.08000000","0.30006000"],["62643.00000000","0.00400000"],["62642.90000000","0.00000000"],["62642.40000000","0.00000000"],["62642.30000000","0.00000000"],["62642.24000000","0.00000000"],["62642.18000000","0.00000000"],["62642.00000000","0.30000000"],["62641.99000000","4.05787000"],["62641.98000000","0.00026000"],["62641.97000000","0.47626000"],["62641.90000000","0.15880000"],["62640.00000000","1.91778000"],["62637.14000000","0.00323000"],["62635.83000000","0.00012000"],["62630.87000000","0.00009000"],["62630.29000000","0.00000000"],["62627.74000000","0.00009000"],["62627.46000000","0.00000000"],["62624.61000000","0.00009000"],["62624.33000000","0.00000000"],["62623.06000000","0.00032000"],["62621.20000000","0.00000000"],["62617.88000000","0.00000000"],["62611.20000000","0.00000000"],["62607.84000000","0.77000000"],["62607.24000000","0.00000000"],["62606.95000000","0.00000000"],["62606.25000000","0.00000000"],["62604.11000000","0.00032000"],["62601.20000000","0.00000000"],["62586.94000000","0.00399000"],["62585.17000000","0.00032000"],["62584.01000000","0.00000000"],["62582.27000000","0.00000000"],["62580.76000000","0.00009000"],["62574.14000000","0.00000000"],["62566.23000000","0.00032000"],["62565.76000000","0.00000000"],["62563.33000000","0.00000000"],["62547.28000000","0.00032000"],["62544.40000000","0.00000000"],["62528.34000000","0.00032000"],["62525.47000000","0.00000000"],["62518.11000000","0.00009000"],["62511.51000000","0.00000000"],["62509.40000000","0.00032000"],["62506.54000000","0.00000000"],["62490.45000000","0.00032000"],["62487.60000000","0.00000000"],["62471.51000000","0.00032000"],["62468.67000000","0.00000000"],["62455.47000000","0.00010000"],["62452.57000000","0.00032000"],["62449.73000000","0.00000000"],["62448.87000000","0.00000000"],["62430.78000000","0.00000000"],["62392.83000000","0.00010000"],["62386.23000000","0.00000000"],["62330.18000000","0.00010000"],["62323.60000000","0.00000000"],["62267.54000000","0.00010000"],["62260.96000000","0.00000000"],["62204.90000000","0.00010000"],["62198.32000000","0.00000000"],["62142.25000000","0.00010000"],["62135.69000000","0.00000000"],["56377.80000000","0.00207000"]],"a":[["62642.00000000","0.00000000"],["62642.01000000","0.00000000"],["62642.19000000","0.00000000"],["62642.25000000","0.00000000"],["62642.41000000","0.00000000"],["62642.91000000","0.00000000"],["62643.09000000","0.00000000"],["62643.20000000","0.00000000"],["62643.40000000","0.00000000"],["62643.41000000","0.21046000"],["62643.42000000","0.00088000"],["62643.43000000","0.00016000"],["62643.44000000","0.00000000"],["62643.95000000","0.00000000"],["62645.31000000","0.00000000"],["62646.55000000","0.07630000"],["62648.33000000","0.00000000"],["62648.59000000","0.00009000"],["62649.70000000","0.13992000"],["62649.92000000","0.17264000"],["62650.25000000","0.08673000"],["62652.15000000","0.00000000"],["62652.97000000","0.13965000"],["62655.68000000","0.00000000"],["62655.86000000","0.00400000"],["62656.40000000","0.00000000"],["62664.50000000","3.32892000"],["62671.00000000","0.00000000"],["62673.94000000","0.00000000"],["62674.00000000","0.02400000"],["62675.00000000","0.01000000"],["62699.00000000","0.00000000"],["62699.44000000","0.47600000"],["62706.05000000","0.00009000"],["62762.07000000","0.00000000"],["62765.97000000","0.00000000"],["62768.70000000","0.00009000"],["62824.71000000","0.00000000"],["62830.78000000","0.00032000"],["62831.34000000","0.00009000"],["62887.35000000","0.00000000"],["62893.98000000","0.00009000"],["62949.98000000","0.00000000"],["62956.63000000","0.00009000"],["63012.62000000","0.00000000"],["63019.27000000","0.00009000"],["63075.26000000","0.00000000"],["63081.91000000","0.00009000"],["63137.89000000","0.00000000"],["63144.56000000","0.00009000"],["63581.63000000","0.00000000"]]}}
{"t":25.164,"stream":"btcusdt@depth20@100ms","data":{"lastUpdateId":97344800923,"bids":[["62643.40000000","5.05099000"],["62643.39000000","0.00034000"],["62643.38000000","0.00016000"],["62643.20000000","0.00008000"],["62643.08000000","0.30006000"],["62643.00000000","0.00400000"],["62642.00000000","0.30000000"],["62641.99000000","4.05787000"],["62641.98000000","0.00026000"],["62641.97000000","0.47626000"],["62641.90000000","0.15880000"],["62641.89000000","0.30502000"],["62641.43000000","0.00400000"],["62641.15000000","0.07518000"],["62641.14000000","0.41310000"],["62640.95000000","0.00008000"],["62640.90000000","0.00008000"],["62640.01000000","0.02421000"],["62640.00000000","1.91778000"],["62639.99000000","0.15846000"]],"asks":[["62643.41000000","0.21046000"],["62643.42000000","0.00088000"],["62643.43000000","0.00016000"],["62643.99000000","0.00018000"],["62644.00000000","0.02418000"],["62644.12000000","0.00008000"],["62644.29000000","0.00008000"],["62644.69000000","0.00009000"],["62645.00000000","0.00008000"],["62645.47000000","0.00009000"],["62645.55000000","0.00032000"],["62645.99000000","0.00018000"],["62646.00000000","0.02418000"],["62646.40000000","0.00008000"],["62646.54000000","0.00018000"],["62646.55000000","0.07630000"],["62647.42000000","0.00008000"],["62647.59000000","0.00008000"],["62647.80000000","0.00574000"],["62647.84000000","0.00009000"]]}}
{"t":25.2263,"stream":"btcusdt@aggTrade","data":{"e":"aggTrade","E":1783948027876,"s":"BTCUSDT","a":4013160643,"p":"62643.41000000","q":"0.00458000","f":6501834063,"l":6501834068,"T":1783948027876,"m":false,"M":true}}
{"t":25.2641,"stream":"btcusdt@depth@100ms","data":{"e":"depthUpdate","E":1783948027914,"s":"BTCUSDT","U":97344800924,"u":97344800992,"b":[["62643.40000000","4.89096000"],["62643.08000000","0.30024000"],["62642.11000000","0.00010000"],["62642.00000000","0.30018000"],["62641.99000000","4.05551000"],["62641.98000000","0.00008000"],["62640.01000000","0.02403000"],["62639.99000000","0.15830000"],["62638.38000000","0.00000000"],["62636.11000000","0.00000000"],["62635.24000000","0.00000000"],["62632.11000000","0.00000000"],["62628.98000000","0.00000000"],["62612.00000000","0.03400000"],["62610.00000000","0.03409000"],["62609.16000000","0.00000000"],["62479.08000000","0.00009000"],["62476.82000000","0.00000000"],["56379.06000000","0.00040000"],["56377.00000000","0.02184000"]],"a":[["62643.41000000","0.17818000"],["62643.42000000","0.00079000"],["62646.54000000","0.00000000"],["62646.55000000","0.00026000"],["62648.59000000","0.00018000"],["62649.67000000","0.00000000"],["62649.68000000","0.00018000"],["62649.69000000","0.00009000"],["62649.70000000","0.13992000"],["62652.81000000","0.00000000"],["62654.24000000","0.02678000"],["62669.71000000","0.00000000"],["62700.02000000","0.00808000"],["62765.97000000","0.00000000"],["62818.80000000","0.00009000"],["62821.93000000","0.00000000"]]}}
{"t":25.2642,"stream":"btcusdt@depth20@100ms","data":{"lastUpdateId":97344800992,"bids":[["62643.40000000","4.89096000"],["62643.39000000","0.00034000"],["62643.38000000","0.00016000"],["62643.20000000","0.00008000"],["62643.08000000","0.30024000"],["62643.00000000","0.00400000"],["62642.11000000","0.00010000"],["62642.00000000","0.30018000"],["62641.99000000","4.05551000"],["62641.98000000","0.00008000"],["62641.97000000","0.47626000"],["62641.90000000","0.15880000"],["62641.89000000","0.30502000"],["62641.43000000","0.00400000"],["62641.15000000","0.07518000"],["62641.14000000","0.41310000"],["62640.95000000","0.00008000"],["62640.90000000","0.00008000"],["62640.01000000","0.02403000"],["62640.00000000","1.91778000"]],"asks":[["62643.41000000","0.17818000"],["62643.42000000","0.00079000"],["62643.43000000","0.00016000"],["62643.99000000","0.00018000"],["62644.00000000","0.02418000"],["62644.12000000","0.00008000"],["62644.29000000","0.00008000"],["62644.69000000","0.00009000"],["62645.00000000","0.00008000"],["62645.47000000","0.00009000"],["62645.55000000","0.00032000"],["62645.99000000","0.00018000"],["62646.00000000","0.02418000"],["62646.40000000","0.00008000"],["62646.55000000","0.00026000"],["62647.42000000","0.00008000"],["62647.59000000","0.00008000"],["62647.80000000","0.00574000"],["62647.84000000","0.00009000"],["62647.99000000","0.00018000"]]}}
{"t":25.3653,"stream":"btcusdt@depth@100ms","data":{"e":"depthUpdate","E":1783948028014,"s":"BTCUSDT","U":97344800993,"u":97344801056,"b":[["62643.40000000","4.90096000"],["62642.01000000","0.59909000"],["62642.00000000","0.07518000"],["62641.99000000","3.82051000"],["62641.89000000","0.30510000"],["62641.67000000","0.07482000"],["62639.99000000","0.15838000"],["62638.53000000","0.07482000"],["62638.30000000","0.00000000"],["62635.40000000","0.04988000"],["62632.27000000","0.04988000"],["62629.38000000","0.00008000"],["62627.12000000","0.00000000"],["62618.29000000","0.00000000"],["62612.08000000","0.03157000"],["62606.95000000","0.22500000"],["62525.79000000","0.09596000"],["62399.57000000","0.00000000"],["60700.00000000","2.82946000"],["56379.06000000","0.00080000"],["56377.00000000","0.02164000"],["50114.72000000","0.00039000"]],"a":[["62643.41000000","0.00148000"],["62643.42000000","0.00088000"],["62645.37000000","0.00068000"],["62646.00000000","0.02418000"],["62646.55000000","0.00008000"],["62646.69000000","0.00018000"],["62646.70000000","0.06884000"],["62648.60000000","0.12764000"],["62649.33000000","0.09730000"],["62649.68000000","0.00000000"],["62649.69000000","0.00000000"],["62649.70000000","0.14000000"],["62649.84000000","0.06884000"],["62649.92000000","0.17274000"],["62650.00000000","0.03418000"],["62650.25000000","0.00000000"],["62652.19000000","0.00000000"],["62652.97000000","0.18554000"],["62654.45000000","0.00008000"],["62656.10000000","0.04589000"],["62767.31000000","0.00000000"]]}}
{"t":25.3656,"stream":"btcusdt@depth20@100ms","data":{"lastUpdateId":97344801056,"bids":[["62643.40000000","4.90096000"],["62643.39000000","0.00034000"],["62643.38000000","0.00016000"],["62643.20000000","0.00008000"],["62643.08000000","0.30024000"],["62643.00000000","0.00400000"],["62642.11000000","0.00010000"],["62642.01000000","0.59909000"],["62642.00000000","0.07518000"],["62641.99000000","3.82051000"],["62641.98000000","0.00008000"],["62641.97000000","0.47626000"],["62641.90000000","0.15880000"],["62641.89000000","0.30510000"],["62641.67000000","0.07482000"],["62641.43000000","0.00400000"],["62641.15000000","0.07518000"],["62641.14000000","0.41310000"],["62640.95000000","0.00008000"],["62640.90000000","0.00008000"]],"asks":[["62643.41000000","0.00148000"],["62643.42000000","0.00088000"],["62643.43000000","0.00016000"],["62643.99000000","0.00018000"],["62644.00000000","0.02418000"],["62644.12000000","0.00008000"],["62644.29000000","0.00008000"],["62644.69000000","0.00009000"],["62645.00000000","0.00008000"],["62645.37000000","0.00068000"],["62645.47000000","0.00009000"],["62645.55000000","0.00032000"],["62645.99000000","0.00018000"],["62646.00000000","0.02418000"],["62646.40000000","0.00008000"],["62646.55000000","0.00008000"],["62646.69000000","0.00018000"],["62646.70000000","0.06884000"],["62647.42000000","0.00008000"],["62647.59000000","0.00008000"]]}}
{"t":25.4643,"stream":"btcusdt@depth@100ms","data":{"e":"depthUpdate","E":1783948028114,"s":"BTCUSDT","U":97344801057,"u":97344801115,"b":[["62643.21000000","0.01200000"],["62643.08000000","0.30032000"],["62642.01000000","0.59927000"],["62641.89000000","0.30492000"],["62641.15000000","0.07500000"],["62639.99000000","0.15822000"],["62638.44000000","0.00000000"],["62636.28000000","0.00000000"],["62590.69000000","0.00113000"],["62528.01000000","0.00000000"],["62427.31000000","0.02500000"],["56379.06000000","0.00120000"],["50114.72000000","0.00039000"],["40000.00000000","258.07540000"]],"a":[["62644.69000000","0.00000000"],["62645.95000000","0.00009000"],["62646.00000000","0.02418000"],["62646.70000000","0.06902000"],["62648.60000000","0.12764000"],["62649.33000000","0.09748000"],["62649.70000000","0.14000000"],["62649.84000000","0.06902000"],["62649.92000000","0.17256000"],["62650.00000000","0.03400000"],["62766.08000000","0.00000000"]]}}
{"t":25.4644,"stream":"btcusdt@depth20@100ms","data":{"lastUpdateId":97344801115,"bids":[["62643.40000000","4.90096000"],["62643.39000000","0.00034000"],["62643.38000000","0.00016000"],["62643.21000000","0.01200000"],["62643.20000000","0.00008000"],["62643.08000000","0.30032000"],["62643.00000000","0.00400000"],["62642.11000000","0.00010000"],["62642.01000000","0.59927000"],["62642.00000000","0.07518000"],["62641.99000000","3.82051000"],["62641.98000000","0.00008000"],["62641.97000000","0.47626000"],["62641.90000000","0.15880000"],["62641.89000000","0.30492000"],["62641.67000000","0.07482000"],["62641.43000000","0.00400000"],["62641.15000000","0.07500000"],["62641.14000000","0.41310000"],["62640.95000000","0.00008000"]],"asks":[["62643.41000000","0.00148000"],["62643.42000000","0.00088000"],["62643.43000000","0.00016000"],["62643.99000000","0.00018000"],["62644.00000000","0.02418000"],["62644.12000000","0.00008000"],["62644.29000000","0.00008000"],["62645.00000000","0.00008000"],["62645.37000000","0.00068000"],["62645.47000000","0.00009000"],["62645.55000000","0.00032000"],["62645.95000000","0.00009000"],["62645.99000000","0.00018000"],["62646.00000000","0.02418000"],["62646.40000000","0.00008000"],["62646.55000000","0.00008000"],["62646.69000000","0.00018000"],["62646.70000000","0.06902000"],["62647.42000000","0.00008000"],["62647.59000000","0.00008000"]]}}
{"t":25.5637,"stream":"btcusdt@depth@100ms","data":{"e":"depthUpdate","E":1783948028214,"s":"BTCUSDT","U":97344801116,"u":97344801147,"b":[["62643.40000000","4.89997000"],["62641.89000000","0.00024000"],["62640.00000000","1.92378000"],["62610.57000000","0.00015000"],["62543.78000000","0.00015000"],["62540.37000000","0.00015000"],["62537.45000000","0.00023000"],["62534.04000000","0.00000000"],["62514.36000000","0.00000000"],["61703.74000000","0.00030000"],["56379.06000000","0.00160000"],["50114.72000000","0.00000000"]],"a":[["62643.41000000","0.00157000"],["62643.42000000","0.00097000"],["62643.44000000","0.00009000"],["62649.96000000","0.00000000"],["62650.33000000","0.00000000"],["62651.48000000","0.00000000"],["62659.73000000","0.00009000"],["62733.06000000","0.00000000"],["62735.24000000","0.00000000"],["62742.07000000","0.00000000"],["62828.83000000","0.09549000"],["63583.07000000","0.00067000"]]}}
{"t":25.5638,"stream":"btcusdt@depth20@100ms","data":{"lastUpdateId":97344801147,"bids":[["62643.40000000","4.89997000"],["62643.39000000","0.00034000"],["62643.38000000","0.00016000"],["62643.21000000","0.01200000"],["62643.20000000","0.00008000"],["62643.08000000","0.30032000"],["62643.00000000","0.00400000"],["62642.11000000","0.00010000"],["62642.01000000","0.59927000"],["62642.00000000","0.07518000"],["62641.99000000","3.82051000"],["62641.98000000","0.00008000"],["62641.97000000","0.47626000"],["62641.90000000","0.15880000"],["62641.89000000","0.00024000"],["62641.67000000","0.07482000"],["62641.43000000","0.00400000"],["62641.15000000","0.07500000"],["62641.14000000","0.41310000"],["62640.95000000","0.00008000"]],"asks":[["62643.41000000","0.00157000"],["62643.42000000","0.00097000"],["62643.43000000","0.00016000"],["62643.44000000","0.00009000"],["62643.99000000","0.00018000"],["62644.00000000","0.02418000"],["62644.12000000","0.00008000"],["62644.29000000","0.00008000"],["62645.00000000","0.00008000"],["62645.37000000","0.00068000"],["62645.47000000","0.00009000"],["62645.55000000","0.00032000"],["62645.95000000","0.00009000"],["62645.99000000","0.00018000"],["62646.00000000","0.02418000"],["62646.40000000","0.00008000"],["62646.55000000","0.00008000"],["62646.69000000","0.00018000"],["62646.70000000","0.06902000"],["62647.42000000","0.00008000"]]}}
{"t":25.6638,"stream":"btcusdt@depth@100ms","data":{"e":"depthUpdate","E":1783948028314,"s":"BTCUSDT","U":97344801148,"u":97344801166,"b":[["62643.21000000","0.01218000"],["62641.90000000","0.15862000"],["56379.06000000","0.00200000"],["50115.00000000","0.13713000"]],"a":[["62645.55000000","0.00000000"],["62671.12000000","0.00015000"],["62671.23000000","0.02279000"],["62674.18000000","0.03374000"],["62699.24000000","0.06280000"]]}}
{"t":25.6639,"stream":"btcusdt@depth20@100ms","data":{"lastUpdateId":97344801166,"bids":[["62643.40000000","4.89997000"],["62643.39000000","0.00034000"],["62643.38000000","0.00016000"],["62643.21000000","0.01218000"],["62643.20000000","0.00008000"],["62643.08000000","0.30032000"],["62643.00000000","0.00400000"],["62642.11000000","0.00010000"],["62642.01000000","0.59927000"],["62642.00000000","0.07518000"],["62641.99000000","3.82051000"],["62641.98000000","0.00008000"],["62641.97000000","0.47626000"],["62641.90000000","0.15862000"],["62641.89000000","0.00024000"],["62641.67000000","0.07482000"],["62641.43000000","0.00400000"],["62641.15000000","0.07500000"],["62641.14000000","0.41310000"],["62640.95000000","0.00008000"]],"asks":[["62643.41000000","0.00157000"],["62643.42000000","0.00097000"],["62643.43000000","0.00016000"],["62643.44000000","0.00009000"],["62643.99000000","0.00018000"],["62644.00000000","0.02418000"],["62644.12000000","0.00008000"],["62644.29000000","0.00008000"],["62645.00000000","0.00008000"],["62645.37000000","0.00068000"],["62645.47000000","0.00009000"],["62645.95000000","0.00009000"],["62645.99000000","0.00018000"],["62646.00000000","0.02418000"],["62646.40000000","0.00008000"],["62646.55000000","0.00008000"],["62646.69000000","0.00018000"],["62646.70000000","0.06902000"],["62647.42000000","0.00008000"],["62647.59000000","0.00008000"]]}}
{"t":25.7636,"stream":"btcusdt@depth@100ms","data":{"e":"depthUpdate","E":1783948028414,"s":"BTCUSDT","U":97344801167,"u":97344801197,"b":[["62643.40000000","5.07262000"],["62641.90000000","0.15880000"],["62527.63000000","0.02500000"],["62517.76000000","0.00039000"],["62516.71000000","0.00013000"],["56379.06000000","0.00240000"],["50113.00000000","0.00193000"]],"a":[["62643.41000000","0.00157000"],["62643.42000000","0.00097000"],["62646.70000000","0.06910000"],["62648.45000000","0.00009000"],["62648.46000000","0.10835000"],["62648.59000000","0.00009000"],["62649.33000000","0.00018000"],["62649.70000000","0.13992000"],["62649.84000000","0.06884000"],["62649.92000000","0.00000000"],["62662.25000000","0.57497000"],["62677.89000000","0.00000000"],["62736.48000000","0.00015000"]]}}
{"t":25.7638,"stream":"btcusdt@depth20@100ms","data":{"lastUpdateId":97344801197,"bids":[["62643.40000000","5.07262000"],["62643.39000000","0.00034000"],["62643.38000000","0.00016000"],["62643.21000000","0.01218000"],["62643.20000000","0.00008000"],["62643.08000000","0.30032000"],["62643.00000000","0.00400000"],["62642.11000000","0.00010000"],["62642.01000000","0.59927000"],["62642.00000000","0.07518000"],["62641.99000000","3.82051000"],["62641.98000000","0.00008000"],["62641.97000000","0.47626000"],["62641.90000000","0.15880000"],["62641.89000000","0.00024000"],["62641.67000000","0.07482000"],["62641.43000000","0.00400000"],["62641.15000000","0.07500000"],["62641.14000000","0.41310000"],["62640.95000000","0.00008000"]],"asks":[["62643.41000000","0.00157000"],["62643.42000000","0.00097000"],["62643.43000000","0.00016000"],["62643.44000000","0.00009000"],["62643.99000000","0.00018000"],["62644.00000000","0.02418000"],["62644.12000000","0.00008000"],["62644.29000000","0.00008000"],["62645.00000000","0.00008000"],["62645.37000000","0.00068000"],["62645.47000000","0.00009000"],["62645.95000000","0.00009000"],["62645.99000000","0.00018000"],["62646.00000000","0.02418000"],["62646.40000000","0.00008000"],["62646.55000000","0.00008000"],["62646.69000000","0.00018000"],["62646.70000000","0.06910000"],["62647.42000000","0.00008000"],["62647.59000000","0.00008000"]]}}
{"t":25.8651,"stream":"btcusdt@depth@100ms","data":{"e":"depthUpdate","E":1783948028514,"s":"BTCUSDT","U":97344801198,"u":97344801217,"b":[["62643.40000000","5.07281000"],["62079.61000000","0.00010000"],["56379.06000000","0.00280000"]],"a":[["62643.41000000","0.00167000"],["62648.00000000","0.02418000"],["62648.46000000","0.10853000"],["62648.60000000","0.12756000"],["62649.33000000","0.00000000"],["62738.66000000","0.00023000"],["62745.48000000","0.00039000"]]}}
{"t":25.8653,"stream":"btcusdt@depth20@100ms","data":{"lastUpdateId":97344801217,"bids":[["62643.40000000","5.07281000"],["62643.39000000","0.00034000"],["62643.38000000","0.00016000"],["62643.21000000","0.01218000"],["62643.20000000","0.00008000"],["62643.08000000","0.30032000"],["62643.00000000","0.00400000"],["62642.11000000","0.00010000"],["62642.01000000","0.59927000"],["62642.00000000","0.07518000"],["62641.99000000","3.82051000"],["62641.98000000","0.00008000"],["62641.97000000","0.47626000"],["62641.90000000","0.15880000"],["62641.89000000","0.00024000"],["62641.67000000","0.07482000"],["62641.43000000","0.00400000"],["62641.15000000","0.07500000"],["62641.14000000","0.41310000"],["62640.95000000","0.00008000"]],"asks":[["62643.41000000","0.00167000"],["62643.42000000","0.00097000"],["62643.43000000","0.00016000"],["62643.44000000","0.00009000"],["62643.99000000","0.00018000"],["62644.00000000","0.02418000"],["62644.12000000","0.00008000"],["62644.29000000","0.00008000"],["62645.00000000","0.00008000"],["62645.37000000","0.00068000"],["62645.47000000","0.00009000"],["62645.95000000","0.00009000"],["62645.99000000","0.00018000"],["62646.00000000","0.02418000"],["62646.40000000","0.00008000"],["62646.55000000","0.00008000"],["62646.69000000","0.00018000"],["62646.70000000","0.06910000"],["62647.42000000","0.00008000"],["62647.59000000","0.00008000"]]}}
{"t":25.9633,"stream":"btcusdt@depth@100ms","data":{"e":"depthUpdate","E":1783948028614,"s":"BTCUSDT","U":97344801218,"u":97344801225,"b":[["62643.21000000","0.00018000"],["62584.72000000","2.89943000"],["62582.61000000","0.00000000"],["62574.32000000","0.00015000"],["62504.57000000","0.00000000"],["62504.01000000","0.00999000"],["56379.06000000","0.00320000"]],"a":[["62711.56000000","0.00015000"]]}}
{"t":25.9644,"stream":"btcusdt@depth20@100ms","data":{"lastUpdateId":97344801225,"bids":[["62643.40000000","5.07281000"],["62643.39000000","0.00034000"],["62643.38000000","0.00016000"],["62643.21000000","0.00018000"],["62643.20000000","0.00008000"],["62643.08000000","0.30032000"],["62643.00000000","0.00400000"],["62642.11000000","0.00010000"],["62642.01000000","0.59927000"],["62642.00000000","0.07518000"],["62641.99000000","3.82051000"],["62641.98000000","0.00008000"],["62641.97000000","0.47626000"],["62641.90000000","0.15880000"],["62641.89000000","0.00024000"],["62641.67000000","0.07482000"],["62641.43000000","0.00400000"],["62641.15000000","0.07500000"],["62641.14000000","0.41310000"],["62640.95000000","0.00008000"]],"asks":[["62643.41000000","0.00167000"],["62643.42000000","0.00097000"],["62643.43000000","0.00016000"],["62643.44000000","0.00009000"],["62643.99000000","0.00018000"],["62644.00000000","0.02418000"],["62644.12000000","0.00008000"],["62644.29000000","0.00008000"],["62645.00000000","0.00008000"],["62645.37000000","0.00068000"],["62645.47000000","0.00009000"],["62645.95000000","0.00009000"],["62645.99000000","0.00018000"],["62646.00000000","0.02418000"],["62646.40000000","0.00008000"],["62646.55000000","0.00008000"],["62646.69000000","0.00018000"],["62646.70000000","0.06910000"],["62647.42000000","0.00008000"],["62647.59000000","0.00008000"]]}}
{"t":26.064,"stream":"btcusdt@depth@100ms","data":{"e":"depthUpdate","E":1783948028714,"s":"BTCUSDT","U":97344801226,"u":97344801242,"b":[["62643.40000000","5.07281000"],["62643.21000000","0.00000000"],["62527.63000000","0.00000000"],["56379.06000000","0.00360000"]],"a":[["62643.41000000","0.00158000"],["62643.42000000","0.00088000"],["62644.07000000","0.00009000"],["62648.45000000","0.00000000"],["62648.46000000","0.00018000"],["62649.84000000","0.06902000"],["62654.24000000","0.01400000"]]}}
{"t":26.0642,"stream":"btcusdt@depth20@100ms","data":{"lastUpdateId":97344801242,"bids":[["62643.40000000","5.07281000"],["62643.39000000","0.00034000"],["62643.38000000","0.00016000"],["62643.20000000","0.00008000"],["62643.08000000","0.30032000"],["62643.00000000","0.00400000"],["62642.11000000","0.00010000"],["62642.01000000","0.59927000"],["62642.00000000","0.07518000"],["62641.99000000","3.82051000"],["62641.98000000","0.00008000"],["62641.97000000","0.47626000"],["62641.90000000","0.15880000"],["62641.89000000","0.00024000"],["62641.67000000","0.07482000"],["62641.43000000","0.00400000"],["62641.15000000","0.07500000"],["62641.14000000","0.41310000"],["62640.95000000","0.00008000"],["62640.90000000","0.00008000"]],"asks":[["62643.41000000","0.00158000"],["62643.42000000","0.00088000"],["62643.43000000","0.00016000"],["62643.44000000","0.00009000"],["62643.99000000","0.00018000"],["62644.00000000","0.02418000"],["62644.07000000","0.00009000"],["62644.12000000","0.00008000"],["62644.29000000","0.00008000"],["62645.00000000","0.00008000"],["62645.37000000","0.00068000"],["62645.47000000","0.00009000"],["62645.95000000","0.00009000"],["62645.99000000","0.00018000"],["62646.00000000","0.02418000"],["62646.40000000","0.00008000"],["62646.55000000","0.00008000"],["62646.69000000","0.00018000"],["62646.70000000","0.06910000"],["62647.42000000","0.00008000"]]}}
{"t":26.1639,"stream":"btcusdt@depth@100ms","data":{"e":"depthUpdate","E":1783948028814,"s":"BTCUSDT","U":97344801243,"u":97344801271,"b":[["62643.40000000","5.07537000"],["62641.14000000","0.41189000"],["62639.46000000","0.01000000"],["62638.83000000","0.01000000"],["62638.81000000","0.01000000"],["62636.98000000","0.01000000"],["62636.01000000","0.01000000"],["62635.73000000","0.01000000"],["62635.70000000","0.02000000"],["62633.19000000","0.00000000"],["62632.54000000","0.00000000"],["62525.79000000","0.00000000"],["56379.06000000","0.00400000"]],"a":[["62646.40000000","0.00128000"],["62646.70000000","0.06902000"],["62648.00000000","0.02418000"],["62648.36000000","0.00256000"],["62648.46000000","0.00000000"],["62650.00000000","0.03418000"],["62828.83000000","0.00000000"]]}}
{"t":26.1641,"stream":"btcusdt@depth20@100ms","data":{"lastUpdateId":97344801271,"bids":[["62643.40000000","5.07537000"],["62643.39000000","0.00034000"],["62643.38000000","0.00016000"],["62643.20000000","0.00008000"],["62643.08000000","0.30032000"],["62643.00000000","0.00400000"],["62642.11000000","0.00010000"],["62642.01000000","0.59927000"],["62642.00000000","0.07518000"],["62641.99000000","3.82051000"],["62641.98000000","0.00008000"],["62641.97000000","0.47626000"],["62641.90000000","0.15880000"],["62641.89000000","0.00024000"],["62641.67000000","0.07482000"],["62641.43000000","0.00400000"],["62641.15000000","0.07500000"],["62641.14000000","0.41189000"],["62640.95000000","0.00008000"],["62640.90000000","0.00008000"]],"asks":[["62643.41000000","0.00158000"],["62643.42000000","0.00088000"],["62643.43000000","0.00016000"],["62643.44000000","0.00009000"],["62643.99000000","0.00018000"],["62644.00000000","0.02418000"],["62644.07000000","0.00009000"],["62644.12000000","0.00008000"],["62644.29000000","0.00008000"],["62645.00000000","0.00008000"],["62645.37000000","0.00068000"],["62645.47000000","0.00009000"],["62645.95000000","0.00009000"],["62645.99000000","0.00018000"],["62646.00000000","0.02418000"],["62646.40000000","0.00128000"],["62646.55000000","0.00008000"],["62646.69000000","0.00018000"],["62646.70000000","0.06902000"],["62647.42000000","0.00008000"]]}}
{"t":26.2635,"stream":"btcusdt@depth@100ms","data":{"e":"depthUpdate","E":1783948028914,"s":"BTCUSDT","U":97344801272,"u":97344801288,"b":[["62641.14000000","0.41220000"],["62640.00000000","1.92878000"],["62632.56000000","0.00000000"],["62630.71000000","0.00000000"],["62629.75000000","0.00000000"],["62629.47000000","0.01000000"],["62629.43000000","0.01000000"],["62593.03000000","0.00000000"],["62589.90000000","0.00000000"],["56379.06000000","0.00420000"]],"a":[["62643.41000000","0.00167000"],["62643.42000000","0.00097000"],["62648.60000000","0.12764000"],["62649.53000000","0.11196000"],["62675.30000000","0.00038000"],["86422.88000000","0.07564000"]]}}
{"t":26.2636,"stream":"btcusdt@depth20@100ms","data":{"lastUpdateId":97344801288,"bids":[["62643.40000000","5.07537000"],["62643.39000000","0.00034000"],["62643.38000000","0.00016000"],["62643.20000000","0.00008000"],["62643.08000000","0.30032000"],["62643.00000000","0.00400000"],["62642.11000000","0.00010000"],["62642.01000000","0.59927000"],["62642.00000000","0.07518000"],["62641.99000000","3.82051000"],["62641.98000000","0.00008000"],["62641.97000000","0.47626000"],["62641.90000000","0.15880000"],["62641.89000000","0.00024000"],["62641.67000000","0.07482000"],["62641.43000000","0.00400000"],["62641.15000000","0.07500000"],["62641.14000000","0.41220000"],["62640.95000000","0.00008000"],["62640.90000000","0.00008000"]],"asks":[["62643.41000000","0.00167000"],["62643.42000000","0.00097000"],["62643.43000000","0.00016000"],["62643.44000000","0.00009000"],["62643.99000000","0.00018000"],["62644.00000000","0.02418000"],["62644.07000000","0.00009000"],["62644.12000000","0.00008000"],["62644.29000000","0.00008000"],["62645.00000000","0.00008000"],["62645.37000000","0.00068000"],["62645.47000000","0.00009000"],["62645.95000000","0.00009000"],["62645.99000000","0.00018000"],["62646.00000000","0.02418000"],["62646.40000000","0.00128000"],["62646.55000000","0.00008000"],["62646.69000000","0.00018000"],["62646.70000000","0.06902000"],["62647.42000000","0.00008000"]]}}
{"t":26.3647,"stream":"btcusdt@depth@100ms","data":{"e":"depthUpdate","E":1783948029014,"s":"BTCUSDT","U":97344801289,"u":97344801314,"b":[["62636.99000000","0.21360000"],["62634.24000000","0.00000000"],["62629.43000000","0.00000000"],["62629.38000000","0.00008000"],["62590.69000000","0.00113000"],["62528.01000000","0.00045000"],["58600.00000000","7.44736000"],["56379.06000000","0.00460000"],["50114.72000000","0.00039000"]],"a":[["62648.60000000","0.12764000"],["62649.53000000","0.11214000"],["62650.00000000","0.03400000"],["62654.45000000","0.00008000"],["62675.30000000","0.00000000"]]}}
{"t":26.3648,"stream":"btcusdt@depth20@100ms","data":{"lastUpdateId":97344801314,"bids":[["62643.40000000","5.07537000"],["62643.39000000","0.00034000"],["62643.38000000","0.00016000"],["62643.20000000","0.00008000"],["62643.08000000","0.30032000"],["62643.00000000","0.00400000"],["62642.11000000","0.00010000"],["62642.01000000","0.59927000"],["62642.00000000","0.07518000"],["62641.99000000","3.82051000"],["62641.98000000","0.00008000"],["62641.97000000","0.47626000"],["62641.90000000","0.15880000"],["62641.89000000","0.00024000"],["62641.67000000","0.07482000"],["62641.43000000","0.00400000"],["62641.15000000","0.07500000"],["62641.14000000","0.41220000"],["62640.95000000","0.00008000"],["62640.90000000","0.00008000"]],"asks":[["62643.41000000","0.00167000"],["62643.42000000","0.00097000"],["62643.43000000","0.00016000"],["62643.44000000","0.00009000"],["62643.99000000","0.00018000"],["62644.00000000","0.02418000"],["62644.07000000","0.00009000"],["62644.12000000","0.00008000"],["62644.29000000","0.00008000"],["62645.00000000","0.00008000"],["62645.37000000","0.00068000"],["62645.47000000","0.00009000"],["62645.95000000","0.00009000"],["62645.99000000","0.00018000"],["62646.00000000","0.02418000"],["62646.40000000","0.00128000"],["62646.55000000","0.00008000"],["62646.69000000","0.00018000"],["62646.70000000","0.06902000"],["62647.42000000","0.00008000"]]}}
{"t":26.4644,"stream":"btcusdt@depth@100ms","data":{"e":"depthUpdate","E":1783948029114,"s":"BTCUSDT","U":97344801315,"u":97344801333,"b":[["62643.21000000","0.01000000"],["62590.70000000","0.00000000"],["62590.69000000","0.00000000"],["62528.01000000","0.00045000"],["59509.89000000","0.00000000"],["56379.06000000","0.00460000"],["56379.00000000","0.00000000"],["50114.72000000","0.00039000"],["40000.00000000","258.07540000"]],"a":[["62678.80000000","0.00000000"],["62718.82000000","0.00000000"],["62721.08000000","0.00030000"]]}}
{"t":26.4645,"stream":"btcusdt@depth20@100ms","data":{"lastUpdateId":97344801333,"bids":[["62643.40000000","5.07537000"],["62643.39000000","0.00034000"],["62643.38000000","0.00016000"],["62643.21000000","0.01000000"],["62643.20000000","0.00008000"],["62643.08000000","0.30032000"],["62643.00000000","0.00400000"],["62642.11000000","0.00010000"],["62642.01000000","0.59927000"],["62642.00000000","0.07518000"],["62641.99000000","3.82051000"],["62641.98000000","0.00008000"],["62641.97000000","0.47626000"],["62641.90000000","0.15880000"],["62641.89000000","0.00024000"],["62641.67000000","0.07482000"],["62641.43000000","0.00400000"],["62641.15000000","0.07500000"],["62641.14000000","0.41220000"],["62640.95000000","0.00008000"]],"asks":[["62643.41000000","0.00167000"],["62643.42000000","0.00097000"],["62643.43000000","0.00016000"],["62643.44000000","0.00009000"],["62643.99000000","0.00018000"],["62644.00000000","0.02418000"],["62644.07000000","0.00009000"],["62644.12000000","0.00008000"],["62644.29000000","0.00008000"],["62645.00000000","0.00008000"],["62645.37000000","0.00068000"],["62645.47000000","0.00009000"],["62645.95000000","0.00009000"],["62645.99000000","0.00018000"],["62646.00000000","0.02418000"],["62646.40000000","0.00128000"],["62646.55000000","0.00008000"],["62646.69000000","0.00018000"],["62646.70000000","0.06902000"],["62647.42000000","0.00008000"]]}}
{"t":26.5637,"stream":"btcusdt@depth@100ms","data":{"e":"depthUpdate","E":1783948029214,"s":"BTCUSDT","U":97344801334,"u":97344801356,"b":[["62643.40000000","5.07537000"],["62636.79000000","0.00000000"],["62636.78000000","0.00000000"],["61703.74000000","0.00030000"],["56379.06000000","0.00460000"],["56377.80000000","0.00010000"],["50114.72000000","0.00000000"]],"a":[["62654.33000000","0.01258000"],["62673.33000000","0.00000000"],["62675.97000000","0.00400000"],["62679.47000000","0.00011000"],["62680.68000000","0.00000000"],["63583.07000000","0.00067000"],["79890.03000000","0.42420000"]]}}
{"t":26.5639,"stream":"btcusdt@depth20@100ms","data":{"lastUpdateId":97344801356,"bids":[["62643.40000000","5.07537000"],["62643.39000000","0.00034000"],["62643.38000000","0.00016000"],["62643.21000000","0.01000000"],["62643.20000000","0.00008000"],["62643.08000000","0.30032000"],["62643.00000000","0.00400000"],["62642.11000000","0.00010000"],["62642.01000000","0.59927000"],["62642.00000000","0.07518000"],["62641.99000000","3.82051000"],["62641.98000000","0.00008000"],["62641.97000000","0.47626000"],["62641.90000000","0.15880000"],["62641.89000000","0.00024000"],["62641.67000000","0.07482000"],["62641.43000000","0.00400000"],["62641.15000000","0.07500000"],["62641.14000000","0.41220000"],["62640.95000000","0.00008000"]],"asks":[["62643.41000000","0.00167000"],["62643.42000000","0.00097000"],["62643.43000000","0.00016000"],["62643.44000000","0.00009000"],["62643.99000000","0.00018000"],["62644.00000000","0.02418000"],["62644.07000000","0.00009000"],["62644.12000000","0.00008000"],["62644.29000000","0.00008000"],["62645.00000000","0.00008000"],["62645.37000000","0.00068000"],["62645.47000000","0.00009000"],["62645.95000000","0.00009000"],["62645.99000000","0.00018000"],["62646.00000000","0.02418000"],["62646.40000000","0.00128000"],["62646.55000000","0.00008000"],["62646.69000000","0.00018000"],["62646.70000000","0.06902000"],["62647.42000000","0.00008000"]]}}
{"t":26.6196,"stream":"btcusdt@aggTrade","data":{"e":"aggTrade","E":1783948029268,"s":"BTCUSDT","a":4013160644,"p":"62643.41000000","q":"0.00080000","f":6501834069,"l":6501834077,"T":1783948029268,"m":false,"M":true}}
{"t":26.6641,"stream":"btcusdt@depth@100ms","data":{"e":"depthUpdate","E":1783948029314,"s":"BTCUSDT","U":97344801357,"u":97344801383,"b":[["62643.40000000","5.07546000"],["62637.55000000","0.00008000"],["62633.88000000","0.14477000"],["62632.31000000","0.15110000"],["62629.88000000","0.00000000"],["62628.31000000","0.00000000"],["56379.06000000","0.00460000"],["56377.01000000","0.00177000"]],"a":[["62643.41000000","0.00156000"],["62654.40000000","0.00000000"],["62655.97000000","0.00000000"],["62766.01000000","0.00638000"]]}}
{"t":26.6642,"stream":"btcusdt@depth20@100ms","data":{"lastUpdateId":97344801383,"bids":[["62643.40000000","5.07546000"],["62643.39000000","0.00034000"],["62643.38000000","0.00016000"],["62643.21000000","0.01000000"],["62643.20000000","0.00008000"],["62643.08000000","0.30032000"],["62643.00000000","0.00400000"],["62642.11000000","0.00010000"],["62642.01000000","0.59927000"],["62642.00000000","0.07518000"],["62641.99000000","3.82051000"],["62641.98000000","0.00008000"],["62641.97000000","0.47626000"],["62641.90000000","0.15880000"],["62641.89000000","0.00024000"],["62641.67000000","0.07482000"],["62641.43000000","0.00400000"],["62641.15000000","0.07500000"],["62641.14000000","0.41220000"],["62640.95000000","0.00008000"]],"asks":[["62643.41000000","0.00156000"],["62643.42000000","0.00097000"],["62643.43000000","0.00016000"],["62643.44000000","0.00009000"],["62643.99000000","0.00018000"],["62644.00000000","0.02418000"],["62644.07000000","0.00009000"],["62644.12000000","0.00008000"],["62644.29000000","0.00008000"],["62645.00000000","0.00008000"],["62645.37000000","0.00068000"],["62645.47000000","0.00009000"],["62645.95000000","0.00009000"],["62645.99000000","0.00018000"],["62646.00000000","0.02418000"],["62646.40000000","0.00128000"],["62646.55000000","0.00008000"],["62646.69000000","0.00018000"],["62646.70000000","0.06902000"],["62647.42000000","0.00008000"]]}}
{"t":26.7631,"stream":"btcusdt@depth@100ms","data":{"e":"depthUpdate","E":1783948029414,"s":"BTCUSDT","U":97344801384,"u":97344801451,"b":[["62643.40000000","3.95810000"],["62643.21000000","0.01018000"],["62643.09000000","0.00018000"],["62642.12000000","0.00798000"],["62642.02000000","0.47618000"],["62642.01000000","0.00036000"],["62642.00000000","0.07536000"],["62641.99000000","0.62773000"],["62641.97000000","0.00026000"],["62636.99000000","0.00000000"],["62636.81000000","0.59910000"],["62635.74000000","0.15664000"],["62635.60000000","3.19267000"],["62633.31000000","0.00000000"],["62528.01000000","0.00000000"],["56379.06000000","0.00460000"]],"a":[["62643.41000000","0.71175000"],["62643.42000000","0.00106000"],["62644.87000000","0.00068000"],["62645.37000000","0.00000000"],["62646.70000000","0.06910000"],["62647.25000000","0.09028000"],["62647.80000000","0.00592000"],["62647.81000000","0.13965000"],["62648.59000000","0.00000000"],["62648.60000000","0.12772000"],["62648.87000000","0.00000000"],["62649.53000000","0.00018000"],["62649.84000000","0.06884000"],["62652.96000000","1.91755000"],["62766.01000000","0.00000000"],["62817.11000000","0.00009000"]]}}
{"t":26.7632,"stream":"btcusdt@depth20@100ms","data":{"lastUpdateId":97344801451,"bids":[["62643.40000000","3.95810000"],["62643.39000000","0.00034000"],["62643.38000000","0.00016000"],["62643.21000000","0.01018000"],["62643.20000000","0.00008000"],["62643.09000000","0.00018000"],["62643.08000000","0.30032000"],["62643.00000000","0.00400000"],["62642.12000000","0.00798000"],["62642.11000000","0.00010000"],["62642.02000000","0.47618000"],["62642.01000000","0.00036000"],["62642.00000000","0.07536000"],["62641.99000000","0.62773000"],["62641.98000000","0.00008000"],["62641.97000000","0.00026000"],["62641.90000000","0.15880000"],["62641.89000000","0.00024000"],["62641.67000000","0.07482000"],["62641.43000000","0.00400000"]],"asks":[["62643.41000000","0.71175000"],["62643.42000000","0.00106000"],["62643.43000000","0.00016000"],["62643.44000000","0.00009000"],["62643.99000000","0.00018000"],["62644.00000000","0.02418000"],["62644.07000000","0.00009000"],["62644.12000000","0.00008000"],["62644.29000000","0.00008000"],["62644.87000000","0.00068000"],["62645.00000000","0.00008000"],["62645.47000000","0.00009000"],["62645.95000000","0.00009000"],["62645.99000000","0.00018000"],["62646.00000000","0.02418000"],["62646.40000000","0.00128000"],["62646.55000000","0.00008000"],["62646.69000000","0.00018000"],["62646.70000000","0.06910000"],["62647.25000000","0.09028000"]]}}
{"t":26.8642,"stream":"btcusdt@depth@100ms","data":{"e":"depthUpdate","E":1783948029514,"s":"BTCUSDT","U":97344801452,"u":97344801545,"b":[["62643.08000000","0.30040000"],["62642.12000000","0.00816000"],["62642.03000000","0.00018000"],["62642.02000000","0.47618000"],["62642.01000000","0.00018000"],["62641.99000000","0.62773000"],["62641.97000000","0.00008000"],["62641.91000000","0.00009000"],["62637.15000000","0.59910000"],["62636.81000000","0.00000000"],["62636.02000000","0.10986000"],["62635.74000000","0.00000000"],["62635.41000000","0.00000000"],["62634.01000000","0.00000000"],["62633.41000000","0.00000000"],["62617.73000000","0.57538000"],["62584.72000000","0.00000000"],["56379.06000000","0.00460000"]],"a":[["62643.41000000","0.02253000"],["62643.42000000","0.00115000"],["62644.77000000","0.00000000"],["62644.87000000","0.00000000"],["62645.35000000","0.00068000"],["62646.27000000","0.00256000"],["62646.62000000","0.10583000"],["62646.70000000","0.06918000"],["62647.24000000","0.00018000"],["62647.25000000","0.00018000"],["62647.41000000","0.00000000"],["62647.42000000","0.00008000"],["62647.80000000","0.00583000"],["62647.81000000","0.13983000"],["62647.99000000","0.00000000"],["62648.60000000","0.12756000"],["62649.53000000","0.00000000"],["62649.70000000","0.13974000"],["62650.35000000","0.00017000"],["62655.20000000","0.00012000"],["62655.76000000","0.00000000"],["62681.85000000","0.00000000"],["62818.80000000","0.00000000"]]}}
{"t":26.8643,"stream":"btcusdt@depth20@100ms","data":{"lastUpdateId":97344801545,"bids":[["62643.40000000","3.95810000"],["62643.39000000","0.00034000"],["62643.38000000","0.00016000"],["62643.21000000","0.01018000"],["62643.20000000","0.00008000"],["62643.09000000","0.00018000"],["62643.08000000","0.30040000"],["62643.00000000","0.00400000"],["62642.12000000","0.00816000"],["62642.11000000","0.00010000"],["62642.03000000","0.00018000"],["62642.02000000","0.47618000"],["62642.01000000","0.00018000"],["62642.00000000","0.07536000"],["62641.99000000","0.62773000"],["62641.98000000","0.00008000"],["62641.97000000","0.00008000"],["62641.91000000","0.00009000"],["62641.90000000","0.15880000"],["62641.89000000","0.00024000"]],"asks":[["62643.41000000","0.02253000"],["62643.42000000","0.00115000"],["62643.43000000","0.00016000"],["62643.44000000","0.00009000"],["62643.99000000","0.00018000"],["62644.00000000","0.02418000"],["62644.07000000","0.00009000"],["62644.12000000","0.00008000"],["62644.29000000","0.00008000"],["62645.00000000","0.00008000"],["62645.35000000","0.00068000"],["62645.47000000","0.00009000"],["62645.95000000","0.00009000"],["62645.99000000","0.00018000"],["62646.00000000","0.02418000"],["62646.27000000","0.00256000"],["62646.40000000","0.00128000"],["62646.55000000","0.00008000"],["62646.62000000","0.10583000"],["62646.69000000","0.00018000"]]}}
{"t":26.9642,"stream":"btcusdt@depth@100ms","data":{"e":"depthUpdate","E":1783948029614,"s":"BTCUSDT","U":97344801546,"u":97344801580,"b":[["62643.21000000","0.00018000"],["56379.06000000","0.00460000"],["50115.00000000","0.13713000"]],"a":[["62643.41000000","0.12252000"],["62643.42000000","0.00106000"],["62645.26000000","0.00068000"],["62645.35000000","0.00000000"],["62646.00000000","0.02418000"],["62646.61000000","0.00018000"],["62646.62000000","0.10601000"],["62646.70000000","0.06910000"],["62647.24000000","0.00000000"],["62647.25000000","0.00000000"]]}}
{"t":26.9643,"stream":"btcusdt@depth20@100ms","data":{"lastUpdateId":97344801580,"bids":[["62643.40000000","3.95810000"],["62643.39000000","0.00034000"],["62643.38000000","0.00016000"],["62643.21000000","0.00018000"],["62643.20000000","0.00008000"],["62643.09000000","0.00018000"],["62643.08000000","0.30040000"],["62643.00000000","0.00400000"],["62642.12000000","0.00816000"],["62642.11000000","0.00010000"],["62642.03000000","0.00018000"],["62642.02000000","0.47618000"],["62642.01000000","0.00018000"],["62642.00000000","0.07536000"],["62641.99000000","0.62773000"],["62641.98000000","0.00008000"],["62641.97000000","0.00008000"],["62641.91000000","0.00009000"],["62641.90000000","0.15880000"],["62641.89000000","0.00024000"]],"asks":[["62643.41000000","0.12252000"],["62643.42000000","0.00106000"],["62643.43000000","0.00016000"],["62643.44000000","0.00009000"],["62643.99000000","0.00018000"],["62644.00000000","0.02418000"],["62644.07000000","0.00009000"],["62644.12000000","0.00008000"],["62644.29000000","0.00008000"],["62645.00000000","0.00008000"],["62645.26000000","0.00068000"],["62645.47000000","0.00009000"],["62645.95000000","0.00009000"],["62645.99000000","0.00018000"],["62646.00000000","0.02418000"],["62646.27000000","0.00256000"],["62646.40000000","0.00128000"],["62646.55000000","0.00008000"],["62646.61000000","0.00018000"],["62646.62000000","0.10601000"]]}}
{"t":27.0638,"stream":"btcusdt@depth@100ms","data":{"e":"depthUpdate","E":1783948029714,"s":"BTCUSDT","U":97344801581,"u":97344801605,"b":[["62643.40000000","3.95653000"],["62643.21000000","0.00000000"],["62641.67000000","0.07500000"],["62640.20000000","0.00168000"],["62633.31000000","0.36191000"],["62607.84000000","0.07000000"],["62504.01000000","0.00000000"],["62500.02000000","0.02102000"],["62391.73000000","0.00000000"],["62389.86000000","0.01711000"],["56379.06000000","0.00460000"]],"a":[["62643.41000000","0.12270000"],["62643.42000000","0.00124000"],["62659.79000000","0.57499000"],["62668.77000000","0.00000000"],["62786.19000000","0.01253000"]]}}
{"t":27.0639,"stream":"btcusdt@depth20@100ms","data":{"lastUpdateId":97344801605,"bids":[["62643.40000000","3.95653000"],["62643.39000000","0.00034000"],["62643.38000000","0.00016000"],["62643.20000000","0.00008000"],["62643.09000000","0.00018000"],["62643.08000000","0.30040000"],["62643.00000000","0.00400000"],["62642.12000000","0.00816000"],["62642.11000000","0.00010000"],["62642.03000000","0.00018000"],["62642.02000000","0.47618000"],["62642.01000000","0.00018000"],["62642.00000000","0.07536000"],["62641.99000000","0.62773000"],["62641.98000000","0.00008000"],["62641.97000000","0.00008000"],["62641.91000000","0.00009000"],["62641.90000000","0.15880000"],["62641.89000000","0.00024000"],["62641.67000000","0.07500000"]],"asks":[["62643.41000000","0.12270000"],["62643.42000000","0.00124000"],["62643.43000000","0.00016000"],["62643.44000000","0.00009000"],["62643.99000000","0.00018000"],["62644.00000000","0.02418000"],["62644.07000000","0.00009000"],["62644.12000000","0.00008000"],["62644.29000000","0.00008000"],["62645.00000000","0.00008000"],["62645.26000000","0.00068000"],["62645.47000000","0.00009000"],["62645.95000000","0.00009000"],["62645.99000000","0.00018000"],["62646.00000000","0.02418000"],["62646.27000000","0.00256000"],["62646.40000000","0.00128000"],["62646.55000000","0.00008000"],["62646.61000000","0.00018000"],["62646.62000000","0.10601000"]]}}
{"t":27.1637,"stream":"btcusdt@depth@100ms","data":{"e":"depthUpdate","E":1783948029814,"s":"BTCUSDT","U":97344801606,"u":97344801614,"b":[["62593.10000000","0.01000000"],["62589.97000000","0.01000000"],["56379.06000000","0.00460000"]],"a":[["62643.41000000","0.12270000"],["62643.44000000","0.00000000"]]}}
{"t":27.164,"stream":"btcusdt@depth20@100ms","data":{"lastUpdateId":97344801614,"bids":[["62643.40000000","3.95653000"],["62643.39000000","0.00034000"],["62643.38000000","0.00016000"],["62643.20000000","0.00008000"],["62643.09000000","0.00018000"],["62643.08000000","0.30040000"],["62643.00000000","0.00400000"],["62642.12000000","0.00816000"],["62642.11000000","0.00010000"],["62642.03000000","0.00018000"],["62642.02000000","0.47618000"],["62642.01000000","0.00018000"],["62642.00000000","0.07536000"],["62641.99000000","0.62773000"],["62641.98000000","0.00008000"],["62641.97000000","0.00008000"],["62641.91000000","0.00009000"],["62641.90000000","0.15880000"],["62641.89000000","0.00024000"],["62641.67000000","0.07500000"]],"asks":[["62643.41000000","0.12270000"],["62643.42000000","0.00124000"],["62643.43000000","0.00016000"],["62643.99000000","0.00018000"],["62644.00000000","0.02418000"],["62644.07000000","0.00009000"],["62644.12000000","0.00008000"],["62644.29000000","0.00008000"],["62645.00000000","0.00008000"],["62645.26000000","0.00068000"],["62645.47000000","0.00009000"],["62645.95000000","0.00009000"],["62645.99000000","0.00018000"],["62646.00000000","0.02418000"],["62646.27000000","0.00256000"],["62646.40000000","0.00128000"],["62646.55000000","0.00008000"],["62646.61000000","0.00018000"],["62646.62000000","0.10601000"],["62646.69000000","0.00018000"]]}}
{"t":27.2651,"stream":"btcusdt@depth@100ms","data":{"e":"depthUpdate","E":1783948029914,"s":"BTCUSDT","U":97344801615,"u":97344801627,"b":[["62643.40000000","3.95784000"],["62641.99000000","0.62613000"],["62640.00000000","1.93678000"],["56379.06000000","0.00480000"],["50115.00000000","0.13713000"],["50113.00000000","0.00193000"]],"a":[["62679.47000000","0.00000000"],["62679.95000000","0.00011000"]]}}
{"t":27.2651,"stream":"btcusdt@depth20@100ms","data":{"lastUpdateId":97344801627,"bids":[["62643.40000000","3.95784000"],["62643.39000000","0.00034000"],["62643.38000000","0.00016000"],["62643.20000000","0.00008000"],["62643.09000000","0.00018000"],["62643.08000000","0.30040000"],["62643.00000000","0.00400000"],["62642.12000000","0.00816000"],["62642.11000000","0.00010000"],["62642.03000000","0.00018000"],["62642.02000000","0.47618000"],["62642.01000000","0.00018000"],["62642.00000000","0.07536000"],["62641.99000000","0.62613000"],["62641.98000000","0.00008000"],["62641.97000000","0.00008000"],["62641.91000000","0.00009000"],["62641.90000000","0.15880000"],["62641.89000000","0.00024000"],["62641.67000000","0.07500000"]],"asks":[["62643.41000000","0.12270000"],["62643.42000000","0.00124000"],["62643.43000000","0.00016000"],["62643.99000000","0.00018000"],["62644.00000000","0.02418000"],["62644.07000000","0.00009000"],["62644.12000000","0.00008000"],["62644.29000000","0.00008000"],["62645.00000000","0.00008000"],["62645.26000000","0.00068000"],["62645.47000000","0.00009000"],["62645.95000000","0.00009000"],["62645.99000000","0.00018000"],["62646.00000000","0.02418000"],["62646.27000000","0.00256000"],["62646.40000000","0.00128000"],["62646.55000000","0.00008000"],["62646.61000000","0.00018000"],["62646.62000000","0.10601000"],["62646.69000000","0.00018000"]]}}
{"t":27.3472,"stream":"btcusdt@aggTrade","data":{"e":"aggTrade","E":1783948029996,"s":"BTCUSDT","a":4013160645,"p":"62643.40000000","q":"0.00078000","f":6501834078,"l":6501834078,"T":1783948029995,"m":true,"M":true}}
{"t":27.3644,"stream":"btcusdt@depth@100ms","data":{"e":"depthUpdate","E":1783948030014,"s":"BTCUSDT","U":97344801628,"u":97344801660,"b":[["62643.40000000","3.95706000"],["62629.38000000","0.00000000"],["62590.69000000","0.00113000"],["62528.01000000","0.00045000"],["56379.06000000","0.00480000"],["50114.72000000","0.00039000"]],"a":[["62643.41000000","0.10200000"],["62646.61000000","0.00000000"],["62646.62000000","0.00018000"],["62647.80000000","0.00592000"],["62647.99000000","0.00009000"],["62654.45000000","0.00000000"],["62675.30000000","0.02662000"],["62766.80000000","0.00000000"],["62766.81000000","0.12270000"]]}}
{"t":27.3645,"stream":"btcusdt@depth20@100ms","data":{"lastUpdateId":97344801660,"bids":[["62643.40000000","3.95706000"],["62643.39000000","0.00034000"],["62643.38000000","0.00016000"],["62643.20000000","0.00008000"],["62643.09000000","0.00018000"],["62643.08000000","0.30040000"],["62643.00000000","0.00400000"],["62642.12000000","0.00816000"],["62642.11000000","0.00010000"],["62642.03000000","0.00018000"],["62642.02000000","0.47618000"],["62642.01000000","0.00018000"],["62642.00000000","0.07536000"],["62641.99000000","0.62613000"],["62641.98000000","0.00008000"],["62641.97000000","0.00008000"],["62641.91000000","0.00009000"],["62641.90000000","0.15880000"],["62641.89000000","0.00024000"],["62641.67000000","0.07500000"]],"asks":[["62643.41000000","0.10200000"],["62643.42000000","0.00124000"],["62643.43000000","0.00016000"],["62643.99000000","0.00018000"],["62644.00000000","0.02418000"],["62644.07000000","0.00009000"],["62644.12000000","0.00008000"],["62644.29000000","0.00008000"],["62645.00000000","0.00008000"],["62645.26000000","0.00068000"],["62645.47000000","0.00009000"],["62645.95000000","0.00009000"],["62645.99000000","0.00018000"],["62646.00000000","0.02418000"],["62646.27000000","0.00256000"],["62646.40000000","0.00128000"],["62646.55000000","0.00008000"],["62646.62000000","0.00018000"],["62646.69000000","0.00018000"],["62646.70000000","0.06910000"]]}}
{"t":27.4646,"stream":"btcusdt@depth@100ms","data":{"e":"depthUpdate","E":1783948030114,"s":"BTCUSDT","U":97344801661,"u":97344801703,"b":[["62643.21000000","0.01000000"],["62629.38000000","0.00008000"],["62590.69000000","0.00000000"],["62528.01000000","0.00045000"],["56379.06000000","0.00480000"],["50114.72000000","0.00039000"],["40000.00000000","258.07540000"]],"a":[["62643.41000000","0.10174000"],["62643.42000000","0.00106000"],["62646.00000000","0.02418000"],["62646.62000000","0.00000000"],["62648.36000000","0.00000000"],["62649.70000000","0.13992000"],["62654.45000000","0.00008000"],["62664.50000000","3.19404000"],["62766.64000000","0.10200000"],["62766.81000000","0.00000000"]]}}
{"t":27.4648,"stream":"btcusdt@depth20@100ms","data":{"lastUpdateId":97344801703,"bids":[["62643.40000000","3.95706000"],["62643.39000000","0.00034000"],["62643.38000000","0.00016000"],["62643.21000000","0.01000000"],["62643.20000000","0.00008000"],["62643.09000000","0.00018000"],["62643.08000000","0.30040000"],["62643.00000000","0.00400000"],["62642.12000000","0.00816000"],["62642.11000000","0.00010000"],["62642.03000000","0.00018000"],["62642.02000000","0.47618000"],["62642.01000000","0.00018000"],["62642.00000000","0.07536000"],["62641.99000000","0.62613000"],["62641.98000000","0.00008000"],["62641.97000000","0.00008000"],["62641.91000000","0.00009000"],["62641.90000000","0.15880000"],["62641.89000000","0.00024000"]],"asks":[["62643.41000000","0.10174000"],["62643.42000000","0.00106000"],["62643.43000000","0.00016000"],["62643.99000000","0.00018000"],["62644.00000000","0.02418000"],["62644.07000000","0.00009000"],["62644.12000000","0.00008000"],["62644.29000000","0.00008000"],["62645.00000000","0.00008000"],["62645.26000000","0.00068000"],["62645.47000000","0.00009000"],["62645.95000000","0.00009000"],["62645.99000000","0.00018000"],["62646.00000000","0.02418000"],["62646.27000000","0.00256000"],["62646.40000000","0.00128000"],["62646.55000000","0.00008000"],["62646.69000000","0.00018000"],["62646.70000000","0.06910000"],["62647.42000000","0.00008000"]]}}
{"t":27.5638,"stream":"btcusdt@depth@100ms","data":{"e":"depthUpdate","E":1783948030214,"s":"BTCUSDT","U":97344801704,"u":97344801766,"b":[["62643.40000000","3.95706000"],["62640.00000000","1.94178000"],["62639.83000000","0.00008000"],["62638.42000000","0.00000000"],["62637.99000000","0.00000000"],["62637.55000000","0.00000000"],["61703.74000000","0.00030000"],["56379.06000000","0.00480000"],["56379.00000000","0.00000000"],["50114.72000000","0.00000000"]],"a":[["62643.41000000","0.10523000"],["62643.42000000","0.00097000"],["62645.55000000","0.00265000"],["62645.56000000","0.17256000"],["62646.27000000","0.00000000"],["62647.99000000","0.00000000"],["62648.68000000","0.11055000"],["62650.35000000","0.00017000"],["62652.96000000","0.00000000"],["62653.50000000","0.00008000"],["62655.51000000","0.13966000"],["62656.40000000","0.13966000"],["62656.65000000","0.00008000"],["62659.80000000","0.00564000"],["62662.95000000","0.00008000"],["62664.71000000","0.13564000"],["62666.10000000","0.00008000"],["62675.30000000","0.00000000"],["62766.64000000","0.00000000"],["62766.65000000","0.00000000"],["63583.07000000","0.00037000"]]}}
{"t":27.5639,"stream":"btcusdt@depth20@100ms","data":{"lastUpdateId":97344801766,"bids":[["62643.40000000","3.95706000"],["62643.39000000","0.00034000"],["62643.38000000","0.00016000"],["62643.21000000","0.01000000"],["62643.20000000","0.00008000"],["62643.09000000","0.00018000"],["62643.08000000","0.30040000"],["62643.00000000","0.00400000"],["62642.12000000","0.00816000"],["62642.11000000","0.00010000"],["62642.03000000","0.00018000"],["62642.02000000","0.47618000"],["62642.01000000","0.00018000"],["62642.00000000","0.07536000"],["62641.99000000","0.62613000"],["62641.98000000","0.00008000"],["62641.97000000","0.00008000"],["62641.91000000","0.00009000"],["62641.90000000","0.15880000"],["62641.89000000","0.00024000"]],"asks":[["62643.41000000","0.10523000"],["62643.42000000","0.00097000"],["62643.43000000","0.00016000"],["62643.99000000","0.00018000"],["62644.00000000","0.02418000"],["62644.07000000","0.00009000"],["62644.12000000","0.00008000"],["62644.29000000","0.00008000"],["62645.00000000","0.00008000"],["62645.26000000","0.00068000"],["62645.47000000","0.00009000"],["62645.55000000","0.00265000"],["62645.56000000","0.17256000"],["62645.95000000","0.00009000"],["62645.99000000","0.00018000"],["62646.00000000","0.02418000"],["62646.40000000","0.00128000"],["62646.55000000","0.00008000"],["62646.69000000","0.00018000"],["62646.70000000","0.06910000"]]}}
{"t":27.6645,"stream":"btcusdt@depth@100ms","data":{"e":"depthUpdate","E":1783948030314,"s":"BTCUSDT","U":97344801767,"u":97344801800,"b":[["62633.10000000","0.00000000"],["62574.32000000","0.00000000"],["62540.91000000","0.00000000"],["56379.06000000","0.00480000"]],"a":[["62643.41000000","0.10200000"],["62643.42000000","0.00115000"],["62644.00000000","0.02418000"],["62645.56000000","0.17274000"],["62648.60000000","0.12756000"],["62649.70000000","0.13974000"],["62657.56000000","0.00000000"],["62727.83000000","0.00009000"],["62766.65000000","0.00000000"],["62766.68000000","0.00000000"],["63583.07000000","0.00067000"]]}}
{"t":27.6646,"stream":"btcusdt@depth20@100ms","data":{"lastUpdateId":97344801800,"bids":[["62643.40000000","3.95706000"],["62643.39000000","0.00034000"],["62643.38000000","0.00016000"],["62643.21000000","0.01000000"],["62643.20000000","0.00008000"],["62643.09000000","0.00018000"],["62643.08000000","0.30040000"],["62643.00000000","0.00400000"],["62642.12000000","0.00816000"],["62642.11000000","0.00010000"],["62642.03000000","0.00018000"],["62642.02000000","0.47618000"],["62642.01000000","0.00018000"],["62642.00000000","0.07536000"],["62641.99000000","0.62613000"],["62641.98000000","0.00008000"],["62641.97000000","0.00008000"],["62641.91000000","0.00009000"],["62641.90000000","0.15880000"],["62641.89000000","0.00024000"]],"asks":[["62643.41000000","0.10200000"],["62643.42000000","0.00115000"],["62643.43000000","0.00016000"],["62643.99000000","0.00018000"],["62644.00000000","0.02418000"],["62644.07000000","0.00009000"],["62644.12000000","0.00008000"],["62644.29000000","0.00008000"],["62645.00000000","0.00008000"],["62645.26000000","0.00068000"],["62645.47000000","0.00009000"],["62645.55000000","0.00265000"],["62645.56000000","0.17274000"],["62645.95000000","0.00009000"],["62645.99000000","0.00018000"],["62646.00000000","0.02418000"],["62646.40000000","0.00128000"],["62646.55000000","0.00008000"],["62646.69000000","0.00018000"],["62646.70000000","0.06910000"]]}}
{"t":27.6647,"stream":"btcusdt@aggTrade","data":{"e":"aggTrade","E":1783948030315,"s":"BTCUSDT","a":4013160646,"p":"62643.40000000","q":"0.00081000","f":6501834079,"l":6501834079,"T":1783948030314,"m":true,"M":true}}
{"t":27.763,"stream":"btcusdt@depth@100ms","data":{"e":"depthUpdate","E":1783948030414,"s":"BTCUSDT","U":97344801801,"u":97344801807,"b":[["62643.40000000","3.95625000"],["56379.06000000","0.00470000"]],"a":[["62643.44000000","0.00009000"],["62674.74000000","0.00011000"]]}}
{"t":27.7701,"stream":"btcusdt@depth20@100ms","data":{"lastUpdateId":97344801807,"bids":[["62643.40000000","3.95625000"],["62643.39000000","0.00034000"],["62643.38000000","0.00016000"],["62643.21000000","0.01000000"],["62643.20000000","0.00008000"],["62643.09000000","0.00018000"],["62643.08000000","0.30040000"],["62643.00000000","0.00400000"],["62642.12000000","0.00816000"],["62642.11000000","0.00010000"],["62642.03000000","0.00018000"],["62642.02000000","0.47618000"],["62642.01000000","0.00018000"],["62642.00000000","0.07536000"],["62641.99000000","0.62613000"],["62641.98000000","0.00008000"],["62641.97000000","0.00008000"],["62641.91000000","0.00009000"],["62641.90000000","0.15880000"],["62641.89000000","0.00024000"]],"asks":[["62643.41000000","0.10200000"],["62643.42000000","0.00115000"],["62643.43000000","0.00016000"],["62643.44000000","0.00009000"],["62643.99000000","0.00018000"],["62644.00000000","0.02418000"],["62644.07000000","0.00009000"],["62644.12000000","0.00008000"],["62644.29000000","0.00008000"],["62645.00000000","0.00008000"],["62645.26000000","0.00068000"],["62645.47000000","0.00009000"],["62645.55000000","0.00265000"],["62645.56000000","0.17274000"],["62645.95000000","0.00009000"],["62645.99000000","0.00018000"],["62646.00000000","0.02418000"],["62646.40000000","0.00128000"],["62646.55000000","0.00008000"],["62646.69000000","0.00018000"]]}}
{"t":27.8648,"stream":"btcusdt@depth@100ms","data":{"e":"depthUpdate","E":1783948030514,"s":"BTCUSDT","U":97344801808,"u":97344801819,"b":[["62643.40000000","3.96414000"],["62642.12000000","0.00018000"],["62582.61000000","2.89943000"],["62509.63000000","0.00000000"],["56379.06000000","0.00470000"]],"a":[["62766.66000000","0.00018000"]]}}
{"t":27.8649,"stream":"btcusdt@depth20@100ms","data":{"lastUpdateId":97344801819,"bids":[["62643.40000000","3.96414000"],["62643.39000000","0.00034000"],["62643.38000000","0.00016000"],["62643.21000000","0.01000000"],["62643.20000000","0.00008000"],["62643.09000000","0.00018000"],["62643.08000000","0.30040000"],["62643.00000000","0.00400000"],["62642.12000000","0.00018000"],["62642.11000000","0.00010000"],["62642.03000000","0.00018000"],["62642.02000000","0.47618000"],["62642.01000000","0.00018000"],["62642.00000000","0.07536000"],["62641.99000000","0.62613000"],["62641.98000000","0.00008000"],["62641.97000000","0.00008000"],["62641.91000000","0.00009000"],["62641.90000000","0.15880000"],["62641.89000000","0.00024000"]],"asks":[["62643.41000000","0.10200000"],["62643.42000000","0.00115000"],["62643.43000000","0.00016000"],["62643.44000000","0.00009000"],["62643.99000000","0.00018000"],["62644.00000000","0.02418000"],["62644.07000000","0.00009000"],["62644.12000000","0.00008000"],["62644.29000000","0.00008000"],["62645.00000000","0.00008000"],["62645.26000000","0.00068000"],["62645.47000000","0.00009000"],["62645.55000000","0.00265000"],["62645.56000000","0.17274000"],["62645.95000000","0.00009000"],["62645.99000000","0.00018000"],["62646.00000000","0.02418000"],["62646.40000000","0.00128000"],["62646.55000000","0.00008000"],["62646.69000000","0.00018000"]]}}
{"t":27.9635,"stream":"btcusdt@depth@100ms","data":{"e":"depthUpdate","E":1783948030614,"s":"BTCUSDT","U":97344801820,"u":97344801848,"b":[["62643.40000000","3.96441000"],["62643.21000000","0.01018000"],["62643.08000000","0.30022000"],["62642.12000000","0.00000000"],["62636.65000000","0.02755000"],["56379.06000000","0.00470000"]],"a":[["62643.41000000","0.10550000"],["62647.81000000","0.13991000"],["62647.95000000","0.10311000"],["62648.68000000","0.00016000"],["62679.95000000","0.00000000"],["62766.65000000","0.00000000"],["62766.66000000","0.00018000"]]}}
{"t":27.9644,"stream":"btcusdt@depth20@100ms","data":{"lastUpdateId":97344801848,"bids":[["62643.40000000","3.96441000"],["62643.39000000","0.00034000"],["62643.38000000","0.00016000"],["62643.21000000","0.01018000"],["62643.20000000","0.00008000"],["62643.09000000","0.00018000"],["62643.08000000","0.30022000"],["62643.00000000","0.00400000"],["62642.11000000","0.00010000"],["62642.03000000","0.00018000"],["62642.02000000","0.47618000"],["62642.01000000","0.00018000"],["62642.00000000","0.07536000"],["62641.99000000","0.62613000"],["62641.98000000","0.00008000"],["62641.97000000","0.00008000"],["62641.91000000","0.00009000"],["62641.90000000","0.15880000"],["62641.89000000","0.00024000"],["62641.67000000","0.07500000"]],"asks":[["62643.41000000","0.10550000"],["62643.42000000","0.00115000"],["62643.43000000","0.00016000"],["62643.44000000","0.00009000"],["62643.99000000","0.00018000"],["62644.00000000","0.02418000"],["62644.07000000","0.00009000"],["62644.12000000","0.00008000"],["62644.29000000","0.00008000"],["62645.00000000","0.00008000"],["62645.26000000","0.00068000"],["62645.47000000","0.00009000"],["62645.55000000","0.00265000"],["62645.56000000","0.17274000"],["62645.95000000","0.00009000"],["62645.99000000","0.00018000"],["62646.00000000","0.02418000"],["62646.40000000","0.00128000"],["62646.55000000","0.00008000"],["62646.69000000","0.00018000"]]}}
{"t":28.0639,"stream":"btcusdt@depth@100ms","data":{"e":"depthUpdate","E":1783948030714,"s":"BTCUSDT","U":97344801849,"u":97344801871,"b":[["62643.21000000","0.00018000"],["62641.14000000","0.41228000"],["62640.02000000","0.59909000"],["62637.15000000","0.00000000"],["62501.77000000","0.00999000"],["62500.02000000","0.01103000"],["56379.06000000","0.00470000"]],"a":[["62643.41000000","0.10191000"],["62647.81000000","0.13991000"],["62647.95000000","0.00018000"],["62648.60000000","0.12738000"],["62680.17000000","0.00011000"],["62741.37000000","0.00000000"],["62766.69000000","0.00000000"]]}}
