{"t":9.8647,"stream":"btcusdt@depth20@100ms","data":{"lastUpdateId":97344795507,"bids":[["62639.99000000","1.33022000"],["62639.98000000","0.00591000"],["62639.97000000","0.00016000"],["62639.85000000","0.00008000"],["62639.83000000","0.00016000"],["62638.95000000","0.00032000"],["62638.85000000","0.00008000"],["62638.44000000","0.00009000"],["62638.42000000","0.00008000"],["62638.11000000","0.00008000"],["62638.01000000","0.00018000"],["62638.00000000","0.02418000"],["62637.99000000","0.00008000"],["62637.75000000","0.00008000"],["62637.55000000","0.00016000"],["62637.18000000","0.00009000"],["62636.80000000","0.00008000"],["62636.79000000","0.00008000"],["62636.78000000","0.00008000"],["62636.27000000","0.00009000"]],"asks":[["62640.00000000","5.63260000"],["62640.01000000","0.00097000"],["62640.02000000","0.00016000"],["62640.90000000","0.00008000"],["62641.14000000","0.00018000"],["62641.15000000","0.07731000"],["62641.43000000","0.00400000"],["62641.56000000","0.00009000"],["62641.97000000","0.00018000"],["62641.98000000","0.21032000"],["62641.99000000","0.15746000"],["62642.00000000","0.03469000"],["62642.11000000","0.00010000"],["62642.25000000","0.00016000"],["62642.64000000","0.02018000"],["62642.72000000","0.00008000"],["62642.90000000","0.00816000"],["62642.91000000","0.00032000"],["62643.00000000","0.00400000"],["62643.06000000","0.00009000"]]}}
{"t":9.9652,"stream":"btcusdt@depth@100ms","data":{"e":"depthUpdate","E":1783948012614,"s":"BTCUSDT","U":97344795508,"u":97344795515,"b":[["62625.97000000","0.00008000"],["62519.96000000","0.00000000"],["61700.39000000","0.00000000"],["56376.00000000","0.00477000"]],"a":[["62651.04000000","0.00008000"],["62819.36000000","0.00000000"]]}}
{"t":9.9654,"stream":"btcusdt@depth20@100ms","data":{"lastUpdateId":97344795515,"bids":[["62639.99000000","1.33022000"],["62639.98000000","0.00591000"],["62639.97000000","0.00016000"],["62639.85000000","0.00008000"],["62639.83000000","0.00016000"],["62638.95000000","0.00032000"],["62638.85000000","0.00008000"],["62638.44000000","0.00009000"],["62638.42000000","0.00008000"],["62638.11000000","0.00008000"],["62638.01000000","0.00018000"],["62638.00000000","0.02418000"],["62637.99000000","0.00008000"],["62637.75000000","0.00008000"],["62637.55000000","0.00016000"],["62637.18000000","0.00009000"],["62636.80000000","0.00008000"],["62636.79000000","0.00008000"],["62636.78000000","0.00008000"],["62636.27000000","0.00009000"]],"asks":[["62640.00000000","5.63260000"],["62640.01000000","0.00097000"],["62640.02000000","0.00016000"],["62640.90000000","0.00008000"],["62641.14000000","0.00018000"],["62641.15000000","0.07731000"],["62641.43000000","0.00400000"],["62641.56000000","0.00009000"],["62641.97000000","0.00018000"],["62641.98000000","0.21032000"],["62641.99000000","0.15746000"],["62642.00000000","0.03469000"],["62642.11000000","0.00010000"],["62642.25000000","0.00016000"],["62642.64000000","0.02018000"],["62642.72000000","0.00008000"],["62642.90000000","0.00816000"],["62642.91000000","0.00032000"],["62643.00000000","0.00400000"],["62643.06000000","0.00009000"]]}}
{"t":10.0647,"stream":"btcusdt@depth@100ms","data":{"e":"depthUpdate","E":1783948012714,"s":"BTCUSDT","U":97344795516,"u":97344795522,"b":[["61700.39000000","0.00030000"],["56376.00000000","0.00477000"],["50111.99000000","0.00000000"]],"a":[]}}
{"t":10.0649,"stream":"btcusdt@depth20@100ms","data":{"lastUpdateId":97344795522,"bids":[["62639.99000000","1.33022000"],["62639.98000000","0.00591000"],["62639.97000000","0.00016000"],["62639.85000000","0.00008000"],["62639.83000000","0.00016000"],["62638.95000000","0.00032000"],["62638.85000000","0.00008000"],["62638.44000000","0.00009000"],["62638.42000000","0.00008000"],["62638.11000000","0.00008000"],["62638.01000000","0.00018000"],["62638.00000000","0.02418000"],["62637.99000000","0.00008000"],["62637.75000000","0.00008000"],["62637.55000000","0.00016000"],["62637.18000000","0.00009000"],["62636.80000000","0.00008000"],["62636.79000000","0.00008000"],["62636.78000000","0.00008000"],["62636.27000000","0.00009000"]],"asks":[["62640.00000000","5.63260000"],["62640.01000000","0.00097000"],["62640.02000000","0.00016000"],["62640.90000000","0.00008000"],["62641.14000000","0.00018000"],["62641.15000000","0.07731000"],["62641.43000000","0.00400000"],["62641.56000000","0.00009000"],["62641.97000000","0.00018000"],["62641.98000000","0.21032000"],["62641.99000000","0.15746000"],["62642.00000000","0.03469000"],["62642.11000000","0.00010000"],["62642.25000000","0.00016000"],["62642.64000000","0.02018000"],["62642.72000000","0.00008000"],["62642.90000000","0.00816000"],["62642.91000000","0.00032000"],["62643.00000000","0.00400000"],["62643.06000000","0.00009000"]]}}
{"t":10.096,"stream":"btcusdt@aggTrade","data":{"e":"aggTrade","E":1783948012744,"s":"BTCUSDT","a":4013160580,"p":"62639.99000000","q":"0.00083000","f":6501833771,"l":6501833771,"T":1783948012744,"m":true,"M":true}}
{"t":10.1326,"stream":"btcusdt@aggTrade","data":{"e":"aggTrade","E":1783948012782,"s":"BTCUSDT","a":4013160581,"p":"62640.00000000","q":"0.08845000","f":6501833772,"l":6501833772,"T":1783948012782,"m":false,"M":true}}
{"t":10.1673,"stream":"btcusdt@depth@100ms","data":{"e":"depthUpdate","E":1783948012814,"s":"BTCUSDT","U":97344795523,"u":97344795532,"b":[["62639.99000000","1.32939000"],["56376.00000000","0.00477000"]],"a":[["62640.00000000","5.51215000"],["62709.20000000","0.00000000"],["62711.30000000","2.15354000"],["62757.13000000","0.15972000"]]}}
{"t":10.1675,"stream":"btcusdt@depth20@100ms","data":{"lastUpdateId":97344795532,"bids":[["62639.99000000","1.32939000"],["62639.98000000","0.00591000"],["62639.97000000","0.00016000"],["62639.85000000","0.00008000"],["62639.83000000","0.00016000"],["62638.95000000","0.00032000"],["62638.85000000","0.00008000"],["62638.44000000","0.00009000"],["62638.42000000","0.00008000"],["62638.11000000","0.00008000"],["62638.01000000","0.00018000"],["62638.00000000","0.02418000"],["62637.99000000","0.00008000"],["62637.75000000","0.00008000"],["62637.55000000","0.00016000"],["62637.18000000","0.00009000"],["62636.80000000","0.00008000"],["62636.79000000","0.00008000"],["62636.78000000","0.00008000"],["62636.27000000","0.00009000"]],"asks":[["62640.00000000","5.51215000"],["62640.01000000","0.00097000"],["62640.02000000","0.00016000"],["62640.90000000","0.00008000"],["62641.14000000","0.00018000"],["62641.15000000","0.07731000"],["62641.43000000","0.00400000"],["62641.56000000","0.00009000"],["62641.97000000","0.00018000"],["62641.98000000","0.21032000"],["62641.99000000","0.15746000"],["62642.00000000","0.03469000"],["62642.11000000","0.00010000"],["62642.25000000","0.00016000"],["62642.64000000","0.02018000"],["62642.72000000","0.00008000"],["62642.90000000","0.00816000"],["62642.91000000","0.00032000"],["62643.00000000","0.00400000"],["62643.06000000","0.00009000"]]}}
{"t":10.2633,"stream":"btcusdt@depth@100ms","data":{"e":"depthUpdate","E":1783948012914,"s":"BTCUSDT","U":97344795533,"u":97344795539,"b":[["56376.00000000","0.00477000"],["50111.99000000","0.00000000"]],"a":[["62757.13000000","0.00000000"]]}}
{"t":10.2635,"stream":"btcusdt@depth20@100ms","data":{"lastUpdateId":97344795539,"bids":[["62639.99000000","1.32939000"],["62639.98000000","0.00591000"],["62639.97000000","0.00016000"],["62639.85000000","0.00008000"],["62639.83000000","0.00016000"],["62638.95000000","0.00032000"],["62638.85000000","0.00008000"],["62638.44000000","0.00009000"],["62638.42000000","0.00008000"],["62638.11000000","0.00008000"],["62638.01000000","0.00018000"],["62638.00000000","0.02418000"],["62637.99000000","0.00008000"],["62637.75000000","0.00008000"],["62637.55000000","0.00016000"],["62637.18000000","0.00009000"],["62636.80000000","0.00008000"],["62636.79000000","0.00008000"],["62636.78000000","0.00008000"],["62636.27000000","0.00009000"]],"asks":[["62640.00000000","5.51215000"],["62640.01000000","0.00097000"],["62640.02000000","0.00016000"],["62640.90000000","0.00008000"],["62641.14000000","0.00018000"],["62641.15000000","0.07731000"],["62641.43000000","0.00400000"],["62641.56000000","0.00009000"],["62641.97000000","0.00018000"],["62641.98000000","0.21032000"],["62641.99000000","0.15746000"],["62642.00000000","0.03469000"],["62642.11000000","0.00010000"],["62642.25000000","0.00016000"],["62642.64000000","0.02018000"],["62642.72000000","0.00008000"],["62642.90000000","0.00816000"],["62642.91000000","0.00032000"],["62643.00000000","0.00400000"],["62643.06000000","0.00009000"]]}}
{"t":10.3649,"stream":"btcusdt@depth@100ms","data":{"e":"depthUpdate","E":1783948013014,"s":"BTCUSDT","U":97344795540,"u":97344795552,"b":[["56376.00000000","0.00477000"],["50112.00000000","0.00975000"]],"a":[["62640.00000000","5.51115000"],["62676.66000000","0.00000000"],["62757.13000000","0.00000000"]]}}
{"t":10.365,"stream":"btcusdt@depth20@100ms","data":{"lastUpdateId":97344795552,"bids":[["62639.99000000","1.32939000"],["62639.98000000","0.00591000"],["62639.97000000","0.00016000"],["62639.85000000","0.00008000"],["62639.83000000","0.00016000"],["62638.95000000","0.00032000"],["62638.85000000","0.00008000"],["62638.44000000","0.00009000"],["62638.42000000","0.00008000"],["62638.11000000","0.00008000"],["62638.01000000","0.00018000"],["62638.00000000","0.02418000"],["62637.99000000","0.00008000"],["62637.75000000","0.00008000"],["62637.55000000","0.00016000"],["62637.18000000","0.00009000"],["62636.80000000","0.00008000"],["62636.79000000","0.00008000"],["62636.78000000","0.00008000"],["62636.27000000","0.00009000"]],"asks":[["62640.00000000","5.51115000"],["62640.01000000","0.00097000"],["62640.02000000","0.00016000"],["62640.90000000","0.00008000"],["62641.14000000","0.00018000"],["62641.15000000","0.07731000"],["62641.43000000","0.00400000"],["62641.56000000","0.00009000"],["62641.97000000","0.00018000"],["62641.98000000","0.21032000"],["62641.99000000","0.15746000"],["62642.00000000","0.03469000"],["62642.11000000","0.00010000"],["62642.25000000","0.00016000"],["62642.64000000","0.02018000"],["62642.72000000","0.00008000"],["62642.90000000","0.00816000"],["62642.91000000","0.00032000"],["62643.00000000","0.00400000"],["62643.06000000","0.00009000"]]}}
{"t":10.4643,"stream":"btcusdt@depth@100ms","data":{"e":"depthUpdate","E":1783948013114,"s":"BTCUSDT","U":97344795553,"u":97344795560,"b":[["56376.00000000","0.00477000"],["40000.00000000","258.07540000"]],"a":[["62640.00000000","5.51215000"],["62676.77000000","0.00011000"]]}}
{"t":10.4643,"stream":"btcusdt@depth20@100ms","data":{"lastUpdateId":97344795560,"bids":[["62639.99000000","1.32939000"],["62639.98000000","0.00591000"],["62639.97000000","0.00016000"],["62639.85000000","0.00008000"],["62639.83000000","0.00016000"],["62638.95000000","0.00032000"],["62638.85000000","0.00008000"],["62638.44000000","0.00009000"],["62638.42000000","0.00008000"],["62638.11000000","0.00008000"],["62638.01000000","0.00018000"],["62638.00000000","0.02418000"],["62637.99000000","0.00008000"],["62637.75000000","0.00008000"],["62637.55000000","0.00016000"],["62637.18000000","0.00009000"],["62636.80000000","0.00008000"],["62636.79000000","0.00008000"],["62636.78000000","0.00008000"],["62636.27000000","0.00009000"]],"asks":[["62640.00000000","5.51215000"],["62640.01000000","0.00097000"],["62640.02000000","0.00016000"],["62640.90000000","0.00008000"],["62641.14000000","0.00018000"],["62641.15000000","0.07731000"],["62641.43000000","0.00400000"],["62641.56000000","0.00009000"],["62641.97000000","0.00018000"],["62641.98000000","0.21032000"],["62641.99000000","0.15746000"],["62642.00000000","0.03469000"],["62642.11000000","0.00010000"],["62642.25000000","0.00016000"],["62642.64000000","0.02018000"],["62642.72000000","0.00008000"],["62642.90000000","0.00816000"],["62642.91000000","0.00032000"],["62643.00000000","0.00400000"],["62643.06000000","0.00009000"]]}}
{"t":10.5486,"stream":"btcusdt@aggTrade","data":{"e":"aggTrade","E":1783948013197,"s":"BTCUSDT","a":4013160582,"p":"62640.00000000","q":"0.00552000","f":6501833773,"l":6501833773,"T":1783948013197,"m":false,"M":true}}
{"t":10.564,"stream":"btcusdt@depth@100ms","data":{"e":"depthUpdate","E":1783948013214,"s":"BTCUSDT","U":97344795561,"u":97344795571,"b":[["56376.00000000","0.00477000"],["50112.00000000","0.00936000"]],"a":[["62640.00000000","5.50654000"],["62709.19000000","2.15344000"],["62711.30000000","0.00010000"],["63579.60000000","0.00030000"]]}}
{"t":10.5642,"stream":"btcusdt@depth20@100ms","data":{"lastUpdateId":97344795571,"bids":[["62639.99000000","1.32939000"],["62639.98000000","0.00591000"],["62639.97000000","0.00016000"],["62639.85000000","0.00008000"],["62639.83000000","0.00016000"],["62638.95000000","0.00032000"],["62638.85000000","0.00008000"],["62638.44000000","0.00009000"],["62638.42000000","0.00008000"],["62638.11000000","0.00008000"],["62638.01000000","0.00018000"],["62638.00000000","0.02418000"],["62637.99000000","0.00008000"],["62637.75000000","0.00008000"],["62637.55000000","0.00016000"],["62637.18000000","0.00009000"],["62636.80000000","0.00008000"],["62636.79000000","0.00008000"],["62636.78000000","0.00008000"],["62636.27000000","0.00009000"]],"asks":[["62640.00000000","5.50654000"],["62640.01000000","0.00097000"],["62640.02000000","0.00016000"],["62640.90000000","0.00008000"],["62641.14000000","0.00018000"],["62641.15000000","0.07731000"],["62641.43000000","0.00400000"],["62641.56000000","0.00009000"],["62641.97000000","0.00018000"],["62641.98000000","0.21032000"],["62641.99000000","0.15746000"],["62642.00000000","0.03469000"],["62642.11000000","0.00010000"],["62642.25000000","0.00016000"],["62642.64000000","0.02018000"],["62642.72000000","0.00008000"],["62642.90000000","0.00816000"],["62642.91000000","0.00032000"],["62643.00000000","0.00400000"],["62643.06000000","0.00009000"]]}}
{"t":10.666,"stream":"btcusdt@depth@100ms","data":{"e":"depthUpdate","E":1783948013314,"s":"BTCUSDT","U":97344795572,"u":97344795575,"b":[["56376.00000000","0.00477000"]],"a":[]}}
{"t":10.6663,"stream":"btcusdt@depth20@100ms","data":{"lastUpdateId":97344795575,"bids":[["62639.99000000","1.32939000"],["62639.98000000","0.00591000"],["62639.97000000","0.00016000"],["62639.85000000","0.00008000"],["62639.83000000","0.00016000"],["62638.95000000","0.00032000"],["62638.85000000","0.00008000"],["62638.44000000","0.00009000"],["62638.42000000","0.00008000"],["62638.11000000","0.00008000"],["62638.01000000","0.00018000"],["62638.00000000","0.02418000"],["62637.99000000","0.00008000"],["62637.75000000","0.00008000"],["62637.55000000","0.00016000"],["62637.18000000","0.00009000"],["62636.80000000","0.00008000"],["62636.79000000","0.00008000"],["62636.78000000","0.00008000"],["62636.27000000","0.00009000"]],"asks":[["62640.00000000","5.50654000"],["62640.01000000","0.00097000"],["62640.02000000","0.00016000"],["62640.90000000","0.00008000"],["62641.14000000","0.00018000"],["62641.15000000","0.07731000"],["62641.43000000","0.00400000"],["62641.56000000","0.00009000"],["62641.97000000","0.00018000"],["62641.98000000","0.21032000"],["62641.99000000","0.15746000"],["62642.00000000","0.03469000"],["62642.11000000","0.00010000"],["62642.25000000","0.00016000"],["62642.64000000","0.02018000"],["62642.72000000","0.00008000"],["62642.90000000","0.00816000"],["62642.91000000","0.00032000"],["62643.00000000","0.00400000"],["62643.06000000","0.00009000"]]}}
{"t":10.7629,"stream":"btcusdt@depth@100ms","data":{"e":"depthUpdate","E":1783948013414,"s":"BTCUSDT","U":97344795576,"u":97344795583,"b":[["56376.00000000","0.00477000"],["50112.00000000","0.00936000"]],"a":[["62757.14000000","0.00000000"]]}}
{"t":10.7633,"stream":"btcusdt@depth20@100ms","data":{"lastUpdateId":97344795583,"bids":[["62639.99000000","1.32939000"],["62639.98000000","0.00591000"],["62639.97000000","0.00016000"],["62639.85000000","0.00008000"],["62639.83000000","0.00016000"],["62638.95000000","0.00032000"],["62638.85000000","0.00008000"],["62638.44000000","0.00009000"],["62638.42000000","0.00008000"],["62638.11000000","0.00008000"],["62638.01000000","0.00018000"],["62638.00000000","0.02418000"],["62637.99000000","0.00008000"],["62637.75000000","0.00008000"],["62637.55000000","0.00016000"],["62637.18000000","0.00009000"],["62636.80000000","0.00008000"],["62636.79000000","0.00008000"],["62636.78000000","0.00008000"],["62636.27000000","0.00009000"]],"asks":[["62640.00000000","5.50654000"],["62640.01000000","0.00097000"],["62640.02000000","0.00016000"],["62640.90000000","0.00008000"],["62641.14000000","0.00018000"],["62641.15000000","0.07731000"],["62641.43000000","0.00400000"],["62641.56000000","0.00009000"],["62641.97000000","0.00018000"],["62641.98000000","0.21032000"],["62641.99000000","0.15746000"],["62642.00000000","0.03469000"],["62642.11000000","0.00010000"],["62642.25000000","0.00016000"],["62642.64000000","0.02018000"],["62642.72000000","0.00008000"],["62642.90000000","0.00816000"],["62642.91000000","0.00032000"],["62643.00000000","0.00400000"],["62643.06000000","0.00009000"]]}}
{"t":10.8636,"stream":"btcusdt@depth@100ms","data":{"e":"depthUpdate","E":1783948013514,"s":"BTCUSDT","U":97344795584,"u":97344795589,"b":[["56376.00000000","0.00477000"],["56375.00000000","0.00375000"]],"a":[["62709.19000000","0.00000000"]]}}
{"t":10.8638,"stream":"btcusdt@depth20@100ms","data":{"lastUpdateId":97344795589,"bids":[["62639.99000000","1.32939000"],["62639.98000000","0.00591000"],["62639.97000000","0.00016000"],["62639.85000000","0.00008000"],["62639.83000000","0.00016000"],["62638.95000000","0.00032000"],["62638.85000000","0.00008000"],["62638.44000000","0.00009000"],["62638.42000000","0.00008000"],["62638.11000000","0.00008000"],["62638.01000000","0.00018000"],["62638.00000000","0.02418000"],["62637.99000000","0.00008000"],["62637.75000000","0.00008000"],["62637.55000000","0.00016000"],["62637.18000000","0.00009000"],["62636.80000000","0.00008000"],["62636.79000000","0.00008000"],["62636.78000000","0.00008000"],["62636.27000000","0.00009000"]],"asks":[["62640.00000000","5.50654000"],["62640.01000000","0.00097000"],["62640.02000000","0.00016000"],["62640.90000000","0.00008000"],["62641.14000000","0.00018000"],["62641.15000000","0.07731000"],["62641.43000000","0.00400000"],["62641.56000000","0.00009000"],["62641.97000000","0.00018000"],["62641.98000000","0.21032000"],["62641.99000000","0.15746000"],["62642.00000000","0.03469000"],["62642.11000000","0.00010000"],["62642.25000000","0.00016000"],["62642.64000000","0.02018000"],["62642.72000000","0.00008000"],["62642.90000000","0.00816000"],["62642.91000000","0.00032000"],["62643.00000000","0.00400000"],["62643.06000000","0.00009000"]]}}
{"t":10.9636,"stream":"btcusdt@depth@100ms","data":{"e":"depthUpdate","E":1783948013614,"s":"BTCUSDT","U":97344795590,"u":97344795596,"b":[["62625.97000000","0.00008000"],["56376.00000000","0.00497000"],["56375.00000000","0.00355000"]],"a":[["62651.04000000","0.00008000"]]}}
{"t":10.9643,"stream":"btcusdt@depth20@100ms","data":{"lastUpdateId":97344795596,"bids":[["62639.99000000","1.32939000"],["62639.98000000","0.00591000"],["62639.97000000","0.00016000"],["62639.85000000","0.00008000"],["62639.83000000","0.00016000"],["62638.95000000","0.00032000"],["62638.85000000","0.00008000"],["62638.44000000","0.00009000"],["62638.42000000","0.00008000"],["62638.11000000","0.00008000"],["62638.01000000","0.00018000"],["62638.00000000","0.02418000"],["62637.99000000","0.00008000"],["62637.75000000","0.00008000"],["62637.55000000","0.00016000"],["62637.18000000","0.00009000"],["62636.80000000","0.00008000"],["62636.79000000","0.00008000"],["62636.78000000","0.00008000"],["62636.27000000","0.00009000"]],"asks":[["62640.00000000","5.50654000"],["62640.01000000","0.00097000"],["62640.02000000","0.00016000"],["62640.90000000","0.00008000"],["62641.14000000","0.00018000"],["62641.15000000","0.07731000"],["62641.43000000","0.00400000"],["62641.56000000","0.00009000"],["62641.97000000","0.00018000"],["62641.98000000","0.21032000"],["62641.99000000","0.15746000"],["62642.00000000","0.03469000"],["62642.11000000","0.00010000"],["62642.25000000","0.00016000"],["62642.64000000","0.02018000"],["62642.72000000","0.00008000"],["62642.90000000","0.00816000"],["62642.91000000","0.00032000"],["62643.00000000","0.00400000"],["62643.06000000","0.00009000"]]}}
{"t":11.0661,"stream":"btcusdt@depth@100ms","data":{"e":"depthUpdate","E":1783948013714,"s":"BTCUSDT","U":97344795597,"u":97344795604,"b":[["62639.99000000","1.33388000"],["61700.39000000","0.00030000"],["56376.00000000","0.00497000"]],"a":[["62676.77000000","0.00000000"]]}}
{"t":11.0663,"stream":"btcusdt@depth20@100ms","data":{"lastUpdateId":97344795604,"bids":[["62639.99000000","1.33388000"],["62639.98000000","0.00591000"],["62639.97000000","0.00016000"],["62639.85000000","0.00008000"],["62639.83000000","0.00016000"],["62638.95000000","0.00032000"],["62638.85000000","0.00008000"],["62638.44000000","0.00009000"],["62638.42000000","0.00008000"],["62638.11000000","0.00008000"],["62638.01000000","0.00018000"],["62638.00000000","0.02418000"],["62637.99000000","0.00008000"],["62637.75000000","0.00008000"],["62637.55000000","0.00016000"],["62637.18000000","0.00009000"],["62636.80000000","0.00008000"],["62636.79000000","0.00008000"],["62636.78000000","0.00008000"],["62636.27000000","0.00009000"]],"asks":[["62640.00000000","5.50654000"],["62640.01000000","0.00097000"],["62640.02000000","0.00016000"],["62640.90000000","0.00008000"],["62641.14000000","0.00018000"],["62641.15000000","0.07731000"],["62641.43000000","0.00400000"],["62641.56000000","0.00009000"],["62641.97000000","0.00018000"],["62641.98000000","0.21032000"],["62641.99000000","0.15746000"],["62642.00000000","0.03469000"],["62642.11000000","0.00010000"],["62642.25000000","0.00016000"],["62642.64000000","0.02018000"],["62642.72000000","0.00008000"],["62642.90000000","0.00816000"],["62642.91000000","0.00032000"],["62643.00000000","0.00400000"],["62643.06000000","0.00009000"]]}}
{"t":11.106,"stream":"btcusdt@aggTrade","data":{"e":"aggTrade","E":1783948013755,"s":"BTCUSDT","a":4013160583,"p":"62640.00000000","q":"0.00081000","f":6501833774,"l":6501833774,"T":1783948013754,"m":false,"M":true}}
{"t":11.1642,"stream":"btcusdt@depth@100ms","data":{"e":"depthUpdate","E":1783948013814,"s":"BTCUSDT","U":97344795605,"u":97344795614,"b":[["57628.79000000","0.00018000"],["56376.00000000","0.00507000"],["50111.99000000","0.00000000"]],"a":[["62640.00000000","5.50573000"],["62676.88000000","0.00011000"]]}}
{"t":11.1644,"stream":"btcusdt@depth20@100ms","data":{"lastUpdateId":97344795614,"bids":[["62639.99000000","1.33388000"],["62639.98000000","0.00591000"],["62639.97000000","0.00016000"],["62639.85000000","0.00008000"],["62639.83000000","0.00016000"],["62638.95000000","0.00032000"],["62638.85000000","0.00008000"],["62638.44000000","0.00009000"],["62638.42000000","0.00008000"],["62638.11000000","0.00008000"],["62638.01000000","0.00018000"],["62638.00000000","0.02418000"],["62637.99000000","0.00008000"],["62637.75000000","0.00008000"],["62637.55000000","0.00016000"],["62637.18000000","0.00009000"],["62636.80000000","0.00008000"],["62636.79000000","0.00008000"],["62636.78000000","0.00008000"],["62636.27000000","0.00009000"]],"asks":[["62640.00000000","5.50573000"],["62640.01000000","0.00097000"],["62640.02000000","0.00016000"],["62640.90000000","0.00008000"],["62641.14000000","0.00018000"],["62641.15000000","0.07731000"],["62641.43000000","0.00400000"],["62641.56000000","0.00009000"],["62641.97000000","0.00018000"],["62641.98000000","0.21032000"],["62641.99000000","0.15746000"],["62642.00000000","0.03469000"],["62642.11000000","0.00010000"],["62642.25000000","0.00016000"],["62642.64000000","0.02018000"],["62642.72000000","0.00008000"],["62642.90000000","0.00816000"],["62642.91000000","0.00032000"],["62643.00000000","0.00400000"],["62643.06000000","0.00009000"]]}}
{"t":11.2641,"stream":"btcusdt@depth@100ms","data":{"e":"depthUpdate","E":1783948013914,"s":"BTCUSDT","U":97344795615,"u":97344795620,"b":[["56376.00000000","0.00507000"],["50111.99000000","0.00000000"]],"a":[]}}
{"t":11.2642,"stream":"btcusdt@depth20@100ms","data":{"lastUpdateId":97344795620,"bids":[["62639.99000000","1.33388000"],["62639.98000000","0.00591000"],["62639.97000000","0.00016000"],["62639.85000000","0.00008000"],["62639.83000000","0.00016000"],["62638.95000000","0.00032000"],["62638.85000000","0.00008000"],["62638.44000000","0.00009000"],["62638.42000000","0.00008000"],["62638.11000000","0.00008000"],["62638.01000000","0.00018000"],["62638.00000000","0.02418000"],["62637.99000000","0.00008000"],["62637.75000000","0.00008000"],["62637.55000000","0.00016000"],["62637.18000000","0.00009000"],["62636.80000000","0.00008000"],["62636.79000000","0.00008000"],["62636.78000000","0.00008000"],["62636.27000000","0.00009000"]],"asks":[["62640.00000000","5.50573000"],["62640.01000000","0.00097000"],["62640.02000000","0.00016000"],["62640.90000000","0.00008000"],["62641.14000000","0.00018000"],["62641.15000000","0.07731000"],["62641.43000000","0.00400000"],["62641.56000000","0.00009000"],["62641.97000000","0.00018000"],["62641.98000000","0.21032000"],["62641.99000000","0.15746000"],["62642.00000000","0.03469000"],["62642.11000000","0.00010000"],["62642.25000000","0.00016000"],["62642.64000000","0.02018000"],["62642.72000000","0.00008000"],["62642.90000000","0.00816000"],["62642.91000000","0.00032000"],["62643.00000000","0.00400000"],["62643.06000000","0.00009000"]]}}
{"t":11.3072,"stream":"btcusdt@aggTrade","data":{"e":"aggTrade","E":1783948013956,"s":"BTCUSDT","a":4013160584,"p":"62639.99000000","q":"0.00082000","f":6501833775,"l":6501833775,"T":1783948013955,"m":true,"M":true}}
{"t":11.3646,"stream":"btcusdt@depth@100ms","data":{"e":"depthUpdate","E":1783948014014,"s":"BTCUSDT","U":97344795621,"u":97344795649,"b":[["62639.99000000","2.17250000"],["62636.11000000","0.06696000"],["62635.56000000","0.27201000"],["62621.69000000","1.04274000"],["62594.41000000","0.00000000"],["56376.00000000","0.00507000"],["50112.00000000","0.00975000"]],"a":[["62640.00000000","4.80484000"],["62640.01000000","0.00097000"],["62642.64000000","0.00018000"],["62642.90000000","0.00018000"],["62643.96000000","0.00798000"],["62644.24000000","0.02000000"]]}}
{"t":11.3648,"stream":"btcusdt@depth20@100ms","data":{"lastUpdateId":97344795649,"bids":[["62639.99000000","2.17250000"],["62639.98000000","0.00591000"],["62639.97000000","0.00016000"],["62639.85000000","0.00008000"],["62639.83000000","0.00016000"],["62638.95000000","0.00032000"],["62638.85000000","0.00008000"],["62638.44000000","0.00009000"],["62638.42000000","0.00008000"],["62638.11000000","0.00008000"],["62638.01000000","0.00018000"],["62638.00000000","0.02418000"],["62637.99000000","0.00008000"],["62637.75000000","0.00008000"],["62637.55000000","0.00016000"],["62637.18000000","0.00009000"],["62636.80000000","0.00008000"],["62636.79000000","0.00008000"],["62636.78000000","0.00008000"],["62636.27000000","0.00009000"]],"asks":[["62640.00000000","4.80484000"],["62640.01000000","0.00097000"],["62640.02000000","0.00016000"],["62640.90000000","0.00008000"],["62641.14000000","0.00018000"],["62641.15000000","0.07731000"],["62641.43000000","0.00400000"],["62641.56000000","0.00009000"],["62641.97000000","0.00018000"],["62641.98000000","0.21032000"],["62641.99000000","0.15746000"],["62642.00000000","0.03469000"],["62642.11000000","0.00010000"],["62642.25000000","0.00016000"],["62642.64000000","0.00018000"],["62642.72000000","0.00008000"],["62642.90000000","0.00018000"],["62642.91000000","0.00032000"],["62643.00000000","0.00400000"],["62643.06000000","0.00009000"]]}}
{"t":11.4282,"stream":"btcusdt@aggTrade","data":{"e":"aggTrade","E":1783948014076,"s":"BTCUSDT","a":4013160585,"p":"62639.99000000","q":"0.00061000","f":6501833776,"l":6501833776,"T":1783948014075,"m":true,"M":true}}
{"t":11.4645,"stream":"btcusdt@depth@100ms","data":{"e":"depthUpdate","E":1783948014114,"s":"BTCUSDT","U":97344795650,"u":97344795720,"b":[["62639.99000000","1.94689000"],["62639.98000000","0.00600000"],["62636.11000000","0.06712000"],["62635.60000000","0.00009000"],["62635.59000000","0.14111000"],["62635.58000000","0.81764000"],["62635.57000000","1.91755000"],["62635.56000000","0.02413000"],["62635.55000000","0.00018000"],["62635.39000000","0.00026000"],["62635.15000000","0.00400000"],["62634.29000000","0.00008000"],["62633.23000000","0.00000000"],["62620.69000000","0.00270000"],["62610.03000000","0.00000000"],["62605.00000000","0.00000000"],["62595.12000000","0.77000000"],["62591.94000000","0.00012000"],["62590.69000000","0.00000000"],["56376.00000000","0.00487000"],["40000.00000000","258.07540000"]],"a":[["62640.00000000","4.80584000"],["62640.01000000","0.00097000"],["62642.00000000","0.03469000"],["62642.64000000","0.00000000"],["62642.90000000","0.00000000"],["62643.43000000","0.02172000"],["62643.96000000","0.00816000"],["62644.00000000","0.02418000"]]}}
{"t":11.4647,"stream":"btcusdt@depth20@100ms","data":{"lastUpdateId":97344795720,"bids":[["62639.99000000","1.94689000"],["62639.98000000","0.00600000"],["62639.97000000","0.00016000"],["62639.85000000","0.00008000"],["62639.83000000","0.00016000"],["62638.95000000","0.00032000"],["62638.85000000","0.00008000"],["62638.44000000","0.00009000"],["62638.42000000","0.00008000"],["62638.11000000","0.00008000"],["62638.01000000","0.00018000"],["62638.00000000","0.02418000"],["62637.99000000","0.00008000"],["62637.75000000","0.00008000"],["62637.55000000","0.00016000"],["62637.18000000","0.00009000"],["62636.80000000","0.00008000"],["62636.79000000","0.00008000"],["62636.78000000","0.00008000"],["62636.27000000","0.00009000"]],"asks":[["62640.00000000","4.80584000"],["62640.01000000","0.00097000"],["62640.02000000","0.00016000"],["62640.90000000","0.00008000"],["62641.14000000","0.00018000"],["62641.15000000","0.07731000"],["62641.43000000","0.00400000"],["62641.56000000","0.00009000"],["62641.97000000","0.00018000"],["62641.98000000","0.21032000"],["62641.99000000","0.15746000"],["62642.00000000","0.03469000"],["62642.11000000","0.00010000"],["62642.25000000","0.00016000"],["62642.72000000","0.00008000"],["62642.91000000","0.00032000"],["62643.00000000","0.00400000"],["62643.06000000","0.00009000"],["62643.07000000","0.47618000"],["62643.09000000","0.00016000"]]}}
{"t":11.5642,"stream":"btcusdt@depth@100ms","data":{"e":"depthUpdate","E":1783948014214,"s":"BTCUSDT","U":97344795721,"u":97344795751,"b":[["62639.99000000","1.94698000"],["62638.79000000","0.17256000"],["62636.11000000","0.06704000"],["62636.00000000","0.02418000"],["62635.59000000","0.14129000"],["62635.58000000","0.81782000"],["62635.57000000","1.91773000"],["62635.56000000","0.02395000"],["62635.55000000","0.00000000"],["62635.39000000","0.00008000"],["56376.00000000","0.00487000"],["50112.00000000","0.00936000"]],"a":[["62709.19000000","2.15344000"],["62757.43000000","0.00000000"],["63579.60000000","0.00030000"]]}}
{"t":11.5644,"stream":"btcusdt@depth20@100ms","data":{"lastUpdateId":97344795751,"bids":[["62639.99000000","1.94698000"],["62639.98000000","0.00600000"],["62639.97000000","0.00016000"],["62639.85000000","0.00008000"],["62639.83000000","0.00016000"],["62638.95000000","0.00032000"],["62638.85000000","0.00008000"],["62638.79000000","0.17256000"],["62638.44000000","0.00009000"],["62638.42000000","0.00008000"],["62638.11000000","0.00008000"],["62638.01000000","0.00018000"],["62638.00000000","0.02418000"],["62637.99000000","0.00008000"],["62637.75000000","0.00008000"],["62637.55000000","0.00016000"],["62637.18000000","0.00009000"],["62636.80000000","0.00008000"],["62636.79000000","0.00008000"],["62636.78000000","0.00008000"]],"asks":[["62640.00000000","4.80584000"],["62640.01000000","0.00097000"],["62640.02000000","0.00016000"],["62640.90000000","0.00008000"],["62641.14000000","0.00018000"],["62641.15000000","0.07731000"],["62641.43000000","0.00400000"],["62641.56000000","0.00009000"],["62641.97000000","0.00018000"],["62641.98000000","0.21032000"],["62641.99000000","0.15746000"],["62642.00000000","0.03469000"],["62642.11000000","0.00010000"],["62642.25000000","0.00016000"],["62642.72000000","0.00008000"],["62642.91000000","0.00032000"],["62643.00000000","0.00400000"],["62643.06000000","0.00009000"],["62643.07000000","0.47618000"],["62643.09000000","0.00016000"]]}}
{"t":11.6634,"stream":"btcusdt@depth@100ms","data":{"e":"depthUpdate","E":1783948014314,"s":"BTCUSDT","U":97344795752,"u":97344795767,"b":[["62639.99000000","1.94715000"],["62639.98000000","0.00609000"],["62638.80000000","0.00009000"],["62635.59000000","0.14120000"],["59100.00000000","13.57838000"],["56376.00000000","0.00487000"]],"a":[["62757.43000000","0.00000000"]]}}
{"t":11.6636,"stream":"btcusdt@depth20@100ms","data":{"lastUpdateId":97344795767,"bids":[["62639.99000000","1.94715000"],["62639.98000000","0.00609000"],["62639.97000000","0.00016000"],["62639.85000000","0.00008000"],["62639.83000000","0.00016000"],["62638.95000000","0.00032000"],["62638.85000000","0.00008000"],["62638.80000000","0.00009000"],["62638.79000000","0.17256000"],["62638.44000000","0.00009000"],["62638.42000000","0.00008000"],["62638.11000000","0.00008000"],["62638.01000000","0.00018000"],["62638.00000000","0.02418000"],["62637.99000000","0.00008000"],["62637.75000000","0.00008000"],["62637.55000000","0.00016000"],["62637.18000000","0.00009000"],["62636.80000000","0.00008000"],["62636.79000000","0.00008000"]],"asks":[["62640.00000000","4.80584000"],["62640.01000000","0.00097000"],["62640.02000000","0.00016000"],["62640.90000000","0.00008000"],["62641.14000000","0.00018000"],["62641.15000000","0.07731000"],["62641.43000000","0.00400000"],["62641.56000000","0.00009000"],["62641.97000000","0.00018000"],["62641.98000000","0.21032000"],["62641.99000000","0.15746000"],["62642.00000000","0.03469000"],["62642.11000000","0.00010000"],["62642.25000000","0.00016000"],["62642.72000000","0.00008000"],["62642.91000000","0.00032000"],["62643.00000000","0.00400000"],["62643.06000000","0.00009000"],["62643.07000000","0.47618000"],["62643.09000000","0.00016000"]]}}
{"t":11.6794,"stream":"btcusdt@aggTrade","data":{"e":"aggTrade","E":1783948014329,"s":"BTCUSDT","a":4013160586,"p":"62640.00000000","q":"0.00009000","f":6501833777,"l":6501833777,"T":1783948014329,"m":false,"M":true}}
{"t":11.7633,"stream":"btcusdt@depth@100ms","data":{"e":"depthUpdate","E":1783948014414,"s":"BTCUSDT","U":97344795768,"u":97344795777,"b":[["57628.79000000","0.00000000"],["56376.00000000","0.00487000"],["50112.00000000","0.00936000"]],"a":[["62640.00000000","4.80575000"],["62757.45000000","0.00000000"]]}}
{"t":11.7635,"stream":"btcusdt@depth20@100ms","data":{"lastUpdateId":97344795777,"bids":[["62639.99000000","1.94715000"],["62639.98000000","0.00609000"],["62639.97000000","0.00016000"],["62639.85000000","0.00008000"],["62639.83000000","0.00016000"],["62638.95000000","0.00032000"],["62638.85000000","0.00008000"],["62638.80000000","0.00009000"],["62638.79000000","0.17256000"],["62638.44000000","0.00009000"],["62638.42000000","0.00008000"],["62638.11000000","0.00008000"],["62638.01000000","0.00018000"],["62638.00000000","0.02418000"],["62637.99000000","0.00008000"],["62637.75000000","0.00008000"],["62637.55000000","0.00016000"],["62637.18000000","0.00009000"],["62636.80000000","0.00008000"],["62636.79000000","0.00008000"]],"asks":[["62640.00000000","4.80575000"],["62640.01000000","0.00097000"],["62640.02000000","0.00016000"],["62640.90000000","0.00008000"],["62641.14000000","0.00018000"],["62641.15000000","0.07731000"],["62641.43000000","0.00400000"],["62641.56000000","0.00009000"],["62641.97000000","0.00018000"],["62641.98000000","0.21032000"],["62641.99000000","0.15746000"],["62642.00000000","0.03469000"],["62642.11000000","0.00010000"],["62642.25000000","0.00016000"],["62642.72000000","0.00008000"],["62642.91000000","0.00032000"],["62643.00000000","0.00400000"],["62643.06000000","0.00009000"],["62643.07000000","0.47618000"],["62643.09000000","0.00016000"]]}}
{"t":11.8648,"stream":"btcusdt@depth@100ms","data":{"e":"depthUpdate","E":1783948014514,"s":"BTCUSDT","U":97344795778,"u":97344795784,"b":[["62484.92000000","0.00000000"],["56376.00000000","0.00487000"]],"a":[["62660.60000000","0.02663000"],["62676.88000000","0.00000000"]]}}
{"t":11.865,"stream":"btcusdt@depth20@100ms","data":{"lastUpdateId":97344795784,"bids":[["62639.99000000","1.94715000"],["62639.98000000","0.00609000"],["62639.97000000","0.00016000"],["62639.85000000","0.00008000"],["62639.83000000","0.00016000"],["62638.95000000","0.00032000"],["62638.85000000","0.00008000"],["62638.80000000","0.00009000"],["62638.79000000","0.17256000"],["62638.44000000","0.00009000"],["62638.42000000","0.00008000"],["62638.11000000","0.00008000"],["62638.01000000","0.00018000"],["62638.00000000","0.02418000"],["62637.99000000","0.00008000"],["62637.75000000","0.00008000"],["62637.55000000","0.00016000"],["62637.18000000","0.00009000"],["62636.80000000","0.00008000"],["62636.79000000","0.00008000"]],"asks":[["62640.00000000","4.80575000"],["62640.01000000","0.00097000"],["62640.02000000","0.00016000"],["62640.90000000","0.00008000"],["62641.14000000","0.00018000"],["62641.15000000","0.07731000"],["62641.43000000","0.00400000"],["62641.56000000","0.00009000"],["62641.97000000","0.00018000"],["62641.98000000","0.21032000"],["62641.99000000","0.15746000"],["62642.00000000","0.03469000"],["62642.11000000","0.00010000"],["62642.25000000","0.00016000"],["62642.72000000","0.00008000"],["62642.91000000","0.00032000"],["62643.00000000","0.00400000"],["62643.06000000","0.00009000"],["62643.07000000","0.47618000"],["62643.09000000","0.00016000"]]}}
{"t":11.9642,"stream":"btcusdt@depth@100ms","data":{"e":"depthUpdate","E":1783948014614,"s":"BTCUSDT","U":97344795785,"u":97344795793,"b":[["62625.97000000","0.00008000"],["56376.00000000","0.00487000"],["56375.00000000","0.00375000"]],"a":[["62651.04000000","0.00008000"],["62676.98000000","0.00011000"]]}}
{"t":11.9647,"stream":"btcusdt@depth20@100ms","data":{"lastUpdateId":97344795793,"bids":[["62639.99000000","1.94715000"],["62639.98000000","0.00609000"],["62639.97000000","0.00016000"],["62639.85000000","0.00008000"],["62639.83000000","0.00016000"],["62638.95000000","0.00032000"],["62638.85000000","0.00008000"],["62638.80000000","0.00009000"],["62638.79000000","0.17256000"],["62638.44000000","0.00009000"],["62638.42000000","0.00008000"],["62638.11000000","0.00008000"],["62638.01000000","0.00018000"],["62638.00000000","0.02418000"],["62637.99000000","0.00008000"],["62637.75000000","0.00008000"],["62637.55000000","0.00016000"],["62637.18000000","0.00009000"],["62636.80000000","0.00008000"],["62636.79000000","0.00008000"]],"asks":[["62640.00000000","4.80575000"],["62640.01000000","0.00097000"],["62640.02000000","0.00016000"],["62640.90000000","0.00008000"],["62641.14000000","0.00018000"],["62641.15000000","0.07731000"],["62641.43000000","0.00400000"],["62641.56000000","0.00009000"],["62641.97000000","0.00018000"],["62641.98000000","0.21032000"],["62641.99000000","0.15746000"],["62642.00000000","0.03469000"],["62642.11000000","0.00010000"],["62642.25000000","0.00016000"],["62642.72000000","0.00008000"],["62642.91000000","0.00032000"],["62643.00000000","0.00400000"],["62643.06000000","0.00009000"],["62643.07000000","0.47618000"],["62643.09000000","0.00016000"]]}}
{"t":12.0637,"stream":"btcusdt@depth@100ms","data":{"e":"depthUpdate","E":1783948014714,"s":"BTCUSDT","U":97344795794,"u":97344795801,"b":[["61700.39000000","0.00030000"],["56376.00000000","0.00487000"],["56375.00000000","0.00355000"]],"a":[["62660.60000000","0.00000000"]]}}
{"t":12.0639,"stream":"btcusdt@depth20@100ms","data":{"lastUpdateId":97344795801,"bids":[["62639.99000000","1.94715000"],["62639.98000000","0.00609000"],["62639.97000000","0.00016000"],["62639.85000000","0.00008000"],["62639.83000000","0.00016000"],["62638.95000000","0.00032000"],["62638.85000000","0.00008000"],["62638.80000000","0.00009000"],["62638.79000000","0.17256000"],["62638.44000000","0.00009000"],["62638.42000000","0.00008000"],["62638.11000000","0.00008000"],["62638.01000000","0.00018000"],["62638.00000000","0.02418000"],["62637.99000000","0.00008000"],["62637.75000000","0.00008000"],["62637.55000000","0.00016000"],["62637.18000000","0.00009000"],["62636.80000000","0.00008000"],["62636.79000000","0.00008000"]],"asks":[["62640.00000000","4.80575000"],["62640.01000000","0.00097000"],["62640.02000000","0.00016000"],["62640.90000000","0.00008000"],["62641.14000000","0.00018000"],["62641.15000000","0.07731000"],["62641.43000000","0.00400000"],["62641.56000000","0.00009000"],["62641.97000000","0.00018000"],["62641.98000000","0.21032000"],["62641.99000000","0.15746000"],["62642.00000000","0.03469000"],["62642.11000000","0.00010000"],["62642.25000000","0.00016000"],["62642.72000000","0.00008000"],["62642.91000000","0.00032000"],["62643.00000000","0.00400000"],["62643.06000000","0.00009000"],["62643.07000000","0.47618000"],["62643.09000000","0.00016000"]]}}
{"t":12.1637,"stream":"btcusdt@depth@100ms","data":{"e":"depthUpdate","E":1783948014814,"s":"BTCUSDT","U":97344795802,"u":97344795808,"b":[["62485.58000000","6.47684000"],["56376.00000000","0.00487000"],["50111.99000000","0.00000000"]],"a":[]}}
{"t":12.1644,"stream":"btcusdt@depth20@100ms","data":{"lastUpdateId":97344795808,"bids":[["62639.99000000","1.94715000"],["62639.98000000","0.00609000"],["62639.97000000","0.00016000"],["62639.85000000","0.00008000"],["62639.83000000","0.00016000"],["62638.95000000","0.00032000"],["62638.85000000","0.00008000"],["62638.80000000","0.00009000"],["62638.79000000","0.17256000"],["62638.44000000","0.00009000"],["62638.42000000","0.00008000"],["62638.11000000","0.00008000"],["62638.01000000","0.00018000"],["62638.00000000","0.02418000"],["62637.99000000","0.00008000"],["62637.75000000","0.00008000"],["62637.55000000","0.00016000"],["62637.18000000","0.00009000"],["62636.80000000","0.00008000"],["62636.79000000","0.00008000"]],"asks":[["62640.00000000","4.80575000"],["62640.01000000","0.00097000"],["62640.02000000","0.00016000"],["62640.90000000","0.00008000"],["62641.14000000","0.00018000"],["62641.15000000","0.07731000"],["62641.43000000","0.00400000"],["62641.56000000","0.00009000"],["62641.97000000","0.00018000"],["62641.98000000","0.21032000"],["62641.99000000","0.15746000"],["62642.00000000","0.03469000"],["62642.11000000","0.00010000"],["62642.25000000","0.00016000"],["62642.72000000","0.00008000"],["62642.91000000","0.00032000"],["62643.00000000","0.00400000"],["62643.06000000","0.00009000"],["62643.07000000","0.47618000"],["62643.09000000","0.00016000"]]}}
{"t":12.2638,"stream":"btcusdt@depth@100ms","data":{"e":"depthUpdate","E":1783948014914,"s":"BTCUSDT","U":97344795809,"u":97344795938,"b":[["62639.99000000","2.99839000"],["62639.98000000","0.00510000"],["62638.80000000","0.00000000"],["62638.79000000","0.00000000"],["62638.76000000","0.00032000"],["62636.72000000","0.00400000"],["62636.67000000","0.00000000"],["62636.66000000","0.14093000"],["62636.62000000","0.00163000"],["62636.12000000","0.00000000"],["62636.01000000","0.00000000"],["62635.92000000","0.00000000"],["62635.60000000","0.00000000"],["62635.59000000","0.14111000"],["62635.58000000","0.58586000"],["62634.61000000","0.00798000"],["62634.60000000","0.00008000"],["62633.64000000","0.00400000"],["62633.52000000","0.03966000"],["62630.72000000","0.00000000"],["62630.63000000","0.00023000"],["62629.59000000","0.00000000"],["62629.53000000","0.00010000"],["62623.01000000","0.57533000"],["62611.60000000","0.00000000"],["62610.09000000","0.00000000"],["62607.01000000","0.00000000"],["62593.16000000","0.00000000"],["56376.00000000","0.00487000"],["50111.99000000","0.00000000"]],"a":[["62640.00000000","3.76340000"],["62640.90000000","0.00000000"],["62641.43000000","0.00000000"],["62641.98000000","0.06585000"],["62643.00000000","0.00000000"],["62643.06000000","0.00000000"],["62643.07000000","0.00018000"],["62643.96000000","0.00018000"],["62644.11000000","0.00009000"],["62644.24000000","0.00000000"],["62645.49000000","0.00000000"],["62645.99000000","0.00000000"],["62646.27000000","0.00000000"],["62646.64000000","0.02000000"],["62647.17000000","0.00000000"],["62647.19000000","0.00798000"],["62647.60000000","0.22169000"],["62647.61000000","0.00000000"],["62647.63000000","0.00000000"],["62647.65000000","0.00400000"],["62649.04000000","0.00000000"],["62650.32000000","3.19284000"],["62652.16000000","0.00000000"],["62664.41000000","0.57495000"],["62666.55000000","0.00400000"],["62669.69000000","0.00400000"],["62672.40000000","0.00008000"],["62696.26000000","0.00000000"],["62707.83000000","0.00000000"],["62709.19000000","0.00000000"],["62709.91000000","0.00000000"]]}}
{"t":12.2641,"stream":"btcusdt@depth20@100ms","data":{"lastUpdateId":97344795938,"bids":[["62639.99000000","2.99839000"],["62639.98000000","0.00510000"],["62639.97000000","0.00016000"],["62639.85000000","0.00008000"],["62639.83000000","0.00016000"],["62638.95000000","0.00032000"],["62638.85000000","0.00008000"],["62638.76000000","0.00032000"],["62638.44000000","0.00009000"],["62638.42000000","0.00008000"],["62638.11000000","0.00008000"],["62638.01000000","0.00018000"],["62638.00000000","0.02418000"],["62637.99000000","0.00008000"],["62637.75000000","0.00008000"],["62637.55000000","0.00016000"],["62637.18000000","0.00009000"],["62636.80000000","0.00008000"],["62636.79000000","0.00008000"],["62636.78000000","0.00008000"]],"asks":[["62640.00000000","3.76340000"],["62640.01000000","0.00097000"],["62640.02000000","0.00016000"],["62641.14000000","0.00018000"],["62641.15000000","0.07731000"],["62641.56000000","0.00009000"],["62641.97000000","0.00018000"],["62641.98000000","0.06585000"],["62641.99000000","0.15746000"],["62642.00000000","0.03469000"],["62642.11000000","0.00010000"],["62642.25000000","0.00016000"],["62642.72000000","0.00008000"],["62642.91000000","0.00032000"],["62643.07000000","0.00018000"],["62643.09000000","0.00016000"],["62643.20000000","0.00008000"],["62643.43000000","0.02172000"],["62643.76000000","0.00008000"],["62643.96000000","0.00018000"]]}}
{"t":12.3649,"stream":"btcusdt@depth@100ms","data":{"e":"depthUpdate","E":1783948015014,"s":"BTCUSDT","U":97344795939,"u":97344795998,"b":[["62639.99000000","2.99848000"],["62639.98000000","0.00510000"],["62639.85000000","0.00008000"],["62638.95000000","0.00000000"],["62638.29000000","0.00400000"],["62638.00000000","0.02418000"],["62636.67000000","0.00018000"],["62635.60000000","0.00000000"],["62633.50000000","0.00000000"],["62632.37000000","0.00190000"],["62630.72000000","0.59916000"],["62627.26000000","0.00000000"],["62613.17000000","0.00000000"],["62495.14000000","0.00026000"],["56376.00000000","0.00507000"],["50112.00000000","0.00975000"]],"a":[["62640.00000000","3.73511000"],["62642.00000000","0.03469000"],["62642.25000000","0.00008000"],["62643.07000000","0.00000000"],["62643.42000000","0.00009000"],["62643.43000000","0.02172000"],["62643.96000000","0.00000000"],["62644.12000000","0.05406000"],["62644.13000000","0.01785000"],["62645.31000000","0.00032000"],["62647.94000000","0.00188000"],["62757.67000000","0.00000000"]]}}
{"t":12.3652,"stream":"btcusdt@depth20@100ms","data":{"lastUpdateId":97344795998,"bids":[["62639.99000000","2.99848000"],["62639.98000000","0.00510000"],["62639.97000000","0.00016000"],["62639.85000000","0.00008000"],["62639.83000000","0.00016000"],["62638.85000000","0.00008000"],["62638.76000000","0.00032000"],["62638.44000000","0.00009000"],["62638.42000000","0.00008000"],["62638.29000000","0.00400000"],["62638.11000000","0.00008000"],["62638.01000000","0.00018000"],["62638.00000000","0.02418000"],["62637.99000000","0.00008000"],["62637.75000000","0.00008000"],["62637.55000000","0.00016000"],["62637.18000000","0.00009000"],["62636.80000000","0.00008000"],["62636.79000000","0.00008000"],["62636.78000000","0.00008000"]],"asks":[["62640.00000000","3.73511000"],["62640.01000000","0.00097000"],["62640.02000000","0.00016000"],["62641.14000000","0.00018000"],["62641.15000000","0.07731000"],["62641.56000000","0.00009000"],["62641.97000000","0.00018000"],["62641.98000000","0.06585000"],["62641.99000000","0.15746000"],["62642.00000000","0.03469000"],["62642.11000000","0.00010000"],["62642.25000000","0.00008000"],["62642.72000000","0.00008000"],["62642.91000000","0.00032000"],["62643.09000000","0.00016000"],["62643.20000000","0.00008000"],["62643.42000000","0.00009000"],["62643.43000000","0.02172000"],["62643.76000000","0.00008000"],["62643.97000000","0.00030000"]]}}
{"t":12.3925,"stream":"btcusdt@aggTrade","data":{"e":"aggTrade","E":1783948015041,"s":"BTCUSDT","a":4013160587,"p":"62640.00000000","q":"0.00400000","f":6501833778,"l":6501833778,"T":1783948015041,"m":false,"M":true}}
{"t":12.464,"stream":"btcusdt@depth@100ms","data":{"e":"depthUpdate","E":1783948015114,"s":"BTCUSDT","U":97344795999,"u":97344796059,"b":[["62639.99000000","3.00184000"],["62638.76000000","0.00000000"],["62637.79000000","0.05170000"],["62637.78000000","0.00018000"],["62637.77000000","0.14093000"],["62637.53000000","0.00018000"],["62637.52000000","0.52726000"],["62636.67000000","0.00000000"],["62635.58000000","0.55447000"],["62632.37000000","0.00000000"],["62630.73000000","0.47600000"],["62625.82000000","0.00000000"],["62625.70000000","0.57531000"],["62625.68000000","0.00000000"],["62512.48000000","0.02533000"],["62506.12000000","0.00832000"],["62496.97000000","4.80418000"],["62496.96000000","0.00014000"],["62485.59000000","0.00999000"],["56376.00000000","0.00497000"],["56375.99000000","0.00010000"],["40000.00000000","258.07540000"]],"a":[["62640.00000000","3.50261000"],["62640.01000000","0.00097000"],["62644.57000000","0.00000000"],["62667.32000000","0.57493000"],["62672.83000000","0.00400000"],["62757.97000000","0.00000000"],["62946.98000000","0.22500000"]]}}
{"t":12.4644,"stream":"btcusdt@depth20@100ms","data":{"lastUpdateId":97344796059,"bids":[["62639.99000000","3.00184000"],["62639.98000000","0.00510000"],["62639.97000000","0.00016000"],["62639.85000000","0.00008000"],["62639.83000000","0.00016000"],["62638.85000000","0.00008000"],["62638.44000000","0.00009000"],["62638.42000000","0.00008000"],["62638.29000000","0.00400000"],["62638.11000000","0.00008000"],["62638.01000000","0.00018000"],["62638.00000000","0.02418000"],["62637.99000000","0.00008000"],["62637.79000000","0.05170000"],["62637.78000000","0.00018000"],["62637.77000000","0.14093000"],["62637.75000000","0.00008000"],["62637.55000000","0.00016000"],["62637.53000000","0.00018000"],["62637.52000000","0.52726000"]],"asks":[["62640.00000000","3.50261000"],["62640.01000000","0.00097000"],["62640.02000000","0.00016000"],["62641.14000000","0.00018000"],["62641.15000000","0.07731000"],["62641.56000000","0.00009000"],["62641.97000000","0.00018000"],["62641.98000000","0.06585000"],["62641.99000000","0.15746000"],["62642.00000000","0.03469000"],["62642.11000000","0.00010000"],["62642.25000000","0.00008000"],["62642.72000000","0.00008000"],["62642.91000000","0.00032000"],["62643.09000000","0.00016000"],["62643.20000000","0.00008000"],["62643.42000000","0.00009000"],["62643.43000000","0.02172000"],["62643.76000000","0.00008000"],["62643.97000000","0.00030000"]]}}
{"t":12.4959,"stream":"btcusdt@aggTrade","data":{"e":"aggTrade","E":1783948015145,"s":"BTCUSDT","a":4013160588,"p":"62639.99000000","q":"0.00978000","f":6501833779,"l":6501833779,"T":1783948015144,"m":true,"M":true}}
{"t":12.5639,"stream":"btcusdt@depth@100ms","data":{"e":"depthUpdate","E":1783948015214,"s":"BTCUSDT","U":97344796060,"u":97344796098,"b":[["62639.99000000","2.99214000"],["62638.00000000","0.02418000"],["62637.80000000","0.00018000"],["62637.79000000","0.05170000"],["62637.77000000","0.14111000"],["62637.52000000","0.52744000"],["62635.59000000","0.14093000"],["62635.58000000","0.55429000"],["62635.57000000","1.91755000"],["62634.29000000","0.00000000"],["56376.00000000","0.00497000"],["50112.00000000","0.00936000"]],"a":[["62640.00000000","3.33005000"],["62642.56000000","0.11253000"],["62644.05000000","0.00000000"],["62675.55000000","0.00008000"],["62676.98000000","0.00000000"],["62758.11000000","0.00000000"],["63579.60000000","0.00030000"]]}}
{"t":12.564,"stream":"btcusdt@depth20@100ms","data":{"lastUpdateId":97344796098,"bids":[["62639.99000000","2.99214000"],["62639.98000000","0.00510000"],["62639.97000000","0.00016000"],["62639.85000000","0.00008000"],["62639.83000000","0.00016000"],["62638.85000000","0.00008000"],["62638.44000000","0.00009000"],["62638.42000000","0.00008000"],["62638.29000000","0.00400000"],["62638.11000000","0.00008000"],["62638.01000000","0.00018000"],["62638.00000000","0.02418000"],["62637.99000000","0.00008000"],["62637.80000000","0.00018000"],["62637.79000000","0.05170000"],["62637.78000000","0.00018000"],["62637.77000000","0.14111000"],["62637.75000000","0.00008000"],["62637.55000000","0.00016000"],["62637.53000000","0.00018000"]],"asks":[["62640.00000000","3.33005000"],["62640.01000000","0.00097000"],["62640.02000000","0.00016000"],["62641.14000000","0.00018000"],["62641.15000000","0.07731000"],["62641.56000000","0.00009000"],["62641.97000000","0.00018000"],["62641.98000000","0.06585000"],["62641.99000000","0.15746000"],["62642.00000000","0.03469000"],["62642.11000000","0.00010000"],["62642.25000000","0.00008000"],["62642.56000000","0.11253000"],["62642.72000000","0.00008000"],["62642.91000000","0.00032000"],["62643.09000000","0.00016000"],["62643.20000000","0.00008000"],["62643.42000000","0.00009000"],["62643.43000000","0.02172000"],["62643.76000000","0.00008000"]]}}
{"t":12.6637,"stream":"btcusdt@depth@100ms","data":{"e":"depthUpdate","E":1783948015314,"s":"BTCUSDT","U":97344796099,"u":97344796146,"b":[["62639.99000000","2.99230000"],["62639.49000000","0.22366000"],["62639.48000000","0.52725000"],["62638.01000000","0.00000000"],["62637.80000000","0.00000000"],["62637.79000000","0.00018000"],["62637.53000000","0.00000000"],["62637.52000000","0.00018000"],["62635.72000000","0.00008000"],["62634.97000000","0.00000000"],["62633.72000000","0.22900000"],["62633.64000000","0.00000000"],["62630.74000000","0.47600000"],["62630.73000000","0.00000000"],["62624.07000000","0.47600000"],["62624.05000000","0.00000000"],["62581.15000000","0.95879000"],["62574.54000000","0.00000000"],["56376.00000000","0.00497000"]],"a":[["62640.00000000","2.48802000"],["62640.18000000","0.00068000"],["62641.99000000","0.15754000"],["62642.00000000","0.03469000"],["62642.55000000","0.00009000"],["62642.56000000","0.11271000"],["62643.42000000","0.00000000"],["62644.13000000","0.01767000"],["62677.08000000","0.00011000"],["62699.81000000","0.00878000"],["62700.81000000","0.31439000"],["62702.68000000","0.95879000"]]}}
{"t":12.6638,"stream":"btcusdt@depth20@100ms","data":{"lastUpdateId":97344796146,"bids":[["62639.99000000","2.99230000"],["62639.98000000","0.00510000"],["62639.97000000","0.00016000"],["62639.85000000","0.00008000"],["62639.83000000","0.00016000"],["62639.49000000","0.22366000"],["62639.48000000","0.52725000"],["62638.85000000","0.00008000"],["62638.44000000","0.00009000"],["62638.42000000","0.00008000"],["62638.29000000","0.00400000"],["62638.11000000","0.00008000"],["62638.00000000","0.02418000"],["62637.99000000","0.00008000"],["62637.79000000","0.00018000"],["62637.78000000","0.00018000"],["62637.77000000","0.14111000"],["62637.75000000","0.00008000"],["62637.55000000","0.00016000"],["62637.52000000","0.00018000"]],"asks":[["62640.00000000","2.48802000"],["62640.01000000","0.00097000"],["62640.02000000","0.00016000"],["62640.18000000","0.00068000"],["62641.14000000","0.00018000"],["62641.15000000","0.07731000"],["62641.56000000","0.00009000"],["62641.97000000","0.00018000"],["62641.98000000","0.06585000"],["62641.99000000","0.15754000"],["62642.00000000","0.03469000"],["62642.11000000","0.00010000"],["62642.25000000","0.00008000"],["62642.55000000","0.00009000"],["62642.56000000","0.11271000"],["62642.72000000","0.00008000"],["62642.91000000","0.00032000"],["62643.09000000","0.00016000"],["62643.20000000","0.00008000"],["62643.43000000","0.02172000"]]}}
{"t":12.7647,"stream":"btcusdt@depth@100ms","data":{"e":"depthUpdate","E":1783948015414,"s":"BTCUSDT","U":97344796147,"u":97344796190,"b":[["62639.99000000","2.99241000"],["62639.98000000","0.00528000"],["62639.50000000","0.00018000"],["62639.49000000","0.22402000"],["62639.48000000","0.52743000"],["62638.00000000","0.02418000"],["62637.79000000","0.00000000"],["62637.77000000","0.14111000"],["62637.52000000","0.00000000"],["62512.48000000","0.00033000"],["56376.00000000","0.00497000"]],"a":[["62640.00000000","2.48859000"],["62640.01000000","0.00106000"],["62647.40000000","0.00000000"],["62647.45000000","0.00000000"],["62649.51000000","0.13094000"]]}}
{"t":12.7649,"stream":"btcusdt@depth20@100ms","data":{"lastUpdateId":97344796190,"bids":[["62639.99000000","2.99241000"],["62639.98000000","0.00528000"],["62639.97000000","0.00016000"],["62639.85000000","0.00008000"],["62639.83000000","0.00016000"],["62639.50000000","0.00018000"],["62639.49000000","0.22402000"],["62639.48000000","0.52743000"],["62638.85000000","0.00008000"],["62638.44000000","0.00009000"],["62638.42000000","0.00008000"],["62638.29000000","0.00400000"],["62638.11000000","0.00008000"],["62638.00000000","0.02418000"],["62637.99000000","0.00008000"],["62637.78000000","0.00018000"],["62637.77000000","0.14111000"],["62637.75000000","0.00008000"],["62637.55000000","0.00016000"],["62637.18000000","0.00009000"]],"asks":[["62640.00000000","2.48859000"],["62640.01000000","0.00106000"],["62640.02000000","0.00016000"],["62640.18000000","0.00068000"],["62641.14000000","0.00018000"],["62641.15000000","0.07731000"],["62641.56000000","0.00009000"],["62641.97000000","0.00018000"],["62641.98000000","0.06585000"],["62641.99000000","0.15754000"],["62642.00000000","0.03469000"],["62642.11000000","0.00010000"],["62642.25000000","0.00008000"],["62642.55000000","0.00009000"],["62642.56000000","0.11271000"],["62642.72000000","0.00008000"],["62642.91000000","0.00032000"],["62643.09000000","0.00016000"],["62643.20000000","0.00008000"],["62643.43000000","0.02172000"]]}}
{"t":12.8647,"stream":"btcusdt@depth@100ms","data":{"e":"depthUpdate","E":1783948015514,"s":"BTCUSDT","U":97344796191,"u":97344796202,"b":[["62636.67000000","0.00018000"],["62606.22000000","0.00000000"],["56376.00000000","0.00497000"]],"a":[["62640.00000000","2.48811000"],["62647.39000000","0.00000000"],["62647.48000000","0.00000000"]]}}
{"t":12.8648,"stream":"btcusdt@depth20@100ms","data":{"lastUpdateId":97344796202,"bids":[["62639.99000000","2.99241000"],["62639.98000000","0.00528000"],["62639.97000000","0.00016000"],["62639.85000000","0.00008000"],["62639.83000000","0.00016000"],["62639.50000000","0.00018000"],["62639.49000000","0.22402000"],["62639.48000000","0.52743000"],["62638.85000000","0.00008000"],["62638.44000000","0.00009000"],["62638.42000000","0.00008000"],["62638.29000000","0.00400000"],["62638.11000000","0.00008000"],["62638.00000000","0.02418000"],["62637.99000000","0.00008000"],["62637.78000000","0.00018000"],["62637.77000000","0.14111000"],["62637.75000000","0.00008000"],["62637.55000000","0.00016000"],["62637.18000000","0.00009000"]],"asks":[["62640.00000000","2.48811000"],["62640.01000000","0.00106000"],["62640.02000000","0.00016000"],["62640.18000000","0.00068000"],["62641.14000000","0.00018000"],["62641.15000000","0.07731000"],["62641.56000000","0.00009000"],["62641.97000000","0.00018000"],["62641.98000000","0.06585000"],["62641.99000000","0.15754000"],["62642.00000000","0.03469000"],["62642.11000000","0.00010000"],["62642.25000000","0.00008000"],["62642.55000000","0.00009000"],["62642.56000000","0.11271000"],["62642.72000000","0.00008000"],["62642.91000000","0.00032000"],["62643.09000000","0.00016000"],["62643.20000000","0.00008000"],["62643.43000000","0.02172000"]]}}
{"t":12.9202,"stream":"btcusdt@aggTrade","data":{"e":"aggTrade","E":1783948015570,"s":"BTCUSDT","a":4013160589,"p":"62640.00000000","q":"0.00082000","f":6501833780,"l":6501833780,"T":1783948015570,"m":false,"M":true}}
{"t":12.9643,"stream":"btcusdt@depth@100ms","data":{"e":"depthUpdate","E":1783948015614,"s":"BTCUSDT","U":97344796203,"u":97344796214,"b":[["62639.06000000","0.00009000"],["62638.44000000","0.00000000"],["62625.97000000","0.00008000"],["56376.00000000","0.00477000"]],"a":[["62640.00000000","2.48825000"],["62651.04000000","0.00008000"],["62664.20000000","0.00039000"]]}}
{"t":12.9643,"stream":"btcusdt@depth20@100ms","data":{"lastUpdateId":97344796214,"bids":[["62639.99000000","2.99241000"],["62639.98000000","0.00528000"],["62639.97000000","0.00016000"],["62639.85000000","0.00008000"],["62639.83000000","0.00016000"],["62639.50000000","0.00018000"],["62639.49000000","0.22402000"],["62639.48000000","0.52743000"],["62639.06000000","0.00009000"],["62638.85000000","0.00008000"],["62638.42000000","0.00008000"],["62638.29000000","0.00400000"],["62638.11000000","0.00008000"],["62638.00000000","0.02418000"],["62637.99000000","0.00008000"],["62637.78000000","0.00018000"],["62637.77000000","0.14111000"],["62637.75000000","0.00008000"],["62637.55000000","0.00016000"],["62637.18000000","0.00009000"]],"asks":[["62640.00000000","2.48825000"],["62640.01000000","0.00106000"],["62640.02000000","0.00016000"],["62640.18000000","0.00068000"],["62641.14000000","0.00018000"],["62641.15000000","0.07731000"],["62641.56000000","0.00009000"],["62641.97000000","0.00018000"],["62641.98000000","0.06585000"],["62641.99000000","0.15754000"],["62642.00000000","0.03469000"],["62642.11000000","0.00010000"],["62642.25000000","0.00008000"],["62642.55000000","0.00009000"],["62642.56000000","0.11271000"],["62642.72000000","0.00008000"],["62642.91000000","0.00032000"],["62643.09000000","0.00016000"],["62643.20000000","0.00008000"],["62643.43000000","0.02172000"]]}}
{"t":13.064,"stream":"btcusdt@depth@100ms","data":{"e":"depthUpdate","E":1783948015714,"s":"BTCUSDT","U":97344796215,"u":97344796222,"b":[["61700.39000000","0.00030000"],["56376.00000000","0.00477000"]],"a":[["62653.67000000","0.00057000"],["62664.20000000","0.00000000"]]}}
{"t":13.0641,"stream":"btcusdt@depth20@100ms","data":{"lastUpdateId":97344796222,"bids":[["62639.99000000","2.99241000"],["62639.98000000","0.00528000"],["62639.97000000","0.00016000"],["62639.85000000","0.00008000"],["62639.83000000","0.00016000"],["62639.50000000","0.00018000"],["62639.49000000","0.22402000"],["62639.48000000","0.52743000"],["62639.06000000","0.00009000"],["62638.85000000","0.00008000"],["62638.42000000","0.00008000"],["62638.29000000","0.00400000"],["62638.11000000","0.00008000"],["62638.00000000","0.02418000"],["62637.99000000","0.00008000"],["62637.78000000","0.00018000"],["62637.77000000","0.14111000"],["62637.75000000","0.00008000"],["62637.55000000","0.00016000"],["62637.18000000","0.00009000"]],"asks":[["62640.00000000","2.48825000"],["62640.01000000","0.00106000"],["62640.02000000","0.00016000"],["62640.18000000","0.00068000"],["62641.14000000","0.00018000"],["62641.15000000","0.07731000"],["62641.56000000","0.00009000"],["62641.97000000","0.00018000"],["62641.98000000","0.06585000"],["62641.99000000","0.15754000"],["62642.00000000","0.03469000"],["62642.11000000","0.00010000"],["62642.25000000","0.00008000"],["62642.55000000","0.00009000"],["62642.56000000","0.11271000"],["62642.72000000","0.00008000"],["62642.91000000","0.00032000"],["62643.09000000","0.00016000"],["62643.20000000","0.00008000"],["62643.43000000","0.02172000"]]}}
{"t":13.1657,"stream":"btcusdt@depth@100ms","data":{"e":"depthUpdate","E":1783948015814,"s":"BTCUSDT","U":97344796223,"u":97344796230,"b":[["62616.80000000","0.00000000"],["62613.05000000","0.06746000"],["56376.00000000","0.00477000"],["50111.99000000","0.00000000"]],"a":[]}}
{"t":13.1659,"stream":"btcusdt@depth20@100ms","data":{"lastUpdateId":97344796230,"bids":[["62639.99000000","2.99241000"],["62639.98000000","0.00528000"],["62639.97000000","0.00016000"],["62639.85000000","0.00008000"],["62639.83000000","0.00016000"],["62639.50000000","0.00018000"],["62639.49000000","0.22402000"],["62639.48000000","0.52743000"],["62639.06000000","0.00009000"],["62638.85000000","0.00008000"],["62638.42000000","0.00008000"],["62638.29000000","0.00400000"],["62638.11000000","0.00008000"],["62638.00000000","0.02418000"],["62637.99000000","0.00008000"],["62637.78000000","0.00018000"],["62637.77000000","0.14111000"],["62637.75000000","0.00008000"],["62637.55000000","0.00016000"],["62637.18000000","0.00009000"]],"asks":[["62640.00000000","2.48825000"],["62640.01000000","0.00106000"],["62640.02000000","0.00016000"],["62640.18000000","0.00068000"],["62641.14000000","0.00018000"],["62641.15000000","0.07731000"],["62641.56000000","0.00009000"],["62641.97000000","0.00018000"],["62641.98000000","0.06585000"],["62641.99000000","0.15754000"],["62642.00000000","0.03469000"],["62642.11000000","0.00010000"],["62642.25000000","0.00008000"],["62642.55000000","0.00009000"],["62642.56000000","0.11271000"],["62642.72000000","0.00008000"],["62642.91000000","0.00032000"],["62643.09000000","0.00016000"],["62643.20000000","0.00008000"],["62643.43000000","0.02172000"]]}}
{"t":13.2634,"stream":"btcusdt@depth@100ms","data":{"e":"depthUpdate","E":1783948015914,"s":"BTCUSDT","U":97344796231,"u":97344796239,"b":[["56376.00000000","0.00477000"],["56375.00000000","0.00355000"],["50111.99000000","0.00000000"]],"a":[["62713.41000000","2.15344000"]]}}
{"t":13.2638,"stream":"btcusdt@depth20@100ms","data":{"lastUpdateId":97344796239,"bids":[["62639.99000000","2.99241000"],["62639.98000000","0.00528000"],["62639.97000000","0.00016000"],["62639.85000000","0.00008000"],["62639.83000000","0.00016000"],["62639.50000000","0.00018000"],["62639.49000000","0.22402000"],["62639.48000000","0.52743000"],["62639.06000000","0.00009000"],["62638.85000000","0.00008000"],["62638.42000000","0.00008000"],["62638.29000000","0.00400000"],["62638.11000000","0.00008000"],["62638.00000000","0.02418000"],["62637.99000000","0.00008000"],["62637.78000000","0.00018000"],["62637.77000000","0.14111000"],["62637.75000000","0.00008000"],["62637.55000000","0.00016000"],["62637.18000000","0.00009000"]],"asks":[["62640.00000000","2.48825000"],["62640.01000000","0.00106000"],["62640.02000000","0.00016000"],["62640.18000000","0.00068000"],["62641.14000000","0.00018000"],["62641.15000000","0.07731000"],["62641.56000000","0.00009000"],["62641.97000000","0.00018000"],["62641.98000000","0.06585000"],["62641.99000000","0.15754000"],["62642.00000000","0.03469000"],["62642.11000000","0.00010000"],["62642.25000000","0.00008000"],["62642.55000000","0.00009000"],["62642.56000000","0.11271000"],["62642.72000000","0.00008000"],["62642.91000000","0.00032000"],["62643.09000000","0.00016000"],["62643.20000000","0.00008000"],["62643.43000000","0.02172000"]]}}
{"t":13.3648,"stream":"btcusdt@depth@100ms","data":{"e":"depthUpdate","E":1783948016014,"s":"BTCUSDT","U":97344796240,"u":97344796273,"b":[["56376.00000000","0.00477000"],["50112.00000000","0.00975000"]],"a":[["62640.00000000","2.48750000"],["62640.01000000","0.00115000"],["62640.95000000","0.00018000"],["62640.96000000","0.17284000"],["62640.97000000","0.17256000"],["62641.97000000","0.00000000"],["62641.98000000","0.00044000"],["62642.55000000","0.00000000"],["62644.05000000","0.00008000"],["62644.11000000","0.00000000"],["62675.55000000","0.00000000"],["62677.08000000","0.00000000"],["62758.45000000","0.00000000"]]}}
{"t":13.3651,"stream":"btcusdt@depth20@100ms","data":{"lastUpdateId":97344796273,"bids":[["62639.99000000","2.99241000"],["62639.98000000","0.00528000"],["62639.97000000","0.00016000"],["62639.85000000","0.00008000"],["62639.83000000","0.00016000"],["62639.50000000","0.00018000"],["62639.49000000","0.22402000"],["62639.48000000","0.52743000"],["62639.06000000","0.00009000"],["62638.85000000","0.00008000"],["62638.42000000","0.00008000"],["62638.29000000","0.00400000"],["62638.11000000","0.00008000"],["62638.00000000","0.02418000"],["62637.99000000","0.00008000"],["62637.78000000","0.00018000"],["62637.77000000","0.14111000"],["62637.75000000","0.00008000"],["62637.55000000","0.00016000"],["62637.18000000","0.00009000"]],"asks":[["62640.00000000","2.48750000"],["62640.01000000","0.00115000"],["62640.02000000","0.00016000"],["62640.18000000","0.00068000"],["62640.95000000","0.00018000"],["62640.96000000","0.17284000"],["62640.97000000","0.17256000"],["62641.14000000","0.00018000"],["62641.15000000","0.07731000"],["62641.56000000","0.00009000"],["62641.98000000","0.00044000"],["62641.99000000","0.15754000"],["62642.00000000","0.03469000"],["62642.11000000","0.00010000"],["62642.25000000","0.00008000"],["62642.56000000","0.11271000"],["62642.72000000","0.00008000"],["62642.91000000","0.00032000"],["62643.09000000","0.00016000"],["62643.20000000","0.00008000"]]}}
{"t":13.4647,"stream":"btcusdt@depth@100ms","data":{"e":"depthUpdate","E":1783948016114,"s":"BTCUSDT","U":97344796274,"u":97344796293,"b":[["62496.98000000","0.00999000"],["62485.59000000","0.00000000"],["56376.00000000","0.00477000"],["40000.00000000","258.07540000"]],"a":[["62640.00000000","2.48768000"],["62640.96000000","0.17302000"],["62640.97000000","0.17274000"],["62641.15000000","0.07713000"],["62641.98000000","0.00026000"],["62644.12000000","0.05388000"],["62677.18000000","0.00011000"]]}}
{"t":13.4649,"stream":"btcusdt@depth20@100ms","data":{"lastUpdateId":97344796293,"bids":[["62639.99000000","2.99241000"],["62639.98000000","0.00528000"],["62639.97000000","0.00016000"],["62639.85000000","0.00008000"],["62639.83000000","0.00016000"],["62639.50000000","0.00018000"],["62639.49000000","0.22402000"],["62639.48000000","0.52743000"],["62639.06000000","0.00009000"],["62638.85000000","0.00008000"],["62638.42000000","0.00008000"],["62638.29000000","0.00400000"],["62638.11000000","0.00008000"],["62638.00000000","0.02418000"],["62637.99000000","0.00008000"],["62637.78000000","0.00018000"],["62637.77000000","0.14111000"],["62637.75000000","0.00008000"],["62637.55000000","0.00016000"],["62637.18000000","0.00009000"]],"asks":[["62640.00000000","2.48768000"],["62640.01000000","0.00115000"],["62640.02000000","0.00016000"],["62640.18000000","0.00068000"],["62640.95000000","0.00018000"],["62640.96000000","0.17302000"],["62640.97000000","0.17274000"],["62641.14000000","0.00018000"],["62641.15000000","0.07713000"],["62641.56000000","0.00009000"],["62641.98000000","0.00026000"],["62641.99000000","0.15754000"],["62642.00000000","0.03469000"],["62642.11000000","0.00010000"],["62642.25000000","0.00008000"],["62642.56000000","0.11271000"],["62642.72000000","0.00008000"],["62642.91000000","0.00032000"],["62643.09000000","0.00016000"],["62643.20000000","0.00008000"]]}}
{"t":13.5638,"stream":"btcusdt@depth@100ms","data":{"e":"depthUpdate","E":1783948016214,"s":"BTCUSDT","U":97344796294,"u":97344796302,"b":[["56376.00000000","0.00477000"],["50112.00000000","0.00936000"]],"a":[["62758.45000000","0.00000000"],["63579.60000000","0.00030000"]]}}
{"t":13.564,"stream":"btcusdt@depth20@100ms","data":{"lastUpdateId":97344796302,"bids":[["62639.99000000","2.99241000"],["62639.98000000","0.00528000"],["62639.97000000","0.00016000"],["62639.85000000","0.00008000"],["62639.83000000","0.00016000"],["62639.50000000","0.00018000"],["62639.49000000","0.22402000"],["62639.48000000","0.52743000"],["62639.06000000","0.00009000"],["62638.85000000","0.00008000"],["62638.42000000","0.00008000"],["62638.29000000","0.00400000"],["62638.11000000","0.00008000"],["62638.00000000","0.02418000"],["62637.99000000","0.00008000"],["62637.78000000","0.00018000"],["62637.77000000","0.14111000"],["62637.75000000","0.00008000"],["62637.55000000","0.00016000"],["62637.18000000","0.00009000"]],"asks":[["62640.00000000","2.48768000"],["62640.01000000","0.00115000"],["62640.02000000","0.00016000"],["62640.18000000","0.00068000"],["62640.95000000","0.00018000"],["62640.96000000","0.17302000"],["62640.97000000","0.17274000"],["62641.14000000","0.00018000"],["62641.15000000","0.07713000"],["62641.56000000","0.00009000"],["62641.98000000","0.00026000"],["62641.99000000","0.15754000"],["62642.00000000","0.03469000"],["62642.11000000","0.00010000"],["62642.25000000","0.00008000"],["62642.56000000","0.11271000"],["62642.72000000","0.00008000"],["62642.91000000","0.00032000"],["62643.09000000","0.00016000"],["62643.20000000","0.00008000"]]}}
{"t":13.5797,"stream":"btcusdt@aggTrade","data":{"e":"aggTrade","E":1783948016229,"s":"BTCUSDT","a":4013160590,"p":"62639.99000000","q":"0.00080000","f":6501833781,"l":6501833781,"T":1783948016228,"m":true,"M":true}}
{"t":13.6638,"stream":"btcusdt@depth@100ms","data":{"e":"depthUpdate","E":1783948016314,"s":"BTCUSDT","U":97344796303,"u":97344796330,"b":[["62639.99000000","2.99161000"],["62636.67000000","0.00000000"],["62601.48000000","0.07000000"],["62599.89000000","0.70000000"],["62595.12000000","0.00000000"],["56376.00000000","0.00477000"],["56375.99000000","0.00000000"],["50112.00000000","0.00936000"]],"a":[["62640.00000000","2.48750000"],["62641.15000000","0.07731000"],["62758.45000000","0.00000000"]]}}
{"t":13.664,"stream":"btcusdt@depth20@100ms","data":{"lastUpdateId":97344796330,"bids":[["62639.99000000","2.99161000"],["62639.98000000","0.00528000"],["62639.97000000","0.00016000"],["62639.85000000","0.00008000"],["62639.83000000","0.00016000"],["62639.50000000","0.00018000"],["62639.49000000","0.22402000"],["62639.48000000","0.52743000"],["62639.06000000","0.00009000"],["62638.85000000","0.00008000"],["62638.42000000","0.00008000"],["62638.29000000","0.00400000"],["62638.11000000","0.00008000"],["62638.00000000","0.02418000"],["62637.99000000","0.00008000"],["62637.78000000","0.00018000"],["62637.77000000","0.14111000"],["62637.75000000","0.00008000"],["62637.55000000","0.00016000"],["62637.18000000","0.00009000"]],"asks":[["62640.00000000","2.48750000"],["62640.01000000","0.00115000"],["62640.02000000","0.00016000"],["62640.18000000","0.00068000"],["62640.95000000","0.00018000"],["62640.96000000","0.17302000"],["62640.97000000","0.17274000"],["62641.14000000","0.00018000"],["62641.15000000","0.07731000"],["62641.56000000","0.00009000"],["62641.98000000","0.00026000"],["62641.99000000","0.15754000"],["62642.00000000","0.03469000"],["62642.11000000","0.00010000"],["62642.25000000","0.00008000"],["62642.56000000","0.11271000"],["62642.72000000","0.00008000"],["62642.91000000","0.00032000"],["62643.09000000","0.00016000"],["62643.20000000","0.00008000"]]}}
{"t":13.7633,"stream":"btcusdt@depth@100ms","data":{"e":"depthUpdate","E":1783948016414,"s":"BTCUSDT","U":97344796331,"u":97344796335,"b":[["56376.00000000","0.00477000"]],"a":[["62758.47000000","0.15972000"]]}}
{"t":13.7634,"stream":"btcusdt@depth20@100ms","data":{"lastUpdateId":97344796335,"bids":[["62639.99000000","2.99161000"],["62639.98000000","0.00528000"],["62639.97000000","0.00016000"],["62639.85000000","0.00008000"],["62639.83000000","0.00016000"],["62639.50000000","0.00018000"],["62639.49000000","0.22402000"],["62639.48000000","0.52743000"],["62639.06000000","0.00009000"],["62638.85000000","0.00008000"],["62638.42000000","0.00008000"],["62638.29000000","0.00400000"],["62638.11000000","0.00008000"],["62638.00000000","0.02418000"],["62637.99000000","0.00008000"],["62637.78000000","0.00018000"],["62637.77000000","0.14111000"],["62637.75000000","0.00008000"],["62637.55000000","0.00016000"],["62637.18000000","0.00009000"]],"asks":[["62640.00000000","2.48750000"],["62640.01000000","0.00115000"],["62640.02000000","0.00016000"],["62640.18000000","0.00068000"],["62640.95000000","0.00018000"],["62640.96000000","0.17302000"],["62640.97000000","0.17274000"],["62641.14000000","0.00018000"],["62641.15000000","0.07731000"],["62641.56000000","0.00009000"],["62641.98000000","0.00026000"],["62641.99000000","0.15754000"],["62642.00000000","0.03469000"],["62642.11000000","0.00010000"],["62642.25000000","0.00008000"],["62642.56000000","0.11271000"],["62642.72000000","0.00008000"],["62642.91000000","0.00032000"],["62643.09000000","0.00016000"],["62643.20000000","0.00008000"]]}}
{"t":13.7734,"stream":"btcusdt@aggTrade","data":{"e":"aggTrade","E":1783948016422,"s":"BTCUSDT","a":4013160591,"p":"62639.99000000","q":"0.05139000","f":6501833782,"l":6501833782,"T":1783948016422,"m":true,"M":true}}
{"t":13.8648,"stream":"btcusdt@depth@100ms","data":{"e":"depthUpdate","E":1783948016514,"s":"BTCUSDT","U":97344796336,"u":97344796343,"b":[["62639.99000000","2.94022000"],["62636.67000000","0.00018000"],["56376.00000000","0.00497000"]],"a":[["62713.40000000","0.65286000"],["62758.47000000","0.00000000"]]}}
{"t":13.865,"stream":"btcusdt@depth20@100ms","data":{"lastUpdateId":97344796343,"bids":[["62639.99000000","2.94022000"],["62639.98000000","0.00528000"],["62639.97000000","0.00016000"],["62639.85000000","0.00008000"],["62639.83000000","0.00016000"],["62639.50000000","0.00018000"],["62639.49000000","0.22402000"],["62639.48000000","0.52743000"],["62639.06000000","0.00009000"],["62638.85000000","0.00008000"],["62638.42000000","0.00008000"],["62638.29000000","0.00400000"],["62638.11000000","0.00008000"],["62638.00000000","0.02418000"],["62637.99000000","0.00008000"],["62637.78000000","0.00018000"],["62637.77000000","0.14111000"],["62637.75000000","0.00008000"],["62637.55000000","0.00016000"],["62637.18000000","0.00009000"]],"asks":[["62640.00000000","2.48750000"],["62640.01000000","0.00115000"],["62640.02000000","0.00016000"],["62640.18000000","0.00068000"],["62640.95000000","0.00018000"],["62640.96000000","0.17302000"],["62640.97000000","0.17274000"],["62641.14000000","0.00018000"],["62641.15000000","0.07731000"],["62641.56000000","0.00009000"],["62641.98000000","0.00026000"],["62641.99000000","0.15754000"],["62642.00000000","0.03469000"],["62642.11000000","0.00010000"],["62642.25000000","0.00008000"],["62642.56000000","0.11271000"],["62642.72000000","0.00008000"],["62642.91000000","0.00032000"],["62643.09000000","0.00016000"],["62643.20000000","0.00008000"]]}}
{"t":13.9643,"stream":"btcusdt@depth@100ms","data":{"e":"depthUpdate","E":1783948016614,"s":"BTCUSDT","U":97344796344,"u":97344796350,"b":[["62625.97000000","0.00000000"],["62550.00000000","6.66520000"],["62547.76000000","0.00010000"],["56376.00000000","0.00497000"]],"a":[["62651.04000000","0.00000000"]]}}
{"t":13.9644,"stream":"btcusdt@depth20@100ms","data":{"lastUpdateId":97344796350,"bids":[["62639.99000000","2.94022000"],["62639.98000000","0.00528000"],["62639.97000000","0.00016000"],["62639.85000000","0.00008000"],["62639.83000000","0.00016000"],["62639.50000000","0.00018000"],["62639.49000000","0.22402000"],["62639.48000000","0.52743000"],["62639.06000000","0.00009000"],["62638.85000000","0.00008000"],["62638.42000000","0.00008000"],["62638.29000000","0.00400000"],["62638.11000000","0.00008000"],["62638.00000000","0.02418000"],["62637.99000000","0.00008000"],["62637.78000000","0.00018000"],["62637.77000000","0.14111000"],["62637.75000000","0.00008000"],["62637.55000000","0.00016000"],["62637.18000000","0.00009000"]],"asks":[["62640.00000000","2.48750000"],["62640.01000000","0.00115000"],["62640.02000000","0.00016000"],["62640.18000000","0.00068000"],["62640.95000000","0.00018000"],["62640.96000000","0.17302000"],["62640.97000000","0.17274000"],["62641.14000000","0.00018000"],["62641.15000000","0.07731000"],["62641.56000000","0.00009000"],["62641.98000000","0.00026000"],["62641.99000000","0.15754000"],["62642.00000000","0.03469000"],["62642.11000000","0.00010000"],["62642.25000000","0.00008000"],["62642.56000000","0.11271000"],["62642.72000000","0.00008000"],["62642.91000000","0.00032000"],["62643.09000000","0.00016000"],["62643.20000000","0.00008000"]]}}
{"t":14.0236,"stream":"btcusdt@aggTrade","data":{"e":"aggTrade","E":1783948016673,"s":"BTCUSDT","a":4013160592,"p":"62639.99000000","q":"0.00079000","f":6501833783,"l":6501833783,"T":1783948016672,"m":true,"M":true}}
{"t":14.0237,"stream":"btcusdt@aggTrade","data":{"e":"aggTrade","E":1783948016673,"s":"BTCUSDT","a":4013160593,"p":"62639.99000000","q":"0.00079000","f":6501833784,"l":6501833784,"T":1783948016673,"m":true,"M":true}}
{"t":14.0238,"stream":"btcusdt@aggTrade","data":{"e":"aggTrade","E":1783948016673,"s":"BTCUSDT","a":4013160594,"p":"62639.99000000","q":"0.00079000","f":6501833785,"l":6501833785,"T":1783948016673,"m":true,"M":true}}
{"t":14.0245,"stream":"btcusdt@aggTrade","data":{"e":"aggTrade","E":1783948016673,"s":"BTCUSDT","a":4013160595,"p":"62639.99000000","q":"0.00079000","f":6501833786,"l":6501833786,"T":1783948016673,"m":true,"M":true}}
{"t":14.0246,"stream":"btcusdt@aggTrade","data":{"e":"aggTrade","E":1783948016674,"s":"BTCUSDT","a":4013160596,"p":"62639.99000000","q":"0.00556000","f":6501833787,"l":6501833787,"T":1783948016674,"m":true,"M":true}}
{"t":14.0246,"stream":"btcusdt@aggTrade","data":{"e":"aggTrade","E":1783948016674,"s":"BTCUSDT","a":4013160597,"p":"62639.99000000","q":"0.00715000","f":6501833788,"l":6501833788,"T":1783948016674,"m":true,"M":true}}
{"t":14.0445,"stream":"btcusdt@aggTrade","data":{"e":"aggTrade","E":1783948016692,"s":"BTCUSDT","a":4013160598,"p":"62640.00000000","q":"0.09252000","f":6501833789,"l":6501833789,"T":1783948016692,"m":false,"M":true}}
{"t":14.0638,"stream":"btcusdt@depth@100ms","data":{"e":"depthUpdate","E":1783948016714,"s":"BTCUSDT","U":97344796351,"u":97344796368,"b":[["62639.99000000","2.92435000"],["62625.97000000","0.00008000"],["61700.39000000","0.00030000"],["56376.00000000","0.00497000"],["33000.00000000","33.37028000"]],"a":[["62640.00000000","2.39498000"],["62651.04000000","0.00008000"],["62677.18000000","0.00000000"]]}}
{"t":14.0639,"stream":"btcusdt@depth20@100ms","data":{"lastUpdateId":97344796368,"bids":[["62639.99000000","2.92435000"],["62639.98000000","0.00528000"],["62639.97000000","0.00016000"],["62639.85000000","0.00008000"],["62639.83000000","0.00016000"],["62639.50000000","0.00018000"],["62639.49000000","0.22402000"],["62639.48000000","0.52743000"],["62639.06000000","0.00009000"],["62638.85000000","0.00008000"],["62638.42000000","0.00008000"],["62638.29000000","0.00400000"],["62638.11000000","0.00008000"],["62638.00000000","0.02418000"],["62637.99000000","0.00008000"],["62637.78000000","0.00018000"],["62637.77000000","0.14111000"],["62637.75000000","0.00008000"],["62637.55000000","0.00016000"],["62637.18000000","0.00009000"]],"asks":[["62640.00000000","2.39498000"],["62640.01000000","0.00115000"],["62640.02000000","0.00016000"],["62640.18000000","0.00068000"],["62640.95000000","0.00018000"],["62640.96000000","0.17302000"],["62640.97000000","0.17274000"],["62641.14000000","0.00018000"],["62641.15000000","0.07731000"],["62641.56000000","0.00009000"],["62641.98000000","0.00026000"],["62641.99000000","0.15754000"],["62642.00000000","0.03469000"],["62642.11000000","0.00010000"],["62642.25000000","0.00008000"],["62642.56000000","0.11271000"],["62642.72000000","0.00008000"],["62642.91000000","0.00032000"],["62643.09000000","0.00016000"],["62643.20000000","0.00008000"]]}}
{"t":14.1638,"stream":"btcusdt@depth@100ms","data":{"e":"depthUpdate","E":1783948016814,"s":"BTCUSDT","U":97344796369,"u":97344796376,"b":[["56376.00000000","0.00497000"],["56375.99000000","0.00010000"],["50111.99000000","0.00000000"]],"a":[["62677.28000000","0.00011000"]]}}
{"t":14.164,"stream":"btcusdt@depth20@100ms","data":{"lastUpdateId":97344796376,"bids":[["62639.99000000","2.92435000"],["62639.98000000","0.00528000"],["62639.97000000","0.00016000"],["62639.85000000","0.00008000"],["62639.83000000","0.00016000"],["62639.50000000","0.00018000"],["62639.49000000","0.22402000"],["62639.48000000","0.52743000"],["62639.06000000","0.00009000"],["62638.85000000","0.00008000"],["62638.42000000","0.00008000"],["62638.29000000","0.00400000"],["62638.11000000","0.00008000"],["62638.00000000","0.02418000"],["62637.99000000","0.00008000"],["62637.78000000","0.00018000"],["62637.77000000","0.14111000"],["62637.75000000","0.00008000"],["62637.55000000","0.00016000"],["62637.18000000","0.00009000"]],"asks":[["62640.00000000","2.39498000"],["62640.01000000","0.00115000"],["62640.02000000","0.00016000"],["62640.18000000","0.00068000"],["62640.95000000","0.00018000"],["62640.96000000","0.17302000"],["62640.97000000","0.17274000"],["62641.14000000","0.00018000"],["62641.15000000","0.07731000"],["62641.56000000","0.00009000"],["62641.98000000","0.00026000"],["62641.99000000","0.15754000"],["62642.00000000","0.03469000"],["62642.11000000","0.00010000"],["62642.25000000","0.00008000"],["62642.56000000","0.11271000"],["62642.72000000","0.00008000"],["62642.91000000","0.00032000"],["62643.09000000","0.00016000"],["62643.20000000","0.00008000"]]}}
{"t":14.1687,"stream":"btcusdt@aggTrade","data":{"e":"aggTrade","E":1783948016818,"s":"BTCUSDT","a":4013160599,"p":"62640.00000000","q":"0.01900000","f":6501833790,"l":6501833790,"T":1783948016818,"m":false,"M":true}}
{"t":14.2634,"stream":"btcusdt@depth@100ms","data":{"e":"depthUpdate","E":1783948016914,"s":"BTCUSDT","U":97344796377,"u":97344796384,"b":[["56376.00000000","0.00497000"],["56375.99000000","0.00000000"],["50111.99000000","0.00000000"]],"a":[["62640.00000000","2.37598000"]]}}
{"t":14.2635,"stream":"btcusdt@depth20@100ms","data":{"lastUpdateId":97344796384,"bids":[["62639.99000000","2.92435000"],["62639.98000000","0.00528000"],["62639.97000000","0.00016000"],["62639.85000000","0.00008000"],["62639.83000000","0.00016000"],["62639.50000000","0.00018000"],["62639.49000000","0.22402000"],["62639.48000000","0.52743000"],["62639.06000000","0.00009000"],["62638.85000000","0.00008000"],["62638.42000000","0.00008000"],["62638.29000000","0.00400000"],["62638.11000000","0.00008000"],["62638.00000000","0.02418000"],["62637.99000000","0.00008000"],["62637.78000000","0.00018000"],["62637.77000000","0.14111000"],["62637.75000000","0.00008000"],["62637.55000000","0.00016000"],["62637.18000000","0.00009000"]],"asks":[["62640.00000000","2.37598000"],["62640.01000000","0.00115000"],["62640.02000000","0.00016000"],["62640.18000000","0.00068000"],["62640.95000000","0.00018000"],["62640.96000000","0.17302000"],["62640.97000000","0.17274000"],["62641.14000000","0.00018000"],["62641.15000000","0.07731000"],["62641.56000000","0.00009000"],["62641.98000000","0.00026000"],["62641.99000000","0.15754000"],["62642.00000000","0.03469000"],["62642.11000000","0.00010000"],["62642.25000000","0.00008000"],["62642.56000000","0.11271000"],["62642.72000000","0.00008000"],["62642.91000000","0.00032000"],["62643.09000000","0.00016000"],["62643.20000000","0.00008000"]]}}
{"t":14.3637,"stream":"btcusdt@depth@100ms","data":{"e":"depthUpdate","E":1783948017014,"s":"BTCUSDT","U":97344796385,"u":97344796391,"b":[["56376.00000000","0.00497000"],["56375.00000000","0.00355000"],["50112.00000000","0.00975000"]],"a":[]}}
{"t":14.3642,"stream":"btcusdt@depth20@100ms","data":{"lastUpdateId":97344796391,"bids":[["62639.99000000","2.92435000"],["62639.98000000","0.00528000"],["62639.97000000","0.00016000"],["62639.85000000","0.00008000"],["62639.83000000","0.00016000"],["62639.50000000","0.00018000"],["62639.49000000","0.22402000"],["62639.48000000","0.52743000"],["62639.06000000","0.00009000"],["62638.85000000","0.00008000"],["62638.42000000","0.00008000"],["62638.29000000","0.00400000"],["62638.11000000","0.00008000"],["62638.00000000","0.02418000"],["62637.99000000","0.00008000"],["62637.78000000","0.00018000"],["62637.77000000","0.14111000"],["62637.75000000","0.00008000"],["62637.55000000","0.00016000"],["62637.18000000","0.00009000"]],"asks":[["62640.00000000","2.37598000"],["62640.01000000","0.00115000"],["62640.02000000","0.00016000"],["62640.18000000","0.00068000"],["62640.95000000","0.00018000"],["62640.96000000","0.17302000"],["62640.97000000","0.17274000"],["62641.14000000","0.00018000"],["62641.15000000","0.07731000"],["62641.56000000","0.00009000"],["62641.98000000","0.00026000"],["62641.99000000","0.15754000"],["62642.00000000","0.03469000"],["62642.11000000","0.00010000"],["62642.25000000","0.00008000"],["62642.56000000","0.11271000"],["62642.72000000","0.00008000"],["62642.91000000","0.00032000"],["62643.09000000","0.00016000"],["62643.20000000","0.00008000"]]}}
{"t":14.4632,"stream":"btcusdt@depth@100ms","data":{"e":"depthUpdate","E":1783948017114,"s":"BTCUSDT","U":97344796392,"u":97344796398,"b":[["56376.00000000","0.00477000"],["50112.00000000","0.00975000"],["40000.00000000","258.07540000"]],"a":[]}}
{"t":14.4644,"stream":"btcusdt@depth20@100ms","data":{"lastUpdateId":97344796398,"bids":[["62639.99000000","2.92435000"],["62639.98000000","0.00528000"],["62639.97000000","0.00016000"],["62639.85000000","0.00008000"],["62639.83000000","0.00016000"],["62639.50000000","0.00018000"],["62639.49000000","0.22402000"],["62639.48000000","0.52743000"],["62639.06000000","0.00009000"],["62638.85000000","0.00008000"],["62638.42000000","0.00008000"],["62638.29000000","0.00400000"],["62638.11000000","0.00008000"],["62638.00000000","0.02418000"],["62637.99000000","0.00008000"],["62637.78000000","0.00018000"],["62637.77000000","0.14111000"],["62637.75000000","0.00008000"],["62637.55000000","0.00016000"],["62637.18000000","0.00009000"]],"asks":[["62640.00000000","2.37598000"],["62640.01000000","0.00115000"],["62640.02000000","0.00016000"],["62640.18000000","0.00068000"],["62640.95000000","0.00018000"],["62640.96000000","0.17302000"],["62640.97000000","0.17274000"],["62641.14000000","0.00018000"],["62641.15000000","0.07731000"],["62641.56000000","0.00009000"],["62641.98000000","0.00026000"],["62641.99000000","0.15754000"],["62642.00000000","0.03469000"],["62642.11000000","0.00010000"],["62642.25000000","0.00008000"],["62642.56000000","0.11271000"],["62642.72000000","0.00008000"],["62642.91000000","0.00032000"],["62643.09000000","0.00016000"],["62643.20000000","0.00008000"]]}}
{"t":14.564,"stream":"btcusdt@depth@100ms","data":{"e":"depthUpdate","E":1783948017214,"s":"BTCUSDT","U":97344796399,"u":97344796405,"b":[["56376.00000000","0.00477000"],["50112.00000000","0.00936000"]],"a":[["63579.60000000","0.00030000"]]}}
{"t":14.5642,"stream":"btcusdt@depth20@100ms","data":{"lastUpdateId":97344796405,"bids":[["62639.99000000","2.92435000"],["62639.98000000","0.00528000"],["62639.97000000","0.00016000"],["62639.85000000","0.00008000"],["62639.83000000","0.00016000"],["62639.50000000","0.00018000"],["62639.49000000","0.22402000"],["62639.48000000","0.52743000"],["62639.06000000","0.00009000"],["62638.85000000","0.00008000"],["62638.42000000","0.00008000"],["62638.29000000","0.00400000"],["62638.11000000","0.00008000"],["62638.00000000","0.02418000"],["62637.99000000","0.00008000"],["62637.78000000","0.00018000"],["62637.77000000","0.14111000"],["62637.75000000","0.00008000"],["62637.55000000","0.00016000"],["62637.18000000","0.00009000"]],"asks":[["62640.00000000","2.37598000"],["62640.01000000","0.00115000"],["62640.02000000","0.00016000"],["62640.18000000","0.00068000"],["62640.95000000","0.00018000"],["62640.96000000","0.17302000"],["62640.97000000","0.17274000"],["62641.14000000","0.00018000"],["62641.15000000","0.07731000"],["62641.56000000","0.00009000"],["62641.98000000","0.00026000"],["62641.99000000","0.15754000"],["62642.00000000","0.03469000"],["62642.11000000","0.00010000"],["62642.25000000","0.00008000"],["62642.56000000","0.11271000"],["62642.72000000","0.00008000"],["62642.91000000","0.00032000"],["62643.09000000","0.00016000"],["62643.20000000","0.00008000"]]}}
{"t":14.6641,"stream":"btcusdt@depth@100ms","data":{"e":"depthUpdate","E":1783948017314,"s":"BTCUSDT","U":97344796406,"u":97344796409,"b":[["56376.00000000","0.00477000"]],"a":[]}}
{"t":14.6643,"stream":"btcusdt@depth20@100ms","data":{"lastUpdateId":97344796409,"bids":[["62639.99000000","2.92435000"],["62639.98000000","0.00528000"],["62639.97000000","0.00016000"],["62639.85000000","0.00008000"],["62639.83000000","0.00016000"],["62639.50000000","0.00018000"],["62639.49000000","0.22402000"],["62639.48000000","0.52743000"],["62639.06000000","0.00009000"],["62638.85000000","0.00008000"],["62638.42000000","0.00008000"],["62638.29000000","0.00400000"],["62638.11000000","0.00008000"],["62638.00000000","0.02418000"],["62637.99000000","0.00008000"],["62637.78000000","0.00018000"],["62637.77000000","0.14111000"],["62637.75000000","0.00008000"],["62637.55000000","0.00016000"],["62637.18000000","0.00009000"]],"asks":[["62640.00000000","2.37598000"],["62640.01000000","0.00115000"],["62640.02000000","0.00016000"],["62640.18000000","0.00068000"],["62640.95000000","0.00018000"],["62640.96000000","0.17302000"],["62640.97000000","0.17274000"],["62641.14000000","0.00018000"],["62641.15000000","0.07731000"],["62641.56000000","0.00009000"],["62641.98000000","0.00026000"],["62641.99000000","0.15754000"],["62642.00000000","0.03469000"],["62642.11000000","0.00010000"],["62642.25000000","0.00008000"],["62642.56000000","0.11271000"],["62642.72000000","0.00008000"],["62642.91000000","0.00032000"],["62643.09000000","0.00016000"],["62643.20000000","0.00008000"]]}}
{"t":14.7635,"stream":"btcusdt@depth@100ms","data":{"e":"depthUpdate","E":1783948017414,"s":"BTCUSDT","U":97344796410,"u":97344796418,"b":[["62520.44000000","0.09596000"],["56376.00000000","0.00477000"],["50112.00000000","0.00936000"]],"a":[]}}
{"t":14.7636,"stream":"btcusdt@depth20@100ms","data":{"lastUpdateId":97344796418,"bids":[["62639.99000000","2.92435000"],["62639.98000000","0.00528000"],["62639.97000000","0.00016000"],["62639.85000000","0.00008000"],["62639.83000000","0.00016000"],["62639.50000000","0.00018000"],["62639.49000000","0.22402000"],["62639.48000000","0.52743000"],["62639.06000000","0.00009000"],["62638.85000000","0.00008000"],["62638.42000000","0.00008000"],["62638.29000000","0.00400000"],["62638.11000000","0.00008000"],["62638.00000000","0.02418000"],["62637.99000000","0.00008000"],["62637.78000000","0.00018000"],["62637.77000000","0.14111000"],["62637.75000000","0.00008000"],["62637.55000000","0.00016000"],["62637.18000000","0.00009000"]],"asks":[["62640.00000000","2.37598000"],["62640.01000000","0.00115000"],["62640.02000000","0.00016000"],["62640.18000000","0.00068000"],["62640.95000000","0.00018000"],["62640.96000000","0.17302000"],["62640.97000000","0.17274000"],["62641.14000000","0.00018000"],["62641.15000000","0.07731000"],["62641.56000000","0.00009000"],["62641.98000000","0.00026000"],["62641.99000000","0.15754000"],["62642.00000000","0.03469000"],["62642.11000000","0.00010000"],["62642.25000000","0.00008000"],["62642.56000000","0.11271000"],["62642.72000000","0.00008000"],["62642.91000000","0.00032000"],["62643.09000000","0.00016000"],["62643.20000000","0.00008000"]]}}
{"t":14.8647,"stream":"btcusdt@depth@100ms","data":{"e":"depthUpdate","E":1783948017514,"s":"BTCUSDT","U":97344796419,"u":97344796434,"b":[["62639.99000000","2.97492000"],["62576.28000000","2.89959000"],["62569.95000000","0.00000000"],["56376.00000000","0.00477000"]],"a":[["62640.00000000","2.58650000"],["62677.28000000","0.00000000"],["62677.38000000","0.00011000"],["62758.47000000","0.00000000"],["62821.31000000","0.09550000"]]}}
{"t":14.8651,"stream":"btcusdt@depth20@100ms","data":{"lastUpdateId":97344796434,"bids":[["62639.99000000","2.97492000"],["62639.98000000","0.00528000"],["62639.97000000","0.00016000"],["62639.85000000","0.00008000"],["62639.83000000","0.00016000"],["62639.50000000","0.00018000"],["62639.49000000","0.22402000"],["62639.48000000","0.52743000"],["62639.06000000","0.00009000"],["62638.85000000","0.00008000"],["62638.42000000","0.00008000"],["62638.29000000","0.00400000"],["62638.11000000","0.00008000"],["62638.00000000","0.02418000"],["62637.99000000","0.00008000"],["62637.78000000","0.00018000"],["62637.77000000","0.14111000"],["62637.75000000","0.00008000"],["62637.55000000","0.00016000"],["62637.18000000","0.00009000"]],"asks":[["62640.00000000","2.58650000"],["62640.01000000","0.00115000"],["62640.02000000","0.00016000"],["62640.18000000","0.00068000"],["62640.95000000","0.00018000"],["62640.96000000","0.17302000"],["62640.97000000","0.17274000"],["62641.14000000","0.00018000"],["62641.15000000","0.07731000"],["62641.56000000","0.00009000"],["62641.98000000","0.00026000"],["62641.99000000","0.15754000"],["62642.00000000","0.03469000"],["62642.11000000","0.00010000"],["62642.25000000","0.00008000"],["62642.56000000","0.11271000"],["62642.72000000","0.00008000"],["62642.91000000","0.00032000"],["62643.09000000","0.00016000"],["62643.20000000","0.00008000"]]}}
{"t":14.9634,"stream":"btcusdt@depth@100ms","data":{"e":"depthUpdate","E":1783948017614,"s":"BTCUSDT","U":97344796435,"u":97344796462,"b":[["62637.19000000","0.00798000"],["62635.73000000","0.00798000"],["62634.61000000","0.00000000"],["56376.00000000","0.00477000"]],"a":[["62648.53000000","0.00798000"],["62648.77000000","0.00000000"],["62689.38000000","0.00000000"],["62689.99000000","0.00394000"],["62751.42000000","0.00159000"],["62753.69000000","0.00000000"],["62755.62000000","0.00159000"],["62757.30000000","0.00000000"]]}}
{"t":14.9662,"stream":"btcusdt@depth20@100ms","data":{"lastUpdateId":97344796462,"bids":[["62639.99000000","2.97492000"],["62639.98000000","0.00528000"],["62639.97000000","0.00016000"],["62639.85000000","0.00008000"],["62639.83000000","0.00016000"],["62639.50000000","0.00018000"],["62639.49000000","0.22402000"],["62639.48000000","0.52743000"],["62639.06000000","0.00009000"],["62638.85000000","0.00008000"],["62638.42000000","0.00008000"],["62638.29000000","0.00400000"],["62638.11000000","0.00008000"],["62638.00000000","0.02418000"],["62637.99000000","0.00008000"],["62637.78000000","0.00018000"],["62637.77000000","0.14111000"],["62637.75000000","0.00008000"],["62637.55000000","0.00016000"],["62637.19000000","0.00798000"]],"asks":[["62640.00000000","2.58650000"],["62640.01000000","0.00115000"],["62640.02000000","0.00016000"],["62640.18000000","0.00068000"],["62640.95000000","0.00018000"],["62640.96000000","0.17302000"],["62640.97000000","0.17274000"],["62641.14000000","0.00018000"],["62641.15000000","0.07731000"],["62641.56000000","0.00009000"],["62641.98000000","0.00026000"],["62641.99000000","0.15754000"],["62642.00000000","0.03469000"],["62642.11000000","0.00010000"],["62642.25000000","0.00008000"],["62642.56000000","0.11271000"],["62642.72000000","0.00008000"],["62642.91000000","0.00032000"],["62643.09000000","0.00016000"],["62643.20000000","0.00008000"]]}}
{"t":15.0637,"stream":"btcusdt@depth@100ms","data":{"e":"depthUpdate","E":1783948017714,"s":"BTCUSDT","U":97344796463,"u":97344796484,"b":[["62637.77000000","0.14111000"],["62637.19000000","0.00018000"],["62636.00000000","0.02400000"],["62625.97000000","0.00008000"],["61700.39000000","0.00030000"],["56376.00000000","0.00477000"]],"a":[["62648.53000000","0.00000000"],["62648.77000000","0.00000000"],["62651.04000000","0.00008000"],["62758.47000000","0.00000000"]]}}
{"t":15.0638,"stream":"btcusdt@depth20@100ms","data":{"lastUpdateId":97344796484,"bids":[["62639.99000000","2.97492000"],["62639.98000000","0.00528000"],["62639.97000000","0.00016000"],["62639.85000000","0.00008000"],["62639.83000000","0.00016000"],["62639.50000000","0.00018000"],["62639.49000000","0.22402000"],["62639.48000000","0.52743000"],["62639.06000000","0.00009000"],["62638.85000000","0.00008000"],["62638.42000000","0.00008000"],["62638.29000000","0.00400000"],["62638.11000000","0.00008000"],["62638.00000000","0.02418000"],["62637.99000000","0.00008000"],["62637.78000000","0.00018000"],["62637.77000000","0.14111000"],["62637.75000000","0.00008000"],["62637.55000000","0.00016000"],["62637.19000000","0.00018000"]],"asks":[["62640.00000000","2.58650000"],["62640.01000000","0.00115000"],["62640.02000000","0.00016000"],["62640.18000000","0.00068000"],["62640.95000000","0.00018000"],["62640.96000000","0.17302000"],["62640.97000000","0.17274000"],["62641.14000000","0.00018000"],["62641.15000000","0.07731000"],["62641.56000000","0.00009000"],["62641.98000000","0.00026000"],["62641.99000000","0.15754000"],["62642.00000000","0.03469000"],["62642.11000000","0.00010000"],["62642.25000000","0.00008000"],["62642.56000000","0.11271000"],["62642.72000000","0.00008000"],["62642.91000000","0.00032000"],["62643.09000000","0.00016000"],["62643.20000000","0.00008000"]]}}
{"t":15.1639,"stream":"btcusdt@depth@100ms","data":{"e":"depthUpdate","E":1783948017814,"s":"BTCUSDT","U":97344796485,"u":97344796502,"b":[["62637.77000000","0.14111000"],["62637.19000000","0.00000000"],["62636.66000000","0.14111000"],["56376.00000000","0.00477000"],["50111.99000000","0.00000000"]],"a":[["62758.47000000","0.00000000"]]}}
{"t":15.1641,"stream":"btcusdt@depth20@100ms","data":{"lastUpdateId":97344796502,"bids":[["62639.99000000","2.97492000"],["62639.98000000","0.00528000"],["62639.97000000","0.00016000"],["62639.85000000","0.00008000"],["62639.83000000","0.00016000"],["62639.50000000","0.00018000"],["62639.49000000","0.22402000"],["62639.48000000","0.52743000"],["62639.06000000","0.00009000"],["62638.85000000","0.00008000"],["62638.42000000","0.00008000"],["62638.29000000","0.00400000"],["62638.11000000","0.00008000"],["62638.00000000","0.02418000"],["62637.99000000","0.00008000"],["62637.78000000","0.00018000"],["62637.77000000","0.14111000"],["62637.75000000","0.00008000"],["62637.55000000","0.00016000"],["62637.18000000","0.00009000"]],"asks":[["62640.00000000","2.58650000"],["62640.01000000","0.00115000"],["62640.02000000","0.00016000"],["62640.18000000","0.00068000"],["62640.95000000","0.00018000"],["62640.96000000","0.17302000"],["62640.97000000","0.17274000"],["62641.14000000","0.00018000"],["62641.15000000","0.07731000"],["62641.56000000","0.00009000"],["62641.98000000","0.00026000"],["62641.99000000","0.15754000"],["62642.00000000","0.03469000"],["62642.11000000","0.00010000"],["62642.25000000","0.00008000"],["62642.56000000","0.11271000"],["62642.72000000","0.00008000"],["62642.91000000","0.00032000"],["62643.09000000","0.00016000"],["62643.20000000","0.00008000"]]}}
{"t":15.268,"stream":"btcusdt@depth@100ms","data":{"e":"depthUpdate","E":1783948017914,"s":"BTCUSDT","U":97344796503,"u":97344796515,"b":[["62639.99000000","2.97501000"],["56376.00000000","0.00477000"],["50111.99000000","0.00000000"]],"a":[["62640.00000000","2.09270000"],["62640.18000000","0.00000000"],["62640.35000000","0.00068000"],["62659.86000000","0.00000000"],["62662.72000000","0.00200000"],["62770.08000000","0.02500000"],["62778.82000000","0.00079000"]]}}
{"t":15.2682,"stream":"btcusdt@depth20@100ms","data":{"lastUpdateId":97344796515,"bids":[["62639.99000000","2.97501000"],["62639.98000000","0.00528000"],["62639.97000000","0.00016000"],["62639.85000000","0.00008000"],["62639.83000000","0.00016000"],["62639.50000000","0.00018000"],["62639.49000000","0.22402000"],["62639.48000000","0.52743000"],["62639.06000000","0.00009000"],["62638.85000000","0.00008000"],["62638.42000000","0.00008000"],["62638.29000000","0.00400000"],["62638.11000000","0.00008000"],["62638.00000000","0.02418000"],["62637.99000000","0.00008000"],["62637.78000000","0.00018000"],["62637.77000000","0.14111000"],["62637.75000000","0.00008000"],["62637.55000000","0.00016000"],["62637.18000000","0.00009000"]],"asks":[["62640.00000000","2.09270000"],["62640.01000000","0.00115000"],["62640.02000000","0.00016000"],["62640.35000000","0.00068000"],["62640.95000000","0.00018000"],["62640.96000000","0.17302000"],["62640.97000000","0.17274000"],["62641.14000000","0.00018000"],["62641.15000000","0.07731000"],["62641.56000000","0.00009000"],["62641.98000000","0.00026000"],["62641.99000000","0.15754000"],["62642.00000000","0.03469000"],["62642.11000000","0.00010000"],["62642.25000000","0.00008000"],["62642.56000000","0.11271000"],["62642.72000000","0.00008000"],["62642.91000000","0.00032000"],["62643.09000000","0.00016000"],["62643.20000000","0.00008000"]]}}
{"t":15.3285,"stream":"btcusdt@aggTrade","data":{"e":"aggTrade","E":1783948017977,"s":"BTCUSDT","a":4013160600,"p":"62640.00000000","q":"1.40333000","f":6501833791,"l":6501833832,"T":1783948017976,"m":false,"M":true}}
{"t":15.3322,"stream":"btcusdt@aggTrade","data":{"e":"aggTrade","E":1783948017980,"s":"BTCUSDT","a":4013160601,"p":"62640.00000000","q":"0.00296000","f":6501833833,"l":6501833866,"T":1783948017979,"m":false,"M":true}}
{"t":15.3323,"stream":"btcusdt@aggTrade","data":{"e":"aggTrade","E":1783948017980,"s":"BTCUSDT","a":4013160602,"p":"62640.01000000","q":"0.00106000","f":6501833867,"l":6501833877,"T":1783948017979,"m":false,"M":true}}
{"t":15.3336,"stream":"btcusdt@aggTrade","data":{"e":"aggTrade","E":1783948017983,"s":"BTCUSDT","a":4013160603,"p":"62640.02000000","q":"0.00147000","f":6501833878,"l":6501833893,"T":1783948017983,"m":false,"M":true}}
{"t":15.3337,"stream":"btcusdt@aggTrade","data":{"e":"aggTrade","E":1783948017983,"s":"BTCUSDT","a":4013160604,"p":"62640.03000000","q":"0.00063000","f":6501833894,"l":6501833900,"T":1783948017983,"m":false,"M":true}}
{"t":15.3337,"stream":"btcusdt@aggTrade","data":{"e":"aggTrade","E":1783948017983,"s":"BTCUSDT","a":4013160605,"p":"62640.95000000","q":"0.00027000","f":6501833901,"l":6501833903,"T":1783948017983,"m":false,"M":true}}
{"t":15.3353,"stream":"btcusdt@aggTrade","data":{"e":"aggTrade","E":1783948017984,"s":"BTCUSDT","a":4013160606,"p":"62640.96000000","q":"0.00061000","f":6501833904,"l":6501833910,"T":1783948017983,"m":false,"M":true}}
{"t":15.3354,"stream":"btcusdt@aggTrade","data":{"e":"aggTrade","E":1783948017984,"s":"BTCUSDT","a":4013160607,"p":"62640.97000000","q":"0.00034000","f":6501833911,"l":6501833914,"T":1783948017983,"m":false,"M":true}}
{"t":15.3354,"stream":"btcusdt@aggTrade","data":{"e":"aggTrade","E":1783948017984,"s":"BTCUSDT","a":4013160608,"p":"62641.14000000","q":"0.00027000","f":6501833915,"l":6501833917,"T":1783948017983,"m":false,"M":true}}
{"t":15.3354,"stream":"btcusdt@aggTrade","data":{"e":"aggTrade","E":1783948017984,"s":"BTCUSDT","a":4013160609,"p":"62641.15000000","q":"0.00278000","f":6501833918,"l":6501833918,"T":1783948017983,"m":false,"M":true}}
{"t":15.3646,"stream":"btcusdt@depth@100ms","data":{"e":"depthUpdate","E":1783948018014,"s":"BTCUSDT","U":97344796516,"u":97344797179,"b":[["62641.14000000","4.84788000"],["62641.13000000","0.00034000"],["62641.12000000","0.00016000"],["62640.97000000","0.59916000"],["62640.96000000","2.32746000"],["62640.95000000","0.85505000"],["62640.94000000","0.00000000"],["62640.90000000","0.00008000"],["62640.34000000","0.30006000"],["62640.03000000","0.00000000"],["62640.02000000","0.07500000"],["62640.01000000","0.49507000"],["62640.00000000","2.01658000"],["62639.99000000","0.75541000"],["62639.98000000","0.00467000"],["62639.97000000","0.00000000"],["62639.86000000","0.00400000"],["62639.50000000","0.00000000"],["62639.49000000","0.00018000"],["62639.48000000","0.00018000"],["62639.07000000","0.00000000"],["62639.06000000","0.00158000"],["62638.67000000","0.00032000"],["62638.49000000","0.03966000"],["62637.79000000","0.00000000"],["62637.78000000","0.00000000"],["62637.77000000","0.00018000"],["62637.58000000","0.00023000"],["62636.67000000","0.00000000"],["62636.66000000","0.00000000"],["62636.11000000","0.06678000"],["62636.00000000","0.02400000"],["62635.73000000","0.00000000"],["62635.59000000","0.00000000"],["62635.29000000","0.03000000"],["62634.41000000","0.00000000"],["62633.00000000","0.47600000"],["62630.74000000","0.00000000"],["62630.72000000","0.00000000"],["62630.00000000","0.06195000"],["62628.99000000","0.00000000"],["62628.56000000","0.00200000"],["62628.16000000","0.57528000"],["62628.09000000","0.00000000"],["62625.80000000","0.00200000"],["62625.12000000","0.00400000"],["62623.86000000","0.00000000"],["62622.28000000","0.00200000"],["62621.88000000","0.00000000"],["62620.39000000","0.00000000"],["62619.20000000","0.61533000"],["62617.83000000","0.00000000"],["62617.58000000","0.00000000"],["62616.86000000","0.00000000"],["62614.76000000","0.00000000"],["62614.74000000","0.00000000"],["62614.54000000","0.00000000"],["62613.80000000","0.00000000"],["62609.40000000","0.01000000"],["62601.51000000","0.42310000"],["62600.68000000","0.00000000"],["62600.07000000","0.00000000"],["62599.36000000","0.00000000"],["62595.90000000","0.10840000"],["62589.38000000","0.00000000"],["62565.16000000","3.59488000"],["62557.03000000","0.00000000"],["62552.62000000","0.00000000"],["62477.77000000","0.00010000"],["62399.57000000","0.02500000"],["62358.84000000","0.00000000"],["61700.39000000","0.00000000"],["56377.03000000","0.00020000"],["56376.00000000","0.00027000"],["50112.92000000","0.00039000"]],"a":[["62640.00000000","0.00000000"],["62640.01000000","0.00000000"],["62640.02000000","0.00000000"],["62640.03000000","0.00000000"],["62640.35000000","0.00000000"],["62640.71000000","0.00000000"],["62640.95000000","0.00000000"],["62640.96000000","0.00000000"],["62640.97000000","0.00000000"],["62641.14000000","0.00000000"],["62641.15000000","0.08393000"],["62641.16000000","0.00081000"],["62641.49000000","0.00000000"],["62641.98000000","0.00008000"],["62641.99000000","0.00067000"],["62642.56000000","0.00018000"],["62642.62000000","0.00000000"],["62643.42000000","0.00000000"],["62643.43000000","0.00018000"],["62643.99000000","0.00018000"],["62644.05000000","0.00000000"],["62644.11000000","0.00018000"],["62644.12000000","0.05424000"],["62644.13000000","0.01785000"],["62644.25000000","0.00018000"],["62644.26000000","0.01308000"],["62644.28000000","0.00009000"],["62644.29000000","0.07713000"],["62644.80000000","0.00000000"],["62644.96000000","0.00000000"],["62645.31000000","0.00000000"],["62646.14000000","0.00000000"],["62646.64000000","0.00000000"],["62646.67000000","0.00000000"],["62647.19000000","0.00000000"],["62647.20000000","0.00000000"],["62647.42000000","0.05144000"],["62647.59000000","0.14092000"],["62647.65000000","0.00000000"],["62648.37000000","0.00069000"],["62648.65000000","0.00047000"],["62648.86000000","0.03000000"],["62648.87000000","0.00000000"],["62648.88000000","0.13186000"],["62649.05000000","0.00000000"],["62649.12000000","0.00000000"],["62649.50000000","0.00000000"],["62649.52000000","0.00000000"],["62649.54000000","0.00000000"],["62650.27000000","0.02154000"],["62650.31000000","1.91755000"],["62650.32000000","0.14093000"],["62650.33000000","1.42747000"],["62650.35000000","0.59927000"],["62650.37000000","0.00000000"],["62650.74000000","0.00000000"],["62651.10000000","0.00000000"],["62651.37000000","0.00000000"],["62651.53000000","0.00000000"],["62651.60000000","0.00000000"],["62651.77000000","0.00000000"],["62652.74000000","0.01596000"],["62652.83000000","0.00000000"],["62652.96000000","1.91755000"],["62652.97000000","0.00000000"],["62653.49000000","0.00000000"],["62653.52000000","0.00000000"],["62653.53000000","0.00400000"],["62653.85000000","0.02000000"],["62653.98000000","0.00000000"],["62654.19000000","0.00000000"],["62654.26000000","0.00000000"],["62654.32000000","0.00000000"],["62654.36000000","0.19495000"],["62654.40000000","0.00000000"],["62654.89000000","0.00000000"],["62655.64000000","0.00000000"],["62655.88000000","0.00000000"],["62656.43000000","1.91755000"],["62656.44000000","1.14593000"],["62656.45000000","0.00000000"],["62656.60000000","0.00000000"],["62656.78000000","0.13448000"],["62657.83000000","0.29136000"],["62657.84000000","0.00000000"],["62658.04000000","0.00000000"],["62659.06000000","0.00000000"],["62659.13000000","0.00000000"],["62659.99000000","0.79888000"],["62660.05000000","0.00400000"],["62660.17000000","0.00200000"],["62661.55000000","0.00965000"],["62661.78000000","0.00000000"],["62662.72000000","0.00000000"],["62662.81000000","0.00000000"],["62662.86000000","0.00000000"],["62663.84000000","0.00000000"],["62664.85000000","0.02315000"],["62664.89000000","0.00000000"],["62664.92000000","0.00400000"],["62666.07000000","0.00200000"],["62669.85000000","0.57490000"],["62672.00000000","0.02408000"],["62673.00000000","0.01000000"],["62674.40000000","0.00400000"],["62674.96000000","0.00164000"],["62675.55000000","0.00008000"],["62678.70000000","0.00000000"],["62696.25000000","1.71321000"],["62696.26000000","3.19284000"],["62696.27000000","0.00000000"],["62702.68000000","0.00000000"],["62702.98000000","0.95863000"],["62704.30000000","1.91755000"],["62711.71000000","0.00000000"],["62713.40000000","0.00000000"],["62713.41000000","0.00000000"],["63579.60000000","0.00000000"]]}}
{"t":15.3651,"stream":"btcusdt@depth20@100ms","data":{"lastUpdateId":97344797179,"bids":[["62641.14000000","4.84788000"],["62641.13000000","0.00034000"],["62641.12000000","0.00016000"],["62640.97000000","0.59916000"],["62640.96000000","2.32746000"],["62640.95000000","0.85505000"],["62640.90000000","0.00008000"],["62640.34000000","0.30006000"],["62640.02000000","0.07500000"],["62640.01000000","0.49507000"],["62640.00000000","2.01658000"],["62639.99000000","0.75541000"],["62639.98000000","0.00467000"],["62639.86000000","0.00400000"],["62639.85000000","0.00008000"],["62639.83000000","0.00016000"],["62639.49000000","0.00018000"],["62639.48000000","0.00018000"],["62639.06000000","0.00158000"],["62638.85000000","0.00008000"]],"asks":[["62641.15000000","0.08393000"],["62641.16000000","0.00081000"],["62641.56000000","0.00009000"],["62641.98000000","0.00008000"],["62641.99000000","0.00067000"],["62642.00000000","0.03469000"],["62642.11000000","0.00010000"],["62642.25000000","0.00008000"],["62642.56000000","0.00018000"],["62642.72000000","0.00008000"],["62642.91000000","0.00032000"],["62643.09000000","0.00016000"],["62643.20000000","0.00008000"],["62643.43000000","0.00018000"],["62643.76000000","0.00008000"],["62643.97000000","0.00030000"],["62643.99000000","0.00018000"],["62644.00000000","0.02418000"],["62644.11000000","0.00018000"],["62644.12000000","0.05424000"]]}}
{"t":15.4646,"stream":"btcusdt@depth@100ms","data":{"e":"depthUpdate","E":1783948018114,"s":"BTCUSDT","U":97344797180,"u":97344797466,"b":[["62641.14000000","5.16497000"],["62640.98000000","0.47600000"],["62640.97000000","0.00018000"],["62640.96000000","0.00018000"],["62640.95000000","0.63005000"],["62640.61000000","0.00000000"],["62640.35000000","1.09017000"],["62640.34000000","0.30024000"],["62640.03000000","0.00000000"],["62640.02000000","0.07518000"],["62640.01000000","0.38529000"],["62639.99000000","0.75491000"],["62639.98000000","0.00449000"],["62639.85000000","0.00000000"],["62639.77000000","0.04073000"],["62639.49000000","0.00000000"],["62639.48000000","0.00000000"],["62638.85000000","0.00000000"],["62638.11000000","0.00000000"],["62638.00000000","0.02400000"],["62637.77000000","0.00000000"],["62636.89000000","0.00270000"],["62636.62000000","0.00000000"],["62636.28000000","0.59917000"],["62636.11000000","0.00016000"],["62635.82000000","0.00010000"],["62635.72000000","0.00000000"],["62635.39000000","0.00000000"],["62635.30000000","0.09806000"],["62634.40000000","0.00000000"],["62632.97000000","0.00000000"],["62631.88000000","0.57525000"],["62629.84000000","0.00000000"],["62626.71000000","0.22500000"],["62624.06000000","0.00000000"],["62622.15000000","0.00012000"],["62620.69000000","0.00000000"],["62620.08000000","0.00189000"],["62619.50000000","0.53353000"],["62615.19000000","0.64241000"],["62611.88000000","0.03130000"],["62610.59000000","0.00000000"],["62610.19000000","0.00000000"],["62609.27000000","0.40461000"],["62609.00000000","0.01000000"],["62608.77000000","0.00000000"],["62608.48000000","0.00000000"],["62608.00000000","0.02400000"],["62607.11000000","0.00000000"],["62596.47000000","0.00000000"],["62595.90000000","1.16630000"],["62595.79000000","0.00000000"],["62595.41000000","0.00435000"],["62585.23000000","0.00000000"],["62576.29000000","0.38467000"],["62520.44000000","0.00000000"],["62515.85000000","0.01000000"],["62476.82000000","0.00009000"],["62473.69000000","0.00134000"],["56377.03000000","0.00060000"],["40000.00000000","258.07540000"]],"a":[["62641.15000000","0.00921000"],["62641.16000000","0.00054000"],["62641.99000000","0.00041000"],["62642.00000000","0.03469000"],["62642.11000000","0.00000000"],["62642.56000000","0.00000000"],["62642.72000000","0.00000000"],["62643.43000000","0.00000000"],["62644.11000000","0.00000000"],["62644.12000000","0.00026000"],["62644.13000000","0.00018000"],["62644.25000000","0.00000000"],["62644.26000000","0.00018000"],["62644.28000000","0.00000000"],["62644.29000000","0.00026000"],["62644.63000000","0.00000000"],["62645.87000000","0.00018000"],["62645.99000000","0.00018000"],["62646.00000000","0.02418000"],["62646.29000000","0.00000000"],["62646.30000000","0.00000000"],["62647.41000000","0.00000000"],["62647.42000000","0.00016000"],["62647.58000000","0.00018000"],["62647.59000000","0.14101000"],["62647.60000000","0.12360000"],["62647.62000000","0.00000000"],["62647.71000000","0.00000000"],["62648.36000000","0.00048000"],["62648.52000000","0.00048000"],["62648.86000000","0.00000000"],["62649.01000000","0.00000000"],["62649.28000000","0.00000000"],["62649.88000000","0.00000000"],["62650.31000000","0.00000000"],["62650.33000000","0.59730000"],["62650.35000000","0.00009000"],["62650.55000000","0.00000000"],["62651.25000000","0.00000000"],["62651.47000000","0.00000000"],["62652.29000000","0.00000000"],["62652.73000000","0.00000000"],["62652.74000000","0.00000000"],["62652.83000000","0.00000000"],["62652.95000000","0.00000000"],["62652.96000000","0.00000000"],["62653.50000000","0.00000000"],["62653.53000000","0.00000000"],["62653.84000000","0.00798000"],["62653.85000000","0.00000000"],["62653.90000000","0.03858000"],["62654.36000000","0.07495000"],["62654.63000000","0.00400000"],["62655.07000000","0.07000000"],["62655.35000000","0.02000000"],["62655.93000000","0.00000000"],["62656.42000000","1.75436000"],["62656.43000000","1.91755000"],["62656.44000000","0.00000000"],["62656.78000000","0.00000000"],["62657.06000000","0.00000000"],["62657.14000000","0.00000000"],["62657.83000000","0.00000000"],["62657.94000000","0.13723000"],["62659.15000000","0.59914000"],["62659.99000000","0.00000000"],["62660.17000000","0.00000000"],["62660.77000000","0.17639000"],["62661.55000000","0.00000000"],["62661.81000000","0.00000000"],["62662.97000000","0.00200000"],["62664.40000000","0.79881000"],["62664.85000000","0.00000000"],["62664.92000000","0.00000000"],["62665.09000000","0.00000000"],["62665.13000000","0.00000000"],["62665.22000000","0.00000000"],["62666.02000000","0.02259000"],["62666.07000000","0.00000000"],["62667.98000000","0.00400000"],["62669.23000000","0.00200000"],["62669.36000000","0.00976000"],["62669.68000000","0.00000000"],["62670.36000000","0.00000000"],["62671.32000000","0.00000000"],["62671.40000000","0.00000000"],["62672.51000000","0.00000000"],["62673.04000000","0.57487000"],["62674.41000000","0.65541000"],["62674.79000000","0.00000000"],["62675.97000000","0.00400000"],["62677.54000000","0.00400000"],["62678.70000000","0.00008000"],["62680.07000000","0.00434000"],["62680.43000000","0.00431000"],["62685.67000000","0.00000000"],["62696.86000000","0.09283000"],["62700.81000000","0.03422000"],["62702.98000000","0.00000000"],["62703.70000000","0.00000000"],["62704.37000000","0.00000000"],["62704.41000000","0.95860000"],["62711.28000000","1.91755000"],["62711.29000000","0.35832000"],["62722.76000000","1.65930000"],["62724.28000000","3.59488000"],["62821.31000000","0.00000000"]]}}
{"t":15.465,"stream":"btcusdt@depth20@100ms","data":{"lastUpdateId":97344797466,"bids":[["62641.14000000","5.16497000"],["62641.13000000","0.00034000"],["62641.12000000","0.00016000"],["62640.98000000","0.47600000"],["62640.97000000","0.00018000"],["62640.96000000","0.00018000"],["62640.95000000","0.63005000"],["62640.90000000","0.00008000"],["62640.35000000","1.09017000"],["62640.34000000","0.30024000"],["62640.02000000","0.07518000"],["62640.01000000","0.38529000"],["62640.00000000","2.01658000"],["62639.99000000","0.75491000"],["62639.98000000","0.00449000"],["62639.86000000","0.00400000"],["62639.83000000","0.00016000"],["62639.77000000","0.04073000"],["62639.06000000","0.00158000"],["62638.67000000","0.00032000"]],"asks":[["62641.15000000","0.00921000"],["62641.16000000","0.00054000"],["62641.56000000","0.00009000"],["62641.98000000","0.00008000"],["62641.99000000","0.00041000"],["62642.00000000","0.03469000"],["62642.25000000","0.00008000"],["62642.91000000","0.00032000"],["62643.09000000","0.00016000"],["62643.20000000","0.00008000"],["62643.76000000","0.00008000"],["62643.97000000","0.00030000"],["62643.99000000","0.00018000"],["62644.00000000","0.02418000"],["62644.12000000","0.00026000"],["62644.13000000","0.00018000"],["62644.26000000","0.00018000"],["62644.29000000","0.00026000"],["62645.00000000","0.00008000"],["62645.47000000","0.00009000"]]}}
{"t":15.5035,"stream":"btcusdt@aggTrade","data":{"e":"aggTrade","E":1783948018152,"s":"BTCUSDT","a":4013160610,"p":"62641.15000000","q":"0.00400000","f":6501833919,"l":6501833930,"T":1783948018152,"m":false,"M":true}}
{"t":15.5645,"stream":"btcusdt@depth@100ms","data":{"e":"depthUpdate","E":1783948018214,"s":"BTCUSDT","U":97344797467,"u":97344797602,"b":[["62641.14000000","5.16498000"],["62640.98000000","0.00018000"],["62640.97000000","0.00000000"],["62640.96000000","0.00000000"],["62640.95000000","0.63005000"],["62640.35000000","1.09035000"],["62640.01000000","0.16029000"],["62640.00000000","2.01676000"],["62639.99000000","0.75499000"],["62637.37000000","0.06712000"],["62636.29000000","0.95364000"],["62636.28000000","0.59925000"],["62636.11000000","0.00008000"],["62635.59000000","0.47600000"],["62635.58000000","0.00000000"],["62634.23000000","0.06704000"],["62633.79000000","0.00000000"],["62633.00000000","0.00000000"],["62631.10000000","0.04469000"],["62627.97000000","0.04470000"],["62627.02000000","0.05000000"],["62622.52000000","0.00000000"],["62621.41000000","0.00060000"],["62613.40000000","0.01000000"],["62609.20000000","0.00000000"],["62607.15000000","0.00000000"],["62602.72000000","0.00424000"],["62602.08000000","0.00617000"],["62592.33000000","0.00000000"],["62592.24000000","0.01286000"],["62557.04000000","0.00000000"],["62550.00000000","6.60896000"],["62515.85000000","0.02000000"],["56377.03000000","0.00100000"],["50112.92000000","0.00000000"]],"a":[["62641.15000000","0.00616000"],["62641.16000000","0.00063000"],["62642.40000000","0.00018000"],["62642.41000000","0.07671000"],["62643.11000000","0.00068000"],["62643.44000000","0.00009000"],["62644.00000000","0.02418000"],["62644.12000000","0.00008000"],["62644.13000000","0.00000000"],["62644.26000000","0.00000000"],["62644.29000000","0.00008000"],["62645.54000000","0.00018000"],["62645.55000000","0.07671000"],["62645.87000000","0.00000000"],["62646.00000000","0.02418000"],["62647.58000000","0.15721000"],["62647.59000000","0.14118000"],["62647.60000000","0.00026000"],["62647.80000000","0.00574000"],["62648.00000000","0.02418000"],["62648.68000000","0.05109000"],["62648.88000000","0.13212000"],["62649.80000000","0.09911000"],["62650.33000000","1.18199000"],["62651.58000000","0.00000000"],["62651.81000000","0.05109000"],["62652.97000000","2.05596000"],["62653.50000000","0.00008000"],["62655.48000000","0.00000000"],["62657.94000000","0.00000000"],["62661.54000000","0.00000000"],["62666.02000000","0.00000000"],["62666.77000000","0.00012000"],["62667.70000000","0.00000000"],["62673.09000000","0.00000000"],["62680.46000000","0.00631000"],["62680.85000000","0.00425000"],["62704.41000000","0.00000000"],["62735.68000000","0.00000000"],["62735.69000000","0.00000000"],["63580.77000000","0.00030000"]]}}
{"t":15.5648,"stream":"btcusdt@depth20@100ms","data":{"lastUpdateId":97344797602,"bids":[["62641.14000000","5.16498000"],["62641.13000000","0.00034000"],["62641.12000000","0.00016000"],["62640.98000000","0.00018000"],["62640.95000000","0.63005000"],["62640.90000000","0.00008000"],["62640.35000000","1.09035000"],["62640.34000000","0.30024000"],["62640.02000000","0.07518000"],["62640.01000000","0.16029000"],["62640.00000000","2.01676000"],["62639.99000000","0.75499000"],["62639.98000000","0.00449000"],["62639.86000000","0.00400000"],["62639.83000000","0.00016000"],["62639.77000000","0.04073000"],["62639.06000000","0.00158000"],["62638.67000000","0.00032000"],["62638.49000000","0.03966000"],["62638.42000000","0.00008000"]],"asks":[["62641.15000000","0.00616000"],["62641.16000000","0.00063000"],["62641.56000000","0.00009000"],["62641.98000000","0.00008000"],["62641.99000000","0.00041000"],["62642.00000000","0.03469000"],["62642.25000000","0.00008000"],["62642.40000000","0.00018000"],["62642.41000000","0.07671000"],["62642.91000000","0.00032000"],["62643.09000000","0.00016000"],["62643.11000000","0.00068000"],["62643.20000000","0.00008000"],["62643.44000000","0.00009000"],["62643.76000000","0.00008000"],["62643.97000000","0.00030000"],["62643.99000000","0.00018000"],["62644.00000000","0.02418000"],["62644.12000000","0.00008000"],["62644.29000000","0.00008000"]]}}
{"t":15.6638,"stream":"btcusdt@depth@100ms","data":{"e":"depthUpdate","E":1783948018314,"s":"BTCUSDT","U":97344797603,"u":97344797674,"b":[["62641.14000000","5.16517000"],["62640.98000000","0.00000000"],["62640.32000000","0.00009000"],["62639.99000000","0.75517000"],["62627.02000000","0.00000000"],["62615.19000000","0.99123000"],["62614.54000000","1.20739000"],["62613.72000000","0.00000000"],["62613.09000000","0.24902000"],["62581.15000000","0.00000000"],["62551.00000000","0.05145000"],["62391.73000000","0.00710000"],["62389.86000000","0.00000000"],["56377.03000000","0.00140000"]],"a":[["62642.00000000","0.03469000"],["62642.41000000","0.07689000"],["62644.00000000","0.02418000"],["62645.44000000","0.00032000"],["62645.55000000","0.07689000"],["62646.00000000","0.02418000"],["62647.58000000","0.21827000"],["62647.59000000","0.14118000"],["62647.60000000","0.00008000"],["62647.94000000","0.00000000"],["62648.00000000","0.02400000"],["62648.88000000","0.13194000"],["62649.29000000","0.00000000"],["62650.33000000","1.18190000"],["62651.46000000","0.00000000"],["62652.84000000","0.00000000"],["62655.65000000","0.00188000"],["62667.97000000","0.00000000"],["62670.90000000","0.00000000"],["62681.85000000","0.00000000"],["62682.22000000","1.20609000"],["62736.97000000","0.00000000"],["62738.95000000","0.05272000"],["62744.99000000","0.02500000"],["62770.08000000","0.00000000"],["62786.19000000","0.00318000"],["62791.56000000","0.02500000"]]}}
{"t":15.6641,"stream":"btcusdt@depth20@100ms","data":{"lastUpdateId":97344797674,"bids":[["62641.14000000","5.16517000"],["62641.13000000","0.00034000"],["62641.12000000","0.00016000"],["62640.95000000","0.63005000"],["62640.90000000","0.00008000"],["62640.35000000","1.09035000"],["62640.34000000","0.30024000"],["62640.32000000","0.00009000"],["62640.02000000","0.07518000"],["62640.01000000","0.16029000"],["62640.00000000","2.01676000"],["62639.99000000","0.75517000"],["62639.98000000","0.00449000"],["62639.86000000","0.00400000"],["62639.83000000","0.00016000"],["62639.77000000","0.04073000"],["62639.06000000","0.00158000"],["62638.67000000","0.00032000"],["62638.49000000","0.03966000"],["62638.42000000","0.00008000"]],"asks":[["62641.15000000","0.00616000"],["62641.16000000","0.00063000"],["62641.56000000","0.00009000"],["62641.98000000","0.00008000"],["62641.99000000","0.00041000"],["62642.00000000","0.03469000"],["62642.25000000","0.00008000"],["62642.40000000","0.00018000"],["62642.41000000","0.07689000"],["62642.91000000","0.00032000"],["62643.09000000","0.00016000"],["62643.11000000","0.00068000"],["62643.20000000","0.00008000"],["62643.44000000","0.00009000"],["62643.76000000","0.00008000"],["62643.97000000","0.00030000"],["62643.99000000","0.00018000"],["62644.00000000","0.02418000"],["62644.12000000","0.00008000"],["62644.29000000","0.00008000"]]}}
{"t":15.7635,"stream":"btcusdt@depth@100ms","data":{"e":"depthUpdate","E":1783948018414,"s":"BTCUSDT","U":97344797675,"u":97344797689,"b":[["62640.02000000","0.07685000"],["62639.06000000","0.00009000"],["62629.02000000","0.05000000"],["62613.09000000","0.00000000"],["62611.38000000","0.24752000"],["62610.79000000","0.24753000"],["62599.35000000","0.00000000"],["62576.29000000","0.00000000"],["62516.71000000","0.02513000"],["62500.01000000","0.07450000"],["62496.98000000","0.00000000"],["56377.03000000","0.00180000"],["56377.00000000","0.02184000"]],"a":[["62711.36000000","0.95855000"],["62791.56000000","0.00000000"]]}}
{"t":15.7636,"stream":"btcusdt@depth20@100ms","data":{"lastUpdateId":97344797689,"bids":[["62641.14000000","5.16517000"],["62641.13000000","0.00034000"],["62641.12000000","0.00016000"],["62640.95000000","0.63005000"],["62640.90000000","0.00008000"],["62640.35000000","1.09035000"],["62640.34000000","0.30024000"],["62640.32000000","0.00009000"],["62640.02000000","0.07685000"],["62640.01000000","0.16029000"],["62640.00000000","2.01676000"],["62639.99000000","0.75517000"],["62639.98000000","0.00449000"],["62639.86000000","0.00400000"],["62639.83000000","0.00016000"],["62639.77000000","0.04073000"],["62639.06000000","0.00009000"],["62638.67000000","0.00032000"],["62638.49000000","0.03966000"],["62638.42000000","0.00008000"]],"asks":[["62641.15000000","0.00616000"],["62641.16000000","0.00063000"],["62641.56000000","0.00009000"],["62641.98000000","0.00008000"],["62641.99000000","0.00041000"],["62642.00000000","0.03469000"],["62642.25000000","0.00008000"],["62642.40000000","0.00018000"],["62642.41000000","0.07689000"],["62642.91000000","0.00032000"],["62643.09000000","0.00016000"],["62643.11000000","0.00068000"],["62643.20000000","0.00008000"],["62643.44000000","0.00009000"],["62643.76000000","0.00008000"],["62643.97000000","0.00030000"],["62643.99000000","0.00018000"],["62644.00000000","0.02418000"],["62644.12000000","0.00008000"],["62644.29000000","0.00008000"]]}}
{"t":15.8647,"stream":"btcusdt@depth@100ms","data":{"e":"depthUpdate","E":1783948018514,"s":"BTCUSDT","U":97344797690,"u":97344797709,"b":[["62641.14000000","5.16517000"],["62632.91000000","0.21981000"],["62076.23000000","0.00000000"],["56377.03000000","0.00220000"],["56377.00000000","0.02164000"]],"a":[["62647.58000000","0.18632000"],["62650.33000000","0.59721000"],["62650.85000000","0.00000000"],["62652.87000000","0.01260000"],["62652.97000000","0.13841000"],["62656.01000000","0.01268000"],["62659.15000000","0.61166000"],["62661.80000000","0.57498000"],["62662.29000000","0.01274000"],["62665.43000000","0.01277000"],["62679.11000000","0.00400000"]]}}
{"t":15.865,"stream":"btcusdt@depth20@100ms","data":{"lastUpdateId":97344797709,"bids":[["62641.14000000","5.16517000"],["62641.13000000","0.00034000"],["62641.12000000","0.00016000"],["62640.95000000","0.63005000"],["62640.90000000","0.00008000"],["62640.35000000","1.09035000"],["62640.34000000","0.30024000"],["62640.32000000","0.00009000"],["62640.02000000","0.07685000"],["62640.01000000","0.16029000"],["62640.00000000","2.01676000"],["62639.99000000","0.75517000"],["62639.98000000","0.00449000"],["62639.86000000","0.00400000"],["62639.83000000","0.00016000"],["62639.77000000","0.04073000"],["62639.06000000","0.00009000"],["62638.67000000","0.00032000"],["62638.49000000","0.03966000"],["62638.42000000","0.00008000"]],"asks":[["62641.15000000","0.00616000"],["62641.16000000","0.00063000"],["62641.56000000","0.00009000"],["62641.98000000","0.00008000"],["62641.99000000","0.00041000"],["62642.00000000","0.03469000"],["62642.25000000","0.00008000"],["62642.40000000","0.00018000"],["62642.41000000","0.07689000"],["62642.91000000","0.00032000"],["62643.09000000","0.00016000"],["62643.11000000","0.00068000"],["62643.20000000","0.00008000"],["62643.44000000","0.00009000"],["62643.76000000","0.00008000"],["62643.97000000","0.00030000"],["62643.99000000","0.00018000"],["62644.00000000","0.02418000"],["62644.12000000","0.00008000"],["62644.29000000","0.00008000"]]}}
{"t":15.9631,"stream":"btcusdt@depth@100ms","data":{"e":"depthUpdate","E":1783948018614,"s":"BTCUSDT","U":97344797710,"u":97344797723,"b":[["62627.78000000","0.00000000"],["62608.30000000","0.00015000"],["62589.83000000","0.95855000"],["56377.03000000","0.00240000"]],"a":[["62641.15000000","0.00625000"],["62641.16000000","0.00072000"],["62645.55000000","0.07697000"],["62646.80000000","0.17256000"],["62650.35000000","0.00017000"],["62667.90000000","0.00419000"],["62668.85000000","0.00015000"],["62744.99000000","0.00000000"],["62756.97000000","0.00000000"]]}}
{"t":15.9642,"stream":"btcusdt@depth20@100ms","data":{"lastUpdateId":97344797723,"bids":[["62641.14000000","5.16517000"],["62641.13000000","0.00034000"],["62641.12000000","0.00016000"],["62640.95000000","0.63005000"],["62640.90000000","0.00008000"],["62640.35000000","1.09035000"],["62640.34000000","0.30024000"],["62640.32000000","0.00009000"],["62640.02000000","0.07685000"],["62640.01000000","0.16029000"],["62640.00000000","2.01676000"],["62639.99000000","0.75517000"],["62639.98000000","0.00449000"],["62639.86000000","0.00400000"],["62639.83000000","0.00016000"],["62639.77000000","0.04073000"],["62639.06000000","0.00009000"],["62638.67000000","0.00032000"],["62638.49000000","0.03966000"],["62638.42000000","0.00008000"]],"asks":[["62641.15000000","0.00625000"],["62641.16000000","0.00072000"],["62641.56000000","0.00009000"],["62641.98000000","0.00008000"],["62641.99000000","0.00041000"],["62642.00000000","0.03469000"],["62642.25000000","0.00008000"],["62642.40000000","0.00018000"],["62642.41000000","0.07689000"],["62642.91000000","0.00032000"],["62643.09000000","0.00016000"],["62643.11000000","0.00068000"],["62643.20000000","0.00008000"],["62643.44000000","0.00009000"],["62643.76000000","0.00008000"],["62643.97000000","0.00030000"],["62643.99000000","0.00018000"],["62644.00000000","0.02418000"],["62644.12000000","0.00008000"],["62644.29000000","0.00008000"]]}}
{"t":16.064,"stream":"btcusdt@depth@100ms","data":{"e":"depthUpdate","E":1783948018714,"s":"BTCUSDT","U":97344797724,"u":97344797742,"b":[["62638.67000000","0.00000000"],["62627.12000000","0.00008000"],["62625.97000000","0.00000000"],["58057.01000000","0.00000000"],["56377.03000000","0.00280000"]],"a":[["62646.00000000","0.02418000"],["62646.80000000","0.17274000"],["62647.80000000","0.00556000"],["62648.72000000","0.09748000"],["62649.80000000","0.00000000"],["62651.04000000","0.00000000"],["62652.19000000","0.00008000"],["62659.28000000","0.13557000"],["62667.35000000","0.02286000"]]}}
{"t":16.0642,"stream":"btcusdt@depth20@100ms","data":{"lastUpdateId":97344797742,"bids":[["62641.14000000","5.16517000"],["62641.13000000","0.00034000"],["62641.12000000","0.00016000"],["62640.95000000","0.63005000"],["62640.90000000","0.00008000"],["62640.35000000","1.09035000"],["62640.34000000","0.30024000"],["62640.32000000","0.00009000"],["62640.02000000","0.07685000"],["62640.01000000","0.16029000"],["62640.00000000","2.01676000"],["62639.99000000","0.75517000"],["62639.98000000","0.00449000"],["62639.86000000","0.00400000"],["62639.83000000","0.00016000"],["62639.77000000","0.04073000"],["62639.06000000","0.00009000"],["62638.49000000","0.03966000"],["62638.42000000","0.00008000"],["62638.29000000","0.00400000"]],"asks":[["62641.15000000","0.00625000"],["62641.16000000","0.00072000"],["62641.56000000","0.00009000"],["62641.98000000","0.00008000"],["62641.99000000","0.00041000"],["62642.00000000","0.03469000"],["62642.25000000","0.00008000"],["62642.40000000","0.00018000"],["62642.41000000","0.07689000"],["62642.91000000","0.00032000"],["62643.09000000","0.00016000"],["62643.11000000","0.00068000"],["62643.20000000","0.00008000"],["62643.44000000","0.00009000"],["62643.76000000","0.00008000"],["62643.97000000","0.00030000"],["62643.99000000","0.00018000"],["62644.00000000","0.02418000"],["62644.12000000","0.00008000"],["62644.29000000","0.00008000"]]}}
{"t":16.1636,"stream":"btcusdt@depth@100ms","data":{"e":"depthUpdate","E":1783948018814,"s":"BTCUSDT","U":97344797743,"u":97344797752,"b":[["62628.21000000","0.56649000"],["56377.03000000","0.00320000"]],"a":[["62648.72000000","0.00000000"],["62650.33000000","0.59730000"],["62651.49000000","0.01741000"],["62669.65000000","0.04000000"],["62672.78000000","0.01200000"],["62702.64000000","0.00000000"]]}}
{"t":16.1638,"stream":"btcusdt@depth20@100ms","data":{"lastUpdateId":97344797752,"bids":[["62641.14000000","5.16517000"],["62641.13000000","0.00034000"],["62641.12000000","0.00016000"],["62640.95000000","0.63005000"],["62640.90000000","0.00008000"],["62640.35000000","1.09035000"],["62640.34000000","0.30024000"],["62640.32000000","0.00009000"],["62640.02000000","0.07685000"],["62640.01000000","0.16029000"],["62640.00000000","2.01676000"],["62639.99000000","0.75517000"],["62639.98000000","0.00449000"],["62639.86000000","0.00400000"],["62639.83000000","0.00016000"],["62639.77000000","0.04073000"],["62639.06000000","0.00009000"],["62638.49000000","0.03966000"],["62638.42000000","0.00008000"],["62638.29000000","0.00400000"]],"asks":[["62641.15000000","0.00625000"],["62641.16000000","0.00072000"],["62641.56000000","0.00009000"],["62641.98000000","0.00008000"],["62641.99000000","0.00041000"],["62642.00000000","0.03469000"],["62642.25000000","0.00008000"],["62642.40000000","0.00018000"],["62642.41000000","0.07689000"],["62642.91000000","0.00032000"],["62643.09000000","0.00016000"],["62643.11000000","0.00068000"],["62643.20000000","0.00008000"],["62643.44000000","0.00009000"],["62643.76000000","0.00008000"],["62643.97000000","0.00030000"],["62643.99000000","0.00018000"],["62644.00000000","0.02418000"],["62644.12000000","0.00008000"],["62644.29000000","0.00008000"]]}}
{"t":16.2652,"stream":"btcusdt@depth@100ms","data":{"e":"depthUpdate","E":1783948018914,"s":"BTCUSDT","U":97344797753,"u":97344797764,"b":[["62639.06000000","0.00000000"],["62616.50000000","0.01000000"],["62614.57000000","0.17202000"],["62613.40000000","0.00000000"],["62610.79000000","0.00000000"],["56377.03000000","0.00360000"],["50112.91000000","0.00000000"]],"a":[["62642.19000000","0.00009000"],["62700.81000000","0.00000000"],["62702.65000000","0.00000000"]]}}
{"t":16.2655,"stream":"btcusdt@depth20@100ms","data":{"lastUpdateId":97344797764,"bids":[["62641.14000000","5.16517000"],["62641.13000000","0.00034000"],["62641.12000000","0.00016000"],["62640.95000000","0.63005000"],["62640.90000000","0.00008000"],["62640.35000000","1.09035000"],["62640.34000000","0.30024000"],["62640.32000000","0.00009000"],["62640.02000000","0.07685000"],["62640.01000000","0.16029000"],["62640.00000000","2.01676000"],["62639.99000000","0.75517000"],["62639.98000000","0.00449000"],["62639.86000000","0.00400000"],["62639.83000000","0.00016000"],["62639.77000000","0.04073000"],["62638.49000000","0.03966000"],["62638.42000000","0.00008000"],["62638.29000000","0.00400000"],["62638.00000000","0.02400000"]],"asks":[["62641.15000000","0.00625000"],["62641.16000000","0.00072000"],["62641.56000000","0.00009000"],["62641.98000000","0.00008000"],["62641.99000000","0.00041000"],["62642.00000000","0.03469000"],["62642.19000000","0.00009000"],["62642.25000000","0.00008000"],["62642.40000000","0.00018000"],["62642.41000000","0.07689000"],["62642.91000000","0.00032000"],["62643.09000000","0.00016000"],["62643.11000000","0.00068000"],["62643.20000000","0.00008000"],["62643.44000000","0.00009000"],["62643.76000000","0.00008000"],["62643.97000000","0.00030000"],["62643.99000000","0.00018000"],["62644.00000000","0.02418000"],["62644.12000000","0.00008000"]]}}
{"t":16.3648,"stream":"btcusdt@depth@100ms","data":{"e":"depthUpdate","E":1783948019014,"s":"BTCUSDT","U":97344797765,"u":97344797791,"b":[["62641.14000000","4.00655000"],["62640.35000000","0.00018000"],["62637.37000000","0.06704000"],["62636.29000000","0.00000000"],["62635.59000000","0.47608000"],["62632.98000000","0.00000000"],["62630.09000000","0.00000000"],["62627.25000000","0.00000000"],["62624.04000000","0.00000000"],["62621.69000000","0.00000000"],["62617.63000000","0.00000000"],["62615.19000000","0.00000000"],["62614.57000000","0.00000000"],["61701.52000000","0.00030000"],["56377.03000000","0.00400000"],["50112.92000000","0.00039000"],["50112.91000000","0.00000000"]],"a":[["62647.58000000","0.00018000"],["62648.85000000","0.09555000"]]}}
{"t":16.365,"stream":"btcusdt@depth20@100ms","data":{"lastUpdateId":97344797791,"bids":[["62641.14000000","4.00655000"],["62641.13000000","0.00034000"],["62641.12000000","0.00016000"],["62640.95000000","0.63005000"],["62640.90000000","0.00008000"],["62640.35000000","0.00018000"],["62640.34000000","0.30024000"],["62640.32000000","0.00009000"],["62640.02000000","0.07685000"],["62640.01000000","0.16029000"],["62640.00000000","2.01676000"],["62639.99000000","0.75517000"],["62639.98000000","0.00449000"],["62639.86000000","0.00400000"],["62639.83000000","0.00016000"],["62639.77000000","0.04073000"],["62638.49000000","0.03966000"],["62638.42000000","0.00008000"],["62638.29000000","0.00400000"],["62638.00000000","0.02400000"]],"asks":[["62641.15000000","0.00625000"],["62641.16000000","0.00072000"],["62641.56000000","0.00009000"],["62641.98000000","0.00008000"],["62641.99000000","0.00041000"],["62642.00000000","0.03469000"],["62642.19000000","0.00009000"],["62642.25000000","0.00008000"],["62642.40000000","0.00018000"],["62642.41000000","0.07689000"],["62642.91000000","0.00032000"],["62643.09000000","0.00016000"],["62643.11000000","0.00068000"],["62643.20000000","0.00008000"],["62643.44000000","0.00009000"],["62643.76000000","0.00008000"],["62643.97000000","0.00030000"],["62643.99000000","0.00018000"],["62644.00000000","0.02418000"],["62644.12000000","0.00008000"]]}}
{"t":16.449,"stream":"btcusdt@aggTrade","data":{"e":"aggTrade","E":1783948019098,"s":"BTCUSDT","a":4013160611,"p":"62641.15000000","q":"0.00082000","f":6501833931,"l":6501833931,"T":1783948019098,"m":false,"M":true}}
{"t":16.4638,"stream":"btcusdt@depth@100ms","data":{"e":"depthUpdate","E":1783948019114,"s":"BTCUSDT","U":97344797792,"u":97344797861,"b":[["62641.14000000","4.01964000"],["62640.95000000","0.63005000"],["62640.35000000","0.00000000"],["62640.02000000","0.07518000"],["62640.01000000","0.16187000"],["62639.77000000","0.04091000"],["62628.21000000","0.00000000"],["62618.18000000","0.00000000"],["62611.88000000","0.28933000"],["62611.05000000","0.00000000"],["62449.09000000","0.00000000"],["62415.07000000","0.01933000"],["56377.03000000","0.00440000"],["56376.00000000","0.00017000"],["56375.99000000","0.00010000"],["50113.00000000","0.00193000"],["40000.00000000","258.07540000"]],"a":[["62641.15000000","0.00552000"],["62641.16000000","0.00081000"],["62645.55000000","0.07697000"],["62646.57000000","0.09534000"],["62646.80000000","0.17274000"],["62647.58000000","0.00000000"],["62647.59000000","0.14118000"],["62647.80000000","0.00574000"],["62648.10000000","0.00000000"],["62648.85000000","0.00000000"],["62650.33000000","0.00009000"],["62652.25000000","0.14093000"],["62652.96000000","1.91755000"],["62654.36000000","0.00000000"],["62656.41000000","0.14093000"],["62656.42000000","0.00000000"],["62660.16000000","0.00000000"],["62664.49000000","0.00000000"],["62666.84000000","0.00000000"],["62669.17000000","0.00000000"],["62674.41000000","0.00000000"],["62677.64000000","0.00000000"],["62678.56000000","0.00000000"],["62684.13000000","0.00000000"],["62684.66000000","0.00000000"],["62687.89000000","0.00000000"],["62691.66000000","0.00000000"],["62696.25000000","0.00000000"],["62697.07000000","0.00000000"],["62705.70000000","0.00000000"],["62708.28000000","0.00000000"],["62711.29000000","0.00000000"],["62716.28000000","0.00000000"],["62717.66000000","0.00000000"],["62718.82000000","0.00030000"]]}}
{"t":16.4642,"stream":"btcusdt@depth20@100ms","data":{"lastUpdateId":97344797861,"bids":[["62641.14000000","4.01964000"],["62641.13000000","0.00034000"],["62641.12000000","0.00016000"],["62640.95000000","0.63005000"],["62640.90000000","0.00008000"],["62640.34000000","0.30024000"],["62640.32000000","0.00009000"],["62640.02000000","0.07518000"],["62640.01000000","0.16187000"],["62640.00000000","2.01676000"],["62639.99000000","0.75517000"],["62639.98000000","0.00449000"],["62639.86000000","0.00400000"],["62639.83000000","0.00016000"],["62639.77000000","0.04091000"],["62638.49000000","0.03966000"],["62638.42000000","0.00008000"],["62638.29000000","0.00400000"],["62638.00000000","0.02400000"],["62637.99000000","0.00008000"]],"asks":[["62641.15000000","0.00552000"],["62641.16000000","0.00081000"],["62641.56000000","0.00009000"],["62641.98000000","0.00008000"],["62641.99000000","0.00041000"],["62642.00000000","0.03469000"],["62642.19000000","0.00009000"],["62642.25000000","0.00008000"],["62642.40000000","0.00018000"],["62642.41000000","0.07689000"],["62642.91000000","0.00032000"],["62643.09000000","0.00016000"],["62643.11000000","0.00068000"],["62643.20000000","0.00008000"],["62643.44000000","0.00009000"],["62643.76000000","0.00008000"],["62643.97000000","0.00030000"],["62643.99000000","0.00018000"],["62644.00000000","0.02418000"],["62644.12000000","0.00008000"]]}}
{"t":16.5643,"stream":"btcusdt@depth@100ms","data":{"e":"depthUpdate","E":1783948019214,"s":"BTCUSDT","U":97344797862,"u":97344797963,"b":[["62641.14000000","3.88502000"],["62640.03000000","0.00000000"],["62640.02000000","0.00018000"],["62640.01000000","0.00500000"],["62640.00000000","1.91781000"],["62639.99000000","0.59576000"],["62638.50000000","0.00798000"],["62634.87000000","0.00400000"],["62633.72000000","0.22500000"],["62633.27000000","0.00400000"],["62633.17000000","0.00000000"],["62633.16000000","0.00000000"],["62631.88000000","0.00000000"],["62630.00000000","0.05795000"],["62627.00000000","0.00400000"],["62626.90000000","0.00000000"],["62625.12000000","0.00000000"],["62616.29000000","0.57539000"],["62607.27000000","0.00000000"],["62605.92000000","0.00000000"],["62601.51000000","0.00000000"],["62595.90000000","0.00000000"],["62589.83000000","0.00000000"],["62588.93000000","0.00000000"],["62588.27000000","0.00000000"],["62588.01000000","0.00397000"],["62587.57000000","0.95855000"],["62587.34000000","0.00000000"],["62584.01000000","0.00396000"],["62582.69000000","0.00000000"],["62525.82000000","0.00159000"],["62524.43000000","0.00000000"],["56377.03000000","0.00460000"],["50112.92000000","0.00000000"]],"a":[["62641.15000000","0.82153000"],["62641.16000000","0.00081000"],["62642.43000000","0.00068000"],["62642.52000000","0.00000000"],["62643.11000000","0.00000000"],["62644.53000000","0.00000000"],["62645.55000000","0.07705000"],["62645.88000000","0.00009000"],["62645.89000000","0.11685000"],["62645.99000000","0.00009000"],["62646.00000000","0.02418000"],["62646.56000000","0.13013000"],["62646.57000000","0.00018000"],["62646.80000000","0.00018000"],["62647.20000000","0.00008000"],["62647.80000000","0.00556000"],["62648.88000000","0.13186000"],["62651.48000000","0.00798000"],["62652.94000000","0.14093000"],["62652.95000000","0.47600000"],["62652.97000000","0.00000000"],["62653.84000000","0.00000000"],["62656.41000000","0.00000000"],["62659.30000000","0.57500000"],["62668.12000000","0.00400000"],["62669.85000000","0.00000000"],["62678.70000000","0.00000000"],["62679.11000000","0.00000000"],["62692.81000000","0.00000000"],["62693.83000000","0.00399000"],["62705.79000000","0.00000000"],["62751.42000000","0.00000000"],["62753.69000000","0.00159000"],["62755.62000000","0.00000000"],["62756.60000000","0.00159000"],["62763.35000000","0.00000000"],["63580.77000000","0.00030000"]]}}
{"t":16.5647,"stream":"btcusdt@depth20@100ms","data":{"lastUpdateId":97344797963,"bids":[["62641.14000000","3.88502000"],["62641.13000000","0.00034000"],["62641.12000000","0.00016000"],["62640.95000000","0.63005000"],["62640.90000000","0.00008000"],["62640.34000000","0.30024000"],["62640.32000000","0.00009000"],["62640.02000000","0.00018000"],["62640.01000000","0.00500000"],["62640.00000000","1.91781000"],["62639.99000000","0.59576000"],["62639.98000000","0.00449000"],["62639.86000000","0.00400000"],["62639.83000000","0.00016000"],["62639.77000000","0.04091000"],["62638.50000000","0.00798000"],["62638.49000000","0.03966000"],["62638.42000000","0.00008000"],["62638.29000000","0.00400000"],["62638.00000000","0.02400000"]],"asks":[["62641.15000000","0.82153000"],["62641.16000000","0.00081000"],["62641.56000000","0.00009000"],["62641.98000000","0.00008000"],["62641.99000000","0.00041000"],["62642.00000000","0.03469000"],["62642.19000000","0.00009000"],["62642.25000000","0.00008000"],["62642.40000000","0.00018000"],["62642.41000000","0.07689000"],["62642.43000000","0.00068000"],["62642.91000000","0.00032000"],["62643.09000000","0.00016000"],["62643.20000000","0.00008000"],["62643.44000000","0.00009000"],["62643.76000000","0.00008000"],["62643.97000000","0.00030000"],["62643.99000000","0.00018000"],["62644.00000000","0.02418000"],["62644.12000000","0.00008000"]]}}
{"t":16.6638,"stream":"btcusdt@depth@100ms","data":{"e":"depthUpdate","E":1783948019314,"s":"BTCUSDT","U":97344797964,"u":97344798029,"b":[["62641.14000000","3.96170000"],["62640.34000000","0.30016000"],["62640.02000000","0.00000000"],["62639.77000000","0.04091000"],["62638.50000000","0.00816000"],["62638.44000000","0.00009000"],["62636.89000000","0.00000000"],["62626.29000000","0.00270000"],["62607.84000000","0.07000000"],["62601.48000000","0.00000000"],["62563.52000000","0.00000000"],["62539.77000000","0.00000000"],["56377.03000000","0.00460000"]],"a":[["62641.15000000","0.80849000"],["62641.16000000","0.00097000"],["62641.17000000","0.00016000"],["62645.55000000","0.07689000"],["62645.89000000","0.11703000"],["62646.00000000","0.02418000"],["62646.56000000","0.13031000"],["62646.57000000","0.00000000"],["62646.80000000","0.00000000"],["62719.99000000","0.00000000"],["62722.76000000","0.00000000"],["62725.99000000","0.00000000"],["62729.99000000","0.00000000"],["62734.04000000","0.00159000"],["62738.79000000","0.00000000"],["62745.32000000","0.00000000"],["62748.51000000","0.00000000"],["62751.64000000","0.00000000"],["62755.99000000","0.00000000"],["62763.35000000","0.00000000"],["62764.57000000","0.00000000"]]}}
{"t":16.664,"stream":"btcusdt@depth20@100ms","data":{"lastUpdateId":97344798029,"bids":[["62641.14000000","3.96170000"],["62641.13000000","0.00034000"],["62641.12000000","0.00016000"],["62640.95000000","0.63005000"],["62640.90000000","0.00008000"],["62640.34000000","0.30016000"],["62640.32000000","0.00009000"],["62640.01000000","0.00500000"],["62640.00000000","1.91781000"],["62639.99000000","0.59576000"],["62639.98000000","0.00449000"],["62639.86000000","0.00400000"],["62639.83000000","0.00016000"],["62639.77000000","0.04091000"],["62638.50000000","0.00816000"],["62638.49000000","0.03966000"],["62638.44000000","0.00009000"],["62638.42000000","0.00008000"],["62638.29000000","0.00400000"],["62638.00000000","0.02400000"]],"asks":[["62641.15000000","0.80849000"],["62641.16000000","0.00097000"],["62641.17000000","0.00016000"],["62641.56000000","0.00009000"],["62641.98000000","0.00008000"],["62641.99000000","0.00041000"],["62642.00000000","0.03469000"],["62642.19000000","0.00009000"],["62642.25000000","0.00008000"],["62642.40000000","0.00018000"],["62642.41000000","0.07689000"],["62642.43000000","0.00068000"],["62642.91000000","0.00032000"],["62643.09000000","0.00016000"],["62643.20000000","0.00008000"],["62643.44000000","0.00009000"],["62643.76000000","0.00008000"],["62643.97000000","0.00030000"],["62643.99000000","0.00018000"],["62644.00000000","0.02418000"]]}}
{"t":16.7652,"stream":"btcusdt@depth@100ms","data":{"e":"depthUpdate","E":1783948019414,"s":"BTCUSDT","U":97344798030,"u":97344798053,"b":[["62640.01000000","0.02737000"],["62640.00000000","1.91942000"],["62625.95000000","0.55720000"],["62607.16000000","1.14294000"],["62587.57000000","0.00000000"],["62586.93000000","0.95855000"],["62504.01000000","0.00999000"],["62500.01000000","0.06451000"],["57628.79000000","0.00018000"],["56377.03000000","0.00460000"],["50113.00000000","0.00793000"]],"a":[["62641.15000000","0.80491000"],["62641.56000000","0.00000000"],["62642.81000000","0.00009000"],["62650.33000000","0.00000000"],["62677.38000000","0.00000000"]]}}
{"t":16.7655,"stream":"btcusdt@depth20@100ms","data":{"lastUpdateId":97344798053,"bids":[["62641.14000000","3.96170000"],["62641.13000000","0.00034000"],["62641.12000000","0.00016000"],["62640.95000000","0.63005000"],["62640.90000000","0.00008000"],["62640.34000000","0.30016000"],["62640.32000000","0.00009000"],["62640.01000000","0.02737000"],["62640.00000000","1.91942000"],["62639.99000000","0.59576000"],["62639.98000000","0.00449000"],["62639.86000000","0.00400000"],["62639.83000000","0.00016000"],["62639.77000000","0.04091000"],["62638.50000000","0.00816000"],["62638.49000000","0.03966000"],["62638.44000000","0.00009000"],["62638.42000000","0.00008000"],["62638.29000000","0.00400000"],["62638.00000000","0.02400000"]],"asks":[["62641.15000000","0.80491000"],["62641.16000000","0.00097000"],["62641.17000000","0.00016000"],["62641.98000000","0.00008000"],["62641.99000000","0.00041000"],["62642.00000000","0.03469000"],["62642.19000000","0.00009000"],["62642.25000000","0.00008000"],["62642.40000000","0.00018000"],["62642.41000000","0.07689000"],["62642.43000000","0.00068000"],["62642.81000000","0.00009000"],["62642.91000000","0.00032000"],["62643.09000000","0.00016000"],["62643.20000000","0.00008000"],["62643.44000000","0.00009000"],["62643.76000000","0.00008000"],["62643.97000000","0.00030000"],["62643.99000000","0.00018000"],["62644.00000000","0.02418000"]]}}
{"t":16.8631,"stream":"btcusdt@depth@100ms","data":{"e":"depthUpdate","E":1783948019514,"s":"BTCUSDT","U":97344798054,"u":97344798070,"b":[["62641.14000000","3.96320000"],["62640.35000000","0.00798000"],["62639.99000000","0.59426000"],["62638.50000000","0.00018000"],["62508.50000000","0.00000000"],["62410.51000000","0.01933000"],["62357.77000000","0.00000000"],["62077.37000000","0.00010000"],["56377.03000000","0.00480000"],["50113.00000000","0.00193000"]],"a":[["62641.15000000","0.11579000"],["62642.43000000","0.00000000"],["62643.00000000","0.00068000"],["62677.61000000","0.00011000"],["62717.63000000","2.15344000"]]}}
{"t":16.8648,"stream":"btcusdt@depth20@100ms","data":{"lastUpdateId":97344798070,"bids":[["62641.14000000","3.96320000"],["62641.13000000","0.00034000"],["62641.12000000","0.00016000"],["62640.95000000","0.63005000"],["62640.90000000","0.00008000"],["62640.35000000","0.00798000"],["62640.34000000","0.30016000"],["62640.32000000","0.00009000"],["62640.01000000","0.02737000"],["62640.00000000","1.91942000"],["62639.99000000","0.59426000"],["62639.98000000","0.00449000"],["62639.86000000","0.00400000"],["62639.83000000","0.00016000"],["62639.77000000","0.04091000"],["62638.50000000","0.00018000"],["62638.49000000","0.03966000"],["62638.44000000","0.00009000"],["62638.42000000","0.00008000"],["62638.29000000","0.00400000"]],"asks":[["62641.15000000","0.11579000"],["62641.16000000","0.00097000"],["62641.17000000","0.00016000"],["62641.98000000","0.00008000"],["62641.99000000","0.00041000"],["62642.00000000","0.03469000"],["62642.19000000","0.00009000"],["62642.25000000","0.00008000"],["62642.40000000","0.00018000"],["62642.41000000","0.07689000"],["62642.81000000","0.00009000"],["62642.91000000","0.00032000"],["62643.00000000","0.00068000"],["62643.09000000","0.00016000"],["62643.20000000","0.00008000"],["62643.44000000","0.00009000"],["62643.76000000","0.00008000"],["62643.97000000","0.00030000"],["62643.99000000","0.00018000"],["62644.00000000","0.02418000"]]}}
{"t":16.9646,"stream":"btcusdt@depth@100ms","data":{"e":"depthUpdate","E":1783948019614,"s":"BTCUSDT","U":97344798071,"u":97344798113,"b":[["62641.14000000","3.73100000"],["62640.95000000","0.63005000"],["62640.35000000","0.00018000"],["62639.77000000","0.04091000"],["62638.50000000","0.00798000"],["56377.03000000","0.00480000"]],"a":[["62641.15000000","0.82171000"],["62641.16000000","0.00097000"],["62642.41000000","0.07697000"],["62642.44000000","0.00068000"],["62643.00000000","0.00000000"],["62643.72000000","0.11509000"],["62644.88000000","0.00018000"],["62644.89000000","0.00000000"],["62645.88000000","0.00000000"],["62645.89000000","0.00026000"],["62645.99000000","0.00000000"],["62651.04000000","0.00400000"],["62654.63000000","0.00000000"],["62671.26000000","0.00400000"],["62677.54000000","0.00000000"]]}}
{"t":16.9649,"stream":"btcusdt@depth20@100ms","data":{"lastUpdateId":97344798113,"bids":[["62641.14000000","3.73100000"],["62641.13000000","0.00034000"],["62641.12000000","0.00016000"],["62640.95000000","0.63005000"],["62640.90000000","0.00008000"],["62640.35000000","0.00018000"],["62640.34000000","0.30016000"],["62640.32000000","0.00009000"],["62640.01000000","0.02737000"],["62640.00000000","1.91942000"],["62639.99000000","0.59426000"],["62639.98000000","0.00449000"],["62639.86000000","0.00400000"],["62639.83000000","0.00016000"],["62639.77000000","0.04091000"],["62638.50000000","0.00798000"],["62638.49000000","0.03966000"],["62638.44000000","0.00009000"],["62638.42000000","0.00008000"],["62638.29000000","0.00400000"]],"asks":[["62641.15000000","0.82171000"],["62641.16000000","0.00097000"],["62641.17000000","0.00016000"],["62641.98000000","0.00008000"],["62641.99000000","0.00041000"],["62642.00000000","0.03469000"],["62642.19000000","0.00009000"],["62642.25000000","0.00008000"],["62642.40000000","0.00018000"],["62642.41000000","0.07697000"],["62642.44000000","0.00068000"],["62642.81000000","0.00009000"],["62642.91000000","0.00032000"],["62643.09000000","0.00016000"],["62643.20000000","0.00008000"],["62643.44000000","0.00009000"],["62643.72000000","0.11509000"],["62643.76000000","0.00008000"],["62643.97000000","0.00030000"],["62643.99000000","0.00018000"]]}}
{"t":17.0644,"stream":"btcusdt@depth@100ms","data":{"e":"depthUpdate","E":1783948019714,"s":"BTCUSDT","U":97344798114,"u":97344798175,"b":[["62640.96000000","0.00018000"],["62640.95000000","0.63005000"],["62640.35000000","0.00018000"],["62640.01000000","0.02755000"],["62640.00000000","1.91960000"],["62639.99000000","0.54430000"],["62639.77000000","0.04091000"],["62638.50000000","0.00816000"],["62636.28000000","0.00008000"],["62633.53000000","0.59914000"],["62627.12000000","0.00000000"],["62607.84000000","0.00000000"],["62599.89000000","0.00000000"],["56377.03000000","0.00480000"]],"a":[["62641.15000000","0.82171000"],["62641.16000000","0.00097000"],["62642.41000000","0.07697000"],["62643.71000000","0.00000000"],["62643.72000000","0.00018000"],["62644.88000000","0.00000000"],["62645.54000000","0.00018000"],["62645.55000000","0.07689000"],["62645.89000000","0.00008000"],["62645.99000000","0.00009000"],["62650.85000000","0.00400000"],["62652.19000000","0.00000000"],["62675.97000000","0.00000000"],["62740.21000000","0.00000000"]]}}
{"t":17.0646,"stream":"btcusdt@depth20@100ms","data":{"lastUpdateId":97344798175,"bids":[["62641.14000000","3.73100000"],["62641.13000000","0.00034000"],["62641.12000000","0.00016000"],["62640.96000000","0.00018000"],["62640.95000000","0.63005000"],["62640.90000000","0.00008000"],["62640.35000000","0.00018000"],["62640.34000000","0.30016000"],["62640.32000000","0.00009000"],["62640.01000000","0.02755000"],["62640.00000000","1.91960000"],["62639.99000000","0.54430000"],["62639.98000000","0.00449000"],["62639.86000000","0.00400000"],["62639.83000000","0.00016000"],["62639.77000000","0.04091000"],["62638.50000000","0.00816000"],["62638.49000000","0.03966000"],["62638.44000000","0.00009000"],["62638.42000000","0.00008000"]],"asks":[["62641.15000000","0.82171000"],["62641.16000000","0.00097000"],["62641.17000000","0.00016000"],["62641.98000000","0.00008000"],["62641.99000000","0.00041000"],["62642.00000000","0.03469000"],["62642.19000000","0.00009000"],["62642.25000000","0.00008000"],["62642.40000000","0.00018000"],["62642.41000000","0.07697000"],["62642.44000000","0.00068000"],["62642.81000000","0.00009000"],["62642.91000000","0.00032000"],["62643.09000000","0.00016000"],["62643.20000000","0.00008000"],["62643.44000000","0.00009000"],["62643.72000000","0.00018000"],["62643.76000000","0.00008000"],["62643.97000000","0.00030000"],["62643.99000000","0.00018000"]]}}
{"t":17.1636,"stream":"btcusdt@depth@100ms","data":{"e":"depthUpdate","E":1783948019814,"s":"BTCUSDT","U":97344798176,"u":97344798194,"b":[["62627.12000000","0.00008000"],["56377.03000000","0.00480000"]],"a":[["62641.15000000","0.82162000"],["62641.16000000","0.00088000"],["62642.41000000","0.07689000"],["62643.44000000","0.00000000"],["62643.72000000","0.00000000"],["62647.80000000","0.00574000"],["62652.19000000","0.00008000"],["62771.58000000","0.00000000"]]}}
{"t":17.1638,"stream":"btcusdt@depth20@100ms","data":{"lastUpdateId":97344798194,"bids":[["62641.14000000","3.73100000"],["62641.13000000","0.00034000"],["62641.12000000","0.00016000"],["62640.96000000","0.00018000"],["62640.95000000","0.63005000"],["62640.90000000","0.00008000"],["62640.35000000","0.00018000"],["62640.34000000","0.30016000"],["62640.32000000","0.00009000"],["62640.01000000","0.02755000"],["62640.00000000","1.91960000"],["62639.99000000","0.54430000"],["62639.98000000","0.00449000"],["62639.86000000","0.00400000"],["62639.83000000","0.00016000"],["62639.77000000","0.04091000"],["62638.50000000","0.00816000"],["62638.49000000","0.03966000"],["62638.44000000","0.00009000"],["62638.42000000","0.00008000"]],"asks":[["62641.15000000","0.82162000"],["62641.16000000","0.00088000"],["62641.17000000","0.00016000"],["62641.98000000","0.00008000"],["62641.99000000","0.00041000"],["62642.00000000","0.03469000"],["62642.19000000","0.00009000"],["62642.25000000","0.00008000"],["62642.40000000","0.00018000"],["62642.41000000","0.07689000"],["62642.44000000","0.00068000"],["62642.81000000","0.00009000"],["62642.91000000","0.00032000"],["62643.09000000","0.00016000"],["62643.20000000","0.00008000"],["62643.76000000","0.00008000"],["62643.97000000","0.00030000"],["62643.99000000","0.00018000"],["62644.00000000","0.02418000"],["62644.12000000","0.00008000"]]}}
{"t":17.2635,"stream":"btcusdt@depth@100ms","data":{"e":"depthUpdate","E":1783948019914,"s":"BTCUSDT","U":97344798195,"u":97344798208,"b":[["62611.34000000","0.00000000"],["62562.77000000","0.00000000"],["56377.03000000","0.00480000"],["50112.91000000","0.00000000"]],"a":[["62650.33000000","0.00009000"],["62764.13000000","0.15970000"]]}}
{"t":17.2637,"stream":"btcusdt@depth20@100ms","data":{"lastUpdateId":97344798208,"bids":[["62641.14000000","3.73100000"],["62641.13000000","0.00034000"],["62641.12000000","0.00016000"],["62640.96000000","0.00018000"],["62640.95000000","0.63005000"],["62640.90000000","0.00008000"],["62640.35000000","0.00018000"],["62640.34000000","0.30016000"],["62640.32000000","0.00009000"],["62640.01000000","0.02755000"],["62640.00000000","1.91960000"],["62639.99000000","0.54430000"],["62639.98000000","0.00449000"],["62639.86000000","0.00400000"],["62639.83000000","0.00016000"],["62639.77000000","0.04091000"],["62638.50000000","0.00816000"],["62638.49000000","0.03966000"],["62638.44000000","0.00009000"],["62638.42000000","0.00008000"]],"asks":[["62641.15000000","0.82162000"],["62641.16000000","0.00088000"],["62641.17000000","0.00016000"],["62641.98000000","0.00008000"],["62641.99000000","0.00041000"],["62642.00000000","0.03469000"],["62642.19000000","0.00009000"],["62642.25000000","0.00008000"],["62642.40000000","0.00018000"],["62642.41000000","0.07689000"],["62642.44000000","0.00068000"],["62642.81000000","0.00009000"],["62642.91000000","0.00032000"],["62643.09000000","0.00016000"],["62643.20000000","0.00008000"],["62643.76000000","0.00008000"],["62643.97000000","0.00030000"],["62643.99000000","0.00018000"],["62644.00000000","0.02418000"],["62644.12000000","0.00008000"]]}}
{"t":17.3648,"stream":"btcusdt@depth@100ms","data":{"e":"depthUpdate","E":1783948020014,"s":"BTCUSDT","U":97344798209,"u":97344798248,"b":[["62641.14000000","3.73356000"],["62635.30000000","0.00000000"],["62634.01000000","0.59914000"],["62633.53000000","0.00000000"],["62633.00000000","0.08500000"],["62630.09000000","0.79884000"],["62621.68000000","0.00000000"],["62588.02000000","0.00113000"],["62525.48000000","0.00000000"],["61701.52000000","0.00030000"],["57628.79000000","0.00000000"],["56377.03000000","0.00460000"],["56377.00000000","0.02164000"],["50112.92000000","0.00039000"],["50112.91000000","0.00000000"]],"a":[["62642.65000000","0.00256000"],["62652.93000000","0.59914000"],["62657.99000000","0.41474000"],["62659.15000000","0.01252000"],["62659.39000000","0.79884000"],["62660.77000000","0.00000000"],["62664.40000000","0.00000000"],["62674.47000000","0.03696000"],["62764.13000000","0.15970000"]]}}
{"t":17.3651,"stream":"btcusdt@depth20@100ms","data":{"lastUpdateId":97344798248,"bids":[["62641.14000000","3.73356000"],["62641.13000000","0.00034000"],["62641.12000000","0.00016000"],["62640.96000000","0.00018000"],["62640.95000000","0.63005000"],["62640.90000000","0.00008000"],["62640.35000000","0.00018000"],["62640.34000000","0.30016000"],["62640.32000000","0.00009000"],["62640.01000000","0.02755000"],["62640.00000000","1.91960000"],["62639.99000000","0.54430000"],["62639.98000000","0.00449000"],["62639.86000000","0.00400000"],["62639.83000000","0.00016000"],["62639.77000000","0.04091000"],["62638.50000000","0.00816000"],["62638.49000000","0.03966000"],["62638.44000000","0.00009000"],["62638.42000000","0.00008000"]],"asks":[["62641.15000000","0.82162000"],["62641.16000000","0.00088000"],["62641.17000000","0.00016000"],["62641.98000000","0.00008000"],["62641.99000000","0.00041000"],["62642.00000000","0.03469000"],["62642.19000000","0.00009000"],["62642.25000000","0.00008000"],["62642.40000000","0.00018000"],["62642.41000000","0.07689000"],["62642.44000000","0.00068000"],["62642.65000000","0.00256000"],["62642.81000000","0.00009000"],["62642.91000000","0.00032000"],["62643.09000000","0.00016000"],["62643.20000000","0.00008000"],["62643.76000000","0.00008000"],["62643.97000000","0.00030000"],["62643.99000000","0.00018000"],["62644.00000000","0.02418000"]]}}
{"t":17.4644,"stream":"btcusdt@depth@100ms","data":{"e":"depthUpdate","E":1783948020114,"s":"BTCUSDT","U":97344798249,"u":97344798276,"b":[["62635.60000000","0.59914000"],["62635.59000000","0.47600000"],["62634.01000000","0.00000000"],["62632.91000000","0.00000000"],["56377.03000000","0.00460000"],["40000.00000000","258.07540000"]],"a":[["62641.15000000","0.82171000"],["62641.16000000","0.00097000"],["62645.88000000","0.00009000"],["62645.89000000","0.10416000"],["62659.39000000","0.00000000"],["62659.99000000","0.79884000"],["62660.78000000","0.00000000"],["62764.13000000","0.00000000"]]}}
{"t":17.4647,"stream":"btcusdt@depth20@100ms","data":{"lastUpdateId":97344798276,"bids":[["62641.14000000","3.73356000"],["62641.13000000","0.00034000"],["62641.12000000","0.00016000"],["62640.96000000","0.00018000"],["62640.95000000","0.63005000"],["62640.90000000","0.00008000"],["62640.35000000","0.00018000"],["62640.34000000","0.30016000"],["62640.32000000","0.00009000"],["62640.01000000","0.02755000"],["62640.00000000","1.91960000"],["62639.99000000","0.54430000"],["62639.98000000","0.00449000"],["62639.86000000","0.00400000"],["62639.83000000","0.00016000"],["62639.77000000","0.04091000"],["62638.50000000","0.00816000"],["62638.49000000","0.03966000"],["62638.44000000","0.00009000"],["62638.42000000","0.00008000"]],"asks":[["62641.15000000","0.82171000"],["62641.16000000","0.00097000"],["62641.17000000","0.00016000"],["62641.98000000","0.00008000"],["62641.99000000","0.00041000"],["62642.00000000","0.03469000"],["62642.19000000","0.00009000"],["62642.25000000","0.00008000"],["62642.40000000","0.00018000"],["62642.41000000","0.07689000"],["62642.44000000","0.00068000"],["62642.65000000","0.00256000"],["62642.81000000","0.00009000"],["62642.91000000","0.00032000"],["62643.09000000","0.00016000"],["62643.20000000","0.00008000"],["62643.76000000","0.00008000"],["62643.97000000","0.00030000"],["62643.99000000","0.00018000"],["62644.00000000","0.02418000"]]}}
{"t":17.5639,"stream":"btcusdt@depth@100ms","data":{"e":"depthUpdate","E":1783948020214,"s":"BTCUSDT","U":97344798277,"u":97344798315,"b":[["62640.32000000","0.00174000"],["62640.00000000","1.91799000"],["62637.37000000","0.06704000"],["62635.60000000","0.00000000"],["62634.01000000","0.68616000"],["62633.00000000","0.00000000"],["56377.03000000","0.00460000"],["50112.92000000","0.00000000"]],"a":[["62641.15000000","0.82180000"],["62641.16000000","0.00106000"],["62642.41000000","0.07757000"],["62642.44000000","0.00000000"],["62642.98000000","0.00000000"],["62645.55000000","0.07689000"],["62645.89000000","0.10434000"],["62647.80000000","0.00556000"],["62657.99000000","0.12280000"],["62659.99000000","0.00000000"],["62661.79000000","0.79884000"],["62677.61000000","0.00000000"],["62677.73000000","0.00011000"],["62764.13000000","0.00000000"],["63580.77000000","0.00030000"]]}}
{"t":17.5641,"stream":"btcusdt@depth20@100ms","data":{"lastUpdateId":97344798315,"bids":[["62641.14000000","3.73356000"],["62641.13000000","0.00034000"],["62641.12000000","0.00016000"],["62640.96000000","0.00018000"],["62640.95000000","0.63005000"],["62640.90000000","0.00008000"],["62640.35000000","0.00018000"],["62640.34000000","0.30016000"],["62640.32000000","0.00174000"],["62640.01000000","0.02755000"],["62640.00000000","1.91799000"],["62639.99000000","0.54430000"],["62639.98000000","0.00449000"],["62639.86000000","0.00400000"],["62639.83000000","0.00016000"],["62639.77000000","0.04091000"],["62638.50000000","0.00816000"],["62638.49000000","0.03966000"],["62638.44000000","0.00009000"],["62638.42000000","0.00008000"]],"asks":[["62641.15000000","0.82180000"],["62641.16000000","0.00106000"],["62641.17000000","0.00016000"],["62641.98000000","0.00008000"],["62641.99000000","0.00041000"],["62642.00000000","0.03469000"],["62642.19000000","0.00009000"],["62642.25000000","0.00008000"],["62642.40000000","0.00018000"],["62642.41000000","0.07757000"],["62642.65000000","0.00256000"],["62642.81000000","0.00009000"],["62642.91000000","0.00032000"],["62643.09000000","0.00016000"],["62643.20000000","0.00008000"],["62643.76000000","0.00008000"],["62643.97000000","0.00030000"],["62643.99000000","0.00018000"],["62644.00000000","0.02418000"],["62644.12000000","0.00008000"]]}}
{"t":17.6645,"stream":"btcusdt@depth@100ms","data":{"e":"depthUpdate","E":1783948020314,"s":"BTCUSDT","U":97344798316,"u":97344798333,"b":[["62634.01000000","0.59913000"],["62632.62000000","0.13496000"],["56377.03000000","0.00460000"]],"a":[["62641.15000000","0.82180000"],["62641.16000000","0.00106000"],["62642.41000000","0.07765000"],["62645.01000000","0.00018000"],["62645.02000000","0.08487000"],["62645.88000000","0.00000000"],["62645.89000000","0.00026000"],["62645.99000000","0.00000000"],["62764.14000000","0.00000000"]]}}
{"t":17.6646,"stream":"btcusdt@depth20@100ms","data":{"lastUpdateId":97344798333,"bids":[["62641.14000000","3.73356000"],["62641.13000000","0.00034000"],["62641.12000000","0.00016000"],["62640.96000000","0.00018000"],["62640.95000000","0.63005000"],["62640.90000000","0.00008000"],["62640.35000000","0.00018000"],["62640.34000000","0.30016000"],["62640.32000000","0.00174000"],["62640.01000000","0.02755000"],["62640.00000000","1.91799000"],["62639.99000000","0.54430000"],["62639.98000000","0.00449000"],["62639.86000000","0.00400000"],["62639.83000000","0.00016000"],["62639.77000000","0.04091000"],["62638.50000000","0.00816000"],["62638.49000000","0.03966000"],["62638.44000000","0.00009000"],["62638.42000000","0.00008000"]],"asks":[["62641.15000000","0.82180000"],["62641.16000000","0.00106000"],["62641.17000000","0.00016000"],["62641.98000000","0.00008000"],["62641.99000000","0.00041000"],["62642.00000000","0.03469000"],["62642.19000000","0.00009000"],["62642.25000000","0.00008000"],["62642.40000000","0.00018000"],["62642.41000000","0.07765000"],["62642.65000000","0.00256000"],["62642.81000000","0.00009000"],["62642.91000000","0.00032000"],["62643.09000000","0.00016000"],["62643.20000000","0.00008000"],["62643.76000000","0.00008000"],["62643.97000000","0.00030000"],["62643.99000000","0.00018000"],["62644.00000000","0.02418000"],["62644.12000000","0.00008000"]]}}
{"t":17.7401,"stream":"btcusdt@aggTrade","data":{"e":"aggTrade","E":1783948020389,"s":"BTCUSDT","a":4013160612,"p":"62641.15000000","q":"0.00079000","f":6501833932,"l":6501833932,"T":1783948020389,"m":false,"M":true}}
{"t":17.7635,"stream":"btcusdt@depth@100ms","data":{"e":"depthUpdate","E":1783948020414,"s":"BTCUSDT","U":97344798334,"u":97344798365,"b":[["62641.14000000","3.73100000"],["62630.77000000","0.04270000"],["62504.01000000","0.00000000"],["62500.01000000","0.07450000"],["56377.03000000","0.00460000"],["56375.99000000","0.00000000"]],"a":[["62641.15000000","0.82083000"],["62641.16000000","0.00088000"],["62642.41000000","0.07773000"],["62642.65000000","0.00000000"],["62644.00000000","0.11608000"],["62645.01000000","0.00000000"],["62645.02000000","0.00018000"],["62645.55000000","0.07689000"],["62645.89000000","0.00008000"],["62645.99000000","0.00009000"],["62667.68000000","0.61486000"]]}}
{"t":17.7638,"stream":"btcusdt@depth20@100ms","data":{"lastUpdateId":97344798365,"bids":[["62641.14000000","3.73100000"],["62641.13000000","0.00034000"],["62641.12000000","0.00016000"],["62640.96000000","0.00018000"],["62640.95000000","0.63005000"],["62640.90000000","0.00008000"],["62640.35000000","0.00018000"],["62640.34000000","0.30016000"],["62640.32000000","0.00174000"],["62640.01000000","0.02755000"],["62640.00000000","1.91799000"],["62639.99000000","0.54430000"],["62639.98000000","0.00449000"],["62639.86000000","0.00400000"],["62639.83000000","0.00016000"],["62639.77000000","0.04091000"],["62638.50000000","0.00816000"],["62638.49000000","0.03966000"],["62638.44000000","0.00009000"],["62638.42000000","0.00008000"]],"asks":[["62641.15000000","0.82083000"],["62641.16000000","0.00088000"],["62641.17000000","0.00016000"],["62641.98000000","0.00008000"],["62641.99000000","0.00041000"],["62642.00000000","0.03469000"],["62642.19000000","0.00009000"],["62642.25000000","0.00008000"],["62642.40000000","0.00018000"],["62642.41000000","0.07773000"],["62642.81000000","0.00009000"],["62642.91000000","0.00032000"],["62643.09000000","0.00016000"],["62643.20000000","0.00008000"],["62643.76000000","0.00008000"],["62643.97000000","0.00030000"],["62643.99000000","0.00018000"],["62644.00000000","0.11608000"],["62644.12000000","0.00008000"],["62644.29000000","0.00008000"]]}}
{"t":17.8648,"stream":"btcusdt@depth@100ms","data":{"e":"depthUpdate","E":1783948020514,"s":"BTCUSDT","U":97344798366,"u":97344798386,"b":[["56377.03000000","0.00460000"]],"a":[["62642.41000000","0.07765000"],["62644.00000000","0.11608000"],["62645.02000000","0.00000000"],["62647.80000000","0.00574000"],["62764.13000000","0.00000000"]]}}
{"t":17.865,"stream":"btcusdt@depth20@100ms","data":{"lastUpdateId":97344798386,"bids":[["62641.14000000","3.73100000"],["62641.13000000","0.00034000"],["62641.12000000","0.00016000"],["62640.96000000","0.00018000"],["62640.95000000","0.63005000"],["62640.90000000","0.00008000"],["62640.35000000","0.00018000"],["62640.34000000","0.30016000"],["62640.32000000","0.00174000"],["62640.01000000","0.02755000"],["62640.00000000","1.91799000"],["62639.99000000","0.54430000"],["62639.98000000","0.00449000"],["62639.86000000","0.00400000"],["62639.83000000","0.00016000"],["62639.77000000","0.04091000"],["62638.50000000","0.00816000"],["62638.49000000","0.03966000"],["62638.44000000","0.00009000"],["62638.42000000","0.00008000"]],"asks":[["62641.15000000","0.82083000"],["62641.16000000","0.00088000"],["62641.17000000","0.00016000"],["62641.98000000","0.00008000"],["62641.99000000","0.00041000"],["62642.00000000","0.03469000"],["62642.19000000","0.00009000"],["62642.25000000","0.00008000"],["62642.40000000","0.00018000"],["62642.41000000","0.07765000"],["62642.81000000","0.00009000"],["62642.91000000","0.00032000"],["62643.09000000","0.00016000"],["62643.20000000","0.00008000"],["62643.76000000","0.00008000"],["62643.97000000","0.00030000"],["62643.99000000","0.00018000"],["62644.00000000","0.11608000"],["62644.12000000","0.00008000"],["62644.29000000","0.00008000"]]}}
{"t":18.0199,"stream":"btcusdt@depth@100ms","data":{"e":"depthUpdate","E":1783948020614,"s":"BTCUSDT","U":97344798387,"u":97344798398,"b":[["56377.03000000","0.00460000"],["33000.00000000","33.37028000"]],"a":[["62644.00000000","0.02418000"],["62650.92000000","0.01299000"],["62764.13000000","0.00000000"]]}}
{"t":18.0201,"stream":"btcusdt@depth20@100ms","data":{"lastUpdateId":97344798398,"bids":[["62641.14000000","3.73100000"],["62641.13000000","0.00034000"],["62641.12000000","0.00016000"],["62640.96000000","0.00018000"],["62640.95000000","0.63005000"],["62640.90000000","0.00008000"],["62640.35000000","0.00018000"],["62640.34000000","0.30016000"],["62640.32000000","0.00174000"],["62640.01000000","0.02755000"],["62640.00000000","1.91799000"],["62639.99000000","0.54430000"],["62639.98000000","0.00449000"],["62639.86000000","0.00400000"],["62639.83000000","0.00016000"],["62639.77000000","0.04091000"],["62638.50000000","0.00816000"],["62638.49000000","0.03966000"],["62638.44000000","0.00009000"],["62638.42000000","0.00008000"]],"asks":[["62641.15000000","0.82083000"],["62641.16000000","0.00088000"],["62641.17000000","0.00016000"],["62641.98000000","0.00008000"],["62641.99000000","0.00041000"],["62642.00000000","0.03469000"],["62642.19000000","0.00009000"],["62642.25000000","0.00008000"],["62642.40000000","0.00018000"],["62642.41000000","0.07765000"],["62642.81000000","0.00009000"],["62642.91000000","0.00032000"],["62643.09000000","0.00016000"],["62643.20000000","0.00008000"],["62643.76000000","0.00008000"],["62643.97000000","0.00030000"],["62643.99000000","0.00018000"],["62644.00000000","0.02418000"],["62644.12000000","0.00008000"],["62644.29000000","0.00008000"]]}}
{"t":18.0638,"stream":"btcusdt@depth@100ms","data":{"e":"depthUpdate","E":1783948020714,"s":"BTCUSDT","U":97344798399,"u":97344798416,"b":[["62640.33000000","0.00798000"],["62638.50000000","0.00018000"],["62606.25000000","0.77000000"],["56377.03000000","0.00460000"]],"a":[["62641.15000000","0.13161000"],["62642.41000000","0.07697000"],["62642.98000000","0.00068000"],["62651.04000000","0.00000000"],["62652.18000000","0.00400000"],["62746.82000000","0.00031000"],["62764.13000000","0.00000000"]]}}
{"t":18.064,"stream":"btcusdt@depth20@100ms","data":{"lastUpdateId":97344798416,"bids":[["62641.14000000","3.73100000"],["62641.13000000","0.00034000"],["62641.12000000","0.00016000"],["62640.96000000","0.00018000"],["62640.95000000","0.63005000"],["62640.90000000","0.00008000"],["62640.35000000","0.00018000"],["62640.34000000","0.30016000"],["62640.33000000","0.00798000"],["62640.32000000","0.00174000"],["62640.01000000","0.02755000"],["62640.00000000","1.91799000"],["62639.99000000","0.54430000"],["62639.98000000","0.00449000"],["62639.86000000","0.00400000"],["62639.83000000","0.00016000"],["62639.77000000","0.04091000"],["62638.50000000","0.00018000"],["62638.49000000","0.03966000"],["62638.44000000","0.00009000"]],"asks":[["62641.15000000","0.13161000"],["62641.16000000","0.00088000"],["62641.17000000","0.00016000"],["62641.98000000","0.00008000"],["62641.99000000","0.00041000"],["62642.00000000","0.03469000"],["62642.19000000","0.00009000"],["62642.25000000","0.00008000"],["62642.40000000","0.00018000"],["62642.41000000","0.07697000"],["62642.81000000","0.00009000"],["62642.91000000","0.00032000"],["62642.98000000","0.00068000"],["62643.09000000","0.00016000"],["62643.20000000","0.00008000"],["62643.76000000","0.00008000"],["62643.97000000","0.00030000"],["62643.99000000","0.00018000"],["62644.00000000","0.02418000"],["62644.12000000","0.00008000"]]}}
{"t":18.1636,"stream":"btcusdt@depth@100ms","data":{"e":"depthUpdate","E":1783948020814,"s":"BTCUSDT","U":97344798417,"u":97344798449,"b":[["62640.34000000","0.30016000"],["62640.33000000","0.00970000"],["62640.32000000","0.00009000"],["62639.77000000","0.04091000"],["62638.50000000","0.00000000"],["62627.12000000","0.00008000"],["56377.03000000","0.00460000"]],"a":[["62641.15000000","0.13170000"],["62641.16000000","0.00097000"],["62645.55000000","0.07697000"],["62646.21000000","0.08909000"],["62650.92000000","0.00000000"],["62650.94000000","0.01251000"],["62652.19000000","0.00008000"],["62763.91000000","0.00000000"]]}}
{"t":18.1638,"stream":"btcusdt@depth20@100ms","data":{"lastUpdateId":97344798449,"bids":[["62641.14000000","3.73100000"],["62641.13000000","0.00034000"],["62641.12000000","0.00016000"],["62640.96000000","0.00018000"],["62640.95000000","0.63005000"],["62640.90000000","0.00008000"],["62640.35000000","0.00018000"],["62640.34000000","0.30016000"],["62640.33000000","0.00970000"],["62640.32000000","0.00009000"],["62640.01000000","0.02755000"],["62640.00000000","1.91799000"],["62639.99000000","0.54430000"],["62639.98000000","0.00449000"],["62639.86000000","0.00400000"],["62639.83000000","0.00016000"],["62639.77000000","0.04091000"],["62638.49000000","0.03966000"],["62638.44000000","0.00009000"],["62638.42000000","0.00008000"]],"asks":[["62641.15000000","0.13170000"],["62641.16000000","0.00097000"],["62641.17000000","0.00016000"],["62641.98000000","0.00008000"],["62641.99000000","0.00041000"],["62642.00000000","0.03469000"],["62642.19000000","0.00009000"],["62642.25000000","0.00008000"],["62642.40000000","0.00018000"],["62642.41000000","0.07697000"],["62642.81000000","0.00009000"],["62642.91000000","0.00032000"],["62642.98000000","0.00068000"],["62643.09000000","0.00016000"],["62643.20000000","0.00008000"],["62643.76000000","0.00008000"],["62643.97000000","0.00030000"],["62643.99000000","0.00018000"],["62644.00000000","0.02418000"],["62644.12000000","0.00008000"]]}}
{"t":18.2641,"stream":"btcusdt@depth@100ms","data":{"e":"depthUpdate","E":1783948020914,"s":"BTCUSDT","U":97344798450,"u":97344798472,"b":[["62641.14000000","3.73356000"],["56377.03000000","0.00460000"],["50112.91000000","0.00000000"]],"a":[["62642.83000000","0.00256000"],["62646.00000000","0.02418000"],["62646.21000000","0.08927000"],["62647.80000000","0.00556000"],["62677.73000000","0.00000000"],["62763.95000000","0.00000000"],["62763.97000000","0.00000000"]]}}
{"t":18.2645,"stream":"btcusdt@depth20@100ms","data":{"lastUpdateId":97344798472,"bids":[["62641.14000000","3.73356000"],["62641.13000000","0.00034000"],["62641.12000000","0.00016000"],["62640.96000000","0.00018000"],["62640.95000000","0.63005000"],["62640.90000000","0.00008000"],["62640.35000000","0.00018000"],["62640.34000000","0.30016000"],["62640.33000000","0.00970000"],["62640.32000000","0.00009000"],["62640.01000000","0.02755000"],["62640.00000000","1.91799000"],["62639.99000000","0.54430000"],["62639.98000000","0.00449000"],["62639.86000000","0.00400000"],["62639.83000000","0.00016000"],["62639.77000000","0.04091000"],["62638.49000000","0.03966000"],["62638.44000000","0.00009000"],["62638.42000000","0.00008000"]],"asks":[["62641.15000000","0.13170000"],["62641.16000000","0.00097000"],["62641.17000000","0.00016000"],["62641.98000000","0.00008000"],["62641.99000000","0.00041000"],["62642.00000000","0.03469000"],["62642.19000000","0.00009000"],["62642.25000000","0.00008000"],["62642.40000000","0.00018000"],["62642.41000000","0.07697000"],["62642.81000000","0.00009000"],["62642.83000000","0.00256000"],["62642.91000000","0.00032000"],["62642.98000000","0.00068000"],["62643.09000000","0.00016000"],["62643.20000000","0.00008000"],["62643.76000000","0.00008000"],["62643.97000000","0.00030000"],["62643.99000000","0.00018000"],["62644.00000000","0.02418000"]]}}
{"t":18.3636,"stream":"btcusdt@depth@100ms","data":{"e":"depthUpdate","E":1783948021014,"s":"BTCUSDT","U":97344798473,"u":97344798513,"b":[["62635.60000000","0.59914000"],["62634.24000000","0.11434000"],["62634.01000000","0.00000000"],["62632.62000000","0.00000000"],["62588.02000000","0.00113000"],["62560.00000000","1.04295000"],["62525.48000000","0.00000000"],["61701.52000000","0.00030000"],["56377.03000000","0.00480000"],["50112.92000000","0.00039000"],["50112.91000000","0.00000000"]],"a":[["62641.15000000","0.13179000"],["62641.16000000","0.00106000"],["62642.41000000","0.07705000"],["62643.57000000","0.17256000"],["62645.24000000","0.00018000"],["62645.25000000","0.10278000"],["62645.99000000","0.00000000"],["62646.21000000","0.00018000"],["62657.99000000","0.00000000"],["62659.14000000","0.35941000"],["62659.28000000","0.00000000"],["62659.76000000","0.13138000"],["62671.10000000","0.02662000"],["62677.74000000","0.00011000"]]}}
{"t":18.3647,"stream":"btcusdt@depth20@100ms","data":{"lastUpdateId":97344798513,"bids":[["62641.14000000","3.73356000"],["62641.13000000","0.00034000"],["62641.12000000","0.00016000"],["62640.96000000","0.00018000"],["62640.95000000","0.63005000"],["62640.90000000","0.00008000"],["62640.35000000","0.00018000"],["62640.34000000","0.30016000"],["62640.33000000","0.00970000"],["62640.32000000","0.00009000"],["62640.01000000","0.02755000"],["62640.00000000","1.91799000"],["62639.99000000","0.54430000"],["62639.98000000","0.00449000"],["62639.86000000","0.00400000"],["62639.83000000","0.00016000"],["62639.77000000","0.04091000"],["62638.49000000","0.03966000"],["62638.44000000","0.00009000"],["62638.42000000","0.00008000"]],"asks":[["62641.15000000","0.13179000"],["62641.16000000","0.00106000"],["62641.17000000","0.00016000"],["62641.98000000","0.00008000"],["62641.99000000","0.00041000"],["62642.00000000","0.03469000"],["62642.19000000","0.00009000"],["62642.25000000","0.00008000"],["62642.40000000","0.00018000"],["62642.41000000","0.07705000"],["62642.81000000","0.00009000"],["62642.83000000","0.00256000"],["62642.91000000","0.00032000"],["62642.98000000","0.00068000"],["62643.09000000","0.00016000"],["62643.20000000","0.00008000"],["62643.57000000","0.17256000"],["62643.76000000","0.00008000"],["62643.97000000","0.00030000"],["62643.99000000","0.00018000"]]}}
{"t":18.4643,"stream":"btcusdt@depth@100ms","data":{"e":"depthUpdate","E":1783948021114,"s":"BTCUSDT","U":97344798514,"u":97344798553,"b":[["62637.37000000","0.06712000"],["56377.03000000","0.00480000"],["50113.00000000","0.00193000"],["40000.00000000","258.07540000"]],"a":[["62641.15000000","0.13188000"],["62641.16000000","0.00115000"],["62642.41000000","0.07713000"],["62643.56000000","0.00018000"],["62643.57000000","0.17274000"],["62644.00000000","0.02418000"],["62645.25000000","0.10296000"],["62645.54000000","0.00000000"],["62645.55000000","0.07689000"],["62646.00000000","0.02418000"],["62646.21000000","0.00000000"],["62647.42000000","0.00008000"],["62647.59000000","0.14100000"],["62647.60000000","0.00000000"],["62671.10000000","0.00000000"]]}}
{"t":18.4646,"stream":"btcusdt@depth20@100ms","data":{"lastUpdateId":97344798553,"bids":[["62641.14000000","3.73356000"],["62641.13000000","0.00034000"],["62641.12000000","0.00016000"],["62640.96000000","0.00018000"],["62640.95000000","0.63005000"],["62640.90000000","0.00008000"],["62640.35000000","0.00018000"],["62640.34000000","0.30016000"],["62640.33000000","0.00970000"],["62640.32000000","0.00009000"],["62640.01000000","0.02755000"],["62640.00000000","1.91799000"],["62639.99000000","0.54430000"],["62639.98000000","0.00449000"],["62639.86000000","0.00400000"],["62639.83000000","0.00016000"],["62639.77000000","0.04091000"],["62638.49000000","0.03966000"],["62638.44000000","0.00009000"],["62638.42000000","0.00008000"]],"asks":[["62641.15000000","0.13188000"],["62641.16000000","0.00115000"],["62641.17000000","0.00016000"],["62641.98000000","0.00008000"],["62641.99000000","0.00041000"],["62642.00000000","0.03469000"],["62642.19000000","0.00009000"],["62642.25000000","0.00008000"],["62642.40000000","0.00018000"],["62642.41000000","0.07713000"],["62642.81000000","0.00009000"],["62642.83000000","0.00256000"],["62642.91000000","0.00032000"],["62642.98000000","0.00068000"],["62643.09000000","0.00016000"],["62643.20000000","0.00008000"],["62643.56000000","0.00018000"],["62643.57000000","0.17274000"],["62643.76000000","0.00008000"],["62643.97000000","0.00030000"]]}}
{"t":18.5635,"stream":"btcusdt@depth@100ms","data":{"e":"depthUpdate","E":1783948021214,"s":"BTCUSDT","U":97344798554,"u":97344798565,"b":[["62640.33000000","0.00172000"],["62638.50000000","0.00798000"],["56377.03000000","0.00480000"],["56377.00000000","0.02164000"],["50112.92000000","0.00000000"]],"a":[["62641.15000000","0.82110000"],["62642.41000000","0.07781000"],["62642.98000000","0.00000000"],["63580.77000000","0.00030000"]]}}
{"t":18.5639,"stream":"btcusdt@depth20@100ms","data":{"lastUpdateId":97344798565,"bids":[["62641.14000000","3.73356000"],["62641.13000000","0.00034000"],["62641.12000000","0.00016000"],["62640.96000000","0.00018000"],["62640.95000000","0.63005000"],["62640.90000000","0.00008000"],["62640.35000000","0.00018000"],["62640.34000000","0.30016000"],["62640.33000000","0.00172000"],["62640.32000000","0.00009000"],["62640.01000000","0.02755000"],["62640.00000000","1.91799000"],["62639.99000000","0.54430000"],["62639.98000000","0.00449000"],["62639.86000000","0.00400000"],["62639.83000000","0.00016000"],["62639.77000000","0.04091000"],["62638.50000000","0.00798000"],["62638.49000000","0.03966000"],["62638.44000000","0.00009000"]],"asks":[["62641.15000000","0.82110000"],["62641.16000000","0.00115000"],["62641.17000000","0.00016000"],["62641.98000000","0.00008000"],["62641.99000000","0.00041000"],["62642.00000000","0.03469000"],["62642.19000000","0.00009000"],["62642.25000000","0.00008000"],["62642.40000000","0.00018000"],["62642.41000000","0.07781000"],["62642.81000000","0.00009000"],["62642.83000000","0.00256000"],["62642.91000000","0.00032000"],["62643.09000000","0.00016000"],["62643.20000000","0.00008000"],["62643.56000000","0.00018000"],["62643.57000000","0.17274000"],["62643.76000000","0.00008000"],["62643.97000000","0.00030000"],["62643.99000000","0.00018000"]]}}
{"t":18.6645,"stream":"btcusdt@depth@100ms","data":{"e":"depthUpdate","E":1783948021314,"s":"BTCUSDT","U":97344798566,"u":97344798584,"b":[["62640.34000000","0.30016000"],["62640.33000000","0.00154000"],["62639.77000000","0.04091000"],["62638.50000000","0.00816000"],["62634.24000000","0.00000000"],["62633.23000000","0.13521000"],["62540.91000000","0.00072000"],["56377.03000000","0.00480000"]],"a":[["62680.81000000","0.39440000"]]}}
{"t":18.6648,"stream":"btcusdt@depth20@100ms","data":{"lastUpdateId":97344798584,"bids":[["62641.14000000","3.73356000"],["62641.13000000","0.00034000"],["62641.12000000","0.00016000"],["62640.96000000","0.00018000"],["62640.95000000","0.63005000"],["62640.90000000","0.00008000"],["62640.35000000","0.00018000"],["62640.34000000","0.30016000"],["62640.33000000","0.00154000"],["62640.32000000","0.00009000"],["62640.01000000","0.02755000"],["62640.00000000","1.91799000"],["62639.99000000","0.54430000"],["62639.98000000","0.00449000"],["62639.86000000","0.00400000"],["62639.83000000","0.00016000"],["62639.77000000","0.04091000"],["62638.50000000","0.00816000"],["62638.49000000","0.03966000"],["62638.44000000","0.00009000"]],"asks":[["62641.15000000","0.82110000"],["62641.16000000","0.00115000"],["62641.17000000","0.00016000"],["62641.98000000","0.00008000"],["62641.99000000","0.00041000"],["62642.00000000","0.03469000"],["62642.19000000","0.00009000"],["62642.25000000","0.00008000"],["62642.40000000","0.00018000"],["62642.41000000","0.07781000"],["62642.81000000","0.00009000"],["62642.83000000","0.00256000"],["62642.91000000","0.00032000"],["62643.09000000","0.00016000"],["62643.20000000","0.00008000"],["62643.56000000","0.00018000"],["62643.57000000","0.17274000"],["62643.76000000","0.00008000"],["62643.97000000","0.00030000"],["62643.99000000","0.00018000"]]}}
{"t":18.7633,"stream":"btcusdt@depth@100ms","data":{"e":"depthUpdate","E":1783948021414,"s":"BTCUSDT","U":97344798585,"u":97344798592,"b":[["56377.03000000","0.00480000"]],"a":[["62641.15000000","0.13188000"],["62642.41000000","0.07713000"],["62642.98000000","0.00068000"],["62654.40000000","0.14473000"],["62655.97000000","0.15104000"]]}}
{"t":18.7635,"stream":"btcusdt@depth20@100ms","data":{"lastUpdateId":97344798592,"bids":[["62641.14000000","3.73356000"],["62641.13000000","0.00034000"],["62641.12000000","0.00016000"],["62640.96000000","0.00018000"],["62640.95000000","0.63005000"],["62640.90000000","0.00008000"],["62640.35000000","0.00018000"],["62640.34000000","0.30016000"],["62640.33000000","0.00154000"],["62640.32000000","0.00009000"],["62640.01000000","0.02755000"],["62640.00000000","1.91799000"],["62639.99000000","0.54430000"],["62639.98000000","0.00449000"],["62639.86000000","0.00400000"],["62639.83000000","0.00016000"],["62639.77000000","0.04091000"],["62638.50000000","0.00816000"],["62638.49000000","0.03966000"],["62638.44000000","0.00009000"]],"asks":[["62641.15000000","0.13188000"],["62641.16000000","0.00115000"],["62641.17000000","0.00016000"],["62641.98000000","0.00008000"],["62641.99000000","0.00041000"],["62642.00000000","0.03469000"],["62642.19000000","0.00009000"],["62642.25000000","0.00008000"],["62642.40000000","0.00018000"],["62642.41000000","0.07713000"],["62642.81000000","0.00009000"],["62642.83000000","0.00256000"],["62642.91000000","0.00032000"],["62642.98000000","0.00068000"],["62643.09000000","0.00016000"],["62643.20000000","0.00008000"],["62643.56000000","0.00018000"],["62643.57000000","0.17274000"],["62643.76000000","0.00008000"],["62643.97000000","0.00030000"]]}}
{"t":18.8647,"stream":"btcusdt@depth@100ms","data":{"e":"depthUpdate","E":1783948021514,"s":"BTCUSDT","U":97344798593,"u":97344798609,"b":[["62640.91000000","0.00000000"],["62640.34000000","0.30181000"],["62640.33000000","0.00000000"],["62638.51000000","0.00798000"],["62638.50000000","0.00018000"],["62580.50000000","2.89954000"],["62576.28000000","0.00000000"],["62509.63000000","0.00072000"],["56377.03000000","0.00460000"]],"a":[["62641.15000000","0.82110000"],["62642.41000000","0.07781000"],["62642.98000000","0.00000000"],["62651.48000000","0.00000000"],["62652.24000000","0.00798000"],["62764.09000000","0.00000000"],["62785.34000000","0.02500000"],["64500.00000000","21.49134000"],["64600.00000000","8.57300000"]]}}
{"t":18.8649,"stream":"btcusdt@depth20@100ms","data":{"lastUpdateId":97344798609,"bids":[["62641.14000000","3.73356000"],["62641.13000000","0.00034000"],["62641.12000000","0.00016000"],["62640.96000000","0.00018000"],["62640.95000000","0.63005000"],["62640.90000000","0.00008000"],["62640.35000000","0.00018000"],["62640.34000000","0.30181000"],["62640.32000000","0.00009000"],["62640.01000000","0.02755000"],["62640.00000000","1.91799000"],["62639.99000000","0.54430000"],["62639.98000000","0.00449000"],["62639.86000000","0.00400000"],["62639.83000000","0.00016000"],["62639.77000000","0.04091000"],["62638.51000000","0.00798000"],["62638.50000000","0.00018000"],["62638.49000000","0.03966000"],["62638.44000000","0.00009000"]],"asks":[["62641.15000000","0.82110000"],["62641.16000000","0.00115000"],["62641.17000000","0.00016000"],["62641.98000000","0.00008000"],["62641.99000000","0.00041000"],["62642.00000000","0.03469000"],["62642.19000000","0.00009000"],["62642.25000000","0.00008000"],["62642.40000000","0.00018000"],["62642.41000000","0.07781000"],["62642.81000000","0.00009000"],["62642.83000000","0.00256000"],["62642.91000000","0.00032000"],["62643.09000000","0.00016000"],["62643.20000000","0.00008000"],["62643.56000000","0.00018000"],["62643.57000000","0.17274000"],["62643.76000000","0.00008000"],["62643.97000000","0.00030000"],["62643.99000000","0.00018000"]]}}
{"t":18.9641,"stream":"btcusdt@depth@100ms","data":{"e":"depthUpdate","E":1783948021614,"s":"BTCUSDT","U":97344798610,"u":97344798624,"b":[["62639.77000000","0.04091000"],["62638.51000000","0.00816000"],["62638.50000000","0.00000000"],["62624.15000000","0.00981000"],["62616.27000000","0.00000000"],["56377.03000000","0.00460000"]],"a":[["62677.74000000","0.00000000"]]}}
{"t":18.9643,"stream":"btcusdt@depth20@100ms","data":{"lastUpdateId":97344798624,"bids":[["62641.14000000","3.73356000"],["62641.13000000","0.00034000"],["62641.12000000","0.00016000"],["62640.96000000","0.00018000"],["62640.95000000","0.63005000"],["62640.90000000","0.00008000"],["62640.35000000","0.00018000"],["62640.34000000","0.30181000"],["62640.32000000","0.00009000"],["62640.01000000","0.02755000"],["62640.00000000","1.91799000"],["62639.99000000","0.54430000"],["62639.98000000","0.00449000"],["62639.86000000","0.00400000"],["62639.83000000","0.00016000"],["62639.77000000","0.04091000"],["62638.51000000","0.00816000"],["62638.49000000","0.03966000"],["62638.44000000","0.00009000"],["62638.42000000","0.00008000"]],"asks":[["62641.15000000","0.82110000"],["62641.16000000","0.00115000"],["62641.17000000","0.00016000"],["62641.98000000","0.00008000"],["62641.99000000","0.00041000"],["62642.00000000","0.03469000"],["62642.19000000","0.00009000"],["62642.25000000","0.00008000"],["62642.40000000","0.00018000"],["62642.41000000","0.07781000"],["62642.81000000","0.00009000"],["62642.83000000","0.00256000"],["62642.91000000","0.00032000"],["62643.09000000","0.00016000"],["62643.20000000","0.00008000"],["62643.56000000","0.00018000"],["62643.57000000","0.17274000"],["62643.76000000","0.00008000"],["62643.97000000","0.00030000"],["62643.99000000","0.00018000"]]}}
{"t":19.0643,"stream":"btcusdt@depth@100ms","data":{"e":"depthUpdate","E":1783948021714,"s":"BTCUSDT","U":97344798625,"u":97344798630,"b":[["56377.03000000","0.00460000"]],"a":[["62677.93000000","0.00011000"],["62741.37000000","0.00087000"]]}}
