{"t":28.064,"stream":"btcusdt@depth20@100ms","data":{"lastUpdateId":97344801871,"bids":[["62643.40000000","3.96441000"],["62643.39000000","0.00034000"],["62643.38000000","0.00016000"],["62643.21000000","0.00018000"],["62643.20000000","0.00008000"],["62643.09000000","0.00018000"],["62643.08000000","0.30022000"],["62643.00000000","0.00400000"],["62642.11000000","0.00010000"],["62642.03000000","0.00018000"],["62642.02000000","0.47618000"],["62642.01000000","0.00018000"],["62642.00000000","0.07536000"],["62641.99000000","0.62613000"],["62641.98000000","0.00008000"],["62641.97000000","0.00008000"],["62641.91000000","0.00009000"],["62641.90000000","0.15880000"],["62641.89000000","0.00024000"],["62641.67000000","0.07500000"]],"asks":[["62643.41000000","0.10191000"],["62643.42000000","0.00115000"],["62643.43000000","0.00016000"],["62643.44000000","0.00009000"],["62643.99000000","0.00018000"],["62644.00000000","0.02418000"],["62644.07000000","0.00009000"],["62644.12000000","0.00008000"],["62644.29000000","0.00008000"],["62645.00000000","0.00008000"],["62645.26000000","0.00068000"],["62645.47000000","0.00009000"],["62645.55000000","0.00265000"],["62645.56000000","0.17274000"],["62645.95000000","0.00009000"],["62645.99000000","0.00018000"],["62646.00000000","0.02418000"],["62646.40000000","0.00128000"],["62646.55000000","0.00008000"],["62646.69000000","0.00018000"]]}}
{"t":28.1648,"stream":"btcusdt@depth@100ms","data":{"e":"depthUpdate","E":1783948030814,"s":"BTCUSDT","U":97344801872,"u":97344801934,"b":[["62643.40000000","7.15708000"],["62643.21000000","0.00000000"],["62643.09000000","0.00000000"],["62643.08000000","0.30040000"],["62642.03000000","0.00000000"],["62642.01000000","0.00000000"],["62642.00000000","0.07518000"],["62641.91000000","0.00000000"],["62640.20000000","0.00000000"],["62635.60000000","0.00000000"],["62633.09000000","0.57524000"],["62625.70000000","0.00000000"],["62617.73000000","0.00000000"],["56379.06000000","0.00470000"]],"a":[["62643.41000000","0.10200000"],["62643.42000000","0.00124000"],["62645.55000000","0.00000000"],["62645.56000000","0.00018000"],["62647.14000000","0.00256000"],["62647.81000000","0.00018000"],["62647.95000000","0.00000000"],["62647.99000000","0.00009000"],["62648.60000000","0.12756000"],["62650.35000000","0.00009000"],["62655.86000000","0.00000000"],["62657.03000000","0.00400000"],["62659.79000000","0.00000000"],["62660.79000000","0.00015000"],["62661.21000000","0.00000000"],["62662.25000000","0.00000000"],["62662.55000000","0.00000000"],["62662.97000000","0.00000000"],["62663.00000000","0.00400000"],["62663.99000000","0.43597000"],["62664.40000000","0.00000000"],["62665.23000000","0.00200000"],["62666.25000000","0.79878000"],["62675.35000000","0.57485000"],["62766.66000000","0.00018000"],["62766.69000000","0.00000000"]]}}
{"t":28.1651,"stream":"btcusdt@depth20@100ms","data":{"lastUpdateId":97344801934,"bids":[["62643.40000000","7.15708000"],["62643.39000000","0.00034000"],["62643.38000000","0.00016000"],["62643.20000000","0.00008000"],["62643.08000000","0.30040000"],["62643.00000000","0.00400000"],["62642.11000000","0.00010000"],["62642.02000000","0.47618000"],["62642.00000000","0.07518000"],["62641.99000000","0.62613000"],["62641.98000000","0.00008000"],["62641.97000000","0.00008000"],["62641.90000000","0.15880000"],["62641.89000000","0.00024000"],["62641.67000000","0.07500000"],["62641.43000000","0.00400000"],["62641.15000000","0.07500000"],["62641.14000000","0.41228000"],["62640.95000000","0.00008000"],["62640.90000000","0.00008000"]],"asks":[["62643.41000000","0.10200000"],["62643.42000000","0.00124000"],["62643.43000000","0.00016000"],["62643.44000000","0.00009000"],["62643.99000000","0.00018000"],["62644.00000000","0.02418000"],["62644.07000000","0.00009000"],["62644.12000000","0.00008000"],["62644.29000000","0.00008000"],["62645.00000000","0.00008000"],["62645.26000000","0.00068000"],["62645.47000000","0.00009000"],["62645.56000000","0.00018000"],["62645.95000000","0.00009000"],["62645.99000000","0.00018000"],["62646.00000000","0.02418000"],["62646.40000000","0.00128000"],["62646.55000000","0.00008000"],["62646.69000000","0.00018000"],["62646.70000000","0.06910000"]]}}
{"t":28.2637,"stream":"btcusdt@depth@100ms","data":{"e":"depthUpdate","E":1783948030914,"s":"BTCUSDT","U":97344801935,"u":97344801979,"b":[["62643.40000000","7.23385000"],["62643.08000000","0.30032000"],["62607.84000000","0.77000000"],["56379.06000000","0.00470000"]],"a":[["62643.41000000","0.10183000"],["62643.42000000","0.00115000"],["62644.00000000","0.02418000"],["62645.56000000","0.00000000"],["62646.70000000","0.06902000"],["62647.80000000","0.00574000"],["62647.81000000","0.00000000"],["62647.99000000","0.00018000"],["62648.59000000","0.00009000"],["62649.70000000","0.13992000"],["62649.84000000","0.06902000"],["62651.16000000","0.09025000"],["62654.33000000","0.00000000"],["62656.40000000","2.05721000"],["62656.41000000","0.00000000"],["62659.15000000","0.01252000"],["62661.68000000","0.59905000"],["62662.55000000","0.13444000"],["62663.99000000","0.00000000"],["62766.66000000","0.00018000"],["62766.89000000","0.00000000"],["62772.74000000","0.00000000"]]}}
{"t":28.2637,"stream":"btcusdt@depth20@100ms","data":{"lastUpdateId":97344801979,"bids":[["62643.40000000","7.23385000"],["62643.39000000","0.00034000"],["62643.38000000","0.00016000"],["62643.20000000","0.00008000"],["62643.08000000","0.30032000"],["62643.00000000","0.00400000"],["62642.11000000","0.00010000"],["62642.02000000","0.47618000"],["62642.00000000","0.07518000"],["62641.99000000","0.62613000"],["62641.98000000","0.00008000"],["62641.97000000","0.00008000"],["62641.90000000","0.15880000"],["62641.89000000","0.00024000"],["62641.67000000","0.07500000"],["62641.43000000","0.00400000"],["62641.15000000","0.07500000"],["62641.14000000","0.41228000"],["62640.95000000","0.00008000"],["62640.90000000","0.00008000"]],"asks":[["62643.41000000","0.10183000"],["62643.42000000","0.00115000"],["62643.43000000","0.00016000"],["62643.44000000","0.00009000"],["62643.99000000","0.00018000"],["62644.00000000","0.02418000"],["62644.07000000","0.00009000"],["62644.12000000","0.00008000"],["62644.29000000","0.00008000"],["62645.00000000","0.00008000"],["62645.26000000","0.00068000"],["62645.47000000","0.00009000"],["62645.95000000","0.00009000"],["62645.99000000","0.00018000"],["62646.00000000","0.02418000"],["62646.40000000","0.00128000"],["62646.55000000","0.00008000"],["62646.69000000","0.00018000"],["62646.70000000","0.06902000"],["62647.14000000","0.00256000"]]}}
{"t":28.2677,"stream":"btcusdt@aggTrade","data":{"e":"aggTrade","E":1783948030918,"s":"BTCUSDT","a":4013160647,"p":"62643.41000000","q":"0.00400000","f":6501834080,"l":6501834097,"T":1783948030917,"m":false,"M":true}}
{"t":28.3648,"stream":"btcusdt@depth@100ms","data":{"e":"depthUpdate","E":1783948031014,"s":"BTCUSDT","U":97344801980,"u":97344802033,"b":[["62643.40000000","7.23376000"],["62641.15000000","0.07518000"],["62591.53000000","0.00000000"],["62590.69000000","0.00113000"],["62571.41000000","0.00000000"],["62528.01000000","0.00045000"],["56379.06000000","0.00470000"],["50114.72000000","0.00039000"]],"a":[["62643.41000000","0.09914000"],["62643.42000000","0.00106000"],["62647.14000000","0.00000000"],["62648.60000000","0.12764000"],["62648.67000000","0.17512000"],["62650.32000000","0.14101000"],["62650.37000000","0.11806000"],["62651.16000000","0.00000000"],["62655.03000000","0.00000000"],["62659.15000000","0.61161000"],["62661.68000000","0.00000000"],["62681.85000000","0.00008000"],["62766.89000000","0.00000000"]]}}
{"t":28.3649,"stream":"btcusdt@depth20@100ms","data":{"lastUpdateId":97344802033,"bids":[["62643.40000000","7.23376000"],["62643.39000000","0.00034000"],["62643.38000000","0.00016000"],["62643.20000000","0.00008000"],["62643.08000000","0.30032000"],["62643.00000000","0.00400000"],["62642.11000000","0.00010000"],["62642.02000000","0.47618000"],["62642.00000000","0.07518000"],["62641.99000000","0.62613000"],["62641.98000000","0.00008000"],["62641.97000000","0.00008000"],["62641.90000000","0.15880000"],["62641.89000000","0.00024000"],["62641.67000000","0.07500000"],["62641.43000000","0.00400000"],["62641.15000000","0.07518000"],["62641.14000000","0.41228000"],["62640.95000000","0.00008000"],["62640.90000000","0.00008000"]],"asks":[["62643.41000000","0.09914000"],["62643.42000000","0.00106000"],["62643.43000000","0.00016000"],["62643.44000000","0.00009000"],["62643.99000000","0.00018000"],["62644.00000000","0.02418000"],["62644.07000000","0.00009000"],["62644.12000000","0.00008000"],["62644.29000000","0.00008000"],["62645.00000000","0.00008000"],["62645.26000000","0.00068000"],["62645.47000000","0.00009000"],["62645.95000000","0.00009000"],["62645.99000000","0.00018000"],["62646.00000000","0.02418000"],["62646.40000000","0.00128000"],["62646.55000000","0.00008000"],["62646.69000000","0.00018000"],["62646.70000000","0.06902000"],["62647.42000000","0.00008000"]]}}
{"t":28.4261,"stream":"btcusdt@aggTrade","data":{"e":"aggTrade","E":1783948031076,"s":"BTCUSDT","a":4013160648,"p":"62643.41000000","q":"0.00330000","f":6501834098,"l":6501834098,"T":1783948031075,"m":false,"M":true}}
{"t":28.4262,"stream":"btcusdt@aggTrade","data":{"e":"aggTrade","E":1783948031076,"s":"BTCUSDT","a":4013160649,"p":"62643.41000000","q":"0.00330000","f":6501834099,"l":6501834099,"T":1783948031076,"m":false,"M":true}}
{"t":28.4639,"stream":"btcusdt@depth@100ms","data":{"e":"depthUpdate","E":1783948031114,"s":"BTCUSDT","U":97344802034,"u":97344802073,"b":[["62636.02000000","0.68507000"],["62629.38000000","0.00008000"],["62601.50000000","1.92184000"],["62590.69000000","0.00113000"],["62584.13000000","0.01737000"],["62528.01000000","0.00000000"],["56379.06000000","0.00470000"],["50114.72000000","0.00039000"],["40000.00000000","258.07540000"]],"a":[["62643.41000000","0.09236000"],["62643.42000000","0.00097000"],["62648.60000000","0.12764000"],["62648.67000000","0.17530000"],["62649.84000000","0.06884000"],["62650.37000000","0.00000000"],["62654.45000000","0.00008000"],["62655.77000000","0.07000000"],["62656.40000000","0.13966000"],["62658.17000000","0.08000000"],["62678.03000000","0.57483000"]]}}
{"t":28.4642,"stream":"btcusdt@depth20@100ms","data":{"lastUpdateId":97344802073,"bids":[["62643.40000000","7.23376000"],["62643.39000000","0.00034000"],["62643.38000000","0.00016000"],["62643.20000000","0.00008000"],["62643.08000000","0.30032000"],["62643.00000000","0.00400000"],["62642.11000000","0.00010000"],["62642.02000000","0.47618000"],["62642.00000000","0.07518000"],["62641.99000000","0.62613000"],["62641.98000000","0.00008000"],["62641.97000000","0.00008000"],["62641.90000000","0.15880000"],["62641.89000000","0.00024000"],["62641.67000000","0.07500000"],["62641.43000000","0.00400000"],["62641.15000000","0.07518000"],["62641.14000000","0.41228000"],["62640.95000000","0.00008000"],["62640.90000000","0.00008000"]],"asks":[["62643.41000000","0.09236000"],["62643.42000000","0.00097000"],["62643.43000000","0.00016000"],["62643.44000000","0.00009000"],["62643.99000000","0.00018000"],["62644.00000000","0.02418000"],["62644.07000000","0.00009000"],["62644.12000000","0.00008000"],["62644.29000000","0.00008000"],["62645.00000000","0.00008000"],["62645.26000000","0.00068000"],["62645.47000000","0.00009000"],["62645.95000000","0.00009000"],["62645.99000000","0.00018000"],["62646.00000000","0.02418000"],["62646.40000000","0.00128000"],["62646.55000000","0.00008000"],["62646.69000000","0.00018000"],["62646.70000000","0.06902000"],["62647.42000000","0.00008000"]]}}
{"t":28.564,"stream":"btcusdt@depth@100ms","data":{"e":"depthUpdate","E":1783948031214,"s":"BTCUSDT","U":97344802074,"u":97344802090,"b":[["62643.21000000","0.01100000"],["61703.74000000","0.00030000"],["56379.06000000","0.00470000"],["50114.72000000","0.00000000"]],"a":[["62650.32000000","0.14093000"],["62655.77000000","0.03000000"],["62657.97000000","0.04000000"],["62658.81000000","0.13966000"],["62659.14000000","0.13966000"],["62687.15000000","0.00000000"],["62698.47000000","0.01692000"]]}}
{"t":28.5641,"stream":"btcusdt@depth20@100ms","data":{"lastUpdateId":97344802090,"bids":[["62643.40000000","7.23376000"],["62643.39000000","0.00034000"],["62643.38000000","0.00016000"],["62643.21000000","0.01100000"],["62643.20000000","0.00008000"],["62643.08000000","0.30032000"],["62643.00000000","0.00400000"],["62642.11000000","0.00010000"],["62642.02000000","0.47618000"],["62642.00000000","0.07518000"],["62641.99000000","0.62613000"],["62641.98000000","0.00008000"],["62641.97000000","0.00008000"],["62641.90000000","0.15880000"],["62641.89000000","0.00024000"],["62641.67000000","0.07500000"],["62641.43000000","0.00400000"],["62641.15000000","0.07518000"],["62641.14000000","0.41228000"],["62640.95000000","0.00008000"]],"asks":[["62643.41000000","0.09236000"],["62643.42000000","0.00097000"],["62643.43000000","0.00016000"],["62643.44000000","0.00009000"],["62643.99000000","0.00018000"],["62644.00000000","0.02418000"],["62644.07000000","0.00009000"],["62644.12000000","0.00008000"],["62644.29000000","0.00008000"],["62645.00000000","0.00008000"],["62645.26000000","0.00068000"],["62645.47000000","0.00009000"],["62645.95000000","0.00009000"],["62645.99000000","0.00018000"],["62646.00000000","0.02418000"],["62646.40000000","0.00128000"],["62646.55000000","0.00008000"],["62646.69000000","0.00018000"],["62646.70000000","0.06902000"],["62647.42000000","0.00008000"]]}}
{"t":28.6638,"stream":"btcusdt@depth@100ms","data":{"e":"depthUpdate","E":1783948031314,"s":"BTCUSDT","U":97344802091,"u":97344802104,"b":[["62643.40000000","7.23376000"],["62641.14000000","0.41220000"],["62640.02000000","0.00000000"],["62639.99000000","0.15830000"],["62638.82000000","0.59909000"],["56379.06000000","0.00490000"],["56379.00000000","0.00020000"]],"a":[["62680.17000000","0.00000000"],["63583.07000000","0.00067000"]]}}
{"t":28.664,"stream":"btcusdt@depth20@100ms","data":{"lastUpdateId":97344802104,"bids":[["62643.40000000","7.23376000"],["62643.39000000","0.00034000"],["62643.38000000","0.00016000"],["62643.21000000","0.01100000"],["62643.20000000","0.00008000"],["62643.08000000","0.30032000"],["62643.00000000","0.00400000"],["62642.11000000","0.00010000"],["62642.02000000","0.47618000"],["62642.00000000","0.07518000"],["62641.99000000","0.62613000"],["62641.98000000","0.00008000"],["62641.97000000","0.00008000"],["62641.90000000","0.15880000"],["62641.89000000","0.00024000"],["62641.67000000","0.07500000"],["62641.43000000","0.00400000"],["62641.15000000","0.07518000"],["62641.14000000","0.41220000"],["62640.95000000","0.00008000"]],"asks":[["62643.41000000","0.09236000"],["62643.42000000","0.00097000"],["62643.43000000","0.00016000"],["62643.44000000","0.00009000"],["62643.99000000","0.00018000"],["62644.00000000","0.02418000"],["62644.07000000","0.00009000"],["62644.12000000","0.00008000"],["62644.29000000","0.00008000"],["62645.00000000","0.00008000"],["62645.26000000","0.00068000"],["62645.47000000","0.00009000"],["62645.95000000","0.00009000"],["62645.99000000","0.00018000"],["62646.00000000","0.02418000"],["62646.40000000","0.00128000"],["62646.55000000","0.00008000"],["62646.69000000","0.00018000"],["62646.70000000","0.06902000"],["62647.42000000","0.00008000"]]}}
{"t":28.7368,"stream":"btcusdt@aggTrade","data":{"e":"aggTrade","E":1783948031387,"s":"BTCUSDT","a":4013160650,"p":"62643.41000000","q":"0.00053000","f":6501834100,"l":6501834100,"T":1783948031386,"m":false,"M":true}}
{"t":28.7633,"stream":"btcusdt@depth@100ms","data":{"e":"depthUpdate","E":1783948031414,"s":"BTCUSDT","U":97344802105,"u":97344802123,"b":[["62615.33000000","0.00000000"],["56379.06000000","0.00480000"],["56379.05000000","0.00010000"],["56379.00000000","0.00000000"],["50115.00000000","0.14313000"]],"a":[["62643.41000000","0.09183000"],["62651.02000000","0.11678000"],["62651.75000000","0.00000000"],["62656.85000000","0.14472000"],["62658.41000000","0.15104000"],["62680.32000000","0.00011000"]]}}
{"t":28.7635,"stream":"btcusdt@depth20@100ms","data":{"lastUpdateId":97344802123,"bids":[["62643.40000000","7.23376000"],["62643.39000000","0.00034000"],["62643.38000000","0.00016000"],["62643.21000000","0.01100000"],["62643.20000000","0.00008000"],["62643.08000000","0.30032000"],["62643.00000000","0.00400000"],["62642.11000000","0.00010000"],["62642.02000000","0.47618000"],["62642.00000000","0.07518000"],["62641.99000000","0.62613000"],["62641.98000000","0.00008000"],["62641.97000000","0.00008000"],["62641.90000000","0.15880000"],["62641.89000000","0.00024000"],["62641.67000000","0.07500000"],["62641.43000000","0.00400000"],["62641.15000000","0.07518000"],["62641.14000000","0.41220000"],["62640.95000000","0.00008000"]],"asks":[["62643.41000000","0.09183000"],["62643.42000000","0.00097000"],["62643.43000000","0.00016000"],["62643.44000000","0.00009000"],["62643.99000000","0.00018000"],["62644.00000000","0.02418000"],["62644.07000000","0.00009000"],["62644.12000000","0.00008000"],["62644.29000000","0.00008000"],["62645.00000000","0.00008000"],["62645.26000000","0.00068000"],["62645.47000000","0.00009000"],["62645.95000000","0.00009000"],["62645.99000000","0.00018000"],["62646.00000000","0.02418000"],["62646.40000000","0.00128000"],["62646.55000000","0.00008000"],["62646.69000000","0.00018000"],["62646.70000000","0.06902000"],["62647.42000000","0.00008000"]]}}
{"t":28.8647,"stream":"btcusdt@depth@100ms","data":{"e":"depthUpdate","E":1783948031514,"s":"BTCUSDT","U":97344802124,"u":97344802134,"b":[["62618.75000000","0.21500000"],["62079.61000000","0.00000000"],["56379.06000000","0.00480000"],["50115.00000000","0.13713000"]],"a":[["62777.10000000","0.02500000"],["62785.34000000","0.00000000"]]}}
{"t":28.8649,"stream":"btcusdt@depth20@100ms","data":{"lastUpdateId":97344802134,"bids":[["62643.40000000","7.23376000"],["62643.39000000","0.00034000"],["62643.38000000","0.00016000"],["62643.21000000","0.01100000"],["62643.20000000","0.00008000"],["62643.08000000","0.30032000"],["62643.00000000","0.00400000"],["62642.11000000","0.00010000"],["62642.02000000","0.47618000"],["62642.00000000","0.07518000"],["62641.99000000","0.62613000"],["62641.98000000","0.00008000"],["62641.97000000","0.00008000"],["62641.90000000","0.15880000"],["62641.89000000","0.00024000"],["62641.67000000","0.07500000"],["62641.43000000","0.00400000"],["62641.15000000","0.07518000"],["62641.14000000","0.41220000"],["62640.95000000","0.00008000"]],"asks":[["62643.41000000","0.09183000"],["62643.42000000","0.00097000"],["62643.43000000","0.00016000"],["62643.44000000","0.00009000"],["62643.99000000","0.00018000"],["62644.00000000","0.02418000"],["62644.07000000","0.00009000"],["62644.12000000","0.00008000"],["62644.29000000","0.00008000"],["62645.00000000","0.00008000"],["62645.26000000","0.00068000"],["62645.47000000","0.00009000"],["62645.95000000","0.00009000"],["62645.99000000","0.00018000"],["62646.00000000","0.02418000"],["62646.40000000","0.00128000"],["62646.55000000","0.00008000"],["62646.69000000","0.00018000"],["62646.70000000","0.06902000"],["62647.42000000","0.00008000"]]}}
{"t":28.9645,"stream":"btcusdt@depth@100ms","data":{"e":"depthUpdate","E":1783948031614,"s":"BTCUSDT","U":97344802135,"u":97344802146,"b":[["62607.84000000","0.00000000"],["62485.58000000","0.00518000"],["56379.06000000","0.00480000"]],"a":[["62650.32000000","0.14101000"],["62650.37000000","0.11555000"],["62651.02000000","0.00000000"],["62767.12000000","0.00000000"]]}}
{"t":28.9647,"stream":"btcusdt@depth20@100ms","data":{"lastUpdateId":97344802146,"bids":[["62643.40000000","7.23376000"],["62643.39000000","0.00034000"],["62643.38000000","0.00016000"],["62643.21000000","0.01100000"],["62643.20000000","0.00008000"],["62643.08000000","0.30032000"],["62643.00000000","0.00400000"],["62642.11000000","0.00010000"],["62642.02000000","0.47618000"],["62642.00000000","0.07518000"],["62641.99000000","0.62613000"],["62641.98000000","0.00008000"],["62641.97000000","0.00008000"],["62641.90000000","0.15880000"],["62641.89000000","0.00024000"],["62641.67000000","0.07500000"],["62641.43000000","0.00400000"],["62641.15000000","0.07518000"],["62641.14000000","0.41220000"],["62640.95000000","0.00008000"]],"asks":[["62643.41000000","0.09183000"],["62643.42000000","0.00097000"],["62643.43000000","0.00016000"],["62643.44000000","0.00009000"],["62643.99000000","0.00018000"],["62644.00000000","0.02418000"],["62644.07000000","0.00009000"],["62644.12000000","0.00008000"],["62644.29000000","0.00008000"],["62645.00000000","0.00008000"],["62645.26000000","0.00068000"],["62645.47000000","0.00009000"],["62645.95000000","0.00009000"],["62645.99000000","0.00018000"],["62646.00000000","0.02418000"],["62646.40000000","0.00128000"],["62646.55000000","0.00008000"],["62646.69000000","0.00018000"],["62646.70000000","0.06902000"],["62647.42000000","0.00008000"]]}}
{"t":29.0647,"stream":"btcusdt@depth@100ms","data":{"e":"depthUpdate","E":1783948031714,"s":"BTCUSDT","U":97344802147,"u":97344802160,"b":[["62642.02000000","0.47781000"],["62533.79000000","0.02500000"],["56379.06000000","0.00480000"],["33000.00000000","33.37028000"]],"a":[["62643.41000000","0.09192000"],["62648.67000000","0.17538000"],["62649.04000000","0.11600000"],["62650.32000000","0.14093000"],["62650.37000000","0.00000000"],["62664.71000000","0.00000000"]]}}
{"t":29.0649,"stream":"btcusdt@depth20@100ms","data":{"lastUpdateId":97344802160,"bids":[["62643.40000000","7.23376000"],["62643.39000000","0.00034000"],["62643.38000000","0.00016000"],["62643.21000000","0.01100000"],["62643.20000000","0.00008000"],["62643.08000000","0.30032000"],["62643.00000000","0.00400000"],["62642.11000000","0.00010000"],["62642.02000000","0.47781000"],["62642.00000000","0.07518000"],["62641.99000000","0.62613000"],["62641.98000000","0.00008000"],["62641.97000000","0.00008000"],["62641.90000000","0.15880000"],["62641.89000000","0.00024000"],["62641.67000000","0.07500000"],["62641.43000000","0.00400000"],["62641.15000000","0.07518000"],["62641.14000000","0.41220000"],["62640.95000000","0.00008000"]],"asks":[["62643.41000000","0.09192000"],["62643.42000000","0.00097000"],["62643.43000000","0.00016000"],["62643.44000000","0.00009000"],["62643.99000000","0.00018000"],["62644.00000000","0.02418000"],["62644.07000000","0.00009000"],["62644.12000000","0.00008000"],["62644.29000000","0.00008000"],["62645.00000000","0.00008000"],["62645.26000000","0.00068000"],["62645.47000000","0.00009000"],["62645.95000000","0.00009000"],["62645.99000000","0.00018000"],["62646.00000000","0.02418000"],["62646.40000000","0.00128000"],["62646.55000000","0.00008000"],["62646.69000000","0.00018000"],["62646.70000000","0.06902000"],["62647.42000000","0.00008000"]]}}
{"t":29.1633,"stream":"btcusdt@depth@100ms","data":{"e":"depthUpdate","E":1783948031814,"s":"BTCUSDT","U":97344802161,"u":97344802179,"b":[["62584.72000000","2.89943000"],["62582.61000000","0.00000000"],["62504.57000000","0.00999000"],["62501.77000000","0.00000000"],["62496.72000000","6.36757000"],["56379.06000000","0.00480000"]],"a":[["62648.67000000","0.17538000"],["62649.04000000","0.11618000"],["62649.70000000","0.13974000"],["62767.11000000","0.00000000"],["68907.75000000","0.00008000"]]}}
{"t":29.1636,"stream":"btcusdt@depth20@100ms","data":{"lastUpdateId":97344802179,"bids":[["62643.40000000","7.23376000"],["62643.39000000","0.00034000"],["62643.38000000","0.00016000"],["62643.21000000","0.01100000"],["62643.20000000","0.00008000"],["62643.08000000","0.30032000"],["62643.00000000","0.00400000"],["62642.11000000","0.00010000"],["62642.02000000","0.47781000"],["62642.00000000","0.07518000"],["62641.99000000","0.62613000"],["62641.98000000","0.00008000"],["62641.97000000","0.00008000"],["62641.90000000","0.15880000"],["62641.89000000","0.00024000"],["62641.67000000","0.07500000"],["62641.43000000","0.00400000"],["62641.15000000","0.07518000"],["62641.14000000","0.41220000"],["62640.95000000","0.00008000"]],"asks":[["62643.41000000","0.09192000"],["62643.42000000","0.00097000"],["62643.43000000","0.00016000"],["62643.44000000","0.00009000"],["62643.99000000","0.00018000"],["62644.00000000","0.02418000"],["62644.07000000","0.00009000"],["62644.12000000","0.00008000"],["62644.29000000","0.00008000"],["62645.00000000","0.00008000"],["62645.26000000","0.00068000"],["62645.47000000","0.00009000"],["62645.95000000","0.00009000"],["62645.99000000","0.00018000"],["62646.00000000","0.02418000"],["62646.40000000","0.00128000"],["62646.55000000","0.00008000"],["62646.69000000","0.00018000"],["62646.70000000","0.06902000"],["62647.42000000","0.00008000"]]}}
{"t":29.2637,"stream":"btcusdt@depth@100ms","data":{"e":"depthUpdate","E":1783948031914,"s":"BTCUSDT","U":97344802180,"u":97344802188,"b":[["56379.06000000","0.00460000"]],"a":[["62767.11000000","0.09192000"],["68907.75000000","0.00000000"]]}}
{"t":29.2639,"stream":"btcusdt@depth20@100ms","data":{"lastUpdateId":97344802188,"bids":[["62643.40000000","7.23376000"],["62643.39000000","0.00034000"],["62643.38000000","0.00016000"],["62643.21000000","0.01100000"],["62643.20000000","0.00008000"],["62643.08000000","0.30032000"],["62643.00000000","0.00400000"],["62642.11000000","0.00010000"],["62642.02000000","0.47781000"],["62642.00000000","0.07518000"],["62641.99000000","0.62613000"],["62641.98000000","0.00008000"],["62641.97000000","0.00008000"],["62641.90000000","0.15880000"],["62641.89000000","0.00024000"],["62641.67000000","0.07500000"],["62641.43000000","0.00400000"],["62641.15000000","0.07518000"],["62641.14000000","0.41220000"],["62640.95000000","0.00008000"]],"asks":[["62643.41000000","0.09192000"],["62643.42000000","0.00097000"],["62643.43000000","0.00016000"],["62643.44000000","0.00009000"],["62643.99000000","0.00018000"],["62644.00000000","0.02418000"],["62644.07000000","0.00009000"],["62644.12000000","0.00008000"],["62644.29000000","0.00008000"],["62645.00000000","0.00008000"],["62645.26000000","0.00068000"],["62645.47000000","0.00009000"],["62645.95000000","0.00009000"],["62645.99000000","0.00018000"],["62646.00000000","0.02418000"],["62646.40000000","0.00128000"],["62646.55000000","0.00008000"],["62646.69000000","0.00018000"],["62646.70000000","0.06902000"],["62647.42000000","0.00008000"]]}}
{"t":29.2678,"stream":"btcusdt@aggTrade","data":{"e":"aggTrade","E":1783948031917,"s":"BTCUSDT","a":4013160651,"p":"62643.41000000","q":"0.00031000","f":6501834101,"l":6501834101,"T":1783948031917,"m":false,"M":true}}
{"t":29.3552,"stream":"btcusdt@aggTrade","data":{"e":"aggTrade","E":1783948032004,"s":"BTCUSDT","a":4013160652,"p":"62643.41000000","q":"0.03194000","f":6501834102,"l":6501834102,"T":1783948032004,"m":false,"M":true}}
{"t":29.3648,"stream":"btcusdt@depth@100ms","data":{"e":"depthUpdate","E":1783948032014,"s":"BTCUSDT","U":97344802189,"u":97344802205,"b":[["62590.69000000","0.00113000"],["56379.06000000","0.00460000"],["50114.72000000","0.00039000"]],"a":[["62643.41000000","0.05967000"],["62645.26000000","0.00000000"],["62645.34000000","0.00068000"],["62767.11000000","0.00000000"]]}}
{"t":29.3649,"stream":"btcusdt@depth20@100ms","data":{"lastUpdateId":97344802205,"bids":[["62643.40000000","7.23376000"],["62643.39000000","0.00034000"],["62643.38000000","0.00016000"],["62643.21000000","0.01100000"],["62643.20000000","0.00008000"],["62643.08000000","0.30032000"],["62643.00000000","0.00400000"],["62642.11000000","0.00010000"],["62642.02000000","0.47781000"],["62642.00000000","0.07518000"],["62641.99000000","0.62613000"],["62641.98000000","0.00008000"],["62641.97000000","0.00008000"],["62641.90000000","0.15880000"],["62641.89000000","0.00024000"],["62641.67000000","0.07500000"],["62641.43000000","0.00400000"],["62641.15000000","0.07518000"],["62641.14000000","0.41220000"],["62640.95000000","0.00008000"]],"asks":[["62643.41000000","0.05967000"],["62643.42000000","0.00097000"],["62643.43000000","0.00016000"],["62643.44000000","0.00009000"],["62643.99000000","0.00018000"],["62644.00000000","0.02418000"],["62644.07000000","0.00009000"],["62644.12000000","0.00008000"],["62644.29000000","0.00008000"],["62645.00000000","0.00008000"],["62645.34000000","0.00068000"],["62645.47000000","0.00009000"],["62645.95000000","0.00009000"],["62645.99000000","0.00018000"],["62646.00000000","0.02418000"],["62646.40000000","0.00128000"],["62646.55000000","0.00008000"],["62646.69000000","0.00018000"],["62646.70000000","0.06902000"],["62647.42000000","0.00008000"]]}}
{"t":29.4638,"stream":"btcusdt@depth@100ms","data":{"e":"depthUpdate","E":1783948032114,"s":"BTCUSDT","U":97344802206,"u":97344802279,"b":[["62643.08000000","0.30040000"],["62642.03000000","0.47750000"],["62642.02000000","0.00018000"],["62641.99000000","0.56913000"],["62635.59000000","0.00000000"],["62630.65000000","0.47600000"],["62629.38000000","0.00008000"],["62614.54000000","0.00000000"],["62590.69000000","0.00113000"],["56379.06000000","0.00460000"],["50114.72000000","0.00039000"],["40000.00000000","258.07540000"]],"a":[["62643.41000000","0.05949000"],["62643.42000000","0.00088000"],["62648.67000000","0.00026000"],["62649.04000000","0.00018000"],["62649.65000000","0.00256000"],["62653.99000000","0.00000000"],["62654.45000000","0.00008000"],["62655.03000000","0.00009000"],["62655.77000000","0.00000000"],["62656.57000000","0.01000000"],["62657.97000000","0.06000000"],["62662.55000000","0.00000000"],["62663.99000000","0.36478000"],["62665.43000000","0.14829000"],["62671.23000000","0.00000000"],["62674.18000000","0.00000000"],["62680.32000000","0.00000000"],["62682.22000000","0.00000000"],["62682.25000000","0.00400000"],["62699.24000000","0.00000000"],["62767.11000000","0.00000000"],["62767.55000000","0.00000000"]]}}
{"t":29.464,"stream":"btcusdt@depth20@100ms","data":{"lastUpdateId":97344802279,"bids":[["62643.40000000","7.23376000"],["62643.39000000","0.00034000"],["62643.38000000","0.00016000"],["62643.21000000","0.01100000"],["62643.20000000","0.00008000"],["62643.08000000","0.30040000"],["62643.00000000","0.00400000"],["62642.11000000","0.00010000"],["62642.03000000","0.47750000"],["62642.02000000","0.00018000"],["62642.00000000","0.07518000"],["62641.99000000","0.56913000"],["62641.98000000","0.00008000"],["62641.97000000","0.00008000"],["62641.90000000","0.15880000"],["62641.89000000","0.00024000"],["62641.67000000","0.07500000"],["62641.43000000","0.00400000"],["62641.15000000","0.07518000"],["62641.14000000","0.41220000"]],"asks":[["62643.41000000","0.05949000"],["62643.42000000","0.00088000"],["62643.43000000","0.00016000"],["62643.44000000","0.00009000"],["62643.99000000","0.00018000"],["62644.00000000","0.02418000"],["62644.07000000","0.00009000"],["62644.12000000","0.00008000"],["62644.29000000","0.00008000"],["62645.00000000","0.00008000"],["62645.34000000","0.00068000"],["62645.47000000","0.00009000"],["62645.95000000","0.00009000"],["62645.99000000","0.00018000"],["62646.00000000","0.02418000"],["62646.40000000","0.00128000"],["62646.55000000","0.00008000"],["62646.69000000","0.00018000"],["62646.70000000","0.06902000"],["62647.42000000","0.00008000"]]}}
{"t":29.5634,"stream":"btcusdt@depth@100ms","data":{"e":"depthUpdate","E":1783948032214,"s":"BTCUSDT","U":97344802280,"u":97344802325,"b":[["62643.21000000","0.01118000"],["62643.08000000","0.30032000"],["62642.02000000","0.00000000"],["62619.39000000","1.20730000"],["61703.74000000","0.00030000"],["57628.79000000","0.00018000"],["56379.06000000","0.00460000"],["50114.72000000","0.00000000"]],"a":[["62648.60000000","0.12756000"],["62648.67000000","0.00000000"],["62649.04000000","0.00000000"],["62649.70000000","0.13992000"],["62649.84000000","0.06902000"],["62662.55000000","0.00000000"],["62663.98000000","0.47233000"],["62663.99000000","0.00000000"],["62680.49000000","0.00011000"],["62687.07000000","1.20600000"],["62767.29000000","0.00000000"]]}}
{"t":29.5639,"stream":"btcusdt@depth20@100ms","data":{"lastUpdateId":97344802325,"bids":[["62643.40000000","7.23376000"],["62643.39000000","0.00034000"],["62643.38000000","0.00016000"],["62643.21000000","0.01118000"],["62643.20000000","0.00008000"],["62643.08000000","0.30032000"],["62643.00000000","0.00400000"],["62642.11000000","0.00010000"],["62642.03000000","0.47750000"],["62642.00000000","0.07518000"],["62641.99000000","0.56913000"],["62641.98000000","0.00008000"],["62641.97000000","0.00008000"],["62641.90000000","0.15880000"],["62641.89000000","0.00024000"],["62641.67000000","0.07500000"],["62641.43000000","0.00400000"],["62641.15000000","0.07518000"],["62641.14000000","0.41220000"],["62640.95000000","0.00008000"]],"asks":[["62643.41000000","0.05949000"],["62643.42000000","0.00088000"],["62643.43000000","0.00016000"],["62643.44000000","0.00009000"],["62643.99000000","0.00018000"],["62644.00000000","0.02418000"],["62644.07000000","0.00009000"],["62644.12000000","0.00008000"],["62644.29000000","0.00008000"],["62645.00000000","0.00008000"],["62645.34000000","0.00068000"],["62645.47000000","0.00009000"],["62645.95000000","0.00009000"],["62645.99000000","0.00018000"],["62646.00000000","0.02418000"],["62646.40000000","0.00128000"],["62646.55000000","0.00008000"],["62646.69000000","0.00018000"],["62646.70000000","0.06902000"],["62647.42000000","0.00008000"]]}}
{"t":29.658,"stream":"btcusdt@aggTrade","data":{"e":"aggTrade","E":1783948032307,"s":"BTCUSDT","a":4013160653,"p":"62643.41000000","q":"0.05957000","f":6501834103,"l":6501834118,"T":1783948032306,"m":false,"M":true}}
{"t":29.6582,"stream":"btcusdt@aggTrade","data":{"e":"aggTrade","E":1783948032307,"s":"BTCUSDT","a":4013160654,"p":"62643.42000000","q":"0.00097000","f":6501834119,"l":6501834128,"T":1783948032306,"m":false,"M":true}}
{"t":29.6582,"stream":"btcusdt@aggTrade","data":{"e":"aggTrade","E":1783948032307,"s":"BTCUSDT","a":4013160655,"p":"62643.43000000","q":"0.00016000","f":6501834129,"l":6501834129,"T":1783948032306,"m":false,"M":true}}
{"t":29.6583,"stream":"btcusdt@aggTrade","data":{"e":"aggTrade","E":1783948032307,"s":"BTCUSDT","a":4013160656,"p":"62643.44000000","q":"0.00009000","f":6501834130,"l":6501834130,"T":1783948032306,"m":false,"M":true}}
{"t":29.6598,"stream":"btcusdt@aggTrade","data":{"e":"aggTrade","E":1783948032310,"s":"BTCUSDT","a":4013160657,"p":"62643.44000000","q":"0.00088000","f":6501834131,"l":6501834140,"T":1783948032309,"m":false,"M":true}}
{"t":29.6599,"stream":"btcusdt@aggTrade","data":{"e":"aggTrade","E":1783948032310,"s":"BTCUSDT","a":4013160658,"p":"62643.45000000","q":"0.00063000","f":6501834141,"l":6501834147,"T":1783948032309,"m":false,"M":true}}
{"t":29.6599,"stream":"btcusdt@aggTrade","data":{"e":"aggTrade","E":1783948032310,"s":"BTCUSDT","a":4013160659,"p":"62643.99000000","q":"0.00095000","f":6501834148,"l":6501834158,"T":1783948032309,"m":false,"M":true}}
{"t":29.6655,"stream":"btcusdt@depth@100ms","data":{"e":"depthUpdate","E":1783948032314,"s":"BTCUSDT","U":97344802326,"u":97344802769,"b":[["62643.99000000","5.36502000"],["62643.98000000","0.00034000"],["62643.97000000","0.00016000"],["62643.44000000","0.00000000"],["62643.43000000","2.32834000"],["62643.42000000","0.52722000"],["62643.41000000","0.38207000"],["62643.40000000","0.62151000"],["62643.39000000","0.00000000"],["62643.38000000","0.00000000"],["62643.08000000","0.00034000"],["62642.12000000","0.00798000"],["62642.03000000","0.00159000"],["62641.99000000","0.33913000"],["62641.90000000","0.15862000"],["62641.67000000","0.07482000"],["62641.15000000","0.07500000"],["62640.02000000","3.19267000"],["62639.34000000","0.00009000"],["62637.73000000","0.00009000"],["62637.57000000","0.47600000"],["62637.36000000","0.00009000"],["62635.63000000","0.00000000"],["62633.31000000","0.00000000"],["62629.83000000","0.00000000"],["62622.06000000","1.58220000"],["62619.50000000","0.53034000"],["62618.97000000","0.32250000"],["62612.55000000","0.00000000"],["62611.88000000","0.00000000"],["62606.56000000","0.00000000"],["62602.63000000","0.00000000"],["62594.84000000","0.00000000"],["62592.05000000","0.00000000"],["62550.19000000","0.00000000"],["62543.17000000","0.00016000"],["62480.81000000","0.00000000"],["62479.08000000","0.00000000"],["61703.74000000","0.00000000"],["56379.06000000","0.00000000"]],"a":[["62643.41000000","0.00000000"],["62643.42000000","0.00000000"],["62643.43000000","0.00000000"],["62643.44000000","0.00000000"],["62643.45000000","0.00000000"],["62643.99000000","0.00000000"],["62644.00000000","0.02533000"],["62644.01000000","0.00081000"],["62645.34000000","0.00000000"],["62645.47000000","0.00000000"],["62645.95000000","0.00077000"],["62646.70000000","0.06910000"],["62648.24000000","0.00000000"],["62648.54000000","0.00000000"],["62648.57000000","0.00018000"],["62648.58000000","0.00000000"],["62648.60000000","0.00018000"],["62649.48000000","0.17256000"],["62649.70000000","0.00026000"],["62650.00000000","0.03418000"],["62650.25000000","0.00009000"],["62650.32000000","0.00000000"],["62650.75000000","0.00000000"],["62650.80000000","0.00000000"],["62651.38000000","0.00000000"],["62651.39000000","0.00000000"],["62651.40000000","0.00000000"],["62651.42000000","0.00000000"],["62652.26000000","0.00000000"],["62652.94000000","0.09485000"],["62653.26000000","0.00000000"],["62653.90000000","0.00000000"],["62654.24000000","0.00000000"],["62654.52000000","0.00000000"],["62654.56000000","0.00000000"],["62655.51000000","0.00000000"],["62655.55000000","0.00000000"],["62656.57000000","0.00000000"],["62656.84000000","0.00798000"],["62657.03000000","0.00000000"],["62657.83000000","0.00400000"],["62657.97000000","0.02000000"],["62658.17000000","0.00000000"],["62658.27000000","0.13000000"],["62659.14000000","0.00000000"],["62659.15000000","0.01252000"],["62659.16000000","0.00000000"],["62659.39000000","1.91755000"],["62661.99000000","0.59907000"],["62662.56000000","0.55604000"],["62663.98000000","0.00000000"],["62664.82000000","0.00000000"],["62665.43000000","0.01277000"],["62665.76000000","0.00000000"],["62666.61000000","0.00000000"],["62667.90000000","0.00000000"],["62669.23000000","0.00000000"],["62671.92000000","0.00200000"],["62672.90000000","0.00000000"],["62673.00000000","0.02295000"],["62674.96000000","0.00000000"],["62675.00000000","0.00000000"],["62675.20000000","0.00008000"],["62675.85000000","0.00000000"],["62675.95000000","0.03295000"],["62680.49000000","0.57491000"],["62684.57000000","0.00168000"],["62700.91000000","0.00000000"],["62701.01000000","0.06078000"],["62717.62000000","1.91755000"],["62717.63000000","0.00000000"],["62720.31000000","0.00000000"],["62767.29000000","0.00000000"],["62777.10000000","0.00000000"],["63583.07000000","0.00037000"]]}}
{"t":29.6658,"stream":"btcusdt@depth20@100ms","data":{"lastUpdateId":97344802769,"bids":[["62643.99000000","5.36502000"],["62643.98000000","0.00034000"],["62643.97000000","0.00016000"],["62643.43000000","2.32834000"],["62643.42000000","0.52722000"],["62643.41000000","0.38207000"],["62643.40000000","0.62151000"],["62643.21000000","0.01118000"],["62643.20000000","0.00008000"],["62643.08000000","0.00034000"],["62643.00000000","0.00400000"],["62642.12000000","0.00798000"],["62642.11000000","0.00010000"],["62642.03000000","0.00159000"],["62642.00000000","0.07518000"],["62641.99000000","0.33913000"],["62641.98000000","0.00008000"],["62641.97000000","0.00008000"],["62641.90000000","0.15862000"],["62641.89000000","0.00024000"]],"asks":[["62644.00000000","0.02533000"],["62644.01000000","0.00081000"],["62644.07000000","0.00009000"],["62644.12000000","0.00008000"],["62644.29000000","0.00008000"],["62645.00000000","0.00008000"],["62645.95000000","0.00077000"],["62645.99000000","0.00018000"],["62646.00000000","0.02418000"],["62646.40000000","0.00128000"],["62646.55000000","0.00008000"],["62646.69000000","0.00018000"],["62646.70000000","0.06910000"],["62647.42000000","0.00008000"],["62647.59000000","0.00008000"],["62647.80000000","0.00574000"],["62647.84000000","0.00009000"],["62647.99000000","0.00018000"],["62648.00000000","0.02418000"],["62648.40000000","0.00009000"]]}}
{"t":29.6659,"stream":"btcusdt@aggTrade","data":{"e":"aggTrade","E":1783948032316,"s":"BTCUSDT","a":4013160660,"p":"62644.00000000","q":"0.00400000","f":6501834159,"l":6501834159,"T":1783948032315,"m":false,"M":true}}
{"t":29.765,"stream":"btcusdt@depth@100ms","data":{"e":"depthUpdate","E":1783948032414,"s":"BTCUSDT","U":97344802770,"u":97344802905,"b":[["62643.99000000","8.94631000"],["62643.44000000","0.00000000"],["62643.43000000","2.32825000"],["62643.42000000","0.52740000"],["62643.41000000","0.98115000"],["62643.40000000","0.33315000"],["62643.21000000","0.01118000"],["62643.08000000","0.00016000"],["62642.12000000","0.00009000"],["62642.03000000","0.00000000"],["62640.02000000","0.00000000"],["62639.99000000","0.15822000"],["62638.82000000","0.00000000"],["62636.17000000","0.00009000"],["62635.62000000","0.05000000"],["62623.10000000","0.01000000"],["62622.38000000","0.00319000"],["62620.60000000","0.00000000"],["62591.20000000","0.00398000"],["62588.01000000","0.00000000"],["62506.18000000","1.20000000"],["62492.21000000","0.00000000"],["62479.67000000","0.00009000"],["56379.60000000","0.00040000"]],"a":[["62644.00000000","0.12132000"],["62644.01000000","0.00081000"],["62645.95000000","0.00009000"],["62646.40000000","0.00008000"],["62646.55000000","0.00000000"],["62646.70000000","0.06910000"],["62648.00000000","0.02418000"],["62648.57000000","0.00000000"],["62648.59000000","0.00000000"],["62648.60000000","0.00000000"],["62648.68000000","0.00008000"],["62649.47000000","0.00018000"],["62649.48000000","0.00018000"],["62649.65000000","0.00000000"],["62649.70000000","0.00008000"],["62649.83000000","0.00009000"],["62649.84000000","0.06926000"],["62650.27000000","0.02172000"],["62651.04000000","0.00000000"],["62651.50000000","0.00256000"],["62651.70000000","0.13966000"],["62652.94000000","0.00000000"],["62653.50000000","0.00000000"],["62656.09000000","0.13966000"],["62658.26000000","0.13966000"],["62659.38000000","0.00000000"],["62661.99000000","0.00000000"],["62662.28000000","0.59905000"],["62664.88000000","0.57495000"],["62666.80000000","0.13210000"],["62668.80000000","0.57499000"],["62673.00000000","0.00000000"],["62675.00000000","0.00419000"],["62675.35000000","0.00000000"],["62675.95000000","0.00000000"],["62676.00000000","0.03400000"],["62678.04000000","0.00000000"],["62680.49000000","0.00011000"],["62695.13000000","0.00000000"],["62696.77000000","0.00398000"],["62701.01000000","0.00000000"],["62741.24000000","0.00009000"],["62756.60000000","0.00000000"],["62759.99000000","0.00159000"],["62768.04000000","0.00000000"],["62768.05000000","0.00000000"]]}}
{"t":29.7652,"stream":"btcusdt@depth20@100ms","data":{"lastUpdateId":97344802905,"bids":[["62643.99000000","8.94631000"],["62643.98000000","0.00034000"],["62643.97000000","0.00016000"],["62643.43000000","2.32825000"],["62643.42000000","0.52740000"],["62643.41000000","0.98115000"],["62643.40000000","0.33315000"],["62643.21000000","0.01118000"],["62643.20000000","0.00008000"],["62643.08000000","0.00016000"],["62643.00000000","0.00400000"],["62642.12000000","0.00009000"],["62642.11000000","0.00010000"],["62642.00000000","0.07518000"],["62641.99000000","0.33913000"],["62641.98000000","0.00008000"],["62641.97000000","0.00008000"],["62641.90000000","0.15862000"],["62641.89000000","0.00024000"],["62641.67000000","0.07482000"]],"asks":[["62644.00000000","0.12132000"],["62644.01000000","0.00081000"],["62644.07000000","0.00009000"],["62644.12000000","0.00008000"],["62644.29000000","0.00008000"],["62645.00000000","0.00008000"],["62645.95000000","0.00009000"],["62645.99000000","0.00018000"],["62646.00000000","0.02418000"],["62646.40000000","0.00008000"],["62646.69000000","0.00018000"],["62646.70000000","0.06910000"],["62647.42000000","0.00008000"],["62647.59000000","0.00008000"],["62647.80000000","0.00574000"],["62647.84000000","0.00009000"],["62647.99000000","0.00018000"],["62648.00000000","0.02418000"],["62648.40000000","0.00009000"],["62648.68000000","0.00008000"]]}}
{"t":29.7671,"stream":"btcusdt@aggTrade","data":{"e":"aggTrade","E":1783948032417,"s":"BTCUSDT","a":4013160661,"p":"62644.00000000","q":"0.12138000","f":6501834160,"l":6501834180,"T":1783948032416,"m":false,"M":true}}
{"t":29.7673,"stream":"btcusdt@aggTrade","data":{"e":"aggTrade","E":1783948032417,"s":"BTCUSDT","a":4013160662,"p":"62644.01000000","q":"0.00063000","f":6501834181,"l":6501834187,"T":1783948032416,"m":false,"M":true}}
{"t":29.7673,"stream":"btcusdt@aggTrade","data":{"e":"aggTrade","E":1783948032417,"s":"BTCUSDT","a":4013160663,"p":"62644.12000000","q":"0.00016000","f":6501834188,"l":6501834189,"T":1783948032416,"m":false,"M":true}}
{"t":29.7674,"stream":"btcusdt@aggTrade","data":{"e":"aggTrade","E":1783948032417,"s":"BTCUSDT","a":4013160664,"p":"62644.29000000","q":"0.00016000","f":6501834190,"l":6501834191,"T":1783948032416,"m":false,"M":true}}
{"t":29.7731,"stream":"btcusdt@aggTrade","data":{"e":"aggTrade","E":1783948032421,"s":"BTCUSDT","a":4013160665,"p":"62645.00000000","q":"0.00112000","f":6501834192,"l":6501834204,"T":1783948032420,"m":false,"M":true}}
{"t":29.7733,"stream":"btcusdt@aggTrade","data":{"e":"aggTrade","E":1783948032421,"s":"BTCUSDT","a":4013160666,"p":"62645.01000000","q":"0.00063000","f":6501834205,"l":6501834211,"T":1783948032420,"m":false,"M":true}}
{"t":29.7733,"stream":"btcusdt@aggTrade","data":{"e":"aggTrade","E":1783948032421,"s":"BTCUSDT","a":4013160667,"p":"62645.95000000","q":"0.00009000","f":6501834212,"l":6501834212,"T":1783948032420,"m":false,"M":true}}
{"t":29.7734,"stream":"btcusdt@aggTrade","data":{"e":"aggTrade","E":1783948032421,"s":"BTCUSDT","a":4013160668,"p":"62645.99000000","q":"0.00027000","f":6501834213,"l":6501834215,"T":1783948032420,"m":false,"M":true}}
{"t":29.8639,"stream":"btcusdt@depth@100ms","data":{"e":"depthUpdate","E":1783948032514,"s":"BTCUSDT","U":97344802906,"u":97344803510,"b":[["62645.99000000","4.86065000"],["62645.98000000","0.00034000"],["62645.97000000","0.00016000"],["62645.94000000","0.00008000"],["62645.00000000","0.00008000"],["62644.99000000","3.85739000"],["62644.98000000","0.00000000"],["62644.97000000","0.00000000"],["62644.57000000","0.00400000"],["62644.29000000","0.47600000"],["62644.28000000","0.31376000"],["62644.11000000","0.00000000"],["62644.06000000","0.00000000"],["62644.05000000","0.00008000"],["62644.00000000","0.00000000"],["62643.99000000","0.41690000"],["62643.98000000","0.00000000"],["62643.97000000","0.00000000"],["62643.43000000","2.10325000"],["62643.42000000","0.00018000"],["62643.41000000","0.38207000"],["62643.40000000","0.09953000"],["62643.21000000","0.01118000"],["62643.08000000","0.00008000"],["62642.24000000","0.00270000"],["62642.12000000","0.00000000"],["62642.00000000","0.07500000"],["62641.99000000","0.33895000"],["62641.90000000","0.15862000"],["62641.89000000","0.00008000"],["62641.67000000","0.00000000"],["62641.15000000","0.00000000"],["62641.14000000","0.41228000"],["62640.91000000","0.59906000"],["62639.99000000","0.15814000"],["62639.73000000","0.00009000"],["62638.65000000","0.57519000"],["62638.53000000","0.00000000"],["62638.49000000","0.00000000"],["62638.17000000","0.00009000"],["62637.73000000","0.00000000"],["62636.43000000","0.14477000"],["62636.15000000","0.00200000"],["62635.40000000","0.00000000"],["62634.86000000","0.15109000"],["62633.88000000","0.00000000"],["62633.12000000","0.00000000"],["62632.31000000","0.00000000"],["62632.27000000","0.00000000"],["62631.97000000","0.03175000"],["62628.56000000","0.00000000"],["62626.29000000","0.00000000"],["62624.66000000","0.61528000"],["62623.06000000","0.00041000"],["62623.01000000","0.00000000"],["62619.93000000","0.00009000"],["62619.60000000","0.00000000"],["62619.45000000","0.00000000"],["62619.20000000","0.00000000"],["62616.80000000","0.00009000"],["62616.46000000","0.00000000"],["62614.40000000","0.00000000"],["62613.67000000","0.00009000"],["62613.33000000","0.00000000"],["62613.22000000","0.00000000"],["62612.08000000","0.00000000"],["62611.03000000","0.00000000"],["62610.88000000","0.74194000"],["62610.20000000","0.00000000"],["62610.18000000","0.01133000"],["62606.95000000","0.00000000"],["62600.98000000","0.00000000"],["62594.36000000","0.95860000"],["62593.47000000","0.00000000"],["62586.93000000","0.00000000"],["62570.02000000","0.00000000"],["62511.89000000","0.00025000"],["62479.67000000","0.00000000"],["62080.19000000","0.00010000"],["56381.40000000","0.00040000"],["56379.60000000","0.00000000"],["56379.05000000","0.00000000"]],"a":[["62644.00000000","0.00000000"],["62644.01000000","0.00000000"],["62644.07000000","0.00000000"],["62644.12000000","0.00000000"],["62644.29000000","0.00000000"],["62645.00000000","0.00000000"],["62645.01000000","0.00000000"],["62645.95000000","0.00000000"],["62645.99000000","0.00000000"],["62646.00000000","0.02595000"],["62646.01000000","0.00081000"],["62646.69000000","0.00000000"],["62646.70000000","0.00018000"],["62647.84000000","0.00000000"],["62648.00000000","0.02418000"],["62648.45000000","0.00009000"],["62649.47000000","0.00000000"],["62649.48000000","0.00000000"],["62649.83000000","0.00000000"],["62649.84000000","0.00034000"],["62649.99000000","0.00018000"],["62650.25000000","0.00000000"],["62650.26000000","0.00018000"],["62650.27000000","0.02172000"],["62651.50000000","0.00000000"],["62651.69000000","0.00018000"],["62651.70000000","0.13984000"],["62651.80000000","0.00897000"],["62651.90000000","0.00008000"],["62651.99000000","0.00009000"],["62652.26000000","0.00009000"],["62652.97000000","0.13965000"],["62653.32000000","0.00000000"],["62654.06000000","0.00000000"],["62654.20000000","0.00000000"],["62654.47000000","0.00128000"],["62655.10000000","0.17384000"],["62655.32000000","0.00000000"],["62655.35000000","0.00000000"],["62655.37000000","0.00009000"],["62655.69000000","0.01713000"],["62655.90000000","0.13964000"],["62655.96000000","0.00256000"],["62656.01000000","0.00000000"],["62656.10000000","0.00000000"],["62656.40000000","0.00000000"],["62656.65000000","0.00000000"],["62656.84000000","0.00000000"],["62656.85000000","0.00000000"],["62657.07000000","0.01303000"],["62657.19000000","0.00000000"],["62657.53000000","0.00009000"],["62657.83000000","0.00000000"],["62658.10000000","0.13204000"],["62658.41000000","0.00000000"],["62658.69000000","0.00798000"],["62658.81000000","0.00000000"],["62659.09000000","0.00400000"],["62659.37000000","0.13094000"],["62659.38000000","1.91755000"],["62659.39000000","0.00000000"],["62660.32000000","0.00000000"],["62660.66000000","0.00009000"],["62661.26000000","0.02000000"],["62661.96000000","0.01766000"],["62662.56000000","0.47600000"],["62663.00000000","0.00000000"],["62663.45000000","0.00000000"],["62663.79000000","0.00009000"],["62664.49000000","0.11423000"],["62664.88000000","0.00000000"],["62665.23000000","0.00000000"],["62665.36000000","0.00400000"],["62666.25000000","0.00000000"],["62666.59000000","0.00000000"],["62666.80000000","0.00000000"],["62666.93000000","0.00009000"],["62667.23000000","0.00200000"],["62667.33000000","0.00000000"],["62667.56000000","0.13591000"],["62667.68000000","0.00000000"],["62668.22000000","0.00000000"],["62668.23000000","0.01742000"],["62668.79000000","0.79874000"],["62669.72000000","0.00000000"],["62670.06000000","0.00009000"],["62670.50000000","0.00400000"],["62672.85000000","0.00000000"],["62673.19000000","0.00009000"],["62673.24000000","0.00000000"],["62673.50000000","0.00000000"],["62673.73000000","0.00000000"],["62674.50000000","0.01761000"],["62676.00000000","0.02400000"],["62676.19000000","0.00000000"],["62676.32000000","0.00009000"],["62676.47000000","0.57484000"],["62676.61000000","0.00000000"],["62676.85000000","0.03394000"],["62677.00000000","0.00000000"],["62678.00000000","0.03409000"],["62680.77000000","0.01768000"],["62688.15000000","0.00008000"],["62691.66000000","0.00000000"],["62693.83000000","0.00399000"],["62694.25000000","0.61925000"],["62701.25000000","0.00000000"],["62701.67000000","0.00000000"],["62701.91000000","0.06276000"],["62711.36000000","0.00000000"],["62711.83000000","0.00009000"],["62715.91000000","0.95860000"],["62753.69000000","0.00000000"],["62756.60000000","0.00159000"],["62968.50000000","0.00008000"]]}}
{"t":29.8645,"stream":"btcusdt@depth20@100ms","data":{"lastUpdateId":97344803510,"bids":[["62645.99000000","4.86065000"],["62645.98000000","0.00034000"],["62645.97000000","0.00016000"],["62645.94000000","0.00008000"],["62645.00000000","0.00008000"],["62644.99000000","3.85739000"],["62644.57000000","0.00400000"],["62644.29000000","0.47600000"],["62644.28000000","0.31376000"],["62644.05000000","0.00008000"],["62643.99000000","0.41690000"],["62643.43000000","2.10325000"],["62643.42000000","0.00018000"],["62643.41000000","0.38207000"],["62643.40000000","0.09953000"],["62643.21000000","0.01118000"],["62643.20000000","0.00008000"],["62643.08000000","0.00008000"],["62643.00000000","0.00400000"],["62642.24000000","0.00270000"]],"asks":[["62646.00000000","0.02595000"],["62646.01000000","0.00081000"],["62646.40000000","0.00008000"],["62646.70000000","0.00018000"],["62647.42000000","0.00008000"],["62647.59000000","0.00008000"],["62647.80000000","0.00574000"],["62647.99000000","0.00018000"],["62648.00000000","0.02418000"],["62648.40000000","0.00009000"],["62648.45000000","0.00009000"],["62648.68000000","0.00008000"],["62649.14000000","0.00023000"],["62649.60000000","0.00008000"],["62649.70000000","0.00008000"],["62649.84000000","0.00034000"],["62649.99000000","0.00018000"],["62650.00000000","0.03418000"],["62650.02000000","0.00250000"],["62650.26000000","0.00018000"]]}}
{"t":29.9645,"stream":"btcusdt@depth@100ms","data":{"e":"depthUpdate","E":1783948032614,"s":"BTCUSDT","U":97344803511,"u":97344803597,"b":[["62645.99000000","4.87083000"],["62644.99000000","3.63239000"],["62644.29000000","0.47618000"],["62644.28000000","0.31384000"],["62644.26000000","0.07482000"],["62643.99000000","0.13382000"],["62643.43000000","2.10307000"],["62643.42000000","0.00000000"],["62641.14000000","0.41236000"],["62641.12000000","0.07482000"],["62637.99000000","0.04988000"],["62635.47000000","0.75237000"],["62634.86000000","0.20097000"],["62631.27000000","0.00955000"],["62626.96000000","0.04320000"],["62624.15000000","0.00000000"],["62614.00000000","0.03400000"],["62613.22000000","0.22500000"],["62612.00000000","0.02400000"],["62606.95000000","0.22500000"],["56381.40000000","0.00080000"]],"a":[["62646.00000000","0.02595000"],["62646.01000000","0.00090000"],["62646.57000000","0.00009000"],["62646.70000000","0.00000000"],["62648.00000000","0.02418000"],["62649.28000000","0.00018000"],["62649.29000000","0.06884000"],["62649.84000000","0.00016000"],["62651.70000000","0.13992000"],["62651.80000000","0.00897000"],["62651.99000000","0.00000000"],["62652.00000000","0.02418000"],["62652.43000000","0.06884000"],["62652.97000000","0.13991000"],["62653.99000000","0.00256000"],["62654.47000000","0.00000000"],["62654.87000000","0.00000000"],["62655.10000000","0.00000000"],["62655.56000000","0.04989000"],["62658.69000000","0.05387000"],["62659.36000000","1.91755000"],["62659.38000000","0.00000000"],["62680.43000000","0.00000000"],["62688.06000000","0.00428000"],["62688.15000000","0.00000000"]]}}
{"t":29.9649,"stream":"btcusdt@depth20@100ms","data":{"lastUpdateId":97344803597,"bids":[["62645.99000000","4.87083000"],["62645.98000000","0.00034000"],["62645.97000000","0.00016000"],["62645.94000000","0.00008000"],["62645.00000000","0.00008000"],["62644.99000000","3.63239000"],["62644.57000000","0.00400000"],["62644.29000000","0.47618000"],["62644.28000000","0.31384000"],["62644.26000000","0.07482000"],["62644.05000000","0.00008000"],["62643.99000000","0.13382000"],["62643.43000000","2.10307000"],["62643.41000000","0.38207000"],["62643.40000000","0.09953000"],["62643.21000000","0.01118000"],["62643.20000000","0.00008000"],["62643.08000000","0.00008000"],["62643.00000000","0.00400000"],["62642.24000000","0.00270000"]],"asks":[["62646.00000000","0.02595000"],["62646.01000000","0.00090000"],["62646.40000000","0.00008000"],["62646.57000000","0.00009000"],["62647.42000000","0.00008000"],["62647.59000000","0.00008000"],["62647.80000000","0.00574000"],["62647.99000000","0.00018000"],["62648.00000000","0.02418000"],["62648.40000000","0.00009000"],["62648.45000000","0.00009000"],["62648.68000000","0.00008000"],["62649.14000000","0.00023000"],["62649.28000000","0.00018000"],["62649.29000000","0.06884000"],["62649.60000000","0.00008000"],["62649.70000000","0.00008000"],["62649.84000000","0.00016000"],["62649.99000000","0.00018000"],["62650.00000000","0.03418000"]]}}
{"t":30.0639,"stream":"btcusdt@depth@100ms","data":{"e":"depthUpdate","E":1783948032714,"s":"BTCUSDT","U":97344803598,"u":97344803644,"b":[["62645.99000000","4.91883000"],["62644.28000000","0.31384000"],["62644.26000000","0.07500000"],["62643.21000000","0.00000000"],["62642.00000000","0.08100000"],["62622.14000000","0.00000000"],["62610.57000000","0.00000000"],["57628.79000000","0.00000000"],["56381.40000000","0.00120000"]],"a":[["62647.94000000","0.00068000"],["62648.00000000","0.02418000"],["62649.29000000","0.06902000"],["62652.00000000","0.02418000"],["62652.97000000","0.13973000"],["62653.14000000","0.10702000"],["62654.10000000","0.00000000"],["62655.03000000","0.00000000"],["62655.69000000","0.00000000"],["62656.02000000","0.00000000"],["62657.07000000","0.00000000"],["62659.35000000","0.13980000"],["62659.37000000","0.00000000"],["62667.56000000","0.00000000"],["62671.12000000","0.00000000"],["62678.40000000","0.00038000"],["62743.63000000","0.00143000"]]}}
{"t":30.064,"stream":"btcusdt@depth20@100ms","data":{"lastUpdateId":97344803644,"bids":[["62645.99000000","4.91883000"],["62645.98000000","0.00034000"],["62645.97000000","0.00016000"],["62645.94000000","0.00008000"],["62645.00000000","0.00008000"],["62644.99000000","3.63239000"],["62644.57000000","0.00400000"],["62644.29000000","0.47618000"],["62644.28000000","0.31384000"],["62644.26000000","0.07500000"],["62644.05000000","0.00008000"],["62643.99000000","0.13382000"],["62643.43000000","2.10307000"],["62643.41000000","0.38207000"],["62643.40000000","0.09953000"],["62643.20000000","0.00008000"],["62643.08000000","0.00008000"],["62643.00000000","0.00400000"],["62642.24000000","0.00270000"],["62642.11000000","0.00010000"]],"asks":[["62646.00000000","0.02595000"],["62646.01000000","0.00090000"],["62646.40000000","0.00008000"],["62646.57000000","0.00009000"],["62647.42000000","0.00008000"],["62647.59000000","0.00008000"],["62647.80000000","0.00574000"],["62647.94000000","0.00068000"],["62647.99000000","0.00018000"],["62648.00000000","0.02418000"],["62648.40000000","0.00009000"],["62648.45000000","0.00009000"],["62648.68000000","0.00008000"],["62649.14000000","0.00023000"],["62649.28000000","0.00018000"],["62649.29000000","0.06902000"],["62649.60000000","0.00008000"],["62649.70000000","0.00008000"],["62649.84000000","0.00016000"],["62649.99000000","0.00018000"]]}}
{"t":30.1347,"stream":"btcusdt@aggTrade","data":{"e":"aggTrade","E":1783948032783,"s":"BTCUSDT","a":4013160669,"p":"62646.00000000","q":"0.02628000","f":6501834216,"l":6501834245,"T":1783948032782,"m":false,"M":true}}
{"t":30.1349,"stream":"btcusdt@aggTrade","data":{"e":"aggTrade","E":1783948032783,"s":"BTCUSDT","a":4013160670,"p":"62646.01000000","q":"0.00090000","f":6501834246,"l":6501834255,"T":1783948032782,"m":false,"M":true}}
{"t":30.1349,"stream":"btcusdt@aggTrade","data":{"e":"aggTrade","E":1783948032783,"s":"BTCUSDT","a":4013160671,"p":"62646.40000000","q":"0.00008000","f":6501834256,"l":6501834256,"T":1783948032782,"m":false,"M":true}}
{"t":30.1349,"stream":"btcusdt@aggTrade","data":{"e":"aggTrade","E":1783948032783,"s":"BTCUSDT","a":4013160672,"p":"62646.57000000","q":"0.00009000","f":6501834257,"l":6501834257,"T":1783948032782,"m":false,"M":true}}
{"t":30.1349,"stream":"btcusdt@aggTrade","data":{"e":"aggTrade","E":1783948032783,"s":"BTCUSDT","a":4013160673,"p":"62647.42000000","q":"0.00016000","f":6501834258,"l":6501834259,"T":1783948032782,"m":false,"M":true}}
{"t":30.1349,"stream":"btcusdt@aggTrade","data":{"e":"aggTrade","E":1783948032783,"s":"BTCUSDT","a":4013160674,"p":"62647.59000000","q":"0.00016000","f":6501834260,"l":6501834261,"T":1783948032782,"m":false,"M":true}}
{"t":30.1349,"stream":"btcusdt@aggTrade","data":{"e":"aggTrade","E":1783948032783,"s":"BTCUSDT","a":4013160675,"p":"62647.80000000","q":"0.00574000","f":6501834262,"l":6501834264,"T":1783948032782,"m":false,"M":true}}
{"t":30.1351,"stream":"btcusdt@aggTrade","data":{"e":"aggTrade","E":1783948032783,"s":"BTCUSDT","a":4013160676,"p":"62647.94000000","q":"0.00068000","f":6501834265,"l":6501834265,"T":1783948032782,"m":false,"M":true}}
{"t":30.1351,"stream":"btcusdt@aggTrade","data":{"e":"aggTrade","E":1783948032783,"s":"BTCUSDT","a":4013160677,"p":"62647.99000000","q":"0.00027000","f":6501834266,"l":6501834268,"T":1783948032782,"m":false,"M":true}}
{"t":30.1351,"stream":"btcusdt@aggTrade","data":{"e":"aggTrade","E":1783948032783,"s":"BTCUSDT","a":4013160678,"p":"62648.00000000","q":"0.02418000","f":6501834269,"l":6501834274,"T":1783948032782,"m":false,"M":true}}
{"t":30.1351,"stream":"btcusdt@aggTrade","data":{"e":"aggTrade","E":1783948032783,"s":"BTCUSDT","a":4013160679,"p":"62648.40000000","q":"0.00009000","f":6501834275,"l":6501834275,"T":1783948032782,"m":false,"M":true}}
{"t":30.1352,"stream":"btcusdt@aggTrade","data":{"e":"aggTrade","E":1783948032783,"s":"BTCUSDT","a":4013160680,"p":"62648.45000000","q":"0.00009000","f":6501834276,"l":6501834276,"T":1783948032782,"m":false,"M":true}}
{"t":30.1352,"stream":"btcusdt@aggTrade","data":{"e":"aggTrade","E":1783948032783,"s":"BTCUSDT","a":4013160681,"p":"62648.68000000","q":"0.00016000","f":6501834277,"l":6501834278,"T":1783948032782,"m":false,"M":true}}
{"t":30.1352,"stream":"btcusdt@aggTrade","data":{"e":"aggTrade","E":1783948032783,"s":"BTCUSDT","a":4013160682,"p":"62649.14000000","q":"0.00023000","f":6501834279,"l":6501834279,"T":1783948032782,"m":false,"M":true}}
{"t":30.1352,"stream":"btcusdt@aggTrade","data":{"e":"aggTrade","E":1783948032783,"s":"BTCUSDT","a":4013160683,"p":"62649.28000000","q":"0.00027000","f":6501834280,"l":6501834282,"T":1783948032782,"m":false,"M":true}}
{"t":30.1353,"stream":"btcusdt@aggTrade","data":{"e":"aggTrade","E":1783948032783,"s":"BTCUSDT","a":4013160684,"p":"62649.29000000","q":"0.02811000","f":6501834283,"l":6501834283,"T":1783948032782,"m":false,"M":true}}
{"t":30.1658,"stream":"btcusdt@depth@100ms","data":{"e":"depthUpdate","E":1783948032814,"s":"BTCUSDT","U":97344803645,"u":97344804121,"b":[["62649.28000000","5.74226000"],["62649.27000000","0.00034000"],["62649.26000000","0.00016000"],["62649.13000000","0.00000000"],["62649.03000000","0.02154000"],["62648.67000000","0.00000000"],["62648.18000000","0.00000000"],["62647.99000000","0.00000000"],["62647.98000000","0.29998000"],["62647.79000000","0.00000000"],["62647.71000000","0.00400000"],["62647.58000000","0.00000000"],["62647.20000000","0.00008000"],["62646.69000000","0.00000000"],["62646.48000000","0.00000000"],["62646.40000000","0.00008000"],["62646.39000000","0.00000000"],["62646.14000000","0.00400000"],["62646.02000000","0.00000000"],["62646.00000000","5.20917000"],["62645.99000000","0.57563000"],["62645.98000000","0.00000000"],["62645.97000000","0.00000000"],["62644.99000000","0.43972000"],["62643.43000000","2.10325000"],["62643.40000000","0.09935000"],["62643.02000000","0.00009000"],["62643.01000000","0.00400000"],["62642.78000000","0.00400000"],["62642.60000000","0.01000000"],["62642.38000000","0.00009000"],["62642.10000000","0.00012000"],["62641.99000000","0.15703000"],["62641.98000000","0.02008000"],["62641.97000000","0.00000000"],["62641.90000000","0.00000000"],["62641.14000000","0.30882000"],["62640.01000000","0.16879000"],["62639.99000000","0.07606000"],["62639.87000000","0.00009000"],["62639.83000000","0.00000000"],["62639.73000000","0.00000000"],["62639.48000000","0.02000000"],["62638.85000000","0.01000000"],["62638.44000000","0.15108000"],["62636.75000000","0.00009000"],["62636.53000000","0.00400000"],["62636.43000000","0.00000000"],["62635.80000000","0.00556000"],["62635.26000000","0.00008000"],["62635.14000000","0.00200000"],["62634.87000000","0.00000000"],["62634.86000000","0.04988000"],["62634.85000000","0.00000000"],["62633.86000000","0.00200000"],["62633.62000000","0.00009000"],["62633.60000000","0.00017000"],["62633.46000000","0.00009000"],["62633.27000000","0.00000000"],["62632.34000000","0.00000000"],["62630.87000000","0.00000000"],["62630.49000000","0.00024000"],["62630.10000000","0.01000000"],["62629.47000000","0.00000000"],["62629.38000000","0.00000000"],["62627.74000000","0.00000000"],["62627.35000000","0.00009000"],["62627.21000000","0.00319000"],["62627.00000000","0.00000000"],["62625.80000000","0.00000000"],["62624.61000000","0.00000000"],["62624.22000000","0.00032000"],["62624.16000000","0.00000000"],["62623.46000000","0.00000000"],["62623.20000000","0.00000000"],["62623.06000000","0.00032000"],["62622.59000000","0.00000000"],["62622.28000000","0.00000000"],["62621.09000000","0.00009000"],["62621.02000000","0.00000000"],["62619.93000000","0.00000000"],["62617.96000000","0.00009000"],["62617.60000000","0.47600000"],["62616.80000000","0.00000000"],["62615.70000000","0.00000000"],["62614.69000000","0.00000000"],["62613.67000000","0.00000000"],["62611.69000000","0.00015000"],["62604.40000000","0.00000000"],["62593.07000000","0.00000000"],["62592.90000000","0.00015000"],["62590.57000000","0.01000000"],["62585.61000000","0.00000000"],["62579.62000000","0.00000000"],["62574.10000000","0.00015000"],["62566.82000000","0.00000000"],["62555.31000000","0.00015000"],["62550.40000000","0.00000000"],["62548.03000000","0.00000000"],["62522.60000000","0.00010000"],["62482.55000000","0.00000000"],["62336.00000000","0.04812000"],["56384.36000000","0.00020000"],["56381.40000000","0.00000000"],["56381.00000000","0.05340000"]],"a":[["62646.00000000","0.00000000"],["62646.01000000","0.00000000"],["62646.40000000","0.00000000"],["62646.57000000","0.00000000"],["62647.42000000","0.00000000"],["62647.59000000","0.00000000"],["62647.80000000","0.00000000"],["62647.94000000","0.00000000"],["62647.99000000","0.00000000"],["62648.00000000","0.00000000"],["62648.40000000","0.00000000"],["62648.45000000","0.00000000"],["62648.68000000","0.00000000"],["62649.14000000","0.00000000"],["62649.28000000","0.00000000"],["62649.29000000","0.04224000"],["62649.30000000","0.00081000"],["62650.35000000","0.00000000"],["62651.49000000","0.00000000"],["62651.50000000","0.00000000"],["62651.69000000","0.00000000"],["62651.70000000","0.00026000"],["62651.99000000","0.00018000"],["62652.26000000","0.00000000"],["62652.27000000","0.00000000"],["62652.42000000","0.00018000"],["62652.43000000","0.06902000"],["62652.50000000","0.00000000"],["62652.75000000","0.00000000"],["62652.78000000","0.17512000"],["62652.86000000","0.00000000"],["62652.96000000","0.00009000"],["62652.97000000","0.13991000"],["62652.98000000","1.58158000"],["62653.03000000","0.00000000"],["62653.14000000","0.00008000"],["62653.99000000","0.00000000"],["62654.30000000","0.00256000"],["62654.45000000","0.00000000"],["62654.79000000","0.00000000"],["62655.55000000","0.00009000"],["62655.56000000","0.04589000"],["62655.90000000","0.00000000"],["62655.96000000","0.00000000"],["62656.09000000","0.00000000"],["62656.65000000","0.00008000"],["62656.93000000","0.00000000"],["62657.53000000","0.00000000"],["62657.88000000","0.00009000"],["62657.93000000","0.02100000"],["62657.97000000","0.03700000"],["62658.56000000","0.02000000"],["62658.57000000","0.04400000"],["62658.59000000","0.02000000"],["62658.69000000","0.04589000"],["62659.09000000","0.00000000"],["62659.36000000","0.00000000"],["62660.33000000","0.00008000"],["62660.39000000","0.00009000"],["62660.44000000","0.02100000"],["62660.66000000","0.00000000"],["62660.79000000","0.00000000"],["62661.07000000","0.01900000"],["62661.08000000","0.01800000"],["62661.41000000","0.01400000"],["62661.58000000","0.00400000"],["62661.61000000","0.00798000"],["62661.70000000","0.02300000"],["62661.73000000","0.02600000"],["62661.82000000","0.00009000"],["62662.28000000","0.00000000"],["62663.79000000","0.00000000"],["62664.11000000","0.14470000"],["62664.49000000","0.00000000"],["62664.95000000","0.00009000"],["62665.36000000","0.00000000"],["62665.67000000","0.15102000"],["62666.76000000","0.59905000"],["62666.93000000","0.00000000"],["62667.07000000","0.08646000"],["62667.23000000","0.00000000"],["62667.32000000","0.00000000"],["62667.87000000","0.00400000"],["62668.08000000","0.00183000"],["62668.29000000","0.00000000"],["62668.79000000","0.00000000"],["62670.06000000","0.00000000"],["62670.25000000","0.00200000"],["62670.50000000","0.00000000"],["62671.22000000","0.00009000"],["62671.92000000","0.00000000"],["62672.78000000","0.00000000"],["62673.03000000","0.79874000"],["62673.19000000","0.00000000"],["62674.14000000","0.00400000"],["62674.35000000","0.00009000"],["62674.45000000","0.00000000"],["62676.32000000","0.00000000"],["62676.50000000","0.00200000"],["62676.85000000","0.00000000"],["62677.40000000","0.61476000"],["62677.48000000","0.00009000"],["62677.98000000","0.03394000"],["62678.00000000","0.02409000"],["62678.40000000","0.00008000"],["62679.11000000","0.00400000"],["62679.57000000","0.57481000"],["62679.59000000","0.00000000"],["62679.97000000","0.00023000"],["62680.61000000","0.00109000"],["62681.00000000","0.01000000"],["62682.95000000","0.00000000"],["62686.88000000","0.00015000"],["62688.15000000","0.00000000"],["62698.38000000","0.00000000"],["62701.91000000","0.00000000"],["62702.64000000","0.00000000"],["62702.65000000","0.02000000"],["62703.04000000","0.06293000"],["62703.18000000","0.00000000"],["62703.53000000","0.01400000"],["62703.57000000","0.02100000"],["62704.22000000","0.02400000"],["62705.67000000","0.00015000"],["62705.79000000","0.01200000"],["62706.01000000","0.02000000"],["62706.08000000","0.24600000"],["62708.49000000","0.01800000"],["62709.12000000","0.01100000"],["62714.84000000","0.01700000"],["62717.17000000","0.00000000"],["62718.60000000","0.02600000"],["62724.47000000","0.00015000"],["62735.96000000","0.00000000"],["62743.26000000","0.00015000"],["62752.00000000","0.02417000"],["62775.00000000","0.00143000"],["62953.25000000","0.22500000"]]}}
{"t":30.1662,"stream":"btcusdt@depth20@100ms","data":{"lastUpdateId":97344804121,"bids":[["62649.28000000","5.74226000"],["62649.27000000","0.00034000"],["62649.26000000","0.00016000"],["62649.03000000","0.02154000"],["62647.98000000","0.29998000"],["62647.71000000","0.00400000"],["62647.20000000","0.00008000"],["62646.40000000","0.00008000"],["62646.14000000","0.00400000"],["62646.00000000","5.20917000"],["62645.99000000","0.57563000"],["62645.94000000","0.00008000"],["62645.00000000","0.00008000"],["62644.99000000","0.43972000"],["62644.57000000","0.00400000"],["62644.29000000","0.47618000"],["62644.28000000","0.31384000"],["62644.26000000","0.07500000"],["62644.05000000","0.00008000"],["62643.99000000","0.13382000"]],"asks":[["62649.29000000","0.04224000"],["62649.30000000","0.00081000"],["62649.60000000","0.00008000"],["62649.70000000","0.00008000"],["62649.84000000","0.00016000"],["62649.99000000","0.00018000"],["62650.00000000","0.03418000"],["62650.02000000","0.00250000"],["62650.26000000","0.00018000"],["62650.27000000","0.02172000"],["62650.77000000","0.00009000"],["62651.61000000","0.00009000"],["62651.70000000","0.00026000"],["62651.80000000","0.00897000"],["62651.86000000","0.00032000"],["62651.90000000","0.00008000"],["62651.99000000","0.00018000"],["62652.00000000","0.02418000"],["62652.31000000","0.00029000"],["62652.42000000","0.00018000"]]}}
{"t":30.2648,"stream":"btcusdt@depth@100ms","data":{"e":"depthUpdate","E":1783948032914,"s":"BTCUSDT","U":97344804122,"u":97344804219,"b":[["62649.28000000","5.75678000"],["62649.03000000","0.02172000"],["62647.98000000","0.30016000"],["62645.99000000","0.56563000"],["62644.94000000","0.00032000"],["62644.28000000","0.00034000"],["62644.26000000","0.00018000"],["62643.99000000","0.13364000"],["62643.43000000","2.10307000"],["62643.41000000","0.07531000"],["62641.98000000","0.02000000"],["62641.46000000","0.00009000"],["62641.14000000","0.30874000"],["62641.12000000","0.00000000"],["62639.99000000","0.06828000"],["62637.99000000","0.00000000"],["62634.86000000","0.00000000"],["62632.60000000","0.01000000"],["62630.10000000","0.00000000"],["62622.38000000","0.00000000"],["62617.00000000","0.01000000"],["62614.00000000","0.02400000"],["62607.16000000","0.00000000"],["62589.38000000","0.00112000"],["62588.54000000","0.00536000"],["62576.25000000","0.00000000"],["62575.28000000","0.00000000"],["62485.68000000","0.00000000"],["56384.36000000","0.00060000"],["56381.00000000","0.05320000"]],"a":[["62649.29000000","0.00501000"],["62649.30000000","0.00081000"],["62650.27000000","0.00018000"],["62651.70000000","0.00008000"],["62652.42000000","0.00000000"],["62652.43000000","0.00026000"],["62652.77000000","0.00018000"],["62652.78000000","0.17530000"],["62652.97000000","0.13983000"],["62652.98000000","1.58158000"],["62653.14000000","0.00000000"],["62655.56000000","0.00000000"],["62657.13000000","0.02554000"],["62657.45000000","0.01732000"],["62658.09000000","0.13979000"],["62658.69000000","0.00000000"],["62669.65000000","0.02000000"],["62671.78000000","0.00000000"],["62672.19000000","0.00000000"],["62680.07000000","0.00000000"],["62680.46000000","0.00000000"],["62680.85000000","0.00000000"],["62688.58000000","0.00617000"],["62688.70000000","0.00434000"],["62689.03000000","0.00426000"],["62706.01000000","0.00000000"],["62718.60000000","0.01300000"],["62821.54000000","0.00009000"],["62824.67000000","0.00000000"]]}}
{"t":30.2653,"stream":"btcusdt@depth20@100ms","data":{"lastUpdateId":97344804219,"bids":[["62649.28000000","5.75678000"],["62649.27000000","0.00034000"],["62649.26000000","0.00016000"],["62649.03000000","0.02172000"],["62647.98000000","0.30016000"],["62647.71000000","0.00400000"],["62647.20000000","0.00008000"],["62646.40000000","0.00008000"],["62646.14000000","0.00400000"],["62646.00000000","5.20917000"],["62645.99000000","0.56563000"],["62645.94000000","0.00008000"],["62645.00000000","0.00008000"],["62644.99000000","0.43972000"],["62644.94000000","0.00032000"],["62644.57000000","0.00400000"],["62644.29000000","0.47618000"],["62644.28000000","0.00034000"],["62644.26000000","0.00018000"],["62644.05000000","0.00008000"]],"asks":[["62649.29000000","0.00501000"],["62649.30000000","0.00081000"],["62649.60000000","0.00008000"],["62649.70000000","0.00008000"],["62649.84000000","0.00016000"],["62649.99000000","0.00018000"],["62650.00000000","0.03418000"],["62650.02000000","0.00250000"],["62650.26000000","0.00018000"],["62650.27000000","0.00018000"],["62650.77000000","0.00009000"],["62651.61000000","0.00009000"],["62651.70000000","0.00008000"],["62651.80000000","0.00897000"],["62651.86000000","0.00032000"],["62651.90000000","0.00008000"],["62651.99000000","0.00018000"],["62652.00000000","0.02418000"],["62652.31000000","0.00029000"],["62652.43000000","0.00026000"]]}}
{"t":30.3225,"stream":"btcusdt@aggTrade","data":{"e":"aggTrade","E":1783948032972,"s":"BTCUSDT","a":4013160685,"p":"62649.29000000","q":"0.00526000","f":6501834284,"l":6501834304,"T":1783948032972,"m":false,"M":true}}
{"t":30.328,"stream":"btcusdt@aggTrade","data":{"e":"aggTrade","E":1783948032972,"s":"BTCUSDT","a":4013160686,"p":"62649.30000000","q":"0.00081000","f":6501834305,"l":6501834313,"T":1783948032972,"m":false,"M":true}}
{"t":30.3281,"stream":"btcusdt@aggTrade","data":{"e":"aggTrade","E":1783948032972,"s":"BTCUSDT","a":4013160687,"p":"62649.60000000","q":"0.00008000","f":6501834314,"l":6501834314,"T":1783948032972,"m":false,"M":true}}
{"t":30.3281,"stream":"btcusdt@aggTrade","data":{"e":"aggTrade","E":1783948032972,"s":"BTCUSDT","a":4013160688,"p":"62649.70000000","q":"0.00016000","f":6501834315,"l":6501834316,"T":1783948032972,"m":false,"M":true}}
{"t":30.3281,"stream":"btcusdt@aggTrade","data":{"e":"aggTrade","E":1783948032972,"s":"BTCUSDT","a":4013160689,"p":"62649.84000000","q":"0.00032000","f":6501834317,"l":6501834320,"T":1783948032972,"m":false,"M":true}}
{"t":30.3282,"stream":"btcusdt@aggTrade","data":{"e":"aggTrade","E":1783948032972,"s":"BTCUSDT","a":4013160690,"p":"62649.99000000","q":"0.00027000","f":6501834321,"l":6501834323,"T":1783948032972,"m":false,"M":true}}
{"t":30.3282,"stream":"btcusdt@aggTrade","data":{"e":"aggTrade","E":1783948032972,"s":"BTCUSDT","a":4013160691,"p":"62650.00000000","q":"0.03418000","f":6501834324,"l":6501834330,"T":1783948032972,"m":false,"M":true}}
{"t":30.3282,"stream":"btcusdt@aggTrade","data":{"e":"aggTrade","E":1783948032972,"s":"BTCUSDT","a":4013160692,"p":"62650.02000000","q":"0.00250000","f":6501834331,"l":6501834331,"T":1783948032972,"m":false,"M":true}}
{"t":30.3282,"stream":"btcusdt@aggTrade","data":{"e":"aggTrade","E":1783948032972,"s":"BTCUSDT","a":4013160693,"p":"62650.77000000","q":"0.00009000","f":6501834332,"l":6501834332,"T":1783948032972,"m":false,"M":true}}
{"t":30.3282,"stream":"btcusdt@aggTrade","data":{"e":"aggTrade","E":1783948032972,"s":"BTCUSDT","a":4013160694,"p":"62651.61000000","q":"0.00009000","f":6501834333,"l":6501834333,"T":1783948032972,"m":false,"M":true}}
{"t":30.3282,"stream":"btcusdt@aggTrade","data":{"e":"aggTrade","E":1783948032972,"s":"BTCUSDT","a":4013160695,"p":"62651.70000000","q":"0.00016000","f":6501834334,"l":6501834335,"T":1783948032972,"m":false,"M":true}}
{"t":30.3283,"stream":"btcusdt@aggTrade","data":{"e":"aggTrade","E":1783948032972,"s":"BTCUSDT","a":4013160696,"p":"62651.80000000","q":"0.00897000","f":6501834336,"l":6501834338,"T":1783948032972,"m":false,"M":true}}
{"t":30.3283,"stream":"btcusdt@aggTrade","data":{"e":"aggTrade","E":1783948032972,"s":"BTCUSDT","a":4013160697,"p":"62651.86000000","q":"0.00032000","f":6501834339,"l":6501834339,"T":1783948032972,"m":false,"M":true}}
{"t":30.3283,"stream":"btcusdt@aggTrade","data":{"e":"aggTrade","E":1783948032972,"s":"BTCUSDT","a":4013160698,"p":"62651.90000000","q":"0.00016000","f":6501834340,"l":6501834341,"T":1783948032972,"m":false,"M":true}}
{"t":30.3283,"stream":"btcusdt@aggTrade","data":{"e":"aggTrade","E":1783948032972,"s":"BTCUSDT","a":4013160699,"p":"62651.99000000","q":"0.00027000","f":6501834342,"l":6501834344,"T":1783948032972,"m":false,"M":true}}
{"t":30.3283,"stream":"btcusdt@aggTrade","data":{"e":"aggTrade","E":1783948032972,"s":"BTCUSDT","a":4013160700,"p":"62652.00000000","q":"0.02418000","f":6501834345,"l":6501834350,"T":1783948032972,"m":false,"M":true}}
{"t":30.3285,"stream":"btcusdt@aggTrade","data":{"e":"aggTrade","E":1783948032972,"s":"BTCUSDT","a":4013160701,"p":"62652.31000000","q":"0.00029000","f":6501834351,"l":6501834351,"T":1783948032972,"m":false,"M":true}}
{"t":30.3285,"stream":"btcusdt@aggTrade","data":{"e":"aggTrade","E":1783948032972,"s":"BTCUSDT","a":4013160702,"p":"62652.43000000","q":"0.00016000","f":6501834352,"l":6501834353,"T":1783948032972,"m":false,"M":true}}
{"t":30.3286,"stream":"btcusdt@aggTrade","data":{"e":"aggTrade","E":1783948032972,"s":"BTCUSDT","a":4013160703,"p":"62652.77000000","q":"0.00027000","f":6501834354,"l":6501834356,"T":1783948032972,"m":false,"M":true}}
{"t":30.3286,"stream":"btcusdt@aggTrade","data":{"e":"aggTrade","E":1783948032972,"s":"BTCUSDT","a":4013160704,"p":"62652.78000000","q":"0.00144000","f":6501834357,"l":6501834357,"T":1783948032972,"m":false,"M":true}}
{"t":30.3659,"stream":"btcusdt@depth@100ms","data":{"e":"depthUpdate","E":1783948033014,"s":"BTCUSDT","U":97344804220,"u":97344804701,"b":[["62652.77000000","3.81354000"],["62652.76000000","0.00034000"],["62652.75000000","0.00016000"],["62652.63000000","0.00018000"],["62652.62000000","0.52714000"],["62652.42000000","0.00000000"],["62652.30000000","0.00000000"],["62651.99000000","0.00000000"],["62651.89000000","0.00000000"],["62651.80000000","0.00000000"],["62651.79000000","0.00000000"],["62651.69000000","0.00000000"],["62651.60000000","0.00000000"],["62650.85000000","0.00400000"],["62650.76000000","0.00000000"],["62650.57000000","0.00000000"],["62650.35000000","0.00008000"],["62650.26000000","0.00000000"],["62650.01000000","0.00000000"],["62650.00000000","0.00000000"],["62649.99000000","0.00000000"],["62649.98000000","0.00000000"],["62649.83000000","0.00000000"],["62649.72000000","0.00009000"],["62649.69000000","0.00000000"],["62649.60000000","0.00008000"],["62649.59000000","0.00000000"],["62649.30000000","0.00018000"],["62649.29000000","0.37516000"],["62649.28000000","2.43653000"],["62649.27000000","0.00000000"],["62649.26000000","0.00000000"],["62648.65000000","0.07903000"],["62647.98000000","0.00018000"],["62647.53000000","0.04073000"],["62646.50000000","0.00009000"],["62646.01000000","0.59906000"],["62646.00000000","5.20935000"],["62645.99000000","0.18209000"],["62645.51000000","0.07903000"],["62644.99000000","0.30784000"],["62644.89000000","0.00009000"],["62644.30000000","0.23319000"],["62644.29000000","0.47618000"],["62644.28000000","0.00008000"],["62644.26000000","0.00000000"],["62643.99000000","0.00186000"],["62643.40000000","0.01743000"],["62643.02000000","0.00000000"],["62643.01000000","0.22908000"],["62642.38000000","0.05278000"],["62642.00000000","0.00600000"],["62641.99000000","0.15695000"],["62641.89000000","0.00000000"],["62641.15000000","0.77602000"],["62641.14000000","0.30858000"],["62640.95000000","0.00000000"],["62640.91000000","0.00000000"],["62640.24000000","0.00009000"],["62640.01000000","0.16871000"],["62639.99000000","0.06820000"],["62639.77000000","0.00000000"],["62639.25000000","0.05269000"],["62637.36000000","0.00000000"],["62637.11000000","0.00009000"],["62636.75000000","0.00000000"],["62636.02000000","0.57521000"],["62635.79000000","0.00879000"],["62633.97000000","0.00009000"],["62633.73000000","0.00000000"],["62633.62000000","0.00000000"],["62633.22000000","0.00000000"],["62632.60000000","0.00000000"],["62631.69000000","0.00159000"],["62630.84000000","0.00009000"],["62630.52000000","0.00319000"],["62630.49000000","0.00015000"],["62627.71000000","0.00009000"],["62627.35000000","0.00000000"],["62625.73000000","0.00000000"],["62624.58000000","0.00009000"],["62624.22000000","0.00023000"],["62621.44000000","0.00009000"],["62621.09000000","0.00000000"],["62620.80000000","0.00000000"],["62619.39000000","0.00000000"],["62618.85000000","0.00000000"],["62618.00000000","0.02400000"],["62617.96000000","0.00000000"],["62617.59000000","1.91755000"],["62606.95000000","0.00000000"],["62600.01000000","0.00113000"],["62595.41000000","0.00000000"],["62590.69000000","0.00000000"],["62590.12000000","0.00009000"],["62582.19000000","0.00000000"],["62580.76000000","0.00000000"],["62575.64000000","0.00000000"],["62553.46000000","0.00000000"],["62527.46000000","0.00009000"],["62518.11000000","0.00000000"],["62488.81000000","0.00000000"],["62464.81000000","0.00010000"],["62455.47000000","0.00000000"],["62402.16000000","0.00010000"],["62392.83000000","0.00000000"],["62339.51000000","0.00010000"],["62338.50000000","0.02397000"],["62330.18000000","0.00000000"],["62276.85000000","0.00010000"],["62267.54000000","0.00000000"],["62214.20000000","0.00010000"],["62204.90000000","0.00000000"],["62151.55000000","0.00010000"],["62142.25000000","0.00000000"],["56387.50000000","0.00043000"],["56384.36000000","0.00000000"],["50122.22000000","0.00039000"]],"a":[["62649.29000000","0.00000000"],["62649.30000000","0.00000000"],["62649.60000000","0.00000000"],["62649.70000000","0.00000000"],["62649.84000000","0.00000000"],["62649.99000000","0.00000000"],["62650.00000000","0.00000000"],["62650.02000000","0.00000000"],["62650.26000000","0.00000000"],["62650.27000000","0.00000000"],["62650.77000000","0.00000000"],["62651.61000000","0.00000000"],["62651.70000000","0.00000000"],["62651.80000000","0.00000000"],["62651.86000000","0.00000000"],["62651.90000000","0.00000000"],["62651.99000000","0.00000000"],["62652.00000000","0.00000000"],["62652.31000000","0.00000000"],["62652.43000000","0.00000000"],["62652.77000000","0.00000000"],["62652.78000000","0.70974000"],["62652.79000000","0.00097000"],["62652.80000000","0.00016000"],["62652.96000000","0.00000000"],["62652.97000000","0.00044000"],["62653.69000000","0.06477000"],["62654.00000000","0.02418000"],["62654.04000000","0.00018000"],["62654.05000000","0.08499000"],["62654.53000000","0.00000000"],["62655.14000000","0.00000000"],["62655.37000000","0.00000000"],["62655.55000000","0.00000000"],["62656.00000000","0.02426000"],["62656.65000000","0.00000000"],["62656.83000000","0.06469000"],["62657.13000000","0.02572000"],["62657.45000000","0.00000000"],["62657.86000000","0.01717000"],["62658.08000000","0.00018000"],["62658.09000000","0.13987000"],["62658.10000000","0.00008000"],["62658.25000000","0.00000000"],["62658.26000000","0.00026000"],["62659.05000000","0.00009000"],["62659.15000000","0.00000000"],["62659.19000000","0.01281000"],["62659.34000000","0.00009000"],["62659.96000000","0.04308000"],["62661.58000000","0.00000000"],["62661.82000000","0.00000000"],["62662.90000000","0.00009000"],["62663.09000000","0.04308000"],["62663.21000000","0.00400000"],["62664.95000000","0.00000000"],["62665.31000000","0.00018000"],["62667.07000000","0.00000000"],["62667.87000000","0.00000000"],["62668.08000000","0.00174000"],["62668.44000000","0.00009000"],["62668.79000000","0.23190000"],["62669.45000000","0.13624000"],["62669.65000000","0.00000000"],["62670.01000000","0.00400000"],["62670.47000000","0.00000000"],["62671.22000000","0.00000000"],["62671.58000000","0.00009000"],["62674.35000000","0.00000000"],["62674.71000000","0.00009000"],["62675.62000000","0.02319000"],["62677.48000000","0.00000000"],["62677.84000000","0.00009000"],["62677.98000000","0.00000000"],["62680.61000000","0.00100000"],["62680.97000000","0.00009000"],["62681.00000000","0.00000000"],["62681.60000000","0.00008000"],["62684.11000000","0.00009000"],["62685.00000000","0.01008000"],["62688.15000000","0.00008000"],["62693.83000000","0.00000000"],["62696.77000000","0.00000000"],["62701.99000000","0.00397000"],["62703.04000000","0.00000000"],["62705.70000000","0.00398000"],["62706.05000000","0.00000000"],["62715.43000000","0.00009000"],["62768.70000000","0.00000000"],["62778.09000000","0.00009000"],["62831.34000000","0.00000000"],["62840.74000000","0.00009000"],["62893.98000000","0.00000000"],["62903.39000000","0.00009000"],["62956.63000000","0.00000000"],["62966.04000000","0.00009000"],["63019.27000000","0.00000000"],["63028.70000000","0.00009000"],["63081.91000000","0.00000000"],["63091.35000000","0.00009000"],["63144.56000000","0.00000000"],["63154.00000000","0.00009000"]]}}
{"t":30.3661,"stream":"btcusdt@depth20@100ms","data":{"lastUpdateId":97344804701,"bids":[["62652.77000000","3.81354000"],["62652.76000000","0.00034000"],["62652.75000000","0.00016000"],["62652.63000000","0.00018000"],["62652.62000000","0.52714000"],["62650.85000000","0.00400000"],["62650.35000000","0.00008000"],["62649.72000000","0.00009000"],["62649.60000000","0.00008000"],["62649.30000000","0.00018000"],["62649.29000000","0.37516000"],["62649.28000000","2.43653000"],["62649.03000000","0.02172000"],["62648.65000000","0.07903000"],["62647.98000000","0.00018000"],["62647.71000000","0.00400000"],["62647.53000000","0.04073000"],["62647.20000000","0.00008000"],["62646.50000000","0.00009000"],["62646.40000000","0.00008000"]],"asks":[["62652.78000000","0.70974000"],["62652.79000000","0.00097000"],["62652.80000000","0.00016000"],["62652.97000000","0.00044000"],["62652.98000000","1.58158000"],["62653.67000000","0.00057000"],["62653.69000000","0.06477000"],["62654.00000000","0.02418000"],["62654.04000000","0.00018000"],["62654.05000000","0.08499000"],["62654.30000000","0.00256000"],["62654.68000000","0.00009000"],["62654.69000000","0.00010000"],["62655.20000000","0.00012000"],["62655.65000000","0.00188000"],["62655.78000000","0.00048000"],["62655.80000000","0.00009000"],["62656.00000000","0.02426000"],["62656.74000000","0.00047000"],["62656.83000000","0.06469000"]]}}
{"t":30.4639,"stream":"btcusdt@depth@100ms","data":{"e":"depthUpdate","E":1783948033114,"s":"BTCUSDT","U":97344804702,"u":97344804822,"b":[["62652.77000000","3.82772000"],["62652.76000000","0.00043000"],["62652.62000000","0.52740000"],["62649.29000000","0.37534000"],["62649.28000000","2.42645000"],["62649.03000000","0.02172000"],["62648.65000000","0.00026000"],["62647.98000000","0.00000000"],["62645.99000000","0.18183000"],["62645.51000000","0.00000000"],["62644.99000000","0.30766000"],["62644.29000000","0.47600000"],["62643.99000000","0.00168000"],["62643.40000000","0.01735000"],["62642.38000000","0.00009000"],["62641.99000000","0.15687000"],["62641.14000000","0.30831000"],["62639.25000000","0.00000000"],["62627.21000000","0.00000000"],["62621.00000000","0.01000000"],["62617.00000000","0.00000000"],["62613.15000000","0.00015000"],["62605.64000000","0.02428000"],["62600.02000000","0.00113000"],["62600.01000000","0.00000000"],["56387.50000000","0.00083000"],["50122.22000000","0.00039000"],["40000.00000000","258.07540000"]],"a":[["62652.78000000","0.71516000"],["62652.79000000","0.00097000"],["62652.97000000","0.00026000"],["62652.98000000","1.58158000"],["62653.47000000","0.00009000"],["62653.69000000","0.00034000"],["62654.00000000","0.02418000"],["62654.05000000","0.08517000"],["62656.00000000","0.02426000"],["62656.83000000","0.00026000"],["62656.91000000","0.00027000"],["62657.13000000","0.02572000"],["62657.86000000","0.01735000"],["62659.96000000","0.00000000"],["62663.09000000","0.00000000"],["62673.71000000","0.00015000"],["62704.22000000","0.00000000"],["62708.49000000","0.00000000"],["62709.12000000","0.00000000"],["62718.60000000","0.00000000"],["62721.08000000","0.00000000"],["62730.46000000","0.00030000"],["62769.76000000","0.00000000"],["62771.75000000","0.00000000"],["62823.35000000","0.00009000"],["62826.48000000","0.00009000"]]}}
{"t":30.4644,"stream":"btcusdt@depth20@100ms","data":{"lastUpdateId":97344804822,"bids":[["62652.77000000","3.82772000"],["62652.76000000","0.00043000"],["62652.75000000","0.00016000"],["62652.63000000","0.00018000"],["62652.62000000","0.52740000"],["62650.85000000","0.00400000"],["62650.35000000","0.00008000"],["62649.72000000","0.00009000"],["62649.60000000","0.00008000"],["62649.30000000","0.00018000"],["62649.29000000","0.37534000"],["62649.28000000","2.42645000"],["62649.03000000","0.02172000"],["62648.65000000","0.00026000"],["62647.71000000","0.00400000"],["62647.53000000","0.04073000"],["62647.20000000","0.00008000"],["62646.50000000","0.00009000"],["62646.40000000","0.00008000"],["62646.14000000","0.00400000"]],"asks":[["62652.78000000","0.71516000"],["62652.79000000","0.00097000"],["62652.80000000","0.00016000"],["62652.97000000","0.00026000"],["62652.98000000","1.58158000"],["62653.47000000","0.00009000"],["62653.67000000","0.00057000"],["62653.69000000","0.00034000"],["62654.00000000","0.02418000"],["62654.04000000","0.00018000"],["62654.05000000","0.08517000"],["62654.30000000","0.00256000"],["62654.68000000","0.00009000"],["62654.69000000","0.00010000"],["62655.20000000","0.00012000"],["62655.65000000","0.00188000"],["62655.78000000","0.00048000"],["62655.80000000","0.00009000"],["62656.00000000","0.02426000"],["62656.74000000","0.00047000"]]}}
{"t":30.5644,"stream":"btcusdt@depth@100ms","data":{"e":"depthUpdate","E":1783948033214,"s":"BTCUSDT","U":97344804823,"u":97344804895,"b":[["62652.77000000","4.00034000"],["62652.62000000","0.52748000"],["62652.15000000","0.00018000"],["62652.14000000","0.07902000"],["62650.00000000","0.00600000"],["62649.31000000","0.00026000"],["62649.29000000","0.37542000"],["62649.28000000","2.20145000"],["62649.03000000","0.02172000"],["62649.00000000","0.07903000"],["62648.65000000","0.00008000"],["62648.00000000","0.00600000"],["62647.53000000","0.04091000"],["62645.99000000","0.18191000"],["62645.87000000","0.05269000"],["62643.40000000","0.01727000"],["62643.08000000","0.00000000"],["62642.74000000","0.05269000"],["62626.84000000","0.00000000"],["62613.15000000","0.00000000"],["62553.13000000","0.00015000"],["62543.78000000","0.00000000"],["62537.45000000","0.00000000"],["62517.76000000","0.00000000"],["62508.01000000","0.00999000"],["62504.57000000","0.00000000"],["62308.22000000","1.21333000"],["62270.82000000","2.42811000"],["61712.97000000","0.00030000"],["56387.50000000","0.00123000"],["50122.22000000","0.00000000"]],"a":[["62652.78000000","0.71525000"],["62652.98000000","1.58158000"],["62653.12000000","0.17253000"],["62653.69000000","0.00016000"],["62654.05000000","0.08525000"],["62654.13000000","0.00061000"],["62656.00000000","0.02426000"],["62656.65000000","0.00008000"],["62656.83000000","0.00008000"],["62657.18000000","0.06461000"],["62657.93000000","0.02118000"],["62657.97000000","0.03718000"],["62660.32000000","0.06461000"],["62663.45000000","0.04307000"],["62666.58000000","0.04307000"],["62673.71000000","0.00000000"],["62688.15000000","0.00000000"],["62703.57000000","0.00000000"],["62706.08000000","0.22500000"],["62714.84000000","0.00000000"],["62736.48000000","0.00000000"],["62738.66000000","0.00000000"],["62745.48000000","0.00000000"]]}}
{"t":30.5647,"stream":"btcusdt@depth20@100ms","data":{"lastUpdateId":97344804895,"bids":[["62652.77000000","4.00034000"],["62652.76000000","0.00043000"],["62652.75000000","0.00016000"],["62652.63000000","0.00018000"],["62652.62000000","0.52748000"],["62652.15000000","0.00018000"],["62652.14000000","0.07902000"],["62650.85000000","0.00400000"],["62650.35000000","0.00008000"],["62650.00000000","0.00600000"],["62649.72000000","0.00009000"],["62649.60000000","0.00008000"],["62649.31000000","0.00026000"],["62649.30000000","0.00018000"],["62649.29000000","0.37542000"],["62649.28000000","2.20145000"],["62649.03000000","0.02172000"],["62649.00000000","0.07903000"],["62648.65000000","0.00008000"],["62648.00000000","0.00600000"]],"asks":[["62652.78000000","0.71525000"],["62652.79000000","0.00097000"],["62652.80000000","0.00016000"],["62652.97000000","0.00026000"],["62652.98000000","1.58158000"],["62653.12000000","0.17253000"],["62653.47000000","0.00009000"],["62653.67000000","0.00057000"],["62653.69000000","0.00016000"],["62654.00000000","0.02418000"],["62654.04000000","0.00018000"],["62654.05000000","0.08525000"],["62654.13000000","0.00061000"],["62654.30000000","0.00256000"],["62654.68000000","0.00009000"],["62654.69000000","0.00010000"],["62655.20000000","0.00012000"],["62655.65000000","0.00188000"],["62655.78000000","0.00048000"],["62655.80000000","0.00009000"]]}}
{"t":30.6635,"stream":"btcusdt@depth@100ms","data":{"e":"depthUpdate","E":1783948033314,"s":"BTCUSDT","U":97344804896,"u":97344804956,"b":[["62652.77000000","4.00052000"],["62652.76000000","0.00061000"],["62652.62000000","0.52748000"],["62652.14000000","0.07920000"],["62650.00000000","0.00618000"],["62649.03000000","0.02172000"],["62647.53000000","0.04073000"],["62646.00000000","5.21517000"],["62644.00000000","0.00600000"],["62643.40000000","0.01608000"],["62643.01000000","0.22900000"],["62636.24000000","0.00009000"],["62633.36000000","0.56488000"],["56387.50000000","0.00163000"]],"a":[["62652.78000000","0.71542000"],["62652.79000000","0.00106000"],["62652.98000000","1.58158000"],["62653.11000000","0.00018000"],["62653.12000000","0.17279000"],["62653.30000000","0.00018000"],["62653.31000000","0.09404000"],["62654.04000000","0.00000000"],["62654.05000000","0.00026000"],["62657.13000000","0.02572000"],["62657.18000000","0.06479000"],["62657.93000000","0.02100000"],["62657.97000000","0.03700000"],["62659.34000000","0.00000000"],["62688.48000000","0.00833000"],["62771.69000000","0.00000000"],["63592.58000000","0.00030000"]]}}
{"t":30.6638,"stream":"btcusdt@depth20@100ms","data":{"lastUpdateId":97344804956,"bids":[["62652.77000000","4.00052000"],["62652.76000000","0.00061000"],["62652.75000000","0.00016000"],["62652.63000000","0.00018000"],["62652.62000000","0.52748000"],["62652.15000000","0.00018000"],["62652.14000000","0.07920000"],["62650.85000000","0.00400000"],["62650.35000000","0.00008000"],["62650.00000000","0.00618000"],["62649.72000000","0.00009000"],["62649.60000000","0.00008000"],["62649.31000000","0.00026000"],["62649.30000000","0.00018000"],["62649.29000000","0.37542000"],["62649.28000000","2.20145000"],["62649.03000000","0.02172000"],["62649.00000000","0.07903000"],["62648.65000000","0.00008000"],["62648.00000000","0.00600000"]],"asks":[["62652.78000000","0.71542000"],["62652.79000000","0.00106000"],["62652.80000000","0.00016000"],["62652.97000000","0.00026000"],["62652.98000000","1.58158000"],["62653.11000000","0.00018000"],["62653.12000000","0.17279000"],["62653.30000000","0.00018000"],["62653.31000000","0.09404000"],["62653.47000000","0.00009000"],["62653.67000000","0.00057000"],["62653.69000000","0.00016000"],["62654.00000000","0.02418000"],["62654.05000000","0.00026000"],["62654.13000000","0.00061000"],["62654.30000000","0.00256000"],["62654.68000000","0.00009000"],["62654.69000000","0.00010000"],["62655.20000000","0.00012000"],["62655.65000000","0.00188000"]]}}
{"t":30.7158,"stream":"btcusdt@aggTrade","data":{"e":"aggTrade","E":1783948033365,"s":"BTCUSDT","a":4013160705,"p":"62652.77000000","q":"0.00027000","f":6501834358,"l":6501834358,"T":1783948033365,"m":true,"M":true}}
{"t":30.7639,"stream":"btcusdt@depth@100ms","data":{"e":"depthUpdate","E":1783948033414,"s":"BTCUSDT","U":97344804957,"u":97344805021,"b":[["62652.77000000","3.77588000"],["62652.76000000","0.00097000"],["62652.63000000","0.00000000"],["62652.62000000","0.00034000"],["62652.14000000","0.07928000"],["62650.22000000","0.00018000"],["62650.21000000","0.52716000"],["62649.00000000","0.07921000"],["62648.62000000","0.00156000"],["62645.48000000","0.00009000"],["62644.99000000","0.30751000"],["62642.41000000","0.00009000"],["62606.95000000","0.22500000"],["62546.80000000","0.00023000"],["56387.50000000","0.00183000"]],"a":[["62652.78000000","1.51198000"],["62652.79000000","0.00106000"],["62653.12000000","0.17279000"],["62653.31000000","0.09422000"],["62653.67000000","0.00118000"],["62653.99000000","0.00000000"],["62654.00000000","0.02418000"],["62654.05000000","0.00008000"],["62654.13000000","0.00000000"],["62659.39000000","1.91755000"],["62676.17000000","0.03104000"],["62690.78000000","0.05002000"],["62836.32000000","0.09548000"]]}}
{"t":30.7641,"stream":"btcusdt@depth20@100ms","data":{"lastUpdateId":97344805021,"bids":[["62652.77000000","3.77588000"],["62652.76000000","0.00097000"],["62652.75000000","0.00016000"],["62652.62000000","0.00034000"],["62652.15000000","0.00018000"],["62652.14000000","0.07928000"],["62650.85000000","0.00400000"],["62650.35000000","0.00008000"],["62650.22000000","0.00018000"],["62650.21000000","0.52716000"],["62650.00000000","0.00618000"],["62649.72000000","0.00009000"],["62649.60000000","0.00008000"],["62649.31000000","0.00026000"],["62649.30000000","0.00018000"],["62649.29000000","0.37542000"],["62649.28000000","2.20145000"],["62649.03000000","0.02172000"],["62649.00000000","0.07921000"],["62648.65000000","0.00008000"]],"asks":[["62652.78000000","1.51198000"],["62652.79000000","0.00106000"],["62652.80000000","0.00016000"],["62652.97000000","0.00026000"],["62652.98000000","1.58158000"],["62653.11000000","0.00018000"],["62653.12000000","0.17279000"],["62653.30000000","0.00018000"],["62653.31000000","0.09422000"],["62653.47000000","0.00009000"],["62653.67000000","0.00118000"],["62653.69000000","0.00016000"],["62654.00000000","0.02418000"],["62654.05000000","0.00008000"],["62654.30000000","0.00256000"],["62654.68000000","0.00009000"],["62654.69000000","0.00010000"],["62655.20000000","0.00012000"],["62655.65000000","0.00188000"],["62655.78000000","0.00048000"]]}}
{"t":30.8645,"stream":"btcusdt@depth@100ms","data":{"e":"depthUpdate","E":1783948033514,"s":"BTCUSDT","U":97344805022,"u":97344805083,"b":[["62652.77000000","3.53764000"],["62652.76000000","0.00097000"],["62652.62000000","0.00016000"],["62652.14000000","0.07928000"],["62649.29000000","0.30042000"],["62649.28000000","1.99275000"],["62648.65000000","0.00000000"],["62646.02000000","0.00000000"],["62646.01000000","0.00000000"],["62646.00000000","2.02250000"],["62645.56000000","0.03966000"],["62644.99000000","0.30743000"],["62644.30000000","0.00000000"],["62643.44000000","0.59905000"],["62643.40000000","0.01600000"],["62642.75000000","0.14206000"],["62641.15000000","0.00000000"],["62640.02000000","3.19219000"],["62638.66000000","0.72959000"],["62619.92000000","0.00015000"],["62527.12000000","0.00039000"],["62508.01000000","0.00000000"],["62504.57000000","0.00999000"],["56387.50000000","0.00223000"]],"a":[["62652.78000000","2.13078000"],["62653.32000000","0.00061000"],["62653.39000000","0.00000000"],["62653.67000000","0.00057000"],["62654.72000000","0.00009000"],["62656.89000000","0.00000000"],["62656.99000000","0.00000000"],["62658.08000000","0.00018000"],["62658.26000000","0.00017000"],["62678.56000000","0.03352000"],["62680.48000000","0.00047000"],["62703.62000000","0.06069000"],["62721.85000000","2.15344000"],["62745.85000000","0.00024000"],["62771.68000000","0.00000000"],["62968.50000000","0.00000000"]]}}
{"t":30.8649,"stream":"btcusdt@depth20@100ms","data":{"lastUpdateId":97344805083,"bids":[["62652.77000000","3.53764000"],["62652.76000000","0.00097000"],["62652.75000000","0.00016000"],["62652.62000000","0.00016000"],["62652.15000000","0.00018000"],["62652.14000000","0.07928000"],["62650.85000000","0.00400000"],["62650.35000000","0.00008000"],["62650.22000000","0.00018000"],["62650.21000000","0.52716000"],["62650.00000000","0.00618000"],["62649.72000000","0.00009000"],["62649.60000000","0.00008000"],["62649.31000000","0.00026000"],["62649.30000000","0.00018000"],["62649.29000000","0.30042000"],["62649.28000000","1.99275000"],["62649.03000000","0.02172000"],["62649.00000000","0.07921000"],["62648.62000000","0.00156000"]],"asks":[["62652.78000000","2.13078000"],["62652.79000000","0.00106000"],["62652.80000000","0.00016000"],["62652.97000000","0.00026000"],["62652.98000000","1.58158000"],["62653.11000000","0.00018000"],["62653.12000000","0.17279000"],["62653.30000000","0.00018000"],["62653.31000000","0.09422000"],["62653.32000000","0.00061000"],["62653.47000000","0.00009000"],["62653.67000000","0.00057000"],["62653.69000000","0.00016000"],["62654.00000000","0.02418000"],["62654.05000000","0.00008000"],["62654.30000000","0.00256000"],["62654.68000000","0.00009000"],["62654.69000000","0.00010000"],["62654.72000000","0.00009000"],["62655.20000000","0.00012000"]]}}
{"t":30.9637,"stream":"btcusdt@depth@100ms","data":{"e":"depthUpdate","E":1783948033614,"s":"BTCUSDT","U":97344805084,"u":97344805106,"b":[["62652.77000000","3.53773000"],["62651.60000000","0.00009000"],["62642.00000000","0.01400000"],["62612.61000000","0.77000000"],["62600.03000000","0.00398000"],["62596.14000000","0.00398000"],["62591.20000000","0.00000000"],["62586.94000000","0.00000000"],["62536.44000000","0.00159000"],["62533.41000000","0.00159000"],["62525.82000000","0.00000000"],["62520.91000000","0.00000000"],["56387.50000000","0.00263000"]],"a":[["62652.78000000","2.13174000"],["62653.47000000","0.00000000"],["62655.78000000","0.00000000"],["62656.74000000","0.00000000"],["62669.45000000","0.00000000"],["62669.71000000","0.13398000"],["62748.04000000","0.00023000"],["62756.60000000","0.00000000"],["62759.99000000","0.00000000"],["62764.66000000","0.00159000"],["62768.17000000","0.00159000"],["62771.67000000","0.00000000"]]}}
{"t":30.9638,"stream":"btcusdt@depth20@100ms","data":{"lastUpdateId":97344805106,"bids":[["62652.77000000","3.53773000"],["62652.76000000","0.00097000"],["62652.75000000","0.00016000"],["62652.62000000","0.00016000"],["62652.15000000","0.00018000"],["62652.14000000","0.07928000"],["62651.60000000","0.00009000"],["62650.85000000","0.00400000"],["62650.35000000","0.00008000"],["62650.22000000","0.00018000"],["62650.21000000","0.52716000"],["62650.00000000","0.00618000"],["62649.72000000","0.00009000"],["62649.60000000","0.00008000"],["62649.31000000","0.00026000"],["62649.30000000","0.00018000"],["62649.29000000","0.30042000"],["62649.28000000","1.99275000"],["62649.03000000","0.02172000"],["62649.00000000","0.07921000"]],"asks":[["62652.78000000","2.13174000"],["62652.79000000","0.00106000"],["62652.80000000","0.00016000"],["62652.97000000","0.00026000"],["62652.98000000","1.58158000"],["62653.11000000","0.00018000"],["62653.12000000","0.17279000"],["62653.30000000","0.00018000"],["62653.31000000","0.09422000"],["62653.32000000","0.00061000"],["62653.67000000","0.00057000"],["62653.69000000","0.00016000"],["62654.00000000","0.02418000"],["62654.05000000","0.00008000"],["62654.30000000","0.00256000"],["62654.68000000","0.00009000"],["62654.69000000","0.00010000"],["62654.72000000","0.00009000"],["62655.20000000","0.00012000"],["62655.65000000","0.00188000"]]}}
{"t":30.9639,"stream":"btcusdt@aggTrade","data":{"e":"aggTrade","E":1783948033614,"s":"BTCUSDT","a":4013160706,"p":"62652.77000000","q":"0.26790000","f":6501834359,"l":6501834359,"T":1783948033614,"m":true,"M":true}}
{"t":31.0637,"stream":"btcusdt@depth@100ms","data":{"e":"depthUpdate","E":1783948033714,"s":"BTCUSDT","U":97344805107,"u":97344805116,"b":[["62652.77000000","3.26983000"],["62646.01000000","0.00009000"],["62645.99000000","0.13191000"],["62528.43000000","0.09595000"],["56387.50000000","0.00303000"],["56387.49000000","0.00010000"]],"a":[["62653.20000000","0.00061000"],["62653.32000000","0.00000000"],["62669.71000000","0.00000000"],["62754.86000000","0.00039000"]]}}
{"t":31.0639,"stream":"btcusdt@depth20@100ms","data":{"lastUpdateId":97344805116,"bids":[["62652.77000000","3.26983000"],["62652.76000000","0.00097000"],["62652.75000000","0.00016000"],["62652.62000000","0.00016000"],["62652.15000000","0.00018000"],["62652.14000000","0.07928000"],["62651.60000000","0.00009000"],["62650.85000000","0.00400000"],["62650.35000000","0.00008000"],["62650.22000000","0.00018000"],["62650.21000000","0.52716000"],["62650.00000000","0.00618000"],["62649.72000000","0.00009000"],["62649.60000000","0.00008000"],["62649.31000000","0.00026000"],["62649.30000000","0.00018000"],["62649.29000000","0.30042000"],["62649.28000000","1.99275000"],["62649.03000000","0.02172000"],["62649.00000000","0.07921000"]],"asks":[["62652.78000000","2.13174000"],["62652.79000000","0.00106000"],["62652.80000000","0.00016000"],["62652.97000000","0.00026000"],["62652.98000000","1.58158000"],["62653.11000000","0.00018000"],["62653.12000000","0.17279000"],["62653.20000000","0.00061000"],["62653.30000000","0.00018000"],["62653.31000000","0.09422000"],["62653.67000000","0.00057000"],["62653.69000000","0.00016000"],["62654.00000000","0.02418000"],["62654.05000000","0.00008000"],["62654.30000000","0.00256000"],["62654.68000000","0.00009000"],["62654.69000000","0.00010000"],["62654.72000000","0.00009000"],["62655.20000000","0.00012000"],["62655.65000000","0.00188000"]]}}
{"t":31.1033,"stream":"btcusdt@aggTrade","data":{"e":"aggTrade","E":1783948033749,"s":"BTCUSDT","a":4013160707,"p":"62652.77000000","q":"0.00037000","f":6501834360,"l":6501834360,"T":1783948033749,"m":true,"M":true}}
{"t":31.1638,"stream":"btcusdt@depth@100ms","data":{"e":"depthUpdate","E":1783948033814,"s":"BTCUSDT","U":97344805117,"u":97344805133,"b":[["62652.77000000","3.26946000"],["62646.00000000","2.02750000"],["62644.00000000","0.01100000"],["62642.00000000","0.01900000"],["62635.47000000","0.00000000"],["62635.26000000","0.00000000"],["62633.36000000","0.00000000"],["62593.13000000","0.01000000"],["62590.63000000","0.01000000"],["56387.50000000","0.00343000"]],"a":[["62658.08000000","0.00000000"],["62658.26000000","0.00008000"],["62660.33000000","0.00000000"],["62669.13000000","0.00009000"],["62702.65000000","0.04000000"],["62703.18000000","0.01900000"]]}}
{"t":31.164,"stream":"btcusdt@depth20@100ms","data":{"lastUpdateId":97344805133,"bids":[["62652.77000000","3.26946000"],["62652.76000000","0.00097000"],["62652.75000000","0.00016000"],["62652.62000000","0.00016000"],["62652.15000000","0.00018000"],["62652.14000000","0.07928000"],["62651.60000000","0.00009000"],["62650.85000000","0.00400000"],["62650.35000000","0.00008000"],["62650.22000000","0.00018000"],["62650.21000000","0.52716000"],["62650.00000000","0.00618000"],["62649.72000000","0.00009000"],["62649.60000000","0.00008000"],["62649.31000000","0.00026000"],["62649.30000000","0.00018000"],["62649.29000000","0.30042000"],["62649.28000000","1.99275000"],["62649.03000000","0.02172000"],["62649.00000000","0.07921000"]],"asks":[["62652.78000000","2.13174000"],["62652.79000000","0.00106000"],["62652.80000000","0.00016000"],["62652.97000000","0.00026000"],["62652.98000000","1.58158000"],["62653.11000000","0.00018000"],["62653.12000000","0.17279000"],["62653.20000000","0.00061000"],["62653.30000000","0.00018000"],["62653.31000000","0.09422000"],["62653.67000000","0.00057000"],["62653.69000000","0.00016000"],["62654.00000000","0.02418000"],["62654.05000000","0.00008000"],["62654.30000000","0.00256000"],["62654.68000000","0.00009000"],["62654.69000000","0.00010000"],["62654.72000000","0.00009000"],["62655.20000000","0.00012000"],["62655.65000000","0.00188000"]]}}
{"t":31.1941,"stream":"btcusdt@aggTrade","data":{"e":"aggTrade","E":1783948033843,"s":"BTCUSDT","a":4013160708,"p":"62652.77000000","q":"0.04809000","f":6501834361,"l":6501834361,"T":1783948033843,"m":true,"M":true}}
{"t":31.263,"stream":"btcusdt@depth@100ms","data":{"e":"depthUpdate","E":1783948033914,"s":"BTCUSDT","U":97344805134,"u":97344805166,"b":[["62652.77000000","2.78223000"],["62649.30000000","0.00000000"],["62649.29000000","0.00044000"],["62649.28000000","1.98477000"],["62647.72000000","0.00798000"],["62646.01000000","0.00018000"],["62645.99000000","0.08195000"],["62642.78000000","0.00000000"],["62642.75000000","0.00000000"],["62641.15000000","0.25581000"],["62640.83000000","0.00400000"],["62640.00000000","1.95178000"],["62638.75000000","0.00008000"],["62633.36000000","0.54386000"],["56387.50000000","0.00383000"]],"a":[["62652.78000000","2.27260000"],["62653.01000000","0.00061000"],["62653.09000000","0.00000000"],["62653.20000000","0.00000000"],["62653.50000000","0.00008000"],["62654.30000000","0.00000000"],["62659.63000000","0.00400000"],["62663.21000000","0.00000000"],["62663.82000000","0.00008000"],["62665.44000000","0.57526000"],["62679.57000000","0.00000000"],["62680.68000000","0.00400000"],["62682.25000000","0.00000000"]]}}
{"t":31.2632,"stream":"btcusdt@depth20@100ms","data":{"lastUpdateId":97344805166,"bids":[["62652.77000000","2.78223000"],["62652.76000000","0.00097000"],["62652.75000000","0.00016000"],["62652.62000000","0.00016000"],["62652.15000000","0.00018000"],["62652.14000000","0.07928000"],["62651.60000000","0.00009000"],["62650.85000000","0.00400000"],["62650.35000000","0.00008000"],["62650.22000000","0.00018000"],["62650.21000000","0.52716000"],["62650.00000000","0.00618000"],["62649.72000000","0.00009000"],["62649.60000000","0.00008000"],["62649.31000000","0.00026000"],["62649.29000000","0.00044000"],["62649.28000000","1.98477000"],["62649.03000000","0.02172000"],["62649.00000000","0.07921000"],["62648.62000000","0.00156000"]],"asks":[["62652.78000000","2.27260000"],["62652.79000000","0.00106000"],["62652.80000000","0.00016000"],["62652.97000000","0.00026000"],["62652.98000000","1.58158000"],["62653.01000000","0.00061000"],["62653.11000000","0.00018000"],["62653.12000000","0.17279000"],["62653.30000000","0.00018000"],["62653.31000000","0.09422000"],["62653.50000000","0.00008000"],["62653.67000000","0.00057000"],["62653.69000000","0.00016000"],["62654.00000000","0.02418000"],["62654.05000000","0.00008000"],["62654.68000000","0.00009000"],["62654.69000000","0.00010000"],["62654.72000000","0.00009000"],["62655.20000000","0.00012000"],["62655.65000000","0.00188000"]]}}
{"t":31.3653,"stream":"btcusdt@depth@100ms","data":{"e":"depthUpdate","E":1783948034014,"s":"BTCUSDT","U":97344805167,"u":97344805186,"b":[["62650.21000000","0.52734000"],["62650.00000000","0.00618000"],["62649.29000000","0.00026000"],["62642.24000000","0.00000000"],["62632.58000000","0.00270000"],["62600.04000000","0.00113000"],["62600.02000000","0.00000000"],["56387.50000000","0.00423000"],["50122.22000000","0.00039000"]],"a":[["62652.78000000","2.27296000"]]}}
{"t":31.3659,"stream":"btcusdt@depth20@100ms","data":{"lastUpdateId":97344805186,"bids":[["62652.77000000","2.78223000"],["62652.76000000","0.00097000"],["62652.75000000","0.00016000"],["62652.62000000","0.00016000"],["62652.15000000","0.00018000"],["62652.14000000","0.07928000"],["62651.60000000","0.00009000"],["62650.85000000","0.00400000"],["62650.35000000","0.00008000"],["62650.22000000","0.00018000"],["62650.21000000","0.52734000"],["62650.00000000","0.00618000"],["62649.72000000","0.00009000"],["62649.60000000","0.00008000"],["62649.31000000","0.00026000"],["62649.29000000","0.00026000"],["62649.28000000","1.98477000"],["62649.03000000","0.02172000"],["62649.00000000","0.07921000"],["62648.62000000","0.00156000"]],"asks":[["62652.78000000","2.27296000"],["62652.79000000","0.00106000"],["62652.80000000","0.00016000"],["62652.97000000","0.00026000"],["62652.98000000","1.58158000"],["62653.01000000","0.00061000"],["62653.11000000","0.00018000"],["62653.12000000","0.17279000"],["62653.30000000","0.00018000"],["62653.31000000","0.09422000"],["62653.50000000","0.00008000"],["62653.67000000","0.00057000"],["62653.69000000","0.00016000"],["62654.00000000","0.02418000"],["62654.05000000","0.00008000"],["62654.68000000","0.00009000"],["62654.69000000","0.00010000"],["62654.72000000","0.00009000"],["62655.20000000","0.00012000"],["62655.65000000","0.00188000"]]}}
{"t":31.4649,"stream":"btcusdt@depth@100ms","data":{"e":"depthUpdate","E":1783948034114,"s":"BTCUSDT","U":97344805187,"u":97344805199,"b":[["62600.04000000","0.00113000"],["56387.50000000","0.00463000"],["56387.00000000","0.00374000"],["50122.22000000","0.00039000"],["40000.00000000","258.07540000"]],"a":[]}}
{"t":31.4652,"stream":"btcusdt@depth20@100ms","data":{"lastUpdateId":97344805199,"bids":[["62652.77000000","2.78223000"],["62652.76000000","0.00097000"],["62652.75000000","0.00016000"],["62652.62000000","0.00016000"],["62652.15000000","0.00018000"],["62652.14000000","0.07928000"],["62651.60000000","0.00009000"],["62650.85000000","0.00400000"],["62650.35000000","0.00008000"],["62650.22000000","0.00018000"],["62650.21000000","0.52734000"],["62650.00000000","0.00618000"],["62649.72000000","0.00009000"],["62649.60000000","0.00008000"],["62649.31000000","0.00026000"],["62649.29000000","0.00026000"],["62649.28000000","1.98477000"],["62649.03000000","0.02172000"],["62649.00000000","0.07921000"],["62648.62000000","0.00156000"]],"asks":[["62652.78000000","2.27296000"],["62652.79000000","0.00106000"],["62652.80000000","0.00016000"],["62652.97000000","0.00026000"],["62652.98000000","1.58158000"],["62653.01000000","0.00061000"],["62653.11000000","0.00018000"],["62653.12000000","0.17279000"],["62653.30000000","0.00018000"],["62653.31000000","0.09422000"],["62653.50000000","0.00008000"],["62653.67000000","0.00057000"],["62653.69000000","0.00016000"],["62654.00000000","0.02418000"],["62654.05000000","0.00008000"],["62654.68000000","0.00009000"],["62654.69000000","0.00010000"],["62654.72000000","0.00009000"],["62655.20000000","0.00012000"],["62655.65000000","0.00188000"]]}}
{"t":31.5635,"stream":"btcusdt@depth@100ms","data":{"e":"depthUpdate","E":1783948034214,"s":"BTCUSDT","U":97344805200,"u":97344805221,"b":[["62652.77000000","2.78214000"],["62652.76000000","0.00097000"],["62643.83000000","0.00319000"],["62637.14000000","0.00000000"],["62308.22000000","0.00000000"],["61712.97000000","0.00030000"],["56387.50000000","0.00483000"],["56387.00000000","0.00354000"],["50122.22000000","0.00000000"]],"a":[["62652.78000000","2.27334000"],["62652.79000000","0.00097000"],["62654.09000000","0.00009000"],["62669.73000000","0.13522000"],["62771.66000000","0.00000000"]]}}
{"t":31.5639,"stream":"btcusdt@depth20@100ms","data":{"lastUpdateId":97344805221,"bids":[["62652.77000000","2.78214000"],["62652.76000000","0.00097000"],["62652.75000000","0.00016000"],["62652.62000000","0.00016000"],["62652.15000000","0.00018000"],["62652.14000000","0.07928000"],["62651.60000000","0.00009000"],["62650.85000000","0.00400000"],["62650.35000000","0.00008000"],["62650.22000000","0.00018000"],["62650.21000000","0.52734000"],["62650.00000000","0.00618000"],["62649.72000000","0.00009000"],["62649.60000000","0.00008000"],["62649.31000000","0.00026000"],["62649.29000000","0.00026000"],["62649.28000000","1.98477000"],["62649.03000000","0.02172000"],["62649.00000000","0.07921000"],["62648.62000000","0.00156000"]],"asks":[["62652.78000000","2.27334000"],["62652.79000000","0.00097000"],["62652.80000000","0.00016000"],["62652.97000000","0.00026000"],["62652.98000000","1.58158000"],["62653.01000000","0.00061000"],["62653.11000000","0.00018000"],["62653.12000000","0.17279000"],["62653.30000000","0.00018000"],["62653.31000000","0.09422000"],["62653.50000000","0.00008000"],["62653.67000000","0.00057000"],["62653.69000000","0.00016000"],["62654.00000000","0.02418000"],["62654.05000000","0.00008000"],["62654.09000000","0.00009000"],["62654.68000000","0.00009000"],["62654.69000000","0.00010000"],["62654.72000000","0.00009000"],["62655.20000000","0.00012000"]]}}
{"t":31.664,"stream":"btcusdt@depth@100ms","data":{"e":"depthUpdate","E":1783948034314,"s":"BTCUSDT","U":97344805222,"u":97344805233,"b":[["62528.43000000","0.00000000"],["62270.82000000","0.00000000"],["56387.50000000","0.00503000"]],"a":[["62771.66000000","0.00000000"],["62836.32000000","0.00000000"],["63592.58000000","0.00030000"]]}}
{"t":31.6641,"stream":"btcusdt@depth20@100ms","data":{"lastUpdateId":97344805233,"bids":[["62652.77000000","2.78214000"],["62652.76000000","0.00097000"],["62652.75000000","0.00016000"],["62652.62000000","0.00016000"],["62652.15000000","0.00018000"],["62652.14000000","0.07928000"],["62651.60000000","0.00009000"],["62650.85000000","0.00400000"],["62650.35000000","0.00008000"],["62650.22000000","0.00018000"],["62650.21000000","0.52734000"],["62650.00000000","0.00618000"],["62649.72000000","0.00009000"],["62649.60000000","0.00008000"],["62649.31000000","0.00026000"],["62649.29000000","0.00026000"],["62649.28000000","1.98477000"],["62649.03000000","0.02172000"],["62649.00000000","0.07921000"],["62648.62000000","0.00156000"]],"asks":[["62652.78000000","2.27334000"],["62652.79000000","0.00097000"],["62652.80000000","0.00016000"],["62652.97000000","0.00026000"],["62652.98000000","1.58158000"],["62653.01000000","0.00061000"],["62653.11000000","0.00018000"],["62653.12000000","0.17279000"],["62653.30000000","0.00018000"],["62653.31000000","0.09422000"],["62653.50000000","0.00008000"],["62653.67000000","0.00057000"],["62653.69000000","0.00016000"],["62654.00000000","0.02418000"],["62654.05000000","0.00008000"],["62654.09000000","0.00009000"],["62654.68000000","0.00009000"],["62654.69000000","0.00010000"],["62654.72000000","0.00009000"],["62655.20000000","0.00012000"]]}}
{"t":31.7413,"stream":"btcusdt@aggTrade","data":{"e":"aggTrade","E":1783948034391,"s":"BTCUSDT","a":4013160709,"p":"62652.77000000","q":"0.00079000","f":6501834362,"l":6501834362,"T":1783948034390,"m":true,"M":true}}
{"t":31.7653,"stream":"btcusdt@depth@100ms","data":{"e":"depthUpdate","E":1783948034414,"s":"BTCUSDT","U":97344805234,"u":97344805243,"b":[["62652.77000000","2.78135000"],["62557.82000000","0.00009000"],["56387.50000000","0.00503000"]],"a":[["62652.78000000","2.27733000"],["62658.08000000","0.00018000"],["62740.70000000","0.00009000"]]}}
{"t":31.7654,"stream":"btcusdt@depth20@100ms","data":{"lastUpdateId":97344805243,"bids":[["62652.77000000","2.78135000"],["62652.76000000","0.00097000"],["62652.75000000","0.00016000"],["62652.62000000","0.00016000"],["62652.15000000","0.00018000"],["62652.14000000","0.07928000"],["62651.60000000","0.00009000"],["62650.85000000","0.00400000"],["62650.35000000","0.00008000"],["62650.22000000","0.00018000"],["62650.21000000","0.52734000"],["62650.00000000","0.00618000"],["62649.72000000","0.00009000"],["62649.60000000","0.00008000"],["62649.31000000","0.00026000"],["62649.29000000","0.00026000"],["62649.28000000","1.98477000"],["62649.03000000","0.02172000"],["62649.00000000","0.07921000"],["62648.62000000","0.00156000"]],"asks":[["62652.78000000","2.27733000"],["62652.79000000","0.00097000"],["62652.80000000","0.00016000"],["62652.97000000","0.00026000"],["62652.98000000","1.58158000"],["62653.01000000","0.00061000"],["62653.11000000","0.00018000"],["62653.12000000","0.17279000"],["62653.30000000","0.00018000"],["62653.31000000","0.09422000"],["62653.50000000","0.00008000"],["62653.67000000","0.00057000"],["62653.69000000","0.00016000"],["62654.00000000","0.02418000"],["62654.05000000","0.00008000"],["62654.09000000","0.00009000"],["62654.68000000","0.00009000"],["62654.69000000","0.00010000"],["62654.72000000","0.00009000"],["62655.20000000","0.00012000"]]}}
{"t":31.8648,"stream":"btcusdt@depth@100ms","data":{"e":"depthUpdate","E":1783948034514,"s":"BTCUSDT","U":97344805244,"u":97344805256,"b":[["62504.57000000","0.00000000"],["62503.01000000","0.00999000"],["62354.24000000","0.00000000"],["62316.82000000","2.42632000"],["62080.19000000","0.00000000"],["56387.50000000","0.00503000"]],"a":[["62658.08000000","0.00000000"],["62771.66000000","0.00000000"]]}}
{"t":31.8649,"stream":"btcusdt@depth20@100ms","data":{"lastUpdateId":97344805256,"bids":[["62652.77000000","2.78135000"],["62652.76000000","0.00097000"],["62652.75000000","0.00016000"],["62652.62000000","0.00016000"],["62652.15000000","0.00018000"],["62652.14000000","0.07928000"],["62651.60000000","0.00009000"],["62650.85000000","0.00400000"],["62650.35000000","0.00008000"],["62650.22000000","0.00018000"],["62650.21000000","0.52734000"],["62650.00000000","0.00618000"],["62649.72000000","0.00009000"],["62649.60000000","0.00008000"],["62649.31000000","0.00026000"],["62649.29000000","0.00026000"],["62649.28000000","1.98477000"],["62649.03000000","0.02172000"],["62649.00000000","0.07921000"],["62648.62000000","0.00156000"]],"asks":[["62652.78000000","2.27733000"],["62652.79000000","0.00097000"],["62652.80000000","0.00016000"],["62652.97000000","0.00026000"],["62652.98000000","1.58158000"],["62653.01000000","0.00061000"],["62653.11000000","0.00018000"],["62653.12000000","0.17279000"],["62653.30000000","0.00018000"],["62653.31000000","0.09422000"],["62653.50000000","0.00008000"],["62653.67000000","0.00057000"],["62653.69000000","0.00016000"],["62654.00000000","0.02418000"],["62654.05000000","0.00008000"],["62654.09000000","0.00009000"],["62654.68000000","0.00009000"],["62654.69000000","0.00010000"],["62654.72000000","0.00009000"],["62655.20000000","0.00012000"]]}}
{"t":31.9649,"stream":"btcusdt@depth@100ms","data":{"e":"depthUpdate","E":1783948034614,"s":"BTCUSDT","U":97344805257,"u":97344805262,"b":[["62316.82000000","0.00000000"],["56387.50000000","0.00503000"]],"a":[["62680.49000000","0.00000000"]]}}
{"t":31.965,"stream":"btcusdt@depth20@100ms","data":{"lastUpdateId":97344805262,"bids":[["62652.77000000","2.78135000"],["62652.76000000","0.00097000"],["62652.75000000","0.00016000"],["62652.62000000","0.00016000"],["62652.15000000","0.00018000"],["62652.14000000","0.07928000"],["62651.60000000","0.00009000"],["62650.85000000","0.00400000"],["62650.35000000","0.00008000"],["62650.22000000","0.00018000"],["62650.21000000","0.52734000"],["62650.00000000","0.00618000"],["62649.72000000","0.00009000"],["62649.60000000","0.00008000"],["62649.31000000","0.00026000"],["62649.29000000","0.00026000"],["62649.28000000","1.98477000"],["62649.03000000","0.02172000"],["62649.00000000","0.07921000"],["62648.62000000","0.00156000"]],"asks":[["62652.78000000","2.27733000"],["62652.79000000","0.00097000"],["62652.80000000","0.00016000"],["62652.97000000","0.00026000"],["62652.98000000","1.58158000"],["62653.01000000","0.00061000"],["62653.11000000","0.00018000"],["62653.12000000","0.17279000"],["62653.30000000","0.00018000"],["62653.31000000","0.09422000"],["62653.50000000","0.00008000"],["62653.67000000","0.00057000"],["62653.69000000","0.00016000"],["62654.00000000","0.02418000"],["62654.05000000","0.00008000"],["62654.09000000","0.00009000"],["62654.68000000","0.00009000"],["62654.69000000","0.00010000"],["62654.72000000","0.00009000"],["62655.20000000","0.00012000"]]}}
{"t":32.064,"stream":"btcusdt@depth@100ms","data":{"e":"depthUpdate","E":1783948034714,"s":"BTCUSDT","U":97344805263,"u":97344805269,"b":[["59520.13000000","0.00093000"],["56387.50000000","0.00503000"]],"a":[["62654.72000000","0.00000000"],["62680.51000000","0.00011000"]]}}
{"t":32.0641,"stream":"btcusdt@depth20@100ms","data":{"lastUpdateId":97344805269,"bids":[["62652.77000000","2.78135000"],["62652.76000000","0.00097000"],["62652.75000000","0.00016000"],["62652.62000000","0.00016000"],["62652.15000000","0.00018000"],["62652.14000000","0.07928000"],["62651.60000000","0.00009000"],["62650.85000000","0.00400000"],["62650.35000000","0.00008000"],["62650.22000000","0.00018000"],["62650.21000000","0.52734000"],["62650.00000000","0.00618000"],["62649.72000000","0.00009000"],["62649.60000000","0.00008000"],["62649.31000000","0.00026000"],["62649.29000000","0.00026000"],["62649.28000000","1.98477000"],["62649.03000000","0.02172000"],["62649.00000000","0.07921000"],["62648.62000000","0.00156000"]],"asks":[["62652.78000000","2.27733000"],["62652.79000000","0.00097000"],["62652.80000000","0.00016000"],["62652.97000000","0.00026000"],["62652.98000000","1.58158000"],["62653.01000000","0.00061000"],["62653.11000000","0.00018000"],["62653.12000000","0.17279000"],["62653.30000000","0.00018000"],["62653.31000000","0.09422000"],["62653.50000000","0.00008000"],["62653.67000000","0.00057000"],["62653.69000000","0.00016000"],["62654.00000000","0.02418000"],["62654.05000000","0.00008000"],["62654.09000000","0.00009000"],["62654.68000000","0.00009000"],["62654.69000000","0.00010000"],["62655.20000000","0.00012000"],["62655.65000000","0.00188000"]]}}
{"t":32.1635,"stream":"btcusdt@depth@100ms","data":{"e":"depthUpdate","E":1783948034814,"s":"BTCUSDT","U":97344805270,"u":97344805368,"b":[["62652.77000000","0.93973000"],["62651.34000000","0.00018000"],["62651.33000000","0.00000000"],["62650.86000000","0.00256000"],["62650.85000000","0.00000000"],["62650.22000000","0.00000000"],["62650.21000000","0.00018000"],["62649.28000000","1.95277000"],["62649.00000000","0.07921000"],["62648.62000000","0.00000000"],["62648.57000000","0.00000000"],["62648.56000000","0.00000000"],["62648.00000000","0.00618000"],["62647.83000000","0.02000000"],["62647.72000000","0.00000000"],["62646.00000000","1.96048000"],["62645.99000000","0.04987000"],["62645.00000000","0.00009000"],["62644.98000000","0.00173000"],["62644.74000000","0.00047000"],["62644.73000000","0.00048000"],["62644.54000000","0.00187000"],["62644.30000000","0.00000000"],["62644.29000000","0.00000000"],["62643.44000000","0.00000000"],["62643.41000000","0.07523000"],["62641.16000000","0.59908000"],["62641.15000000","0.00000000"],["62640.83000000","0.00000000"],["62639.49000000","0.18028000"],["62638.66000000","0.00000000"],["62638.65000000","0.00000000"],["62638.57000000","0.00400000"],["62636.53000000","0.00000000"],["62636.03000000","0.79873000"],["62635.14000000","0.00000000"],["62633.86000000","0.00000000"],["62633.61000000","0.00400000"],["62631.91000000","0.00200000"],["62630.65000000","0.47800000"],["62623.20000000","0.57533000"],["62622.59000000","0.00400000"],["62594.36000000","0.00000000"],["62593.35000000","0.95860000"],["62407.67000000","0.00000000"],["62370.22000000","2.42424000"],["62338.50000000","0.02406000"],["56387.50000000","0.00483000"]],"a":[["62652.78000000","2.61191000"],["62652.79000000","0.00097000"],["62653.01000000","0.00000000"],["62653.31000000","0.09430000"],["62655.56000000","0.00400000"],["62655.65000000","0.00000000"],["62657.17000000","0.12982000"],["62662.55000000","0.59908000"],["62662.79000000","0.03966000"],["62662.92000000","0.57497000"],["62663.28000000","0.00400000"],["62663.99000000","0.17805000"],["62666.76000000","0.00000000"],["62667.07000000","0.79873000"],["62668.79000000","0.00000000"],["62670.01000000","0.00000000"],["62673.03000000","0.00000000"],["62678.03000000","0.00000000"],["62680.68000000","0.00000000"]]}}
{"t":32.1638,"stream":"btcusdt@depth20@100ms","data":{"lastUpdateId":97344805368,"bids":[["62652.77000000","0.93973000"],["62652.76000000","0.00097000"],["62652.75000000","0.00016000"],["62652.62000000","0.00016000"],["62652.15000000","0.00018000"],["62652.14000000","0.07928000"],["62651.60000000","0.00009000"],["62651.34000000","0.00018000"],["62650.86000000","0.00256000"],["62650.35000000","0.00008000"],["62650.21000000","0.00018000"],["62650.00000000","0.00618000"],["62649.72000000","0.00009000"],["62649.60000000","0.00008000"],["62649.31000000","0.00026000"],["62649.29000000","0.00026000"],["62649.28000000","1.95277000"],["62649.03000000","0.02172000"],["62649.00000000","0.07921000"],["62648.00000000","0.00618000"]],"asks":[["62652.78000000","2.61191000"],["62652.79000000","0.00097000"],["62652.80000000","0.00016000"],["62652.97000000","0.00026000"],["62652.98000000","1.58158000"],["62653.11000000","0.00018000"],["62653.12000000","0.17279000"],["62653.30000000","0.00018000"],["62653.31000000","0.09430000"],["62653.50000000","0.00008000"],["62653.67000000","0.00057000"],["62653.69000000","0.00016000"],["62654.00000000","0.02418000"],["62654.05000000","0.00008000"],["62654.09000000","0.00009000"],["62654.68000000","0.00009000"],["62654.69000000","0.00010000"],["62655.20000000","0.00012000"],["62655.56000000","0.00400000"],["62655.80000000","0.00009000"]]}}
{"t":32.1708,"stream":"btcusdt@aggTrade","data":{"e":"aggTrade","E":1783948034821,"s":"BTCUSDT","a":4013160710,"p":"62652.78000000","q":"0.00234000","f":6501834363,"l":6501834368,"T":1783948034820,"m":false,"M":true}}
{"t":32.2629,"stream":"btcusdt@depth@100ms","data":{"e":"depthUpdate","E":1783948034914,"s":"BTCUSDT","U":97344805369,"u":97344805454,"b":[["62652.77000000","0.93964000"],["62652.14000000","0.07920000"],["62651.34000000","0.00000000"],["62650.35000000","0.00000000"],["62650.21000000","0.00000000"],["62648.00000000","0.00618000"],["62647.83000000","0.02018000"],["62647.53000000","0.04091000"],["62646.00000000","1.95250000"],["62645.87000000","0.05277000"],["62645.67000000","0.00018000"],["62645.66000000","0.52720000"],["62645.00000000","0.00000000"],["62644.29000000","0.00798000"],["62643.44000000","0.00000000"],["62638.75000000","0.00008000"],["62636.02000000","0.00000000"],["62620.70000000","0.57535000"],["62612.61000000","0.00000000"],["62593.35000000","0.00000000"],["62592.76000000","0.95860000"],["62370.22000000","0.00000000"],["56387.50000000","0.00483000"],["56387.49000000","0.00000000"],["56387.48000000","0.00010000"]],"a":[["62652.78000000","2.60982000"],["62652.79000000","0.00106000"],["62655.79000000","0.00798000"],["62657.13000000","0.02572000"],["62657.17000000","0.13000000"],["62657.86000000","0.01717000"],["62661.61000000","0.00000000"],["62663.82000000","0.00008000"],["63179.84000000","0.00000000"],["64200.00000000","13.15482000"]]}}
{"t":32.2632,"stream":"btcusdt@depth20@100ms","data":{"lastUpdateId":97344805454,"bids":[["62652.77000000","0.93964000"],["62652.76000000","0.00097000"],["62652.75000000","0.00016000"],["62652.62000000","0.00016000"],["62652.15000000","0.00018000"],["62652.14000000","0.07920000"],["62651.60000000","0.00009000"],["62650.86000000","0.00256000"],["62650.00000000","0.00618000"],["62649.72000000","0.00009000"],["62649.60000000","0.00008000"],["62649.31000000","0.00026000"],["62649.29000000","0.00026000"],["62649.28000000","1.95277000"],["62649.03000000","0.02172000"],["62649.00000000","0.07921000"],["62648.00000000","0.00618000"],["62647.83000000","0.02018000"],["62647.71000000","0.00400000"],["62647.53000000","0.04091000"]],"asks":[["62652.78000000","2.60982000"],["62652.79000000","0.00106000"],["62652.80000000","0.00016000"],["62652.97000000","0.00026000"],["62652.98000000","1.58158000"],["62653.11000000","0.00018000"],["62653.12000000","0.17279000"],["62653.30000000","0.00018000"],["62653.31000000","0.09430000"],["62653.50000000","0.00008000"],["62653.67000000","0.00057000"],["62653.69000000","0.00016000"],["62654.00000000","0.02418000"],["62654.05000000","0.00008000"],["62654.09000000","0.00009000"],["62654.68000000","0.00009000"],["62654.69000000","0.00010000"],["62655.20000000","0.00012000"],["62655.56000000","0.00400000"],["62655.79000000","0.00798000"]]}}
{"t":32.3647,"stream":"btcusdt@depth@100ms","data":{"e":"depthUpdate","E":1783948035014,"s":"BTCUSDT","U":97344805455,"u":97344805495,"b":[["62652.77000000","0.93955000"],["62652.76000000","0.00097000"],["62652.14000000","0.07928000"],["62650.86000000","0.00000000"],["62649.56000000","0.00018000"],["62649.55000000","0.17509000"],["62649.28000000","1.94877000"],["62644.99000000","0.15056000"],["62625.73000000","0.00400000"],["62618.85000000","0.00008000"],["62600.05000000","0.00113000"],["62600.04000000","0.00000000"],["62592.76000000","0.00000000"],["62592.00000000","1.03072000"],["62389.86000000","0.02239000"],["56387.50000000","0.00483000"],["50122.22000000","0.00039000"]],"a":[["62654.00000000","0.02418000"],["62655.79000000","0.00816000"],["62657.18000000","0.06461000"],["62771.28000000","0.00000000"],["62786.19000000","0.01403000"]]}}
{"t":32.3648,"stream":"btcusdt@depth20@100ms","data":{"lastUpdateId":97344805495,"bids":[["62652.77000000","0.93955000"],["62652.76000000","0.00097000"],["62652.75000000","0.00016000"],["62652.62000000","0.00016000"],["62652.15000000","0.00018000"],["62652.14000000","0.07928000"],["62651.60000000","0.00009000"],["62650.00000000","0.00618000"],["62649.72000000","0.00009000"],["62649.60000000","0.00008000"],["62649.56000000","0.00018000"],["62649.55000000","0.17509000"],["62649.31000000","0.00026000"],["62649.29000000","0.00026000"],["62649.28000000","1.94877000"],["62649.03000000","0.02172000"],["62649.00000000","0.07921000"],["62648.00000000","0.00618000"],["62647.83000000","0.02018000"],["62647.71000000","0.00400000"]],"asks":[["62652.78000000","2.60982000"],["62652.79000000","0.00106000"],["62652.80000000","0.00016000"],["62652.97000000","0.00026000"],["62652.98000000","1.58158000"],["62653.11000000","0.00018000"],["62653.12000000","0.17279000"],["62653.30000000","0.00018000"],["62653.31000000","0.09430000"],["62653.50000000","0.00008000"],["62653.67000000","0.00057000"],["62653.69000000","0.00016000"],["62654.00000000","0.02418000"],["62654.05000000","0.00008000"],["62654.09000000","0.00009000"],["62654.68000000","0.00009000"],["62654.69000000","0.00010000"],["62655.20000000","0.00012000"],["62655.56000000","0.00400000"],["62655.79000000","0.00816000"]]}}
{"t":32.3946,"stream":"btcusdt@aggTrade","data":{"e":"aggTrade","E":1783948035044,"s":"BTCUSDT","a":4013160711,"p":"62652.77000000","q":"0.03128000","f":6501834369,"l":6501834457,"T":1783948035043,"m":true,"M":true}}
{"t":32.3947,"stream":"btcusdt@aggTrade","data":{"e":"aggTrade","E":1783948035044,"s":"BTCUSDT","a":4013160712,"p":"62652.76000000","q":"0.00097000","f":6501834458,"l":6501834467,"T":1783948035043,"m":true,"M":true}}
{"t":32.3947,"stream":"btcusdt@aggTrade","data":{"e":"aggTrade","E":1783948035044,"s":"BTCUSDT","a":4013160713,"p":"62652.75000000","q":"0.00016000","f":6501834468,"l":6501834468,"T":1783948035043,"m":true,"M":true}}
{"t":32.3947,"stream":"btcusdt@aggTrade","data":{"e":"aggTrade","E":1783948035044,"s":"BTCUSDT","a":4013160714,"p":"62652.62000000","q":"0.00080000","f":6501834469,"l":6501834478,"T":1783948035043,"m":true,"M":true}}
{"t":32.3947,"stream":"btcusdt@aggTrade","data":{"e":"aggTrade","E":1783948035044,"s":"BTCUSDT","a":4013160715,"p":"62652.15000000","q":"0.00027000","f":6501834479,"l":6501834481,"T":1783948035043,"m":true,"M":true}}
{"t":32.3948,"stream":"btcusdt@aggTrade","data":{"e":"aggTrade","E":1783948035044,"s":"BTCUSDT","a":4013160716,"p":"62652.14000000","q":"0.07936000","f":6501834482,"l":6501834486,"T":1783948035043,"m":true,"M":true}}
{"t":32.3981,"stream":"btcusdt@aggTrade","data":{"e":"aggTrade","E":1783948035047,"s":"BTCUSDT","a":4013160717,"p":"62652.14000000","q":"0.00115000","f":6501834487,"l":6501834499,"T":1783948035046,"m":true,"M":true}}
{"t":32.3981,"stream":"btcusdt@aggTrade","data":{"e":"aggTrade","E":1783948035047,"s":"BTCUSDT","a":4013160718,"p":"62652.13000000","q":"0.00045000","f":6501834500,"l":6501834504,"T":1783948035046,"m":true,"M":true}}
{"t":32.3982,"stream":"btcusdt@aggTrade","data":{"e":"aggTrade","E":1783948035047,"s":"BTCUSDT","a":4013160719,"p":"62651.60000000","q":"0.00068000","f":6501834505,"l":6501834512,"T":1783948035046,"m":true,"M":true}}
{"t":32.3982,"stream":"btcusdt@aggTrade","data":{"e":"aggTrade","E":1783948035047,"s":"BTCUSDT","a":4013160720,"p":"62651.59000000","q":"0.00018000","f":6501834513,"l":6501834514,"T":1783948035046,"m":true,"M":true}}
{"t":32.4249,"stream":"btcusdt@aggTrade","data":{"e":"aggTrade","E":1783948035074,"s":"BTCUSDT","a":4013160721,"p":"62650.00000000","q":"0.00756000","f":6501834515,"l":6501834533,"T":1783948035073,"m":true,"M":true}}
{"t":32.4252,"stream":"btcusdt@aggTrade","data":{"e":"aggTrade","E":1783948035074,"s":"BTCUSDT","a":4013160722,"p":"62649.99000000","q":"0.00081000","f":6501834534,"l":6501834542,"T":1783948035073,"m":true,"M":true}}
{"t":32.4253,"stream":"btcusdt@aggTrade","data":{"e":"aggTrade","E":1783948035074,"s":"BTCUSDT","a":4013160723,"p":"62649.72000000","q":"0.00009000","f":6501834543,"l":6501834543,"T":1783948035073,"m":true,"M":true}}
{"t":32.4253,"stream":"btcusdt@aggTrade","data":{"e":"aggTrade","E":1783948035074,"s":"BTCUSDT","a":4013160724,"p":"62649.60000000","q":"0.00008000","f":6501834544,"l":6501834544,"T":1783948035073,"m":true,"M":true}}
{"t":32.4253,"stream":"btcusdt@aggTrade","data":{"e":"aggTrade","E":1783948035074,"s":"BTCUSDT","a":4013160725,"p":"62649.55000000","q":"0.00018000","f":6501834545,"l":6501834546,"T":1783948035073,"m":true,"M":true}}
{"t":32.4254,"stream":"btcusdt@aggTrade","data":{"e":"aggTrade","E":1783948035074,"s":"BTCUSDT","a":4013160726,"p":"62649.31000000","q":"0.00026000","f":6501834547,"l":6501834547,"T":1783948035073,"m":true,"M":true}}
{"t":32.4259,"stream":"btcusdt@aggTrade","data":{"e":"aggTrade","E":1783948035076,"s":"BTCUSDT","a":4013160727,"p":"62649.29000000","q":"0.00041000","f":6501834548,"l":6501834552,"T":1783948035075,"m":true,"M":true}}
{"t":32.4269,"stream":"btcusdt@aggTrade","data":{"e":"aggTrade","E":1783948035077,"s":"BTCUSDT","a":4013160728,"p":"62649.28000000","q":"0.00238000","f":6501834553,"l":6501834556,"T":1783948035076,"m":true,"M":true}}
{"t":32.4654,"stream":"btcusdt@depth@100ms","data":{"e":"depthUpdate","E":1783948035114,"s":"BTCUSDT","U":97344805496,"u":97344806590,"b":[["62652.77000000","0.00000000"],["62652.76000000","0.00000000"],["62652.75000000","0.00000000"],["62652.62000000","0.00000000"],["62652.15000000","0.00000000"],["62652.14000000","0.00000000"],["62652.13000000","0.00000000"],["62651.60000000","0.00000000"],["62651.59000000","0.00000000"],["62650.00000000","0.00000000"],["62649.99000000","0.00000000"],["62649.72000000","0.00000000"],["62649.60000000","0.00000000"],["62649.56000000","0.00000000"],["62649.55000000","0.00000000"],["62649.31000000","0.00000000"],["62649.29000000","0.00000000"],["62649.28000000","0.14746000"],["62649.27000000","0.00072000"],["62649.04000000","0.00000000"],["62649.03000000","0.00018000"],["62649.00000000","0.00018000"],["62648.12000000","0.00000000"],["62648.01000000","0.00000000"],["62647.83000000","0.00018000"],["62647.71000000","0.00000000"],["62647.54000000","0.00018000"],["62647.53000000","0.04091000"],["62647.20000000","0.00000000"],["62646.50000000","0.00000000"],["62646.14000000","0.00000000"],["62646.01000000","0.00000000"],["62646.00000000","0.01118000"],["62645.99000000","0.00035000"],["62645.87000000","0.00018000"],["62645.67000000","0.00000000"],["62645.66000000","0.00000000"],["62645.57000000","0.00000000"],["62645.56000000","0.00000000"],["62644.99000000","0.00008000"],["62644.98000000","0.00000000"],["62644.94000000","0.00000000"],["62644.74000000","0.00000000"],["62644.73000000","0.00000000"],["62644.57000000","0.00000000"],["62644.54000000","0.00000000"],["62644.42000000","0.00000000"],["62644.29000000","0.00000000"],["62644.10000000","0.00000000"],["62644.05000000","0.00000000"],["62643.99000000","0.00000000"],["62643.83000000","0.00000000"],["62643.74000000","0.00009000"],["62643.73000000","0.00000000"],["62643.59000000","0.00000000"],["62643.44000000","0.00000000"],["62643.43000000","0.00000000"],["62643.41000000","0.00000000"],["62643.40000000","0.00000000"],["62643.01000000","0.00000000"],["62643.00000000","0.00000000"],["62642.74000000","0.00000000"],["62642.53000000","0.00026000"],["62642.50000000","0.00018000"],["62642.49000000","0.02154000"],["62642.01000000","0.00018000"],["62641.99000000","0.00018000"],["62641.58000000","0.13965000"],["62641.43000000","0.00000000"],["62641.29000000","0.00000000"],["62641.21000000","0.00009000"],["62641.20000000","0.13973000"],["62641.16000000","0.00000000"],["62641.14000000","0.00031000"],["62641.12000000","0.00000000"],["62640.98000000","0.00000000"],["62640.90000000","0.00000000"],["62640.77000000","0.00000000"],["62640.70000000","0.00047000"],["62640.52000000","0.00187000"],["62640.36000000","0.00000000"],["62640.24000000","0.00000000"],["62640.19000000","0.00000000"],["62640.10000000","0.13973000"],["62640.03000000","1.91755000"],["62640.02000000","0.00000000"],["62640.01000000","0.14484000"],["62640.00000000","0.03679000"],["62639.99000000","0.24073000"],["62639.89000000","0.00000000"],["62639.49000000","0.00000000"],["62639.39000000","0.00048000"],["62639.00000000","0.13965000"],["62638.92000000","0.02000000"],["62638.87000000","0.00161000"],["62638.66000000","0.00000000"],["62638.65000000","0.00256000"],["62638.57000000","0.00000000"],["62638.49000000","0.00000000"],["62638.29000000","0.00400000"],["62638.19000000","0.03000000"],["62637.90000000","0.13965000"],["62637.76000000","0.00798000"],["62637.75000000","0.00008000"],["62637.58000000","0.00000000"],["62637.57000000","0.00000000"],["62637.53000000","0.00000000"],["62637.39000000","0.04000000"],["62637.19000000","0.08000000"],["62637.11000000","0.00000000"],["62637.06000000","0.00400000"],["62637.00000000","0.00000000"],["62636.80000000","0.13973000"],["62636.76000000","0.00009000"],["62636.69000000","0.52727000"],["62636.65000000","0.00000000"],["62636.15000000","0.00000000"],["62636.03000000","0.00000000"],["62635.72000000","0.00000000"],["62635.71000000","0.13965000"],["62635.63000000","0.00000000"],["62635.58000000","1.91755000"],["62635.57000000","0.00000000"],["62634.76000000","0.00000000"],["62634.74000000","0.00000000"],["62634.60000000","0.00008000"],["62634.11000000","0.00000000"],["62633.97000000","0.00000000"],["62633.73000000","0.13965000"],["62633.63000000","0.00009000"],["62633.61000000","0.00000000"],["62633.36000000","0.00000000"],["62633.09000000","0.00000000"],["62632.63000000","0.59914000"],["62632.62000000","0.13965000"],["62632.58000000","0.00000000"],["62632.39000000","0.00000000"],["62631.97000000","0.00000000"],["62631.91000000","0.00000000"],["62631.45000000","0.00008000"],["62631.28000000","0.00000000"],["62631.27000000","0.00000000"],["62630.84000000","0.00000000"],["62630.80000000","0.00400000"],["62630.66000000","0.18196000"],["62630.65000000","0.47600000"],["62630.64000000","0.00000000"],["62630.50000000","0.00009000"],["62630.47000000","0.00000000"],["62629.74000000","0.00000000"],["62629.72000000","0.00000000"],["62628.88000000","3.19219000"],["62628.16000000","0.00000000"],["62627.89000000","0.00200000"],["62627.84000000","0.00000000"],["62627.71000000","0.00000000"],["62627.36000000","0.00009000"],["62627.25000000","0.79884000"],["62627.15000000","0.00933000"],["62626.74000000","0.00000000"],["62626.13000000","0.00400000"],["62626.08000000","0.00000000"],["62625.45000000","0.00000000"],["62624.58000000","0.00000000"],["62624.23000000","0.00009000"],["62624.16000000","0.00400000"],["62622.77000000","0.00200000"],["62622.64000000","0.00200000"],["62621.44000000","0.00000000"],["62621.10000000","0.00009000"],["62621.02000000","0.00400000"],["62621.00000000","0.00000000"],["62620.80000000","0.00008000"],["62620.00000000","0.03400000"],["62619.98000000","0.00000000"],["62619.56000000","0.57536000"],["62618.97000000","0.00000000"],["62618.75000000","0.00000000"],["62618.00000000","0.02400000"],["62617.97000000","0.00009000"],["62617.88000000","0.00400000"],["62617.00000000","0.01000000"],["62615.70000000","0.00008000"],["62615.31000000","0.00000000"],["62615.01000000","0.57541000"],["62614.74000000","0.00400000"],["62614.68000000","0.00000000"],["62612.55000000","0.00008000"],["62612.29000000","0.00000000"],["62612.01000000","0.02395000"],["62611.66000000","0.00000000"],["62611.60000000","0.00400000"],["62609.97000000","0.22300000"],["62609.40000000","0.01008000"],["62609.34000000","0.33450000"],["62609.25000000","0.00270000"],["62605.01000000","0.00023000"],["62600.68000000","0.22500000"],["62600.06000000","0.00000000"],["62600.05000000","0.00000000"],["62600.04000000","0.00000000"],["62600.03000000","0.00000000"],["62599.20000000","0.00023000"],["62596.63000000","0.00396000"],["62596.14000000","0.00000000"],["62593.15000000","0.00397000"],["62592.00000000","0.07212000"],["62584.72000000","0.00000000"],["62581.83000000","0.95862000"],["62581.81000000","0.00000000"],["62581.54000000","0.00000000"],["62556.53000000","0.00000000"],["62487.33000000","0.00009000"],["62486.71000000","0.00000000"],["62484.20000000","0.00009000"],["62461.11000000","0.00000000"],["62423.62000000","2.42216000"],["61712.97000000","0.00000000"],["56387.50000000","0.00023000"],["56385.00000000","0.00417000"],["50122.22000000","0.00039000"],["40000.00000000","258.07540000"]],"a":[["62649.29000000","4.37588000"],["62649.30000000","0.53742000"],["62649.31000000","0.00016000"],["62649.32000000","0.00000000"],["62649.56000000","0.00000000"],["62649.60000000","0.00008000"],["62649.73000000","0.00000000"],["62650.00000000","0.07500000"],["62650.01000000","0.48924000"],["62650.02000000","0.00000000"],["62650.03000000","0.00000000"],["62650.15000000","0.00000000"],["62650.35000000","0.00008000"],["62650.85000000","0.00400000"],["62651.11000000","0.00000000"],["62651.60000000","0.00000000"],["62651.61000000","0.00000000"],["62651.66000000","0.03032000"],["62652.13000000","0.59912000"],["62652.14000000","0.17508000"],["62652.15000000","2.39985000"],["62652.16000000","0.00000000"],["62652.17000000","0.00000000"],["62652.42000000","0.00400000"],["62652.63000000","0.00000000"],["62652.77000000","0.23210000"],["62652.78000000","0.42585000"],["62652.79000000","0.30000000"],["62652.80000000","0.00008000"],["62652.87000000","0.01270000"],["62652.97000000","0.47608000"],["62652.98000000","1.88158000"],["62653.11000000","0.00000000"],["62653.12000000","0.00026000"],["62653.30000000","0.00000000"],["62653.31000000","0.00018000"],["62653.51000000","0.57505000"],["62653.69000000","0.00008000"],["62653.92000000","0.00000000"],["62653.99000000","0.00400000"],["62654.05000000","0.00000000"],["62654.98000000","0.00000000"],["62655.79000000","0.00000000"],["62656.00000000","0.02408000"],["62656.01000000","0.01308000"],["62656.08000000","0.00000000"],["62656.28000000","0.00009000"],["62656.29000000","0.00400000"],["62656.30000000","0.03966000"],["62657.13000000","0.00400000"],["62657.17000000","0.00000000"],["62657.18000000","0.00000000"],["62657.36000000","0.00000000"],["62657.46000000","0.00000000"],["62657.97000000","0.01700000"],["62657.98000000","0.00200000"],["62658.09000000","0.00000000"],["62658.10000000","0.00000000"],["62658.26000000","0.00000000"],["62658.27000000","0.12000000"],["62658.55000000","0.10135000"],["62659.05000000","0.00000000"],["62659.31000000","0.00000000"],["62659.35000000","0.00000000"],["62659.55000000","0.00000000"],["62659.92000000","0.57499000"],["62659.99000000","0.00000000"],["62660.32000000","0.00000000"],["62660.85000000","0.00000000"],["62661.26000000","0.00000000"],["62661.83000000","0.00009000"],["62662.55000000","0.79884000"],["62663.28000000","0.00000000"],["62663.45000000","0.00000000"],["62663.99000000","0.00000000"],["62664.96000000","0.00009000"],["62665.24000000","0.00100000"],["62665.27000000","0.00986000"],["62665.31000000","0.00009000"],["62665.42000000","0.00000000"],["62665.44000000","0.57926000"],["62665.84000000","0.00200000"],["62666.58000000","0.00000000"],["62667.07000000","0.00000000"],["62668.09000000","0.00009000"],["62668.14000000","0.02096000"],["62668.39000000","0.00419000"],["62668.44000000","0.00000000"],["62668.69000000","0.00168000"],["62668.80000000","0.00008000"],["62669.78000000","0.00023000"],["62670.25000000","0.00000000"],["62671.23000000","0.00009000"],["62671.58000000","0.00000000"],["62672.22000000","0.02295000"],["62673.04000000","0.00000000"],["62674.14000000","0.00000000"],["62674.36000000","0.00009000"],["62674.71000000","0.00000000"],["62675.62000000","0.00000000"],["62675.97000000","0.00000000"],["62676.47000000","0.00000000"],["62676.50000000","0.00000000"],["62677.49000000","0.00009000"],["62677.54000000","0.00000000"],["62677.59000000","0.00000000"],["62677.84000000","0.00000000"],["62678.18000000","0.61925000"],["62679.11000000","0.00000000"],["62679.97000000","0.00000000"],["62680.62000000","0.00009000"],["62680.97000000","0.00000000"],["62681.60000000","0.00000000"],["62681.85000000","0.00000000"],["62682.14000000","0.00000000"],["62684.00000000","0.03400000"],["62684.11000000","0.00000000"],["62684.57000000","0.00000000"],["62685.00000000","0.00008000"],["62687.07000000","0.00000000"],["62687.28000000","0.00000000"],["62688.58000000","0.00000000"],["62688.70000000","0.00000000"],["62689.03000000","0.00000000"],["62694.25000000","0.00000000"],["62703.34000000","0.95862000"],["62715.91000000","0.00000000"],["63053.99000000","0.00000000"],["63592.58000000","0.00000000"],["65751.59000000","0.00010000"],["65784.47000000","0.00010000"]]}}
{"t":32.4662,"stream":"btcusdt@depth20@100ms","data":{"lastUpdateId":97344806590,"bids":[["62649.28000000","0.14746000"],["62649.27000000","0.00072000"],["62649.03000000","0.00018000"],["62649.00000000","0.00018000"],["62648.00000000","0.00618000"],["62647.83000000","0.00018000"],["62647.54000000","0.00018000"],["62647.53000000","0.04091000"],["62646.40000000","0.00008000"],["62646.00000000","0.01118000"],["62645.99000000","0.00035000"],["62645.94000000","0.00008000"],["62645.87000000","0.00018000"],["62645.48000000","0.00009000"],["62644.99000000","0.00008000"],["62644.89000000","0.00009000"],["62644.28000000","0.00008000"],["62644.00000000","0.01100000"],["62643.74000000","0.00009000"],["62643.20000000","0.00008000"]],"asks":[["62649.29000000","4.37588000"],["62649.30000000","0.53742000"],["62649.31000000","0.00016000"],["62649.60000000","0.00008000"],["62650.00000000","0.07500000"],["62650.01000000","0.48924000"],["62650.35000000","0.00008000"],["62650.85000000","0.00400000"],["62651.66000000","0.03032000"],["62652.13000000","0.59912000"],["62652.14000000","0.17508000"],["62652.15000000","2.39985000"],["62652.42000000","0.00400000"],["62652.77000000","0.23210000"],["62652.78000000","0.42585000"],["62652.79000000","0.30000000"],["62652.80000000","0.00008000"],["62652.87000000","0.01270000"],["62652.97000000","0.47608000"],["62652.98000000","1.88158000"]]}}
{"t":32.5641,"stream":"btcusdt@depth@100ms","data":{"e":"depthUpdate","E":1783948035214,"s":"BTCUSDT","U":97344806591,"u":97344806820,"b":[["62649.28000000","0.15245000"],["62649.27000000","0.00063000"],["62649.03000000","0.00000000"],["62649.00000000","0.00000000"],["62648.66000000","0.00008000"],["62648.00000000","0.00618000"],["62647.84000000","0.00009000"],["62647.83000000","0.00000000"],["62647.54000000","0.00000000"],["62647.53000000","0.00018000"],["62646.00000000","0.01118000"],["62645.99000000","0.00000000"],["62645.94000000","0.00000000"],["62645.87000000","0.00000000"],["62645.10000000","0.00032000"],["62644.99000000","0.00000000"],["62644.73000000","0.00018000"],["62644.72000000","0.06410000"],["62644.28000000","0.00000000"],["62644.00000000","0.01118000"],["62643.79000000","0.00018000"],["62643.78000000","0.13965000"],["62643.02000000","0.00018000"],["62643.01000000","0.22828000"],["62642.69000000","0.00018000"],["62642.68000000","0.13965000"],["62642.60000000","0.01018000"],["62642.54000000","0.01100000"],["62642.50000000","0.00000000"],["62642.49000000","0.02172000"],["62642.01000000","0.00000000"],["62642.00000000","0.01918000"],["62641.99000000","0.00000000"],["62641.98000000","0.02018000"],["62641.87000000","0.00128000"],["62641.83000000","0.00128000"],["62641.59000000","0.00018000"],["62641.58000000","0.20367000"],["62641.21000000","0.00000000"],["62640.90000000","0.00008000"],["62640.11000000","1.94150000"],["62640.10000000","0.00008000"],["62640.03000000","0.00000000"],["62640.01000000","0.00008000"],["62640.00000000","0.03423000"],["62639.99000000","0.06820000"],["62638.65000000","0.00000000"],["62638.45000000","0.04268000"],["62638.44000000","0.00000000"],["62637.06000000","0.00000000"],["62635.62000000","0.00000000"],["62635.38000000","0.00400000"],["62635.32000000","0.04268000"],["62634.86000000","0.00165000"],["62633.88000000","0.00000000"],["62633.73000000","0.00000000"],["62632.62000000","0.00000000"],["62631.62000000","0.05000000"],["62630.67000000","0.47600000"],["62630.65000000","0.00000000"],["62626.96000000","0.00000000"],["62626.13000000","0.00000000"],["62623.10000000","0.00000000"],["62622.85000000","0.00400000"],["62620.00000000","0.04400000"],["62609.97000000","0.00000000"],["62609.40000000","0.01000000"],["62609.34000000","0.00000000"],["62609.25000000","0.00000000"],["62607.17000000","0.20200000"],["62606.54000000","0.30300000"],["62605.64000000","0.02000000"],["62598.94000000","0.00270000"],["62553.13000000","0.00000000"],["62549.64000000","0.00074000"],["62546.80000000","0.00000000"],["62527.12000000","0.00000000"],["62485.65000000","0.00009000"],["62484.20000000","0.00000000"],["62482.52000000","0.00009000"],["62423.62000000","0.00000000"],["61709.54000000","0.00030000"],["56384.36000000","0.00040000"],["50122.22000000","0.00000000"],["50119.42000000","0.00000000"]],"a":[["62649.29000000","3.93162000"],["62649.30000000","0.53750000"],["62649.76000000","0.07963000"],["62650.00000000","0.07518000"],["62650.01000000","0.30787000"],["62650.34000000","0.00798000"],["62650.61000000","0.04000000"],["62651.66000000","0.03050000"],["62652.13000000","0.59930000"],["62652.14000000","0.17526000"],["62652.15000000","2.39985000"],["62652.78000000","0.41559000"],["62652.79000000","0.30008000"],["62652.90000000","0.07963000"],["62652.97000000","0.47608000"],["62652.98000000","1.88140000"],["62653.12000000","0.00000000"],["62653.31000000","0.00000000"],["62653.51000000","0.57513000"],["62653.69000000","0.00000000"],["62654.00000000","0.02400000"],["62654.09000000","0.00000000"],["62656.03000000","0.05309000"],["62656.83000000","0.00000000"],["62656.91000000","0.00000000"],["62659.16000000","0.05309000"],["62659.46000000","0.01500000"],["62661.71000000","0.14471000"],["62663.27000000","0.15102000"],["62664.11000000","0.00000000"],["62665.67000000","0.00000000"],["62675.00000000","0.00000000"],["62678.22000000","0.00632000"],["62678.43000000","0.00435000"],["62678.85000000","0.00425000"],["62679.44000000","0.00432000"],["62681.00000000","0.01000000"],["62684.00000000","0.02400000"],["62688.06000000","0.00000000"],["62688.78000000","0.39951000"],["62745.85000000","0.00009000"],["62748.04000000","0.00000000"],["62754.86000000","0.00000000"],["62766.97000000","0.14746000"],["62819.86000000","0.00009000"],["62826.48000000","0.00000000"]]}}
{"t":32.5644,"stream":"btcusdt@depth20@100ms","data":{"lastUpdateId":97344806820,"bids":[["62649.28000000","0.15245000"],["62649.27000000","0.00063000"],["62648.66000000","0.00008000"],["62648.00000000","0.00618000"],["62647.84000000","0.00009000"],["62647.53000000","0.00018000"],["62646.40000000","0.00008000"],["62646.00000000","0.01118000"],["62645.48000000","0.00009000"],["62645.10000000","0.00032000"],["62644.89000000","0.00009000"],["62644.73000000","0.00018000"],["62644.72000000","0.06410000"],["62644.00000000","0.01118000"],["62643.79000000","0.00018000"],["62643.78000000","0.13965000"],["62643.74000000","0.00009000"],["62643.20000000","0.00008000"],["62643.02000000","0.00018000"],["62643.01000000","0.22828000"]],"asks":[["62649.29000000","3.93162000"],["62649.30000000","0.53750000"],["62649.31000000","0.00016000"],["62649.60000000","0.00008000"],["62649.76000000","0.07963000"],["62650.00000000","0.07518000"],["62650.01000000","0.30787000"],["62650.34000000","0.00798000"],["62650.35000000","0.00008000"],["62650.61000000","0.04000000"],["62650.85000000","0.00400000"],["62651.66000000","0.03050000"],["62652.13000000","0.59930000"],["62652.14000000","0.17526000"],["62652.15000000","2.39985000"],["62652.42000000","0.00400000"],["62652.77000000","0.23210000"],["62652.78000000","0.41559000"],["62652.79000000","0.30008000"],["62652.80000000","0.00008000"]]}}
{"t":32.6637,"stream":"btcusdt@depth@100ms","data":{"e":"depthUpdate","E":1783948035314,"s":"BTCUSDT","U":97344806821,"u":97344806917,"b":[["62649.28000000","0.84158000"],["62649.27000000","0.00063000"],["62648.00000000","0.00618000"],["62647.53000000","0.00000000"],["62646.00000000","0.01118000"],["62644.72000000","0.06428000"],["62644.00000000","0.01118000"],["62643.78000000","0.13983000"],["62643.01000000","0.22846000"],["62642.70000000","0.00018000"],["62642.69000000","0.02413000"],["62642.68000000","0.13983000"],["62642.60000000","0.01018000"],["62642.49000000","0.02154000"],["62642.00000000","0.01900000"],["62641.98000000","0.02000000"],["62641.87000000","0.00000000"],["62641.83000000","0.00000000"],["62641.59000000","0.00000000"],["62641.20000000","0.13981000"],["62640.90000000","0.00000000"],["62640.71000000","0.00256000"],["62640.67000000","0.17253000"],["62640.12000000","0.13965000"],["62639.00000000","0.00000000"],["62638.22000000","0.52726000"],["62637.90000000","0.00000000"],["62636.80000000","0.00008000"],["62636.69000000","0.00000000"],["62626.45000000","0.54007000"],["62620.00000000","0.03400000"],["62614.70000000","0.00270000"],["62612.24000000","0.57543000"],["62609.40000000","0.01008000"],["62607.66000000","1.05845000"],["62598.94000000","0.00000000"],["62595.30000000","0.00435000"],["62482.52000000","0.00000000"],["56384.36000000","0.00080000"]],"a":[["62649.29000000","5.84947000"],["62649.30000000","0.31250000"],["62649.76000000","0.07981000"],["62650.01000000","0.30787000"],["62650.34000000","0.00816000"],["62652.13000000","0.00018000"],["62652.14000000","0.17508000"],["62652.15000000","2.39967000"],["62653.51000000","0.00016000"],["62655.99000000","0.59915000"],["62656.03000000","0.05317000"],["62656.78000000","0.57502000"],["62669.47000000","0.57491000"],["62680.48000000","0.00032000"],["62711.56000000","0.00000000"],["62778.10000000","0.02500000"],["63116.72000000","0.00000000"],["63589.03000000","0.00030000"]]}}
{"t":32.664,"stream":"btcusdt@depth20@100ms","data":{"lastUpdateId":97344806917,"bids":[["62649.28000000","0.84158000"],["62649.27000000","0.00063000"],["62648.66000000","0.00008000"],["62648.00000000","0.00618000"],["62647.84000000","0.00009000"],["62646.40000000","0.00008000"],["62646.00000000","0.01118000"],["62645.48000000","0.00009000"],["62645.10000000","0.00032000"],["62644.89000000","0.00009000"],["62644.73000000","0.00018000"],["62644.72000000","0.06428000"],["62644.00000000","0.01118000"],["62643.79000000","0.00018000"],["62643.78000000","0.13983000"],["62643.74000000","0.00009000"],["62643.20000000","0.00008000"],["62643.02000000","0.00018000"],["62643.01000000","0.22846000"],["62642.70000000","0.00018000"]],"asks":[["62649.29000000","5.84947000"],["62649.30000000","0.31250000"],["62649.31000000","0.00016000"],["62649.60000000","0.00008000"],["62649.76000000","0.07981000"],["62650.00000000","0.07518000"],["62650.01000000","0.30787000"],["62650.34000000","0.00816000"],["62650.35000000","0.00008000"],["62650.61000000","0.04000000"],["62650.85000000","0.00400000"],["62651.66000000","0.03050000"],["62652.13000000","0.00018000"],["62652.14000000","0.17508000"],["62652.15000000","2.39967000"],["62652.42000000","0.00400000"],["62652.77000000","0.23210000"],["62652.78000000","0.41559000"],["62652.79000000","0.30008000"],["62652.80000000","0.00008000"]]}}
{"t":32.7629,"stream":"btcusdt@aggTrade","data":{"e":"aggTrade","E":1783948035412,"s":"BTCUSDT","a":4013160729,"p":"62649.29000000","q":"0.00019000","f":6501834557,"l":6501834557,"T":1783948035412,"m":false,"M":true}}
{"t":32.7631,"stream":"btcusdt@depth@100ms","data":{"e":"depthUpdate","E":1783948035414,"s":"BTCUSDT","U":97344806918,"u":97344806972,"b":[["62649.28000000","0.83990000"],["62643.01000000","0.22846000"],["62642.60000000","0.01000000"],["62640.11000000","0.02395000"],["62638.98000000","0.00400000"],["62638.29000000","0.60314000"],["62638.28000000","0.13965000"],["62638.23000000","1.91755000"],["62635.38000000","0.00000000"],["62632.63000000","0.00000000"],["62631.62000000","0.00000000"],["62628.72000000","0.05000000"],["62619.92000000","0.00000000"],["62619.45000000","0.00400000"],["62616.20000000","0.01000000"],["62611.60000000","0.00000000"],["62592.00000000","0.06094000"],["62576.28000000","2.89900000"],["62550.19000000","0.00009000"],["62543.31000000","0.00023000"],["62523.63000000","0.00039000"],["62507.35000000","0.00000000"],["62469.83000000","2.42037000"],["56800.00000000","37.59288000"],["56384.36000000","0.00120000"],["50119.00000000","0.00000000"]],"a":[["62649.29000000","5.84928000"],["62650.01000000","0.25775000"],["62650.61000000","0.04018000"],["62651.66000000","0.03018000"],["62652.13000000","0.00000000"],["62652.14000000","0.17526000"],["62657.98000000","0.00000000"],["62660.26000000","0.00200000"],["62680.51000000","0.00000000"],["62681.88000000","1.20610000"],["62683.18000000","0.00011000"]]}}
{"t":32.7632,"stream":"btcusdt@depth20@100ms","data":{"lastUpdateId":97344806972,"bids":[["62649.28000000","0.83990000"],["62649.27000000","0.00063000"],["62648.66000000","0.00008000"],["62648.00000000","0.00618000"],["62647.84000000","0.00009000"],["62646.40000000","0.00008000"],["62646.00000000","0.01118000"],["62645.48000000","0.00009000"],["62645.10000000","0.00032000"],["62644.89000000","0.00009000"],["62644.73000000","0.00018000"],["62644.72000000","0.06428000"],["62644.00000000","0.01118000"],["62643.79000000","0.00018000"],["62643.78000000","0.13983000"],["62643.74000000","0.00009000"],["62643.20000000","0.00008000"],["62643.02000000","0.00018000"],["62643.01000000","0.22846000"],["62642.70000000","0.00018000"]],"asks":[["62649.29000000","5.84928000"],["62649.30000000","0.31250000"],["62649.31000000","0.00016000"],["62649.60000000","0.00008000"],["62649.76000000","0.07981000"],["62650.00000000","0.07518000"],["62650.01000000","0.25775000"],["62650.34000000","0.00816000"],["62650.35000000","0.00008000"],["62650.61000000","0.04018000"],["62650.85000000","0.00400000"],["62651.66000000","0.03018000"],["62652.14000000","0.17526000"],["62652.15000000","2.39967000"],["62652.42000000","0.00400000"],["62652.77000000","0.23210000"],["62652.78000000","0.41559000"],["62652.79000000","0.30008000"],["62652.80000000","0.00008000"],["62652.87000000","0.01270000"]]}}
{"t":32.8641,"stream":"btcusdt@depth@100ms","data":{"e":"depthUpdate","E":1783948035514,"s":"BTCUSDT","U":97344806973,"u":97344806997,"b":[["62649.28000000","0.83990000"],["62642.69000000","0.02431000"],["62640.94000000","0.00009000"],["62638.29000000","0.00400000"],["62635.71000000","0.00000000"],["62635.59000000","0.59914000"],["62617.87000000","0.00419000"],["62503.01000000","0.00000000"],["62500.01000000","0.07450000"],["62469.83000000","0.00000000"],["62085.44000000","0.00010000"],["56384.36000000","0.00160000"],["56384.00000000","0.00020000"],["33000.00000000","33.37088000"]],"a":[["62649.29000000","5.84938000"],["62652.00000000","0.00600000"],["62652.15000000","2.34963000"],["62652.26000000","0.01701000"],["62656.29000000","0.00000000"],["62658.18000000","0.00432000"],["62742.36000000","0.00015000"],["62744.54000000","0.00023000"]]}}
{"t":32.8643,"stream":"btcusdt@depth20@100ms","data":{"lastUpdateId":97344806997,"bids":[["62649.28000000","0.83990000"],["62649.27000000","0.00063000"],["62648.66000000","0.00008000"],["62648.00000000","0.00618000"],["62647.84000000","0.00009000"],["62646.40000000","0.00008000"],["62646.00000000","0.01118000"],["62645.48000000","0.00009000"],["62645.10000000","0.00032000"],["62644.89000000","0.00009000"],["62644.73000000","0.00018000"],["62644.72000000","0.06428000"],["62644.00000000","0.01118000"],["62643.79000000","0.00018000"],["62643.78000000","0.13983000"],["62643.74000000","0.00009000"],["62643.20000000","0.00008000"],["62643.02000000","0.00018000"],["62643.01000000","0.22846000"],["62642.70000000","0.00018000"]],"asks":[["62649.29000000","5.84938000"],["62649.30000000","0.31250000"],["62649.31000000","0.00016000"],["62649.60000000","0.00008000"],["62649.76000000","0.07981000"],["62650.00000000","0.07518000"],["62650.01000000","0.25775000"],["62650.34000000","0.00816000"],["62650.35000000","0.00008000"],["62650.61000000","0.04018000"],["62650.85000000","0.00400000"],["62651.66000000","0.03018000"],["62652.00000000","0.00600000"],["62652.14000000","0.17526000"],["62652.15000000","2.34963000"],["62652.26000000","0.01701000"],["62652.42000000","0.00400000"],["62652.77000000","0.23210000"],["62652.78000000","0.41559000"],["62652.79000000","0.30008000"]]}}
{"t":32.9645,"stream":"btcusdt@depth@100ms","data":{"e":"depthUpdate","E":1783948035614,"s":"BTCUSDT","U":97344806998,"u":97344807025,"b":[["62642.18000000","0.00256000"],["62641.20000000","0.13973000"],["62640.90000000","0.00008000"],["62640.67000000","0.00000000"],["62639.58000000","0.52725000"],["62638.24000000","0.13965000"],["62638.22000000","0.00000000"],["62625.83000000","0.57531000"],["62615.01000000","0.00000000"],["62609.40000000","0.01000000"],["62607.17000000","0.00000000"],["56384.36000000","0.00200000"],["56384.00000000","0.00000000"],["33000.00000000","33.37028000"]],"a":[["62650.49000000","0.01256000"],["62651.66000000","0.03018000"],["62652.00000000","0.00618000"],["62652.14000000","0.17508000"],["62714.92000000","0.00354000"],["62751.36000000","0.00039000"],["62777.64000000","0.00398000"]]}}
{"t":32.9647,"stream":"btcusdt@depth20@100ms","data":{"lastUpdateId":97344807025,"bids":[["62649.28000000","0.83990000"],["62649.27000000","0.00063000"],["62648.66000000","0.00008000"],["62648.00000000","0.00618000"],["62647.84000000","0.00009000"],["62646.40000000","0.00008000"],["62646.00000000","0.01118000"],["62645.48000000","0.00009000"],["62645.10000000","0.00032000"],["62644.89000000","0.00009000"],["62644.73000000","0.00018000"],["62644.72000000","0.06428000"],["62644.00000000","0.01118000"],["62643.79000000","0.00018000"],["62643.78000000","0.13983000"],["62643.74000000","0.00009000"],["62643.20000000","0.00008000"],["62643.02000000","0.00018000"],["62643.01000000","0.22846000"],["62642.70000000","0.00018000"]],"asks":[["62649.29000000","5.84938000"],["62649.30000000","0.31250000"],["62649.31000000","0.00016000"],["62649.60000000","0.00008000"],["62649.76000000","0.07981000"],["62650.00000000","0.07518000"],["62650.01000000","0.25775000"],["62650.34000000","0.00816000"],["62650.35000000","0.00008000"],["62650.49000000","0.01256000"],["62650.61000000","0.04018000"],["62650.85000000","0.00400000"],["62651.66000000","0.03018000"],["62652.00000000","0.00618000"],["62652.14000000","0.17508000"],["62652.15000000","2.34963000"],["62652.26000000","0.01701000"],["62652.42000000","0.00400000"],["62652.77000000","0.23210000"],["62652.78000000","0.41559000"]]}}
{"t":33.0632,"stream":"btcusdt@depth@100ms","data":{"e":"depthUpdate","E":1783948035714,"s":"BTCUSDT","U":97344807026,"u":97344807044,"b":[["62642.54000000","0.00000000"],["62560.78000000","0.00000000"],["62523.23000000","2.41831000"],["56384.36000000","0.00240000"]],"a":[["62650.34000000","0.00816000"],["62650.49000000","0.01274000"],["62652.00000000","0.00600000"],["62743.99000000","0.02500000"],["62755.34000000","0.00000000"],["62840.42000000","0.00446000"],["63092.18000000","0.19108000"],["63155.28000000","0.21656000"]]}}
{"t":33.064,"stream":"btcusdt@depth20@100ms","data":{"lastUpdateId":97344807044,"bids":[["62649.28000000","0.83990000"],["62649.27000000","0.00063000"],["62648.66000000","0.00008000"],["62648.00000000","0.00618000"],["62647.84000000","0.00009000"],["62646.40000000","0.00008000"],["62646.00000000","0.01118000"],["62645.48000000","0.00009000"],["62645.10000000","0.00032000"],["62644.89000000","0.00009000"],["62644.73000000","0.00018000"],["62644.72000000","0.06428000"],["62644.00000000","0.01118000"],["62643.79000000","0.00018000"],["62643.78000000","0.13983000"],["62643.74000000","0.00009000"],["62643.20000000","0.00008000"],["62643.02000000","0.00018000"],["62643.01000000","0.22846000"],["62642.70000000","0.00018000"]],"asks":[["62649.29000000","5.84938000"],["62649.30000000","0.31250000"],["62649.31000000","0.00016000"],["62649.60000000","0.00008000"],["62649.76000000","0.07981000"],["62650.00000000","0.07518000"],["62650.01000000","0.25775000"],["62650.34000000","0.00816000"],["62650.35000000","0.00008000"],["62650.49000000","0.01274000"],["62650.61000000","0.04018000"],["62650.85000000","0.00400000"],["62651.66000000","0.03018000"],["62652.00000000","0.00600000"],["62652.14000000","0.17508000"],["62652.15000000","2.34963000"],["62652.26000000","0.01701000"],["62652.42000000","0.00400000"],["62652.77000000","0.23210000"],["62652.78000000","0.41559000"]]}}
{"t":33.1631,"stream":"btcusdt@depth@100ms","data":{"e":"depthUpdate","E":1783948035814,"s":"BTCUSDT","U":97344807045,"u":97344807138,"b":[["62649.28000000","1.06542000"],["62649.27000000","0.00081000"],["62645.99000000","0.00018000"],["62645.98000000","0.13965000"],["62645.63000000","0.00018000"],["62645.62000000","0.02000000"],["62645.27000000","0.00256000"],["62644.89000000","0.00027000"],["62644.88000000","0.13965000"],["62644.05000000","0.00008000"],["62643.78000000","0.13991000"],["62643.74000000","0.00009000"],["62643.73000000","0.00256000"],["62643.02000000","0.00000000"],["62642.70000000","0.00000000"],["62642.69000000","0.02413000"],["62642.18000000","0.00000000"],["62641.20000000","0.13981000"],["62640.98000000","0.52724000"],["62640.75000000","1.91755000"],["62640.71000000","0.00000000"],["62640.12000000","0.00000000"],["62640.10000000","0.00000000"],["62640.01000000","0.00000000"],["62639.58000000","0.00000000"],["62638.92000000","0.00000000"],["62638.24000000","0.47600000"],["62635.80000000","0.10203000"],["62630.66000000","0.00000000"],["62616.43000000","0.00015000"],["62616.31000000","0.00400000"],["62614.74000000","0.00000000"],["62612.55000000","0.00000000"],["62600.68000000","0.00000000"],["62523.23000000","0.00000000"],["56384.36000000","0.00280000"]],"a":[["62649.29000000","3.43310000"],["62649.75000000","0.00018000"],["62649.99000000","0.00018000"],["62650.00000000","1.16972000"],["62650.01000000","0.20775000"],["62650.34000000","0.00018000"],["62650.96000000","0.00009000"],["62651.85000000","0.02000000"],["62652.12000000","0.00009000"],["62652.13000000","1.91755000"],["62652.15000000","0.43208000"],["62652.76000000","0.00798000"],["62656.03000000","0.05309000"],["62656.77000000","1.91755000"],["62656.78000000","0.00000000"],["62658.18000000","0.00032000"],["62660.19000000","0.00400000"],["62665.27000000","0.00000000"],["62668.53000000","0.00940000"],["62672.70000000","0.57488000"],["62676.99000000","0.00015000"],["63218.44000000","0.09699000"]]}}
{"t":33.1636,"stream":"btcusdt@depth20@100ms","data":{"lastUpdateId":97344807138,"bids":[["62649.28000000","1.06542000"],["62649.27000000","0.00081000"],["62648.66000000","0.00008000"],["62648.00000000","0.00618000"],["62647.84000000","0.00009000"],["62646.40000000","0.00008000"],["62646.00000000","0.01118000"],["62645.99000000","0.00018000"],["62645.98000000","0.13965000"],["62645.63000000","0.00018000"],["62645.62000000","0.02000000"],["62645.48000000","0.00009000"],["62645.27000000","0.00256000"],["62645.10000000","0.00032000"],["62644.89000000","0.00027000"],["62644.88000000","0.13965000"],["62644.73000000","0.00018000"],["62644.72000000","0.06428000"],["62644.05000000","0.00008000"],["62644.00000000","0.01118000"]],"asks":[["62649.29000000","3.43310000"],["62649.30000000","0.31250000"],["62649.31000000","0.00016000"],["62649.60000000","0.00008000"],["62649.75000000","0.00018000"],["62649.76000000","0.07981000"],["62649.99000000","0.00018000"],["62650.00000000","1.16972000"],["62650.01000000","0.20775000"],["62650.34000000","0.00018000"],["62650.35000000","0.00008000"],["62650.49000000","0.01274000"],["62650.61000000","0.04018000"],["62650.85000000","0.00400000"],["62650.96000000","0.00009000"],["62651.66000000","0.03018000"],["62651.85000000","0.02000000"],["62652.00000000","0.00600000"],["62652.12000000","0.00009000"],["62652.13000000","1.91755000"]]}}
{"t":33.2641,"stream":"btcusdt@depth@100ms","data":{"e":"depthUpdate","E":1783948035914,"s":"BTCUSDT","U":97344807139,"u":97344807177,"b":[["62649.28000000","0.84059000"],["62648.66000000","0.00000000"],["62646.00000000","0.01118000"],["62645.98000000","0.13983000"],["62645.62000000","0.02018000"],["62644.88000000","0.13983000"],["62643.01000000","0.22828000"],["62642.69000000","0.02395000"],["62642.68000000","0.13965000"],["62641.20000000","0.13973000"],["62638.75000000","0.00000000"],["62635.26000000","0.00008000"],["56384.36000000","0.00320000"]],"a":[["62650.01000000","0.20775000"],["62650.34000000","0.00000000"],["62651.66000000","0.03018000"],["62651.85000000","0.02018000"],["62660.33000000","0.00008000"],["62663.82000000","0.00000000"],["63535.19000000","0.25753000"]]}}
{"t":33.2643,"stream":"btcusdt@depth20@100ms","data":{"lastUpdateId":97344807177,"bids":[["62649.28000000","0.84059000"],["62649.27000000","0.00081000"],["62648.00000000","0.00618000"],["62647.84000000","0.00009000"],["62646.40000000","0.00008000"],["62646.00000000","0.01118000"],["62645.99000000","0.00018000"],["62645.98000000","0.13983000"],["62645.63000000","0.00018000"],["62645.62000000","0.02018000"],["62645.48000000","0.00009000"],["62645.27000000","0.00256000"],["62645.10000000","0.00032000"],["62644.89000000","0.00027000"],["62644.88000000","0.13983000"],["62644.73000000","0.00018000"],["62644.72000000","0.06428000"],["62644.05000000","0.00008000"],["62644.00000000","0.01118000"],["62643.79000000","0.00018000"]],"asks":[["62649.29000000","3.43310000"],["62649.30000000","0.31250000"],["62649.31000000","0.00016000"],["62649.60000000","0.00008000"],["62649.75000000","0.00018000"],["62649.76000000","0.07981000"],["62649.99000000","0.00018000"],["62650.00000000","1.16972000"],["62650.01000000","0.20775000"],["62650.35000000","0.00008000"],["62650.49000000","0.01274000"],["62650.61000000","0.04018000"],["62650.85000000","0.00400000"],["62650.96000000","0.00009000"],["62651.66000000","0.03018000"],["62651.85000000","0.02018000"],["62652.00000000","0.00600000"],["62652.12000000","0.00009000"],["62652.13000000","1.91755000"],["62652.14000000","0.17508000"]]}}
{"t":33.3636,"stream":"btcusdt@depth@100ms","data":{"e":"depthUpdate","E":1783948036014,"s":"BTCUSDT","U":97344807178,"u":97344807195,"b":[["62649.28000000","0.84067000"],["62646.15000000","0.00018000"],["62646.14000000","0.17253000"],["62645.27000000","0.00000000"],["62643.79000000","0.00000000"],["62643.78000000","0.13983000"],["62643.73000000","0.00000000"],["62635.80000000","0.00556000"],["62634.01000000","0.33360000"],["62614.21000000","1.20740000"],["62576.63000000","2.41624000"],["56384.36000000","0.00360000"],["50119.43000000","0.00039000"]],"a":[["62850.44000000","0.00000000"]]}}
{"t":33.3652,"stream":"btcusdt@depth20@100ms","data":{"lastUpdateId":97344807195,"bids":[["62649.28000000","0.84067000"],["62649.27000000","0.00081000"],["62648.00000000","0.00618000"],["62647.84000000","0.00009000"],["62646.40000000","0.00008000"],["62646.15000000","0.00018000"],["62646.14000000","0.17253000"],["62646.00000000","0.01118000"],["62645.99000000","0.00018000"],["62645.98000000","0.13983000"],["62645.63000000","0.00018000"],["62645.62000000","0.02018000"],["62645.48000000","0.00009000"],["62645.10000000","0.00032000"],["62644.89000000","0.00027000"],["62644.88000000","0.13983000"],["62644.73000000","0.00018000"],["62644.72000000","0.06428000"],["62644.05000000","0.00008000"],["62644.00000000","0.01118000"]],"asks":[["62649.29000000","3.43310000"],["62649.30000000","0.31250000"],["62649.31000000","0.00016000"],["62649.60000000","0.00008000"],["62649.75000000","0.00018000"],["62649.76000000","0.07981000"],["62649.99000000","0.00018000"],["62650.00000000","1.16972000"],["62650.01000000","0.20775000"],["62650.35000000","0.00008000"],["62650.49000000","0.01274000"],["62650.61000000","0.04018000"],["62650.85000000","0.00400000"],["62650.96000000","0.00009000"],["62651.66000000","0.03018000"],["62651.85000000","0.02018000"],["62652.00000000","0.00600000"],["62652.12000000","0.00009000"],["62652.13000000","1.91755000"],["62652.14000000","0.17508000"]]}}
{"t":33.4645,"stream":"btcusdt@depth@100ms","data":{"e":"depthUpdate","E":1783948036114,"s":"BTCUSDT","U":97344807196,"u":97344807220,"b":[["62649.28000000","0.84088000"],["62649.27000000","0.00099000"],["62648.00000000","0.00618000"],["62646.14000000","0.17271000"],["62643.78000000","0.13965000"],["62638.28000000","0.00000000"],["62612.87000000","0.20197000"],["56384.36000000","0.00400000"],["40000.00000000","258.07540000"]],"a":[["62649.29000000","3.43410000"],["62694.85000000","0.02096000"],["62747.36000000","0.00000000"],["62761.31000000","0.03062000"],["62882.02000000","0.00266000"]]}}
{"t":33.4646,"stream":"btcusdt@depth20@100ms","data":{"lastUpdateId":97344807220,"bids":[["62649.28000000","0.84088000"],["62649.27000000","0.00099000"],["62648.00000000","0.00618000"],["62647.84000000","0.00009000"],["62646.40000000","0.00008000"],["62646.15000000","0.00018000"],["62646.14000000","0.17271000"],["62646.00000000","0.01118000"],["62645.99000000","0.00018000"],["62645.98000000","0.13983000"],["62645.63000000","0.00018000"],["62645.62000000","0.02018000"],["62645.48000000","0.00009000"],["62645.10000000","0.00032000"],["62644.89000000","0.00027000"],["62644.88000000","0.13983000"],["62644.73000000","0.00018000"],["62644.72000000","0.06428000"],["62644.05000000","0.00008000"],["62644.00000000","0.01118000"]],"asks":[["62649.29000000","3.43410000"],["62649.30000000","0.31250000"],["62649.31000000","0.00016000"],["62649.60000000","0.00008000"],["62649.75000000","0.00018000"],["62649.76000000","0.07981000"],["62649.99000000","0.00018000"],["62650.00000000","1.16972000"],["62650.01000000","0.20775000"],["62650.35000000","0.00008000"],["62650.49000000","0.01274000"],["62650.61000000","0.04018000"],["62650.85000000","0.00400000"],["62650.96000000","0.00009000"],["62651.66000000","0.03018000"],["62651.85000000","0.02018000"],["62652.00000000","0.00600000"],["62652.12000000","0.00009000"],["62652.13000000","1.91755000"],["62652.14000000","0.17508000"]]}}
{"t":33.564,"stream":"btcusdt@depth@100ms","data":{"e":"depthUpdate","E":1783948036214,"s":"BTCUSDT","U":97344807221,"u":97344807245,"b":[["62649.28000000","0.84080000"],["62648.66000000","0.00008000"],["62648.01000000","0.00018000"],["62648.00000000","0.01618000"],["62646.00000000","0.01618000"],["62645.63000000","0.00000000"],["62644.00000000","0.01618000"],["62642.00000000","0.02400000"],["61709.54000000","0.00030000"],["56384.36000000","0.00440000"],["50119.43000000","0.00000000"],["50119.42000000","0.00000000"]],"a":[["62649.29000000","3.53401000"],["62652.14000000","0.07508000"],["62680.77000000","0.00000000"],["62716.15000000","0.00919000"],["77808.30000000","0.00000000"]]}}
{"t":33.564,"stream":"btcusdt@depth20@100ms","data":{"lastUpdateId":97344807245,"bids":[["62649.28000000","0.84080000"],["62649.27000000","0.00099000"],["62648.66000000","0.00008000"],["62648.01000000","0.00018000"],["62648.00000000","0.01618000"],["62647.84000000","0.00009000"],["62646.40000000","0.00008000"],["62646.15000000","0.00018000"],["62646.14000000","0.17271000"],["62646.00000000","0.01618000"],["62645.99000000","0.00018000"],["62645.98000000","0.13983000"],["62645.62000000","0.02018000"],["62645.48000000","0.00009000"],["62645.10000000","0.00032000"],["62644.89000000","0.00027000"],["62644.88000000","0.13983000"],["62644.73000000","0.00018000"],["62644.72000000","0.06428000"],["62644.05000000","0.00008000"]],"asks":[["62649.29000000","3.53401000"],["62649.30000000","0.31250000"],["62649.31000000","0.00016000"],["62649.60000000","0.00008000"],["62649.75000000","0.00018000"],["62649.76000000","0.07981000"],["62649.99000000","0.00018000"],["62650.00000000","1.16972000"],["62650.01000000","0.20775000"],["62650.35000000","0.00008000"],["62650.49000000","0.01274000"],["62650.61000000","0.04018000"],["62650.85000000","0.00400000"],["62650.96000000","0.00009000"],["62651.66000000","0.03018000"],["62651.85000000","0.02018000"],["62652.00000000","0.00600000"],["62652.12000000","0.00009000"],["62652.13000000","1.91755000"],["62652.14000000","0.07508000"]]}}
{"t":33.6637,"stream":"btcusdt@depth@100ms","data":{"e":"depthUpdate","E":1783948036314,"s":"BTCUSDT","U":97344807246,"u":97344807254,"b":[["62649.28000000","0.84096000"],["62649.27000000","0.00115000"],["62649.26000000","0.00016000"],["62636.98000000","0.02500000"],["56384.36000000","0.00460000"]],"a":[["62649.29000000","3.53410000"],["62652.12000000","0.00000000"],["63589.03000000","0.00030000"]]}}
{"t":33.6639,"stream":"btcusdt@depth20@100ms","data":{"lastUpdateId":97344807254,"bids":[["62649.28000000","0.84096000"],["62649.27000000","0.00115000"],["62649.26000000","0.00016000"],["62648.66000000","0.00008000"],["62648.01000000","0.00018000"],["62648.00000000","0.01618000"],["62647.84000000","0.00009000"],["62646.40000000","0.00008000"],["62646.15000000","0.00018000"],["62646.14000000","0.17271000"],["62646.00000000","0.01618000"],["62645.99000000","0.00018000"],["62645.98000000","0.13983000"],["62645.62000000","0.02018000"],["62645.48000000","0.00009000"],["62645.10000000","0.00032000"],["62644.89000000","0.00027000"],["62644.88000000","0.13983000"],["62644.73000000","0.00018000"],["62644.72000000","0.06428000"]],"asks":[["62649.29000000","3.53410000"],["62649.30000000","0.31250000"],["62649.31000000","0.00016000"],["62649.60000000","0.00008000"],["62649.75000000","0.00018000"],["62649.76000000","0.07981000"],["62649.99000000","0.00018000"],["62650.00000000","1.16972000"],["62650.01000000","0.20775000"],["62650.35000000","0.00008000"],["62650.49000000","0.01274000"],["62650.61000000","0.04018000"],["62650.85000000","0.00400000"],["62650.96000000","0.00009000"],["62651.66000000","0.03018000"],["62651.85000000","0.02018000"],["62652.00000000","0.00600000"],["62652.13000000","1.91755000"],["62652.14000000","0.07508000"],["62652.15000000","0.43208000"]]}}
{"t":33.7571,"stream":"btcusdt@aggTrade","data":{"e":"aggTrade","E":1783948036407,"s":"BTCUSDT","a":4013160730,"p":"62649.28000000","q":"0.00052000","f":6501834558,"l":6501834558,"T":1783948036406,"m":true,"M":true}}
{"t":33.7628,"stream":"btcusdt@depth@100ms","data":{"e":"depthUpdate","E":1783948036414,"s":"BTCUSDT","U":97344807255,"u":97344807261,"b":[["62649.28000000","0.84044000"],["62645.98000000","0.00018000"],["56387.48000000","0.00000000"],["56384.36000000","0.00460000"]],"a":[]}}
{"t":33.7634,"stream":"btcusdt@depth20@100ms","data":{"lastUpdateId":97344807261,"bids":[["62649.28000000","0.84044000"],["62649.27000000","0.00115000"],["62649.26000000","0.00016000"],["62648.66000000","0.00008000"],["62648.01000000","0.00018000"],["62648.00000000","0.01618000"],["62647.84000000","0.00009000"],["62646.40000000","0.00008000"],["62646.15000000","0.00018000"],["62646.14000000","0.17271000"],["62646.00000000","0.01618000"],["62645.99000000","0.00018000"],["62645.98000000","0.00018000"],["62645.62000000","0.02018000"],["62645.48000000","0.00009000"],["62645.10000000","0.00032000"],["62644.89000000","0.00027000"],["62644.88000000","0.13983000"],["62644.73000000","0.00018000"],["62644.72000000","0.06428000"]],"asks":[["62649.29000000","3.53410000"],["62649.30000000","0.31250000"],["62649.31000000","0.00016000"],["62649.60000000","0.00008000"],["62649.75000000","0.00018000"],["62649.76000000","0.07981000"],["62649.99000000","0.00018000"],["62650.00000000","1.16972000"],["62650.01000000","0.20775000"],["62650.35000000","0.00008000"],["62650.49000000","0.01274000"],["62650.61000000","0.04018000"],["62650.85000000","0.00400000"],["62650.96000000","0.00009000"],["62651.66000000","0.03018000"],["62651.85000000","0.02018000"],["62652.00000000","0.00600000"],["62652.13000000","1.91755000"],["62652.14000000","0.07508000"],["62652.15000000","0.43208000"]]}}
{"t":33.8649,"stream":"btcusdt@depth@100ms","data":{"e":"depthUpdate","E":1783948036514,"s":"BTCUSDT","U":97344807262,"u":97344807278,"b":[["62649.28000000","0.84036000"],["62646.00000000","0.01618000"],["62645.99000000","0.00000000"],["62645.98000000","0.00000000"],["62645.63000000","0.00018000"],["62643.78000000","0.13983000"],["56384.36000000","0.00460000"]],"a":[]}}
{"t":33.865,"stream":"btcusdt@depth20@100ms","data":{"lastUpdateId":97344807278,"bids":[["62649.28000000","0.84036000"],["62649.27000000","0.00115000"],["62649.26000000","0.00016000"],["62648.66000000","0.00008000"],["62648.01000000","0.00018000"],["62648.00000000","0.01618000"],["62647.84000000","0.00009000"],["62646.40000000","0.00008000"],["62646.15000000","0.00018000"],["62646.14000000","0.17271000"],["62646.00000000","0.01618000"],["62645.63000000","0.00018000"],["62645.62000000","0.02018000"],["62645.48000000","0.00009000"],["62645.10000000","0.00032000"],["62644.89000000","0.00027000"],["62644.88000000","0.13983000"],["62644.73000000","0.00018000"],["62644.72000000","0.06428000"],["62644.05000000","0.00008000"]],"asks":[["62649.29000000","3.53410000"],["62649.30000000","0.31250000"],["62649.31000000","0.00016000"],["62649.60000000","0.00008000"],["62649.75000000","0.00018000"],["62649.76000000","0.07981000"],["62649.99000000","0.00018000"],["62650.00000000","1.16972000"],["62650.01000000","0.20775000"],["62650.35000000","0.00008000"],["62650.49000000","0.01274000"],["62650.61000000","0.04018000"],["62650.85000000","0.00400000"],["62650.96000000","0.00009000"],["62651.66000000","0.03018000"],["62651.85000000","0.02018000"],["62652.00000000","0.00600000"],["62652.13000000","1.91755000"],["62652.14000000","0.07508000"],["62652.15000000","0.43208000"]]}}
{"t":33.9644,"stream":"btcusdt@depth@100ms","data":{"e":"depthUpdate","E":1783948036614,"s":"BTCUSDT","U":97344807279,"u":97344807286,"b":[["62649.28000000","0.84027000"],["62649.27000000","0.00106000"],["56384.36000000","0.00460000"]],"a":[["62657.20000000","0.57502000"],["62672.70000000","0.00000000"]]}}
{"t":33.9645,"stream":"btcusdt@depth20@100ms","data":{"lastUpdateId":97344807286,"bids":[["62649.28000000","0.84027000"],["62649.27000000","0.00106000"],["62649.26000000","0.00016000"],["62648.66000000","0.00008000"],["62648.01000000","0.00018000"],["62648.00000000","0.01618000"],["62647.84000000","0.00009000"],["62646.40000000","0.00008000"],["62646.15000000","0.00018000"],["62646.14000000","0.17271000"],["62646.00000000","0.01618000"],["62645.63000000","0.00018000"],["62645.62000000","0.02018000"],["62645.48000000","0.00009000"],["62645.10000000","0.00032000"],["62644.89000000","0.00027000"],["62644.88000000","0.13983000"],["62644.73000000","0.00018000"],["62644.72000000","0.06428000"],["62644.05000000","0.00008000"]],"asks":[["62649.29000000","3.53410000"],["62649.30000000","0.31250000"],["62649.31000000","0.00016000"],["62649.60000000","0.00008000"],["62649.75000000","0.00018000"],["62649.76000000","0.07981000"],["62649.99000000","0.00018000"],["62650.00000000","1.16972000"],["62650.01000000","0.20775000"],["62650.35000000","0.00008000"],["62650.49000000","0.01274000"],["62650.61000000","0.04018000"],["62650.85000000","0.00400000"],["62650.96000000","0.00009000"],["62651.66000000","0.03018000"],["62651.85000000","0.02018000"],["62652.00000000","0.00600000"],["62652.13000000","1.91755000"],["62652.14000000","0.07508000"],["62652.15000000","0.43208000"]]}}
{"t":34.0641,"stream":"btcusdt@depth@100ms","data":{"e":"depthUpdate","E":1783948036714,"s":"BTCUSDT","U":97344807287,"u":97344807292,"b":[["56384.36000000","0.00460000"]],"a":[["62649.29000000","3.55154000"],["62668.40000000","0.00038000"]]}}
{"t":34.0642,"stream":"btcusdt@depth20@100ms","data":{"lastUpdateId":97344807292,"bids":[["62649.28000000","0.84027000"],["62649.27000000","0.00106000"],["62649.26000000","0.00016000"],["62648.66000000","0.00008000"],["62648.01000000","0.00018000"],["62648.00000000","0.01618000"],["62647.84000000","0.00009000"],["62646.40000000","0.00008000"],["62646.15000000","0.00018000"],["62646.14000000","0.17271000"],["62646.00000000","0.01618000"],["62645.63000000","0.00018000"],["62645.62000000","0.02018000"],["62645.48000000","0.00009000"],["62645.10000000","0.00032000"],["62644.89000000","0.00027000"],["62644.88000000","0.13983000"],["62644.73000000","0.00018000"],["62644.72000000","0.06428000"],["62644.05000000","0.00008000"]],"asks":[["62649.29000000","3.55154000"],["62649.30000000","0.31250000"],["62649.31000000","0.00016000"],["62649.60000000","0.00008000"],["62649.75000000","0.00018000"],["62649.76000000","0.07981000"],["62649.99000000","0.00018000"],["62650.00000000","1.16972000"],["62650.01000000","0.20775000"],["62650.35000000","0.00008000"],["62650.49000000","0.01274000"],["62650.61000000","0.04018000"],["62650.85000000","0.00400000"],["62650.96000000","0.00009000"],["62651.66000000","0.03018000"],["62651.85000000","0.02018000"],["62652.00000000","0.00600000"],["62652.13000000","1.91755000"],["62652.14000000","0.07508000"],["62652.15000000","0.43208000"]]}}
{"t":34.0706,"stream":"btcusdt@aggTrade","data":{"e":"aggTrade","E":1783948036721,"s":"BTCUSDT","a":4013160731,"p":"62649.29000000","q":"0.03194000","f":6501834559,"l":6501834559,"T":1783948036721,"m":false,"M":true}}
{"t":34.1636,"stream":"btcusdt@depth@100ms","data":{"e":"depthUpdate","E":1783948036814,"s":"BTCUSDT","U":97344807293,"u":97344807302,"b":[["56384.36000000","0.00657000"],["56384.35000000","0.00078000"],["56384.00000000","0.00000000"]],"a":[["62649.29000000","3.51960000"],["62668.40000000","0.00000000"]]}}
{"t":34.1638,"stream":"btcusdt@depth20@100ms","data":{"lastUpdateId":97344807302,"bids":[["62649.28000000","0.84027000"],["62649.27000000","0.00106000"],["62649.26000000","0.00016000"],["62648.66000000","0.00008000"],["62648.01000000","0.00018000"],["62648.00000000","0.01618000"],["62647.84000000","0.00009000"],["62646.40000000","0.00008000"],["62646.15000000","0.00018000"],["62646.14000000","0.17271000"],["62646.00000000","0.01618000"],["62645.63000000","0.00018000"],["62645.62000000","0.02018000"],["62645.48000000","0.00009000"],["62645.10000000","0.00032000"],["62644.89000000","0.00027000"],["62644.88000000","0.13983000"],["62644.73000000","0.00018000"],["62644.72000000","0.06428000"],["62644.05000000","0.00008000"]],"asks":[["62649.29000000","3.51960000"],["62649.30000000","0.31250000"],["62649.31000000","0.00016000"],["62649.60000000","0.00008000"],["62649.75000000","0.00018000"],["62649.76000000","0.07981000"],["62649.99000000","0.00018000"],["62650.00000000","1.16972000"],["62650.01000000","0.20775000"],["62650.35000000","0.00008000"],["62650.49000000","0.01274000"],["62650.61000000","0.04018000"],["62650.85000000","0.00400000"],["62650.96000000","0.00009000"],["62651.66000000","0.03018000"],["62651.85000000","0.02018000"],["62652.00000000","0.00600000"],["62652.13000000","1.91755000"],["62652.14000000","0.07508000"],["62652.15000000","0.43208000"]]}}
{"t":34.2634,"stream":"btcusdt@depth@100ms","data":{"e":"depthUpdate","E":1783948036914,"s":"BTCUSDT","U":97344807303,"u":97344807309,"b":[["62635.26000000","0.00000000"],["61900.00000000","6.08667000"],["56384.36000000","0.00657000"],["56384.35000000","0.00068000"]],"a":[["62660.33000000","0.00000000"]]}}
{"t":34.2635,"stream":"btcusdt@depth20@100ms","data":{"lastUpdateId":97344807309,"bids":[["62649.28000000","0.84027000"],["62649.27000000","0.00106000"],["62649.26000000","0.00016000"],["62648.66000000","0.00008000"],["62648.01000000","0.00018000"],["62648.00000000","0.01618000"],["62647.84000000","0.00009000"],["62646.40000000","0.00008000"],["62646.15000000","0.00018000"],["62646.14000000","0.17271000"],["62646.00000000","0.01618000"],["62645.63000000","0.00018000"],["62645.62000000","0.02018000"],["62645.48000000","0.00009000"],["62645.10000000","0.00032000"],["62644.89000000","0.00027000"],["62644.88000000","0.13983000"],["62644.73000000","0.00018000"],["62644.72000000","0.06428000"],["62644.05000000","0.00008000"]],"asks":[["62649.29000000","3.51960000"],["62649.30000000","0.31250000"],["62649.31000000","0.00016000"],["62649.60000000","0.00008000"],["62649.75000000","0.00018000"],["62649.76000000","0.07981000"],["62649.99000000","0.00018000"],["62650.00000000","1.16972000"],["62650.01000000","0.20775000"],["62650.35000000","0.00008000"],["62650.49000000","0.01274000"],["62650.61000000","0.04018000"],["62650.85000000","0.00400000"],["62650.96000000","0.00009000"],["62651.66000000","0.03018000"],["62651.85000000","0.02018000"],["62652.00000000","0.00600000"],["62652.13000000","1.91755000"],["62652.14000000","0.07508000"],["62652.15000000","0.43208000"]]}}
{"t":34.365,"stream":"btcusdt@depth@100ms","data":{"e":"depthUpdate","E":1783948037014,"s":"BTCUSDT","U":97344807310,"u":97344807326,"b":[["62649.28000000","0.84018000"],["62649.27000000","0.00097000"],["62646.15000000","0.00000000"],["62646.14000000","0.00018000"],["62646.01000000","0.00018000"],["62635.26000000","0.00008000"],["62627.15000000","0.00000000"],["62620.85000000","0.00942000"],["56384.36000000","0.00657000"],["50119.43000000","0.00039000"]],"a":[["62652.78000000","0.41459000"],["62660.33000000","0.00008000"]]}}
{"t":34.3651,"stream":"btcusdt@depth20@100ms","data":{"lastUpdateId":97344807326,"bids":[["62649.28000000","0.84018000"],["62649.27000000","0.00097000"],["62649.26000000","0.00016000"],["62648.66000000","0.00008000"],["62648.01000000","0.00018000"],["62648.00000000","0.01618000"],["62647.84000000","0.00009000"],["62646.40000000","0.00008000"],["62646.14000000","0.00018000"],["62646.01000000","0.00018000"],["62646.00000000","0.01618000"],["62645.63000000","0.00018000"],["62645.62000000","0.02018000"],["62645.48000000","0.00009000"],["62645.10000000","0.00032000"],["62644.89000000","0.00027000"],["62644.88000000","0.13983000"],["62644.73000000","0.00018000"],["62644.72000000","0.06428000"],["62644.05000000","0.00008000"]],"asks":[["62649.29000000","3.51960000"],["62649.30000000","0.31250000"],["62649.31000000","0.00016000"],["62649.60000000","0.00008000"],["62649.75000000","0.00018000"],["62649.76000000","0.07981000"],["62649.99000000","0.00018000"],["62650.00000000","1.16972000"],["62650.01000000","0.20775000"],["62650.35000000","0.00008000"],["62650.49000000","0.01274000"],["62650.61000000","0.04018000"],["62650.85000000","0.00400000"],["62650.96000000","0.00009000"],["62651.66000000","0.03018000"],["62651.85000000","0.02018000"],["62652.00000000","0.00600000"],["62652.13000000","1.91755000"],["62652.14000000","0.07508000"],["62652.15000000","0.43208000"]]}}
{"t":34.4644,"stream":"btcusdt@depth@100ms","data":{"e":"depthUpdate","E":1783948037114,"s":"BTCUSDT","U":97344807327,"u":97344807347,"b":[["62649.28000000","0.84160000"],["62648.00000000","0.01618000"],["62646.14000000","0.00000000"],["62643.01000000","0.22846000"],["62606.25000000","0.77000000"],["56384.36000000","0.00657000"],["40000.00000000","258.07540000"]],"a":[["62649.29000000","3.52060000"],["62726.97000000","0.00030000"],["62730.46000000","0.00000000"]]}}
{"t":34.4645,"stream":"btcusdt@depth20@100ms","data":{"lastUpdateId":97344807347,"bids":[["62649.28000000","0.84160000"],["62649.27000000","0.00097000"],["62649.26000000","0.00016000"],["62648.66000000","0.00008000"],["62648.01000000","0.00018000"],["62648.00000000","0.01618000"],["62647.84000000","0.00009000"],["62646.40000000","0.00008000"],["62646.01000000","0.00018000"],["62646.00000000","0.01618000"],["62645.63000000","0.00018000"],["62645.62000000","0.02018000"],["62645.48000000","0.00009000"],["62645.10000000","0.00032000"],["62644.89000000","0.00027000"],["62644.88000000","0.13983000"],["62644.73000000","0.00018000"],["62644.72000000","0.06428000"],["62644.05000000","0.00008000"],["62644.00000000","0.01618000"]],"asks":[["62649.29000000","3.52060000"],["62649.30000000","0.31250000"],["62649.31000000","0.00016000"],["62649.60000000","0.00008000"],["62649.75000000","0.00018000"],["62649.76000000","0.07981000"],["62649.99000000","0.00018000"],["62650.00000000","1.16972000"],["62650.01000000","0.20775000"],["62650.35000000","0.00008000"],["62650.49000000","0.01274000"],["62650.61000000","0.04018000"],["62650.85000000","0.00400000"],["62650.96000000","0.00009000"],["62651.66000000","0.03018000"],["62651.85000000","0.02018000"],["62652.00000000","0.00600000"],["62652.13000000","1.91755000"],["62652.14000000","0.07508000"],["62652.15000000","0.43208000"]]}}
{"t":34.5639,"stream":"btcusdt@depth@100ms","data":{"e":"depthUpdate","E":1783948037214,"s":"BTCUSDT","U":97344807348,"u":97344807356,"b":[["61709.54000000","0.00030000"],["56384.36000000","0.00657000"],["50119.43000000","0.00000000"],["50119.42000000","0.00000000"]],"a":[]}}
